[META]
version=2.0
spawnOnBlockType=2
spawnSunlight=True
spawnDarkness=True
spawnWater=False
spawnLava=False
underFill=False
randomRotation=True
dig=True
tree=False
branch=False
needsFoundation=True
rarity=100
collisionPercentage=20
spawnElevationMin=0
spawnElevationMax=200
spawnInBiome=Custom
[DATA]
-3,-3,0:17.13
4,-3,0:17.13
3,-2,0:17.13
-3,0,0:17.13
-3,1,0:17.13
1,2,0:17.13
1,3,0:17.13
2,4,0:17.13
-2,-2,1:17.13
-1,-1,1:17.13
1,-1,1:17.13
2,-1,1:17.13
-2,0,1:17.13
-1,0,1:17.13
0,0,1:17.13
0,1,1:17.13
0,2,1:17.13
-1,-1,2:17.13
0,-1,2:17.13
1,-1,2:191.0
-1,0,2:17.13
0,0,2:17.13
-2,-1,3:18.7
-1,-1,3:17.13
0,-1,3:17.13
-1,0,3:17.13
0,0,3:17.13
0,-4,4:18.7
0,-3,4:18.7
-1,-2,4:18.7
1,-2,4:18.7
-1,-1,4:191.0
0,-1,4:17.13
-2,0,4:191.0
-1,0,4:17.13
0,0,4:17.13
1,0,4:191.0
-1,3,4:18.7
0,-5,5:18.7
1,-5,5:18.7
2,-4,5:18.7
1,-2,5:17.13
2,-2,5:18.7
2,-1,5:18.7
-2,0,5:17.13
1,0,5:17.13
-2,2,5:18.15
-1,2,5:18.7
0,-5,6:18.7
2,-4,6:18.7
1,-3,6:191.0
1,-2,6:17.13
-2,-1,6:17.13
-2,0,6:18.7
1,0,6:18.7
-4,1,6:18.7
-2,1,6:17.13
1,1,6:17.13
2,1,6:191.0
-2,2,6:191.0
-1,2,6:18.7
-2,3,6:18.7
0,4,6:18.7
1,-6,7:18.7
-4,-4,7:18.7
-4,-3,7:18.7
1,-3,7:18.7
-2,-2,7:18.7
1,-2,7:17.13
2,-2,7:18.7
-3,-1,7:17.13
-2,-1,7:191.0
-2,0,7:18.7
-4,1,7:18.7
-2,1,7:17.13
1,1,7:17.13
-4,2,7:18.7
1,2,7:191.0
-2,3,7:18.7
-2,4,7:18.7
-1,4,7:18.7
2,-6,8:18.7
-4,-5,8:18.7
1,-4,8:18.7
2,-4,8:18.7
3,-4,8:18.7
1,-3,8:18.7
2,-3,8:17.13
3,-3,8:18.7
-4,-2,8:18.7
-3,-2,8:17.13
-2,-2,8:18.7
-1,-2,8:18.7
0,-2,8:18.7
1,-2,8:18.7
-3,-1,8:18.7
-1,-1,8:18.7
0,0,8:18.7
-5,1,8:18.7
-3,1,8:17.13
2,1,8:17.13
-3,2,8:18.7
-2,2,8:18.7
1,2,8:18.7
2,2,8:18.7
3,2,8:18.7
-4,3,8:18.7
1,3,8:18.7
-3,-5,9:18.7
-2,-5,9:18.7
1,-5,9:18.7
-4,-4,9:18.7
-3,-4,9:18.7
-2,-4,9:18.7
-1,-4,9:18.7
0,-4,9:18.7
1,-4,9:18.7
2,-4,9:18.7
-5,-3,9:18.7
-3,-3,9:17.13
1,-3,9:18.7
2,-3,9:17.13
-5,-2,9:18.7
-3,-2,9:18.7
4,-2,9:18.7
-5,-1,9:18.7
-4,0,9:18.7
-3,0,9:18.7
3,0,9:18.7
-4,1,9:18.7
-3,1,9:17.13
2,1,9:17.13
3,1,9:18.7
-4,2,9:18.7
-3,2,9:18.7
-1,2,9:18.7
-6,3,9:18.7
-2,3,9:18.7
3,4,9:18.7
-6,-5,10:18.7
-3,-5,10:18.7
-2,-5,10:18.7
1,-5,10:18.7
-6,-4,10:18.7
-4,-4,10:18.7
-3,-4,10:18.7
2,-4,10:191.0
3,-4,10:18.7
-5,-3,10:18.7
-4,-3,10:17.13
-3,-3,10:18.7
-2,-3,10:18.7
1,-3,10:18.7
2,-3,10:17.13
3,-3,10:18.7
-5,-2,10:18.7
-4,-2,10:18.7
-3,-2,10:18.7
-2,-2,10:18.7
-1,-2,10:18.7
0,-2,10:18.7
1,-2,10:18.7
4,-2,10:18.7
-6,-1,10:18.7
-6,0,10:18.7
-3,0,10:18.7
0,0,10:18.7
3,0,10:18.7
-4,1,10:17.13
-6,2,10:18.7
-4,2,10:18.7
-3,2,10:18.7
-2,2,10:18.7
0,2,10:18.7
2,2,10:17.13
3,2,10:18.7
4,2,10:18.7
-5,3,10:18.7
-4,3,10:18.7
-3,3,10:18.7
-2,3,10:18.7
0,3,10:18.7
1,4,10:18.7
3,4,10:18.7
-4,-6,11:18.7
-3,-6,11:18.7
2,-5,11:18.7
3,-5,11:18.7
-4,-4,11:17.13
0,-4,11:18.7
1,-4,11:18.7
3,-4,11:18.7
4,-4,11:18.7
-3,-3,11:18.7
0,-3,11:18.7
2,-3,11:18.7
3,-3,11:17.13
-4,-2,11:18.7
-2,-2,11:18.7
0,-2,11:18.7
-5,-1,11:18.7
-3,-1,11:18.7
1,-1,11:18.7
2,-1,11:18.7
-6,0,11:18.7
-3,0,11:18.7
-4,1,11:17.13
-2,1,11:18.7
1,1,11:18.7
3,1,11:18.7
4,1,11:18.7
-5,2,11:18.7
-3,2,11:18.7
-2,2,11:18.7
2,2,11:18.7
3,2,11:17.13
4,2,11:18.7
-5,3,11:18.7
-3,3,11:18.7
0,3,11:18.7
1,3,11:18.7
5,3,11:18.7
1,4,11:18.7
2,4,11:18.7
3,4,11:18.7
-4,-6,12:18.7
-6,-5,12:18.7
-4,-5,12:18.7
-2,-5,12:18.7
1,-4,12:18.7
3,-4,12:18.7
1,-3,12:18.7
3,-3,12:18.7
1,-2,12:18.7
3,-2,12:18.7
-3,-1,12:18.7
-4,0,12:18.7
-5,1,12:17.13
-4,1,12:18.7
-3,1,12:18.7
2,1,12:18.7
3,1,12:18.7
-5,2,12:18.7
-4,2,12:18.7
1,2,12:18.7
-4,3,12:18.7
-3,3,12:18.7
1,3,12:18.7
3,3,12:17.13
3,4,12:18.7
4,4,12:18.7
-3,-5,13:18.7
-3,-4,13:18.7
-3,-3,13:18.7
4,1,13:18.7
-3,2,13:18.7
3,2,13:18.7
4,2,13:18.7
1,3,13:18.7
2,3,13:18.7
3,3,13:17.13
5,3,13:18.7
3,4,13:18.7
2,5,13:18.7
4,5,13:18.7
4,2,14:18.7
3,3,14:18.7
2,4,14:18.7
