[META]
version=2.0
spawnOnBlockType=2
spawnSunlight=True
spawnDarkness=True
spawnWater=False
spawnLava=False
underFill=False
randomRotation=True
dig=True
tree=False
branch=False
needsFoundation=True
rarity=100
collisionPercentage=20
spawnElevationMin=0
spawnElevationMax=200
spawnInBiome=Custom
[DATA]
1,-2,0:17.14
-3,1,0:17.14
2,1,0:17.14
0,4,0:17.14
0,-1,1:17.14
-3,1,1:17.14
0,1,1:17.14
1,1,1:17.14
0,4,1:17.14
-1,0,2:17.14
-1,1,2:17.14
-2,2,2:17.14
-1,2,2:17.14
-1,3,2:17.14
-1,2,3:17.14
-1,2,4:17.14
-2,2,5:189.0
-1,2,5:17.14
-1,1,6:189.0
-1,2,6:17.14
-1,3,6:189.0
-3,1,7:18.6
-2,1,7:18.6
-1,2,7:17.14
0,2,7:18.6
-1,3,7:18.6
-2,-1,8:18.6
-1,-1,8:18.6
-2,1,8:18.6
-1,1,8:17.14
0,1,8:189.0
-4,2,8:18.6
-3,2,8:17.14
-2,2,8:17.14
-1,3,8:18.6
-1,4,8:18.6
1,-2,9:18.6
-1,-1,9:18.6
-4,0,9:18.6
1,0,9:18.6
-3,1,9:18.6
0,1,9:17.14
-1,2,9:18.6
1,2,9:18.6
-3,3,9:18.6
-2,3,9:17.14
-3,-2,10:18.6
1,-2,10:18.6
-1,-1,10:18.6
0,-1,10:18.6
2,-1,10:18.6
-1,0,10:18.6
1,0,10:18.6
-4,1,10:18.6
-2,1,10:18.6
-1,1,10:189.0
0,1,10:17.14
2,1,10:18.6
-3,2,10:189.0
-2,2,10:17.14
1,2,10:18.6
-2,3,10:17.14
0,3,10:18.6
-2,4,10:189.0
0,-4,11:18.6
-3,-3,11:18.6
-2,-3,11:18.6
-2,-1,11:18.6
0,-1,11:18.6
1,-1,11:18.6
-3,0,11:18.6
-1,0,11:17.14
0,0,11:17.14
1,0,11:18.6
-2,1,11:18.6
2,1,11:18.6
-2,3,11:17.14
0,3,11:18.6
-3,5,11:18.6
-1,5,11:18.6
2,-3,12:18.6
-2,-2,12:18.6
1,-2,12:18.6
2,-2,12:18.6
-5,-1,12:18.6
-3,-1,12:18.6
0,-1,12:18.6
-5,0,12:18.6
-1,0,12:189.0
0,0,12:17.14
1,0,12:189.0
3,0,12:18.6
-4,1,12:18.6
-3,1,12:18.6
1,1,12:18.6
-4,2,12:18.6
-2,2,12:18.6
-1,2,12:18.6
1,2,12:18.6
-3,3,12:18.6
-2,3,12:17.14
-1,3,12:189.0
-5,4,12:18.6
0,4,12:18.6
-5,5,12:18.6
-3,5,12:18.6
-4,6,12:18.6
-1,-3,13:18.6
0,-3,13:18.6
-4,-2,13:18.6
1,-2,13:18.6
-3,-1,13:18.6
-2,-1,13:18.6
-2,0,13:18.6
1,0,13:17.14
2,0,13:18.6
-4,1,13:18.6
-2,1,13:18.6
0,1,13:18.6
1,1,13:17.14
2,1,13:18.6
-2,2,13:18.6
0,2,13:18.6
-4,3,13:17.14
-3,3,13:17.14
-1,3,13:18.6
-5,4,13:18.6
-3,4,13:18.6
-2,4,13:18.6
-5,5,13:18.6
-3,5,13:18.6
1,5,13:18.6
-4,6,13:18.6
-1,-4,14:18.6
-2,-3,14:18.6
-4,-1,14:18.6
0,-1,14:18.6
1,-1,14:17.14
-4,0,14:18.6
-3,0,14:18.6
2,0,14:18.6
3,0,14:18.6
-2,1,14:18.6
1,1,14:18.6
2,1,14:18.6
-4,2,14:18.6
0,2,14:189.0
1,2,14:17.14
-5,3,14:18.6
-3,3,14:17.14
-2,3,14:18.6
2,3,14:17.14
3,3,14:18.6
-4,4,14:18.6
-3,4,14:189.0
-3,5,14:18.6
-2,5,14:18.6
0,5,14:18.6
-3,-2,15:18.6
-2,-2,15:18.6
-1,-2,15:18.6
-4,-1,15:18.6
1,-1,15:17.14
2,-1,15:18.6
1,0,15:18.6
-4,1,15:18.6
-3,1,15:18.6
-2,1,15:18.6
-1,1,15:18.6
1,2,15:18.6
-4,3,15:18.6
-3,3,15:17.14
-2,3,15:18.6
-1,3,15:18.6
0,3,15:18.6
-2,4,15:18.6
-1,4,15:18.6
2,4,15:17.14
-5,0,16:18.6
-4,0,16:18.6
-3,0,16:18.6
-1,0,16:18.6
0,0,16:18.6
1,0,16:18.6
2,3,16:18.6
-3,4,16:17.14
1,4,16:18.6
-4,5,16:18.6
-2,5,16:18.6
-4,4,17:18.6
