[META]
version=2.0
spawnOnBlockType=2
spawnSunlight=True
spawnDarkness=True
spawnWater=False
spawnLava=False
underFill=False
randomRotation=True
dig=True
tree=False
branch=False
needsFoundation=True
rarity=100
collisionPercentage=20
spawnElevationMin=0
spawnElevationMax=200
spawnInBiome=Custom
[DATA]
-3,-2,0:17.14
1,-2,0:17.14
-2,-1,0:17.14
0,-1,0:17.14
-1,1,0:17.14
-2,2,0:17.14
2,2,0:17.14
-1,0,1:17.14
0,0,1:17.14
1,1,1:17.14
-1,0,2:17.14
0,0,2:17.14
0,0,3:17.14
0,0,4:17.14
0,-1,5:18.6
-1,0,5:17.14
0,0,5:189.0
0,1,5:17.14
1,1,5:18.6
1,-3,6:18.14
1,-2,6:18.6
2,-2,6:18.6
-1,-1,6:18.6
-2,0,6:189.0
-1,0,6:17.14
0,1,6:17.14
1,1,6:17.14
2,1,6:18.6
-1,2,6:18.6
2,2,6:18.6
1,4,6:18.6
0,-3,7:18.14
0,-2,7:18.6
1,-2,7:18.6
2,-2,7:18.6
-1,-1,7:17.14
1,-1,7:18.6
-1,0,7:18.6
1,0,7:18.6
-2,1,7:18.6
-1,1,7:17.14
0,1,7:17.14
-2,2,7:18.6
1,2,7:18.6
1,3,7:18.6
2,3,7:18.6
1,4,7:18.6
-2,-4,8:18.6
0,-4,8:18.14
-3,-3,8:18.6
0,-3,8:18.14
1,-3,8:18.14
-2,-2,8:18.6
-1,-2,8:18.6
0,-2,8:18.6
1,-2,8:18.6
2,-2,8:18.6
-2,-1,8:17.14
0,-1,8:18.6
1,-1,8:18.6
-3,0,8:18.6
-1,0,8:18.6
0,1,8:17.14
1,1,8:189.0
3,1,8:18.6
0,2,8:18.6
1,2,8:18.6
2,3,8:18.6
1,4,8:18.6
-4,-3,9:18.6
1,-3,9:18.6
-3,-2,9:18.6
-2,-2,9:17.14
-4,-1,9:18.6
-3,-1,9:18.6
-2,-1,9:17.14
0,-1,9:18.6
-1,0,9:18.6
2,0,9:18.6
4,0,9:18.6
2,1,9:18.6
4,1,9:18.6
-1,2,9:189.0
0,2,9:17.14
1,2,9:18.6
2,2,9:18.6
4,2,9:18.6
-3,3,9:18.6
3,3,9:18.6
-4,4,9:18.6
-3,4,9:18.6
-2,4,9:18.6
0,4,9:18.6
-2,-4,10:18.6
-3,-3,10:18.6
-3,-2,10:18.6
-2,-2,10:18.6
2,-2,10:18.6
-3,-1,10:189.0
-2,-1,10:17.14
-1,-1,10:189.0
0,-1,10:18.6
-3,0,10:18.6
1,0,10:18.6
0,1,10:18.6
4,1,10:18.6
-1,2,10:17.14
2,2,10:18.6
0,3,10:18.6
1,3,10:18.6
-4,4,10:18.6
-3,4,10:18.6
-2,4,10:18.6
1,4,10:18.6
-1,-5,11:18.6
-3,-4,11:18.6
-1,-4,11:18.6
-2,-3,11:18.6
-1,-3,11:18.6
0,-3,11:18.6
-2,-2,11:18.6
-1,-2,11:17.14
0,-2,11:18.6
-4,-1,11:18.6
-3,-1,11:18.6
-2,-1,11:17.14
-1,-1,11:18.6
1,-1,11:18.6
-1,0,11:18.6
-4,1,11:18.6
-3,1,11:18.6
-1,1,11:18.6
2,1,11:18.6
-2,2,11:17.14
-1,2,11:17.14
-2,3,11:18.6
-1,3,11:17.14
0,3,11:18.6
-2,4,11:18.6
-1,4,11:18.6
-1,5,11:18.6
-3,-5,12:18.6
-1,-5,12:18.6
-4,-3,12:18.6
-3,-3,12:18.6
-1,-3,12:18.6
2,-3,12:18.6
3,-3,12:18.6
-4,-2,12:18.6
-1,-2,12:18.6
0,-2,12:17.14
-3,-1,12:17.14
-2,-1,12:18.6
-1,-1,12:18.6
0,-1,12:18.6
-4,0,12:18.6
-2,0,12:18.6
-1,0,12:18.6
0,0,12:18.6
2,1,12:18.6
-3,2,12:18.6
-1,2,12:17.14
-3,3,12:18.6
-1,4,12:18.6
0,4,12:18.6
-2,5,12:18.6
-1,-5,13:18.6
0,-4,13:18.6
0,-3,13:17.14
-3,-2,13:17.14
-1,-2,13:18.6
1,-2,13:18.6
3,-2,13:18.6
-4,-1,13:18.6
-3,-1,13:18.6
-2,-1,13:18.6
-3,0,13:18.6
-1,0,13:18.6
-3,1,13:18.6
2,1,13:18.6
-1,2,13:18.6
0,2,13:18.6
-3,3,13:18.6
-2,3,13:18.6
-1,3,13:17.14
0,3,13:18.6
-4,4,13:18.6
-3,4,13:18.6
-2,4,13:18.6
-1,4,13:189.0
0,4,13:18.6
-4,5,13:18.6
-2,5,13:18.6
-1,5,13:18.6
-3,-3,14:17.14
0,-3,14:18.6
1,-3,14:18.6
-4,-2,14:18.6
-3,-2,14:17.14
-2,-2,14:18.6
-1,-2,14:18.6
-4,-1,14:18.6
-3,-1,14:189.0
-1,0,14:18.6
0,0,14:18.6
1,0,14:18.6
0,1,14:18.6
1,1,14:18.6
-2,2,14:18.6
-1,2,14:18.6
0,2,14:18.6
-2,3,14:17.14
-1,3,14:17.14
-4,4,14:18.6
-1,4,14:18.6
0,4,14:18.6
-3,5,14:18.6
-2,-5,15:18.6
-5,-2,15:18.6
-4,-2,15:17.14
-3,-2,15:18.6
-2,-2,15:18.6
-3,-1,15:18.6
0,0,15:18.6
-2,1,15:18.6
-1,1,15:18.6
-3,2,15:18.6
-2,2,15:18.6
-1,3,15:17.14
-4,-4,16:18.6
-3,-4,16:18.6
-5,-3,16:18.6
-4,-3,16:18.6
-3,-3,16:18.6
-4,-2,16:17.14
-3,-1,16:18.6
-3,1,16:18.6
-2,2,16:18.6
-3,3,16:18.6
-1,3,16:18.6
0,3,16:18.6
-1,4,16:18.6
-5,-2,17:18.6
-4,-2,17:18.6
-4,-1,17:18.6
-2,1,17:18.6
-3,2,17:18.6
