[META]
version=2.0
spawnOnBlockType=2
spawnSunlight=True
spawnDarkness=True
spawnWater=False
spawnLava=False
underFill=False
randomRotation=True
dig=True
tree=False
branch=False
needsFoundation=True
rarity=100
collisionPercentage=20
spawnElevationMin=0
spawnElevationMax=200
spawnInBiome=Custom
[DATA]
0,-2,0:188.0
-1,-4,1:188.0
1,-4,1:188.0
-1,-3,1:18.12
1,-3,1:18.4
-2,-2,1:18.15
0,-2,1:188.0
1,-2,1:188.0
2,-2,1:18.4
3,-2,1:188.0
-2,-1,1:18.15
-1,-1,1:18.12
0,-1,1:188.0
1,-1,1:18.15
2,-1,1:188.0
-2,0,1:18.15
1,0,1:18.15
-1,1,1:18.15
0,1,1:18.15
-1,-4,2:188.0
0,-4,2:188.0
2,-4,2:188.0
-2,-3,2:188.0
0,-3,2:18.4
2,-3,2:18.7
3,-3,2:188.0
-2,-2,2:188.0
-1,-2,2:18.4
2,-2,2:188.0
3,-2,2:18.4
-3,-1,2:188.0
-1,-1,2:18.4
-3,0,2:18.4
-2,0,2:188.0
-1,0,2:18.4
0,0,2:188.0
1,0,2:188.0
2,0,2:18.7
3,0,2:188.0
-3,1,2:188.0
-2,1,2:18.7
-1,1,2:18.4
3,1,2:18.12
-1,-4,3:18.7
1,-4,3:18.4
-1,-3,3:18.7
0,-3,3:18.7
1,-3,3:18.7
2,-3,3:18.7
3,-3,3:18.7
-3,-2,3:18.15
-2,-2,3:188.0
-1,-2,3:18.7
0,-2,3:18.7
3,-2,3:18.7
-3,-1,3:18.15
-2,-1,3:18.12
-1,-1,3:18.4
2,-1,3:18.4
3,-1,3:18.4
4,-1,3:18.4
2,0,3:18.4
4,0,3:18.12
-3,1,3:18.7
-2,1,3:18.4
0,1,3:188.0
2,1,3:18.4
3,1,3:18.15
2,-4,4:18.4
-2,-3,4:18.15
2,-3,4:18.4
3,-3,4:18.4
-1,-2,4:18.7
1,-2,4:18.4
3,-2,4:18.4
-1,-1,4:18.7
0,-1,4:18.4
1,-1,4:18.4
0,0,4:18.7
1,0,4:18.4
1,1,4:18.7
2,1,4:18.7
-2,-2,5:18.12
-1,-2,5:18.7
-2,-1,5:18.15
1,0,5:18.4
-2,-1,6:38.3
2,1,5:38.3
0,-1,5:38.3
2,-3,5:38.3
0,1,4:38.3
-2,1,4:38.3
4,0,4:38.3
2,-1,4:38.3
-3,-1,4:38.3
-2,-2,4:38.3
1,-3,4:38.3
3,0,3:38.3
1,0,3:38.3
-2,0,3:38.3
-2,-3,3:38.3
2,-4,3:38.3
0,-4,3:38.3
2,-1,2:38.3
0,-1,2:38.3
1,-2,2:38.3
1,-4,2:38.3
