[META]
version=2.0
spawnOnBlockType=2
spawnSunlight=True
spawnDarkness=True
spawnWater=False
spawnLava=False
underFill=False
randomRotation=True
dig=True
tree=False
branch=False
needsFoundation=True
rarity=100
collisionPercentage=20
spawnElevationMin=0
spawnElevationMax=200
spawnInBiome=Custom
[DATA]
-1,-1,0:17.13
-2,0,0:17.13
-2,1,0:17.13
-3,2,0:17.13
-1,2,0:17.13
-2,1,1:17.13
-2,1,2:17.13
-2,-2,3:18.7
-1,-2,3:18.7
-2,0,3:18.7
-1,0,3:18.7
0,0,3:18.7
-4,1,3:18.7
-3,1,3:191.0
-2,1,3:17.13
-1,1,3:18.7
-4,2,3:18.7
-3,2,3:18.7
-2,2,3:18.7
0,2,3:18.7
-3,3,3:18.7
0,3,3:18.7
-3,4,3:18.7
-2,-3,4:18.7
-2,-2,4:18.7
-1,-1,4:18.7
0,-1,4:18.7
-4,0,4:18.7
-2,1,4:17.13
-1,1,4:191.0
-4,2,4:18.7
1,2,4:18.7
-3,3,4:18.7
0,4,4:18.7
-1,5,4:18.7
-2,0,5:18.7
-1,0,5:18.7
0,0,5:18.7
-4,1,5:18.7
-2,1,5:17.13
0,1,5:18.7
-3,2,5:18.7
1,2,5:18.7
-4,3,5:18.7
-3,3,5:18.7
-3,4,5:18.7
-3,-1,6:18.7
-3,0,6:18.7
-2,0,6:191.0
-4,1,6:18.7
-3,1,6:191.0
-2,1,6:17.13
-1,1,6:18.7
-2,2,6:191.0
0,3,6:18.7
-2,4,6:18.7
-3,0,7:18.7
-1,0,7:18.7
-2,1,7:17.13
-1,1,7:18.7
-3,2,7:18.7
-2,2,7:18.7
-1,3,7:18.7
-3,1,8:18.7
-2,1,8:17.13
-1,1,8:18.7
-2,2,8:18.7
-2,0,9:18.7
-2,1,9:17.13
-1,1,9:18.7
-2,2,9:191.0
-2,0,10:18.7
-2,1,10:18.7
-2,1,11:18.7
