[META]
version=2.0
spawnOnBlockType=2
spawnSunlight=True
spawnDarkness=True
spawnWater=False
spawnLava=False
underFill=False
randomRotation=True
dig=True
tree=False
branch=False
needsFoundation=True
rarity=100
collisionPercentage=20
spawnElevationMin=0
spawnElevationMax=200
spawnInBiome=Custom
[DATA]
-4,1,0:17.12
-8,4,0:17.12
-1,6,0:17.12
-4,8,0:17.12
-4,1,1:17.12
-8,4,1:17.12
-2,5,1:17.12
-5,6,1:17.12
-5,7,1:17.12
-4,2,2:17.12
-5,3,2:17.12
-4,3,2:17.12
-7,4,2:17.12
-6,4,2:17.12
-5,4,2:17.12
-4,4,2:17.12
-3,4,2:17.12
-5,5,2:17.12
-5,3,3:17.12
-4,3,3:17.12
-5,4,3:17.12
-4,4,3:17.12
-5,5,3:18.4
-3,5,3:18.4
-9,-6,4:18.12
-8,-5,4:18.4
-7,-5,4:18.4
-8,-4,4:18.4
-7,-4,4:18.4
-10,-3,4:18.4
-11,-2,4:18.4
-9,-2,4:18.12
-11,-1,4:18.4
-10,-1,4:18.4
-11,0,4:18.4
-10,1,4:18.4
-8,2,4:18.4
-5,2,4:18.4
-2,2,4:18.4
-9,3,4:18.12
-6,3,4:18.4
-4,3,4:17.12
-2,3,4:18.4
-11,4,4:18.12
-9,4,4:18.12
-5,4,4:18.4
-4,4,4:17.12
-3,4,4:17.12
-2,4,4:18.4
-5,5,4:18.4
-7,-7,5:18.12
-9,-6,5:18.12
-7,-6,5:18.12
-10,-5,5:18.12
-9,-5,5:18.12
-8,-5,5:18.12
-10,-4,5:18.12
-9,-4,5:18.12
-6,-4,5:18.4
-5,-4,5:18.4
-4,-4,5:18.4
-9,-3,5:18.12
-8,-3,5:18.12
-7,-3,5:18.12
-6,-3,5:18.4
-4,-3,5:18.4
-2,-3,5:18.4
-12,-2,5:18.12
-7,-2,5:18.12
-12,-1,5:18.12
-10,-1,5:18.4
-4,-1,5:18.4
-10,0,5:18.4
-8,0,5:18.4
-5,0,5:17.12
-6,1,5:18.4
-5,1,5:17.12
-4,1,5:18.4
-3,1,5:18.4
-2,1,5:18.4
-8,2,5:18.4
-5,2,5:18.4
-4,2,5:17.12
-4,3,5:17.12
-3,3,5:17.12
-7,4,5:18.12
-5,4,5:18.4
-4,4,5:17.12
-3,4,5:17.12
-2,4,5:18.4
-1,4,5:18.4
-5,5,5:17.12
-4,5,5:18.4
-2,5,5:18.4
-9,6,5:18.4
-8,6,5:18.4
-3,6,5:18.4
-9,7,5:18.4
-2,7,5:18.4
-8,8,5:18.4
-7,8,5:18.4
-6,8,5:18.12
-3,8,5:18.4
1,8,5:18.12
-7,9,5:18.4
-5,9,5:18.12
-4,10,5:18.4
-3,10,5:18.4
-2,10,5:18.4
0,10,5:18.4
-9,-7,6:18.4
-8,-7,6:18.4
-10,-6,6:18.4
-9,-6,6:18.4
-9,-5,6:18.12
-8,-5,6:17.12
-6,-5,6:18.4
-7,-4,6:17.12
-6,-4,6:18.4
-5,-4,6:18.4
-3,-4,6:18.4
-1,-4,6:18.4
-7,-3,6:17.12
-5,-3,6:18.4
-2,-3,6:18.4
-9,-2,6:18.12
-6,-2,6:17.12
-5,-2,6:18.4
-3,-2,6:18.4
0,-2,6:18.12
-9,-1,6:18.12
-6,-1,6:17.12
-2,-1,6:18.4
1,-1,6:18.12
-9,0,6:18.4
0,0,6:18.12
2,0,6:18.12
-8,1,6:18.4
-7,1,6:18.4
-6,1,6:18.4
-4,1,6:18.4
-3,1,6:18.4
-2,1,6:18.4
0,1,6:18.12
-4,2,6:18.4
-1,2,6:18.4
0,2,6:18.4
3,2,6:18.12
-12,3,6:18.12
-9,3,6:18.4
-4,3,6:17.12
-3,3,6:17.12
-2,3,6:18.4
-1,3,6:18.4
-7,4,6:18.4
-4,4,6:17.12
-3,4,6:17.12
-11,5,6:18.4
-10,5,6:18.4
-7,5,6:18.4
-6,5,6:17.12
-2,5,6:17.12
-1,5,6:18.4
-8,6,6:18.4
-7,6,6:17.12
1,6,6:18.12
2,6,6:18.12
3,6,6:18.4
-10,7,6:18.4
-8,7,6:18.4
-5,7,6:18.4
-4,7,6:18.4
-1,7,6:18.12
3,7,6:18.4
-8,8,6:18.4
-3,8,6:18.4
2,8,6:18.12
-8,9,6:18.4
-1,9,6:18.12
0,9,6:18.4
2,9,6:18.12
-9,10,6:18.4
-7,10,6:18.4
-6,10,6:18.4
-3,10,6:18.12
1,10,6:18.4
-7,11,6:18.4
-6,11,6:18.4
-3,11,6:18.12
-2,11,6:18.4
-1,11,6:18.4
-7,-7,7:18.4
-7,-5,7:18.4
-6,-4,7:18.4
-4,-4,7:18.4
-3,-4,7:18.4
-11,-3,7:18.4
-9,-3,7:18.12
-7,-3,7:18.12
0,-3,7:18.12
2,-3,7:18.4
-8,-2,7:18.12
-7,-2,7:18.4
-6,-2,7:18.4
-4,-2,7:18.12
-1,-2,7:18.4
3,-2,7:18.4
-10,-1,7:18.12
-10,0,7:18.4
3,0,7:18.4
-1,1,7:17.12
1,1,7:18.4
-11,2,7:18.12
-7,2,7:18.4
-6,2,7:17.12
-4,2,7:17.12
-3,2,7:18.4
-2,2,7:17.12
-1,2,7:18.4
1,2,7:18.4
2,2,7:18.12
3,2,7:18.12
-8,3,7:18.4
-6,3,7:18.4
-5,3,7:17.12
-4,3,7:17.12
-3,3,7:17.12
1,3,7:18.4
4,3,7:18.4
-4,4,7:17.12
-3,4,7:17.12
-1,4,7:18.4
0,4,7:18.4
1,4,7:18.12
3,4,7:18.12
4,4,7:18.4
-9,5,7:18.4
-6,5,7:18.4
-5,5,7:17.12
-4,5,7:18.4
-3,5,7:18.4
-1,5,7:17.12
1,5,7:18.12
2,5,7:18.12
3,5,7:18.12
-10,6,7:18.12
-8,6,7:17.12
-4,6,7:18.4
-2,6,7:18.12
0,6,7:17.12
1,6,7:18.12
3,6,7:18.4
-13,7,7:18.4
-9,7,7:17.12
-6,7,7:18.4
-3,7,7:18.4
-2,7,7:18.12
2,7,7:18.4
4,7,7:18.4
-11,8,7:18.12
-7,8,7:18.4
-6,8,7:18.12
0,8,7:18.4
1,8,7:18.12
4,8,7:18.4
-13,9,7:18.4
-12,9,7:18.4
-9,9,7:18.4
3,9,7:18.4
-12,10,7:18.4
-3,10,7:18.12
-3,11,7:18.4
1,11,7:18.4
-7,-6,8:18.4
-8,-5,8:18.4
-5,-5,8:18.4
-3,-5,8:18.4
-2,-5,8:18.4
-10,-4,8:18.4
-6,-4,8:18.4
-5,-4,8:18.4
-4,-4,8:18.4
-9,-3,8:18.12
-8,-3,8:18.12
-3,-3,8:18.12
2,-3,8:18.4
-8,-2,8:18.12
-3,-2,8:18.4
1,-2,8:18.12
3,-2,8:18.4
-9,-1,8:18.4
-8,-1,8:18.4
-6,-1,8:18.4
-5,-1,8:18.4
1,-1,8:17.12
2,-1,8:18.4
3,-1,8:18.4
-4,0,8:17.12
-3,0,8:18.4
-1,0,8:18.12
0,0,8:17.12
1,0,8:18.4
-8,1,8:17.12
-4,1,8:17.12
0,1,8:18.4
-7,2,8:17.12
-2,2,8:18.4
-1,2,8:18.4
0,2,8:18.4
3,2,8:18.12
-3,3,8:17.12
0,3,8:18.4
2,3,8:18.12
3,3,8:18.12
-9,4,8:18.4
-8,4,8:18.4
-7,4,8:18.4
-2,4,8:18.12
4,4,8:18.4
-10,5,8:18.12
-7,5,8:18.4
-5,5,8:17.12
-3,5,8:17.12
-1,5,8:18.12
-9,6,8:18.4
-3,6,8:18.4
-2,6,8:18.12
1,6,8:17.12
2,6,8:18.12
3,6,8:18.12
-10,7,8:17.12
-5,7,8:18.4
-4,7,8:18.4
-1,7,8:18.4
2,7,8:17.12
4,7,8:18.12
-11,8,8:17.12
-9,8,8:18.12
-4,8,8:18.4
-3,8,8:18.4
0,8,8:18.12
1,8,8:18.12
4,8,8:18.12
-8,9,8:18.4
-7,9,8:18.12
-6,9,8:18.12
0,9,8:18.12
-12,10,8:18.4
-11,10,8:18.4
-1,10,8:18.4
2,10,8:18.4
-4,11,8:18.4
1,11,8:18.4
-3,12,8:18.4
-6,-8,9:18.4
-5,-8,9:18.4
-6,-7,9:18.4
-5,-6,9:18.12
-4,-6,9:18.12
-3,-5,9:18.12
-4,-4,9:18.12
-3,-4,9:18.12
-2,-4,9:18.4
-4,-3,9:17.12
-6,-2,9:18.4
-4,-2,9:17.12
-3,-2,9:18.4
-2,-2,9:18.12
2,-2,9:17.12
-10,-1,9:18.4
-9,-1,9:18.4
-6,-1,9:18.4
-5,-1,9:18.4
-4,-1,9:17.12
-10,0,9:17.12
-4,0,9:18.4
0,0,9:18.12
2,0,9:18.12
-11,1,9:18.12
-10,1,9:18.12
-9,1,9:17.12
-2,1,9:18.4
2,1,9:18.12
-10,2,9:18.4
-9,2,9:18.4
-7,2,9:18.12
0,2,9:18.4
3,2,9:18.4
-6,3,9:18.12
-5,3,9:18.12
-3,3,9:17.12
0,3,9:18.12
1,3,9:18.12
4,3,9:18.4
-11,4,9:18.4
-10,4,9:18.4
-8,4,9:18.4
0,4,9:18.12
-9,5,9:18.4
-6,5,9:17.12
-2,5,9:18.4
3,5,9:18.12
4,5,9:18.12
-12,6,9:18.4
-11,6,9:18.12
-9,6,9:18.12
-8,6,9:18.4
-7,6,9:18.4
-6,6,9:18.4
-3,6,9:17.12
2,6,9:18.12
-11,7,9:18.12
-8,7,9:18.12
-4,7,9:18.4
-3,7,9:17.12
-1,7,9:18.4
0,7,9:18.12
-3,8,9:18.4
-2,8,9:18.12
2,8,9:18.12
4,8,9:18.12
-8,9,9:18.4
-3,9,9:18.4
-11,10,9:18.4
-10,10,9:18.4
-2,10,9:18.4
-2,11,9:18.12
-1,11,9:18.4
-3,12,9:18.12
-3,13,9:18.12
-1,14,9:18.4
-3,15,9:18.4
-3,16,9:18.4
-2,16,9:18.4
-1,16,9:18.4
-6,-9,10:18.4
-4,-9,10:18.4
-6,-8,10:18.4
-4,-8,10:18.4
-3,-8,10:18.4
-3,-7,10:18.4
-7,-6,10:18.4
-3,-6,10:18.12
-9,-5,10:18.4
-5,-5,10:17.12
-1,-5,10:18.4
-4,-4,10:17.12
-2,-4,10:18.4
-3,-3,10:18.4
-1,-3,10:18.4
0,-3,10:18.4
1,-3,10:18.4
-4,-2,10:18.12
-1,-2,10:18.12
1,-2,10:18.12
2,-2,10:18.12
-10,-1,10:18.4
-9,-1,10:18.12
-5,-1,10:17.12
-3,-1,10:17.12
-2,-1,10:17.12
-1,-1,10:18.4
0,-1,10:18.4
1,-1,10:18.12
-11,0,10:17.12
-10,0,10:18.12
-8,0,10:18.12
-7,0,10:18.12
-5,0,10:18.4
-2,0,10:18.4
-1,0,10:18.4
1,0,10:18.12
4,0,10:18.4
-11,1,10:18.12
-9,1,10:18.4
0,1,10:18.12
2,1,10:18.4
4,1,10:18.4
-12,2,10:18.12
-11,2,10:18.12
-10,2,10:18.12
-9,2,10:18.4
-7,2,10:18.12
-5,2,10:18.12
-1,2,10:18.4
1,2,10:18.4
4,2,10:18.4
-11,3,10:18.4
-10,3,10:18.12
-8,3,10:18.12
-7,3,10:18.12
-5,3,10:18.4
-3,3,10:17.12
2,3,10:18.12
4,3,10:18.4
-12,4,10:18.4
-10,4,10:18.12
-9,4,10:18.12
-6,4,10:17.12
-5,4,10:18.12
-3,4,10:18.12
2,4,10:18.12
3,4,10:18.12
-11,5,10:18.4
-10,5,10:18.4
-9,5,10:18.4
-7,5,10:18.4
0,5,10:18.4
2,5,10:18.12
3,5,10:18.12
-6,6,10:17.12
1,6,10:18.12
-12,7,10:18.4
-11,7,10:18.12
-8,7,10:18.12
-7,7,10:18.4
-12,8,10:18.4
-11,8,10:18.12
-7,8,10:18.4
-6,8,10:18.4
-3,8,10:17.12
2,8,10:18.12
-11,9,10:18.4
-10,9,10:18.4
-8,9,10:18.4
-6,9,10:18.12
-4,9,10:18.4
-3,9,10:17.12
-2,9,10:18.4
-3,10,10:17.12
-3,11,10:17.12
0,11,10:18.4
0,12,10:18.4
-4,13,10:18.12
0,14,10:18.4
-2,15,10:18.4
-1,15,10:18.4
0,15,10:18.4
-1,17,10:18.4
-6,-9,11:18.4
-4,-9,11:18.4
-3,-8,11:18.4
-5,-7,11:17.12
-3,-7,11:18.4
-8,-6,11:18.4
-7,-6,11:18.4
-5,-6,11:17.12
-2,-6,11:18.4
-10,-5,11:18.4
-8,-5,11:18.4
-7,-5,11:18.12
-10,-4,11:18.4
-9,-4,11:18.4
-4,-4,11:18.12
1,-4,11:18.12
2,-4,11:18.4
-5,-3,11:18.4
-9,-2,11:18.4
-7,-2,11:17.12
-6,-2,11:17.12
-1,-2,11:17.12
0,-2,11:17.12
1,-2,11:18.12
3,-2,11:18.12
-2,-1,11:18.4
0,-1,11:18.12
-10,0,11:18.12
-3,0,11:18.4
0,0,11:18.12
1,0,11:18.12
3,0,11:18.4
4,0,11:18.4
-11,1,11:18.12
-10,1,11:18.12
-9,1,11:18.4
-7,1,11:18.4
-3,1,11:18.4
-1,1,11:18.4
2,1,11:18.4
3,1,11:18.4
-12,2,11:18.12
-9,2,11:18.4
-8,2,11:18.4
-7,2,11:18.12
0,2,11:18.4
1,2,11:18.4
2,2,11:18.4
3,2,11:18.4
-9,3,11:18.12
-7,3,11:17.12
-3,3,11:17.12
-2,3,11:18.4
1,3,11:18.12
4,3,11:18.4
-11,4,11:18.4
-8,4,11:18.4
-7,4,11:18.4
-3,4,11:17.12
-2,4,11:18.4
0,4,11:18.4
2,4,11:18.4
3,4,11:18.4
4,4,11:18.4
-11,5,11:18.4
-8,5,11:18.4
-7,5,11:18.4
-6,5,11:18.4
-2,5,11:18.4
1,5,11:18.4
4,5,11:18.12
-6,6,11:17.12
3,6,11:18.4
-9,7,11:18.12
-7,7,11:18.4
-3,7,11:18.12
-2,7,11:18.12
0,7,11:18.12
-9,8,11:18.4
-7,8,11:18.4
-5,8,11:18.4
-2,8,11:18.12
-8,9,11:18.4
-4,9,11:18.4
-3,9,11:18.4
-4,11,11:18.12
-3,11,11:18.12
-2,11,11:18.12
-1,11,11:18.4
-2,12,11:17.12
-1,12,11:18.4
-2,13,11:17.12
-2,14,11:17.12
-1,14,11:18.4
0,14,11:18.4
-4,15,11:18.4
-3,15,11:18.12
-2,15,11:17.12
-2,16,11:18.12
0,16,11:18.4
-3,17,11:18.4
-1,17,11:18.4
-4,-8,12:18.4
-7,-7,12:18.4
-6,-7,12:18.4
-4,-7,12:18.4
-6,-6,12:18.4
-4,-6,12:18.4
-10,-5,12:18.4
-4,-5,12:18.12
-6,-4,12:18.4
0,-4,12:18.12
-10,-3,12:18.4
-8,-3,12:17.12
-6,-3,12:18.4
1,-3,12:18.12
3,-3,12:18.12
-7,-2,12:18.4
1,-2,12:17.12
3,-2,12:18.4
-9,-1,12:18.12
-8,-1,12:18.12
-7,-1,12:18.12
-2,-1,12:18.12
0,-1,12:18.12
-10,0,12:18.4
-9,0,12:18.4
-3,0,12:18.4
0,0,12:18.12
3,0,12:18.4
-9,1,12:18.4
-7,1,12:18.4
1,1,12:18.4
2,1,12:18.4
4,1,12:18.4
-7,2,12:17.12
-6,2,12:18.4
-5,2,12:18.4
-4,2,12:18.4
-3,2,12:18.4
-1,2,12:18.4
1,2,12:18.4
-11,3,12:18.4
-10,3,12:18.12
-9,3,12:18.12
-3,3,12:17.12
-2,3,12:17.12
1,3,12:18.4
-7,4,12:18.4
-6,4,12:18.4
1,4,12:18.4
2,4,12:18.4
-9,5,12:18.12
-7,5,12:18.12
-6,5,12:18.4
-2,5,12:17.12
-10,6,12:18.4
-8,6,12:18.12
-7,6,12:17.12
-2,6,12:17.12
2,6,12:18.4
-5,7,12:17.12
1,7,12:18.12
-8,8,12:18.4
-3,10,12:18.4
-2,10,12:18.4
-4,11,12:18.12
-2,11,12:18.4
2,11,12:18.4
-5,12,12:18.12
-2,13,12:18.4
-2,14,12:18.4
-3,15,12:18.12
-1,15,12:18.12
-4,16,12:18.4
-3,16,12:18.12
-3,17,12:18.4
-5,-8,13:18.12
-3,-7,13:18.4
-9,-6,13:18.4
-8,-6,13:18.4
-9,-5,13:18.4
-8,-5,13:18.4
-7,-5,13:18.4
-6,-5,13:18.4
-2,-4,13:18.12
2,-4,13:18.4
-10,-3,13:18.4
-3,-3,13:18.4
2,-3,13:18.12
-8,-2,13:18.4
-7,-2,13:18.4
2,-2,13:18.4
-8,-1,13:18.4
-7,-1,13:18.4
2,-1,13:18.12
3,-1,13:18.4
-10,0,13:18.12
-7,0,13:18.4
-5,0,13:18.4
0,0,13:18.4
-12,1,13:18.12
-8,1,13:17.12
-7,1,13:18.4
-6,1,13:18.4
-7,2,13:18.4
-6,2,13:18.4
-4,2,13:18.4
-3,2,13:17.12
-2,2,13:18.4
-8,3,13:18.4
-6,3,13:18.4
-2,3,13:17.12
-8,4,13:18.4
0,4,13:18.4
-4,5,13:18.4
-6,6,13:18.4
-5,6,13:18.4
-9,7,13:18.4
-7,7,13:17.12
-3,7,13:18.12
-1,7,13:17.12
0,7,13:18.12
1,7,13:18.12
-8,8,13:18.4
-7,8,13:17.12
-6,8,13:18.4
-5,8,13:17.12
-4,8,13:18.4
-3,8,13:18.4
-2,8,13:18.4
-1,8,13:17.12
0,8,13:18.12
-8,9,13:18.4
0,9,13:18.12
-4,10,13:18.4
-9,11,13:18.4
-3,11,13:18.12
-6,12,13:18.4
-5,12,13:18.12
-2,12,13:18.4
-6,13,13:18.4
-3,14,13:18.4
-3,15,13:18.12
-2,15,13:18.12
-2,16,13:18.4
-4,-7,14:18.4
-3,-7,14:18.4
-1,-7,14:18.4
-5,-6,14:18.4
-3,-6,14:18.4
-7,-5,14:18.4
-6,-5,14:18.4
-4,-5,14:18.12
0,-5,14:18.4
-9,-4,14:18.4
-8,-4,14:18.4
-3,-4,14:18.4
2,-4,14:18.4
-9,-3,14:18.4
-1,-3,14:18.4
-8,-2,14:18.12
0,-2,14:18.12
2,-2,14:18.4
-7,-1,14:18.12
-6,-1,14:18.4
-1,-1,14:18.4
-8,0,14:17.12
-7,0,14:18.4
-6,0,14:18.4
-9,1,14:18.4
-7,1,14:18.4
-6,1,14:18.4
-4,1,14:18.12
-8,2,14:18.4
-7,2,14:18.4
-3,2,14:17.12
-2,2,14:17.12
-1,2,14:18.4
2,2,14:18.4
-8,3,14:18.12
-5,3,14:18.4
-2,3,14:17.12
0,3,14:18.4
-4,4,14:18.4
-1,5,14:18.4
-6,6,14:18.12
-8,7,14:17.12
-5,7,14:18.12
-3,7,14:18.4
1,7,14:18.12
-8,9,14:18.4
-7,9,14:17.12
-5,9,14:18.4
-4,9,14:17.12
-3,9,14:18.4
0,9,14:17.12
-7,10,14:17.12
-5,10,14:18.4
-3,10,14:18.4
0,10,14:17.12
-6,11,14:17.12
-7,12,14:18.4
-6,12,14:17.12
-4,12,14:18.12
1,12,14:18.4
-8,13,14:18.12
-7,13,14:18.12
-6,13,14:18.12
-7,14,14:18.12
-6,14,14:18.12
-4,14,14:18.4
-4,16,14:18.4
-3,16,14:18.4
-4,-7,15:18.4
-3,-7,15:18.4
0,-6,15:18.12
2,-6,15:18.4
-2,-5,15:18.4
0,-5,15:18.12
1,-5,15:18.12
-3,-4,15:18.4
0,-4,15:18.4
1,-4,15:18.4
-4,-3,15:18.4
1,-3,15:18.4
-9,-2,15:18.12
-8,-2,15:18.12
-7,-2,15:18.12
-3,-2,15:18.4
-7,-1,15:18.12
-2,-1,15:18.12
-10,0,15:18.4
-9,0,15:18.12
-7,0,15:18.12
-6,0,15:18.4
-1,0,15:17.12
-10,1,15:18.4
-9,1,15:18.4
-8,1,15:18.4
-7,1,15:18.4
-6,1,15:18.4
-4,1,15:17.12
-2,1,15:18.12
-1,1,15:17.12
1,1,15:18.4
-9,2,15:18.12
-8,2,15:18.12
-7,2,15:18.12
2,2,15:18.4
-9,3,15:18.12
-8,3,15:18.12
-3,3,15:18.4
-2,3,15:17.12
0,3,15:18.12
-10,4,15:18.4
-6,4,15:18.4
-1,4,15:17.12
-12,5,15:18.4
-11,5,15:18.4
-10,5,15:18.4
-2,5,15:18.4
0,5,15:18.4
-9,6,15:18.12
-8,6,15:18.12
-11,7,15:18.12
-8,7,15:17.12
0,7,15:18.12
-6,8,15:18.12
3,8,15:18.4
-11,9,15:18.4
-6,9,15:18.4
-4,9,15:17.12
-3,9,15:18.4
-1,9,15:18.4
0,9,15:18.12
1,9,15:18.12
3,9,15:18.12
-8,10,15:18.4
-7,10,15:18.4
-5,10,15:18.4
-3,10,15:18.4
2,10,15:18.12
-10,11,15:18.4
-6,11,15:18.4
-6,13,15:17.12
-2,13,15:18.4
-6,14,15:17.12
-5,14,15:18.4
-7,15,15:18.4
2,-7,16:18.4
-5,-6,16:18.12
-1,-6,16:18.12
1,-6,16:18.12
-4,-5,16:18.12
1,-5,16:18.12
3,-5,16:18.4
1,-4,16:18.4
2,-4,16:18.4
-3,-3,16:18.4
-2,-3,16:18.4
-1,-3,16:18.4
0,-3,16:18.4
1,-3,16:18.4
2,-3,16:18.4
0,-2,16:17.12
1,-2,16:18.4
-9,-1,16:18.12
-4,-1,16:18.12
-1,-1,16:17.12
-9,0,16:18.12
-6,0,16:18.4
-9,1,16:18.4
-6,1,16:18.4
-4,1,16:17.12
-11,2,16:18.4
-8,2,16:18.12
-5,2,16:18.4
-4,2,16:18.12
-2,2,16:18.12
0,2,16:18.12
-13,3,16:18.4
-12,3,16:18.4
-10,3,16:18.4
-9,3,16:18.12
-4,3,16:18.4
-3,3,16:18.4
-1,3,16:17.12
-11,4,16:18.4
-10,4,16:18.4
-9,4,16:18.4
-3,4,16:18.4
-2,4,16:18.4
-1,4,16:18.12
-13,5,16:18.4
-11,5,16:18.4
-9,5,16:18.4
-8,5,16:18.12
-1,5,16:17.12
0,5,16:18.4
-12,6,16:18.4
-9,6,16:17.12
0,6,16:17.12
-12,7,16:18.4
-8,7,16:18.4
-4,7,16:18.12
1,7,16:17.12
2,7,16:18.4
-8,8,16:17.12
-2,8,16:18.4
0,8,16:18.12
1,8,16:18.12
3,8,16:18.4
-8,9,16:18.4
-7,9,16:18.12
-4,9,16:18.4
3,9,16:18.12
-7,10,16:18.4
-5,10,16:18.4
-4,10,16:18.4
-3,10,16:17.12
-2,10,16:18.4
0,10,16:18.4
2,10,16:18.4
3,10,16:18.4
-7,11,16:18.4
-3,11,16:18.4
-8,12,16:18.4
-6,12,16:18.4
-3,12,16:18.4
-2,12,16:18.4
-1,12,16:18.4
2,12,16:18.4
-5,13,16:18.4
-4,13,16:18.4
-2,13,16:18.4
-8,14,16:18.4
-6,14,16:18.4
-5,14,16:18.4
-4,14,16:18.4
-7,15,16:18.4
-6,15,16:18.4
-5,15,16:18.4
0,-7,17:18.12
-3,-6,17:18.12
-2,-6,17:18.12
0,-6,17:18.12
-7,-5,17:18.12
-5,-5,17:18.12
-2,-5,17:18.12
-1,-5,17:18.12
1,-5,17:17.12
-7,-4,17:18.12
-6,-4,17:18.12
-5,-4,17:18.4
-4,-4,17:18.4
-1,-4,17:18.12
1,-4,17:17.12
3,-4,17:18.4
-5,-3,17:18.4
-4,-3,17:18.4
-1,-3,17:18.4
0,-3,17:17.12
-8,-1,17:18.12
-6,-1,17:18.4
-3,-1,17:18.12
-10,0,17:18.12
-8,0,17:18.12
-6,0,17:18.4
-5,0,17:18.4
-4,0,17:17.12
-3,0,17:18.4
2,0,17:18.4
-7,1,17:18.4
-4,1,17:18.12
-3,1,17:18.12
-11,2,17:18.12
-10,2,17:18.12
-8,2,17:18.12
-7,2,17:18.12
-6,2,17:18.4
-5,2,17:18.4
-13,3,17:18.4
-12,3,17:18.12
-10,3,17:18.12
-7,3,17:18.4
-2,3,17:18.4
1,3,17:18.12
2,3,17:18.4
3,3,17:18.4
-11,4,17:17.12
-10,4,17:18.12
-8,4,17:18.12
-7,4,17:18.12
0,4,17:17.12
1,4,17:18.4
-13,5,17:18.4
-12,5,17:18.4
-10,5,17:17.12
-2,5,17:18.4
1,5,17:18.4
2,5,17:18.12
3,5,17:18.12
-10,6,17:18.4
-7,6,17:18.4
-5,6,17:18.4
-10,7,17:18.4
-7,7,17:18.12
-6,7,17:18.4
2,7,17:18.4
3,7,17:18.4
-10,8,17:18.4
-9,8,17:17.12
1,8,17:17.12
2,8,17:18.12
-10,9,17:18.4
-8,9,17:18.4
2,9,17:17.12
-7,10,17:18.4
-1,10,17:18.4
1,10,17:18.4
2,10,17:18.4
4,10,17:18.4
-3,11,17:17.12
0,11,17:18.4
1,11,17:18.4
-7,12,17:18.4
-4,12,17:18.4
-3,12,17:18.4
-2,12,17:18.4
-1,12,17:18.4
0,12,17:18.4
-6,13,17:18.4
-5,13,17:18.4
-1,13,17:18.4
-7,14,17:18.4
-5,14,17:18.4
0,-7,18:18.12
-6,-6,18:18.12
0,-6,18:18.12
3,-6,18:18.4
-6,-5,18:18.4
-4,-5,18:18.4
-2,-5,18:18.12
3,-5,18:18.4
-6,-4,18:18.12
-1,-4,18:18.4
1,-4,18:18.4
2,-4,18:18.4
3,-4,18:18.4
-8,-3,18:18.4
-6,-3,18:18.4
-5,-3,18:18.4
1,-3,18:18.4
2,-3,18:18.4
-5,-2,18:17.12
-4,-1,18:17.12
-9,0,18:18.12
-8,0,18:18.12
-2,0,18:18.4
1,0,18:18.4
-6,1,18:18.4
-3,1,18:18.12
-1,1,18:18.12
2,1,18:18.12
-11,2,18:18.12
-8,2,18:18.4
-7,2,18:18.4
-5,2,18:18.4
-2,2,18:18.4
-1,2,18:18.12
2,2,18:18.4
-12,3,18:17.12
-9,3,18:18.4
-5,3,18:18.4
-2,3,18:18.12
-1,3,18:18.12
2,3,18:18.4
-13,4,18:18.4
-11,4,18:18.4
0,4,18:18.4
1,4,18:17.12
-12,5,18:18.4
-11,5,18:18.4
-8,5,18:18.12
-2,5,18:18.4
1,5,18:18.4
2,5,18:18.12
-12,6,18:18.4
-7,6,18:18.4
1,6,18:18.4
2,6,18:18.12
3,7,18:18.12
-11,8,18:18.12
-10,8,18:18.4
-9,8,18:17.12
1,8,18:18.4
2,8,18:18.12
-11,9,18:18.12
-10,9,18:18.12
-9,9,18:18.12
-8,9,18:18.12
-6,9,18:18.4
3,9,18:18.4
4,9,18:18.4
-11,10,18:18.4
-10,10,18:18.12
-9,10,18:18.12
-2,10,18:18.12
-1,10,18:18.4
0,10,18:18.4
4,10,18:18.4
-2,11,18:18.12
-1,11,18:18.4
2,11,18:18.4
-4,12,18:18.12
-2,12,18:17.12
-1,12,18:18.12
0,12,18:18.12
2,12,18:18.4
-4,13,18:18.4
-3,13,18:18.4
-3,14,18:18.4
-2,14,18:18.4
-1,14,18:18.4
1,14,18:18.4
-6,-6,19:18.12
-7,-5,19:18.12
2,-5,19:18.4
-7,-4,19:18.4
-6,-4,19:17.12
0,-4,19:18.4
1,-4,19:18.4
2,-4,19:18.4
-7,-3,19:18.4
-6,-3,19:18.12
-5,-3,19:17.12
-4,-3,19:18.12
-6,-2,19:18.12
-4,-2,19:18.12
-2,-2,19:18.12
-4,-1,19:18.12
-1,-1,19:18.4
1,0,19:18.4
-7,2,19:18.4
1,2,19:18.12
-10,3,19:18.4
-7,3,19:18.4
-5,3,19:18.4
2,3,19:18.4
-12,4,19:18.4
-11,4,19:18.4
-10,4,19:18.12
0,4,19:18.4
2,4,19:17.12
4,4,19:18.4
-12,5,19:18.4
-10,5,19:18.4
0,5,19:18.4
2,5,19:18.12
3,5,19:18.12
-5,6,19:18.4
1,6,19:18.4
2,6,19:18.4
-9,7,19:18.12
-6,7,19:18.4
-9,8,19:18.4
-8,8,19:18.4
-6,8,19:18.4
-4,8,19:18.4
-10,9,19:17.12
-8,9,19:18.12
-3,9,19:18.4
1,9,19:18.4
3,9,19:18.4
-12,10,19:18.4
-2,10,19:18.12
-1,10,19:18.4
3,10,19:18.4
-2,11,19:18.4
0,11,19:18.4
1,11,19:18.4
-2,12,19:18.4
-4,13,19:18.4
-2,13,19:18.4
-3,14,19:18.4
-2,14,19:18.4
-1,14,19:18.4
-5,-6,20:18.12
-8,-5,20:18.4
-7,-5,20:18.4
-6,-4,20:18.4
-5,-4,20:18.4
-4,-4,20:18.4
-8,-3,20:18.4
-7,-3,20:18.4
-7,-2,20:18.4
-6,-2,20:18.12
-4,-1,20:18.12
-3,-1,20:18.4
-3,0,20:18.4
-3,2,20:18.4
0,3,20:18.4
2,3,20:18.4
3,3,20:18.4
4,3,20:18.4
0,4,20:18.4
1,4,20:18.4
4,4,20:18.4
-5,5,20:18.4
-4,5,20:18.4
0,5,20:18.4
1,6,20:18.4
-11,7,20:18.12
-4,7,20:18.4
-11,8,20:18.12
-10,8,20:18.4
-8,8,20:18.4
-4,8,20:18.4
-12,9,20:18.12
-10,9,20:17.12
-3,9,20:18.4
-11,10,20:18.12
-9,10,20:18.4
-8,10,20:18.4
-7,10,20:18.4
-4,10,20:18.12
-4,11,20:18.12
-3,11,20:18.12
-1,11,20:18.4
-3,12,20:18.4
-2,12,20:18.4
-3,13,20:18.4
-2,13,20:18.4
-1,13,20:18.4
-7,-4,21:18.4
-6,-4,21:18.4
-5,-4,21:18.4
-5,-3,21:18.12
-3,-2,21:18.4
2,3,21:18.4
3,3,21:18.4
1,4,21:18.4
2,4,21:18.4
3,4,21:18.4
1,5,21:18.4
2,5,21:18.4
3,5,21:18.4
-10,7,21:18.4
-9,7,21:18.4
-11,8,21:18.4
-10,8,21:18.4
-9,8,21:18.4
-10,9,21:18.4
-9,9,21:18.4
-6,9,21:18.4
-10,10,21:18.4
-8,10,21:18.4
-10,11,21:18.4
-9,11,21:18.4
-11,8,22:18.4
-9,9,22:18.4
-11,10,22:18.4
-9,7,17:85.0
0,5,17:85.0
-11,3,17:85.0
-3,9,16:85.0
-7,7,15:85.0
-7,11,14:85.0
1,10,14:85.0
-6,10,14:85.0
-8,-1,14:85.0
-1,3,13:85.0
-1,6,12:85.0
-8,-4,12:85.0
-8,3,11:85.0
-1,-1,11:85.0
-6,-3,11:85.0
-4,6,9:85.0
-5,-3,9:85.0
1,7,8:85.0
-4,3,8:85.0
-8,0,8:85.0
-9,8,7:85.0
-5,6,7:85.0
-5,4,7:85.0
0,1,7:85.0
-3,5,6:85.0
-5,3,4:85.0
