[META]
version=2.0
spawnOnBlockType=2
spawnSunlight=True
spawnDarkness=True
spawnWater=False
spawnLava=False
underFill=False
randomRotation=True
dig=True
tree=False
branch=False
needsFoundation=True
rarity=100
collisionPercentage=20
spawnElevationMin=0
spawnElevationMax=200
spawnInBiome=Custom
[DATA]
-3,-2,0:188.0
-1,-2,0:17.12
0,-2,0:188.0
-3,-1,0:17.12
-4,0,0:188.0
-2,0,0:188.0
-1,0,0:188.0
0,0,0:188.0
-4,1,0:188.0
-3,1,0:188.0
-1,1,0:17.12
0,1,0:188.0
-3,2,0:17.12
-2,2,0:188.0
0,2,0:188.0
-3,-1,1:17.12
-1,-1,1:17.12
-4,0,1:188.0
-3,0,1:188.0
-2,0,1:188.0
-3,1,1:188.0
-2,1,1:188.0
-1,1,1:17.12
-1,2,1:188.0
-3,-1,2:17.12
-2,-1,2:17.12
-3,0,2:17.12
-2,0,2:17.12
-1,1,2:17.12
-3,-1,3:17.12
-2,-1,3:17.12
-3,0,3:17.12
-2,0,3:17.12
-3,-1,4:17.12
-2,-1,4:17.12
-3,0,4:17.12
-2,0,4:17.12
-2,1,4:18.4
0,1,4:18.4
-3,2,4:18.4
-3,-1,5:17.12
-2,-1,5:17.12
-3,0,5:17.12
-2,0,5:17.12
-1,0,5:188.0
1,0,5:18.6
-5,2,5:18.4
-1,2,5:18.6
-2,-3,6:18.6
-2,-2,6:18.6
0,-2,6:18.6
1,-2,6:18.4
-3,-1,6:17.12
-2,-1,6:17.12
-1,-1,6:18.6
2,-1,6:18.4
-6,0,6:18.4
-5,0,6:18.4
-3,0,6:17.12
-2,0,6:17.12
-6,1,6:18.6
-4,1,6:17.12
-3,1,6:17.12
1,1,6:18.6
-1,2,6:18.4
1,2,6:18.4
2,2,6:18.4
3,3,6:18.6
-4,4,6:18.4
-2,4,6:18.6
-1,4,6:18.6
1,4,6:18.4
2,4,6:18.6
-2,5,6:18.6
0,5,6:18.4
0,-3,7:18.4
-4,-2,7:18.6
-4,-1,7:18.4
-3,-1,7:17.12
-2,-1,7:17.12
-1,-1,7:18.6
2,-1,7:18.4
-3,0,7:17.12
-2,0,7:17.12
0,0,7:188.0
-6,1,7:188.0
-4,1,7:18.6
-3,1,7:18.4
-2,1,7:18.6
-1,1,7:17.12
0,1,7:17.12
1,1,7:18.6
2,1,7:18.6
-6,2,7:17.12
-5,2,7:17.12
-4,2,7:18.6
2,2,7:18.6
3,2,7:17.12
4,2,7:18.4
-8,3,7:18.4
-7,3,7:18.4
-6,3,7:18.6
-3,3,7:18.6
-2,3,7:18.6
0,3,7:18.4
-2,4,7:18.4
-1,4,7:18.4
0,4,7:18.6
-3,5,7:18.6
-3,6,7:18.6
-2,6,7:18.4
-5,7,7:18.4
-2,8,7:18.6
1,-6,8:18.4
-3,-5,8:18.4
0,-5,8:18.4
1,-5,8:18.4
-4,-4,8:18.4
-2,-4,8:18.4
-1,-4,8:18.4
1,-4,8:18.6
-6,-3,8:18.4
-5,-3,8:18.6
-3,-3,8:18.4
-1,-3,8:18.6
-3,-2,8:17.12
1,-2,8:18.6
2,-2,8:18.6
-6,-1,8:18.4
-5,-1,8:188.0
-4,-1,8:17.12
-3,-1,8:17.12
-2,-1,8:17.12
1,-1,8:18.6
2,-1,8:18.6
3,-1,8:18.4
-7,0,8:18.6
-5,0,8:18.4
-3,0,8:17.12
-2,0,8:17.12
3,0,8:18.4
-5,1,8:18.4
1,1,8:18.6
2,1,8:17.12
-8,2,8:18.6
-7,2,8:18.4
-6,2,8:18.6
-4,2,8:18.4
-3,2,8:18.6
1,2,8:17.12
2,2,8:17.12
3,2,8:18.4
-8,3,8:18.4
-7,3,8:17.12
-4,3,8:18.6
-2,3,8:18.6
0,3,8:18.6
1,3,8:18.6
2,3,8:18.6
3,3,8:18.6
-7,4,8:18.4
-6,4,8:18.4
-3,4,8:18.6
-1,4,8:18.4
-5,5,8:18.4
-3,5,8:18.4
1,5,8:18.4
-3,6,8:18.6
-2,6,8:18.4
-4,8,8:18.6
-3,8,8:18.4
-2,-6,9:18.6
-5,-5,9:18.4
-3,-5,9:18.4
-1,-5,9:17.12
0,-5,9:18.6
1,-5,9:17.12
2,-5,9:18.6
-5,-4,9:18.6
-4,-4,9:17.12
-3,-4,9:18.4
0,-4,9:17.12
2,-4,9:18.6
-5,-3,9:188.0
-4,-3,9:17.12
-1,-3,9:18.6
0,-3,9:17.12
1,-3,9:188.0
-6,-2,9:18.4
-5,-2,9:18.6
-4,-2,9:18.6
-3,-2,9:18.4
-1,-2,9:17.12
1,-2,9:18.4
3,-2,9:18.6
-7,-1,9:18.6
-5,-1,9:17.12
-2,-1,9:17.12
-1,-1,9:17.12
3,-1,9:18.6
4,-1,9:18.6
-4,0,9:18.6
-3,0,9:17.12
-2,0,9:17.12
3,0,9:17.12
4,0,9:18.6
-4,1,9:18.6
-2,1,9:17.12
-1,1,9:18.4
0,1,9:18.6
3,1,9:18.4
4,1,9:18.6
-4,2,9:18.6
-3,2,9:18.4
-2,2,9:17.12
3,2,9:18.4
-7,3,9:18.4
-5,3,9:18.4
-3,3,9:18.6
-1,3,9:18.4
0,3,9:18.4
-6,4,9:18.4
-5,4,9:18.6
-4,4,9:18.6
1,4,9:18.4
2,4,9:18.6
-6,5,9:18.6
-5,5,9:18.4
-3,5,9:17.12
-2,5,9:17.12
0,5,9:18.4
-2,6,9:17.12
-1,6,9:18.4
-4,7,9:18.4
-3,7,9:18.6
-2,7,9:18.4
-1,7,9:18.4
0,7,9:18.6
-3,8,9:18.4
-2,8,9:18.4
-5,-6,10:18.4
-4,-6,10:18.6
-3,-6,10:18.4
-5,-5,10:17.12
-4,-5,10:18.4
-3,-5,10:18.4
-2,-5,10:18.6
-1,-5,10:18.6
2,-5,10:18.4
-6,-4,10:18.4
-5,-4,10:18.6
1,-4,10:18.6
-6,-3,10:18.6
-4,-3,10:18.4
-2,-3,10:18.4
-1,-3,10:18.6
0,-3,10:18.4
-4,-2,10:18.6
-2,-2,10:18.6
-1,-2,10:18.6
1,-2,10:18.4
2,-2,10:18.4
-5,-1,10:18.6
-4,-1,10:18.4
-2,-1,10:17.12
1,-1,10:18.6
2,-1,10:18.6
3,-1,10:18.4
-5,0,10:18.4
-4,0,10:18.6
-3,0,10:17.12
-1,0,10:18.6
2,0,10:18.6
3,0,10:18.6
4,0,10:18.4
-6,1,10:18.4
-5,1,10:18.6
-3,1,10:18.6
-2,1,10:18.6
-1,1,10:18.6
0,1,10:18.4
2,1,10:18.4
3,1,10:18.4
-4,2,10:18.6
0,2,10:18.6
1,2,10:18.6
-6,3,10:18.6
-5,3,10:18.4
-4,3,10:18.6
-3,3,10:18.4
-2,3,10:17.12
0,3,10:18.4
1,3,10:18.4
-7,4,10:18.4
-6,4,10:18.6
-5,4,10:18.6
-4,4,10:18.6
-3,4,10:188.0
-2,4,10:17.12
-1,4,10:17.12
0,4,10:18.4
1,4,10:18.6
-7,5,10:18.4
-4,5,10:17.12
-3,5,10:18.4
-2,5,10:18.4
-5,6,10:18.4
-3,6,10:18.4
-2,6,10:18.6
-1,6,10:18.6
0,6,10:18.6
-3,7,10:18.6
-2,7,10:17.12
-1,7,10:18.6
-1,8,10:18.6
-2,-6,11:18.4
-1,-6,11:18.4
-5,-5,11:18.4
-4,-5,11:18.6
-3,-5,11:18.4
0,-5,11:18.6
-5,-4,11:18.6
-4,-4,11:18.6
-3,-4,11:18.4
-1,-4,11:18.6
0,-4,11:18.6
2,-3,11:18.6
-6,-2,11:18.6
-5,-2,11:18.4
-4,-2,11:18.6
-6,-1,11:18.6
-5,-1,11:18.4
-4,-1,11:18.6
-2,-1,11:18.6
-1,-1,11:17.12
0,-1,11:18.4
2,-1,11:18.6
-7,0,11:18.6
-6,0,11:18.4
-4,0,11:18.4
-3,0,11:17.12
-2,0,11:18.4
-1,0,11:18.6
1,0,11:18.4
2,0,11:18.4
3,0,11:18.4
-4,1,11:18.4
-3,1,11:18.4
0,1,11:18.4
2,1,11:18.4
-4,2,11:18.4
-2,2,11:18.4
-1,2,11:18.4
-6,3,11:18.6
-5,3,11:18.6
-4,3,11:18.6
-2,3,11:18.4
-1,3,11:18.4
0,3,11:18.4
2,3,11:18.4
-7,4,11:18.6
-4,4,11:18.6
-3,4,11:18.4
-1,4,11:18.6
0,4,11:17.12
1,4,11:18.6
-5,5,11:18.6
-3,5,11:18.6
-1,5,11:18.6
0,5,11:18.4
1,5,11:18.4
-4,6,11:18.6
-4,7,11:18.4
-3,7,11:18.4
-2,7,11:18.4
-2,-6,12:18.6
0,-6,12:18.6
2,-6,12:18.4
-4,-5,12:18.4
-3,-5,12:18.4
-2,-5,12:18.6
0,-5,12:18.4
-1,-4,12:18.6
1,-4,12:18.4
-5,-3,12:18.4
-3,-3,12:18.4
-2,-3,12:18.4
2,-3,12:18.6
-5,-2,12:18.6
-2,-2,12:18.6
-1,-2,12:17.12
-3,-1,12:18.6
-2,-1,12:18.6
-1,-1,12:18.4
0,-1,12:17.12
1,-1,12:17.12
2,-1,12:18.4
3,-1,12:18.4
-4,0,12:17.12
-3,0,12:18.4
0,0,12:18.6
1,0,12:18.6
2,0,12:18.4
-6,1,12:18.6
-4,1,12:17.12
-3,1,12:18.4
-1,1,12:18.4
0,1,12:18.4
1,1,12:18.6
-6,2,12:18.6
-4,2,12:188.0
1,2,12:18.6
-4,3,12:18.6
-1,3,12:18.4
0,3,12:18.6
-4,4,12:18.6
-2,4,12:18.6
-1,4,12:18.6
0,4,12:18.6
1,4,12:18.6
-3,5,12:18.4
-2,5,12:18.4
-3,6,12:18.6
-3,-6,13:18.4
-2,-6,13:18.6
-1,-6,13:18.4
0,-6,13:18.6
1,-6,13:18.6
-2,-5,13:18.4
-2,-4,13:18.6
-1,-4,13:18.4
0,-4,13:18.6
2,-4,13:18.4
3,-4,13:18.4
-3,-3,13:18.4
-2,-3,13:18.6
-1,-3,13:18.6
0,-3,13:18.4
2,-3,13:18.4
-3,-2,13:18.6
-1,-2,13:17.12
0,-2,13:18.6
-5,-1,13:18.6
-1,-1,13:188.0
0,-1,13:18.6
1,-1,13:18.6
3,-1,13:18.6
4,-1,13:18.4
-6,0,13:18.4
-5,0,13:18.4
-4,0,13:17.12
-3,0,13:18.6
-2,0,13:18.4
0,0,13:17.12
2,0,13:17.12
3,0,13:17.12
5,0,13:18.6
-5,1,13:18.4
-4,1,13:18.6
-3,1,13:18.6
-2,1,13:18.4
-1,1,13:18.6
0,1,13:17.12
1,1,13:18.4
2,1,13:17.12
3,1,13:18.4
4,1,13:18.6
-6,2,13:18.4
-5,2,13:18.6
-4,2,13:18.6
-1,2,13:18.6
0,2,13:18.6
2,2,13:18.4
3,2,13:18.4
4,2,13:18.6
-3,3,13:18.4
-2,3,13:18.6
-1,3,13:18.6
3,3,13:18.4
-4,4,13:18.6
-3,4,13:18.4
-1,4,13:18.4
-2,-7,14:18.6
-1,-7,14:18.4
0,-7,14:18.4
-2,-6,14:18.6
-5,-5,14:18.4
1,-5,14:18.6
-4,-4,14:18.4
-3,-4,14:18.4
-1,-4,14:17.12
0,-4,14:18.6
2,-4,14:18.4
-6,-3,14:18.6
-4,-3,14:18.6
-3,-3,14:188.0
-2,-3,14:17.12
-1,-3,14:17.12
0,-3,14:17.12
-5,-2,14:18.4
-4,-2,14:18.4
1,-2,14:18.4
-7,-1,14:18.4
-6,-1,14:18.6
-5,-1,14:17.12
-4,-1,14:18.6
1,-1,14:18.4
3,-1,14:18.4
-6,0,14:17.12
-3,0,14:18.6
-1,0,14:18.4
1,0,14:18.6
2,0,14:18.4
4,0,14:18.4
-7,1,14:18.6
-6,1,14:18.6
-5,1,14:18.6
-4,1,14:18.4
-3,1,14:18.6
-1,1,14:18.4
0,1,14:18.4
2,1,14:18.4
-5,2,14:18.6
-4,2,14:18.4
-3,2,14:18.6
-1,2,14:17.12
0,2,14:18.6
2,2,14:18.4
3,2,14:17.12
4,2,14:18.6
-3,3,14:18.6
-1,3,14:17.12
2,3,14:18.6
-2,4,14:18.6
-1,4,14:18.6
0,4,14:18.6
-3,-5,15:18.4
-2,-5,15:18.4
0,-5,15:18.4
1,-5,15:18.6
-3,-4,15:17.12
-2,-4,15:18.4
0,-4,15:18.4
1,-4,15:17.12
2,-4,15:18.4
-5,-3,15:18.6
-3,-3,15:18.4
-2,-3,15:18.4
0,-3,15:18.4
1,-3,15:18.4
-6,-2,15:18.4
-5,-2,15:18.6
-4,-2,15:18.4
-1,-2,15:18.4
0,-2,15:18.4
-5,-1,15:18.6
-4,-1,15:18.4
-1,-1,15:18.6
2,-1,15:18.6
-6,0,15:18.4
-4,0,15:18.6
0,0,15:18.4
3,0,15:18.4
-6,1,15:18.4
-3,1,15:18.6
-1,1,15:18.6
3,1,15:18.6
-3,2,15:18.6
-1,2,15:18.4
0,2,15:18.4
1,2,15:18.4
2,2,15:18.6
4,2,15:18.6
-2,3,15:18.4
-1,3,15:18.6
0,3,15:18.4
3,3,15:18.4
-1,4,15:18.6
-4,-4,16:18.6
-3,-4,16:18.6
1,-4,16:18.6
2,-4,16:18.6
0,-3,16:18.4
-1,-2,16:18.6
1,-2,16:18.6
-1,0,16:18.6
1,0,16:18.4
2,0,16:18.4
