[META]
version=2.0
spawnOnBlockType=2
spawnSunlight=True
spawnDarkness=True
spawnWater=False
spawnLava=False
underFill=False
randomRotation=True
dig=True
tree=False
branch=False
needsFoundation=True
rarity=100
collisionPercentage=20
spawnElevationMin=0
spawnElevationMax=200
spawnInBiome=Custom
[DATA]
-2,0,0:188.0
-1,0,0:17.12
1,0,0:188.0
2,0,0:188.0
-2,1,0:188.0
-1,2,0:188.0
0,2,0:188.0
1,2,0:188.0
2,2,0:188.0
1,3,0:188.0
2,3,0:17.12
1,0,1:17.12
0,1,1:17.12
1,2,1:17.12
0,1,2:17.12
0,1,3:17.12
0,0,4:188.0
1,0,4:18.4
2,0,4:18.4
-2,1,4:18.6
-1,1,4:18.6
0,1,4:17.12
0,2,4:18.4
1,2,4:18.4
-1,-3,5:18.12
0,-2,5:18.12
-2,-1,5:18.12
-1,-1,5:18.12
0,-1,5:18.12
-3,0,5:18.14
-1,0,5:18.12
1,0,5:18.12
-3,1,5:18.12
-2,1,5:18.12
-1,1,5:17.12
0,1,5:188.0
1,1,5:18.12
-1,2,5:18.12
-2,3,5:18.4
-3,-3,6:18.12
1,-3,6:18.14
-3,-2,6:18.14
-2,-2,6:18.14
-1,-2,6:18.12
1,-2,6:18.14
-3,-1,6:18.12
-2,-1,6:18.14
1,-1,6:18.12
-3,0,6:18.12
-2,0,6:18.12
-1,0,6:17.12
0,0,6:18.12
1,0,6:18.14
2,0,6:18.12
-4,1,6:18.12
-3,1,6:18.12
-1,1,6:17.12
2,1,6:18.12
-2,2,6:18.6
0,2,6:18.12
1,2,6:18.14
-3,3,6:18.4
-1,3,6:18.4
0,3,6:18.4
0,-4,7:18.12
-4,-3,7:18.12
-2,-3,7:18.12
-1,-3,7:18.12
2,-3,7:18.12
-4,-2,7:18.12
-3,-2,7:18.12
-2,-2,7:18.12
-1,-2,7:18.12
0,-2,7:18.12
1,-2,7:18.14
2,-2,7:18.12
3,-2,7:18.12
-4,-1,7:18.12
-3,-1,7:18.12
-2,-1,7:17.12
-1,-1,7:17.12
0,-1,7:18.14
1,-1,7:18.14
-4,0,7:18.12
0,0,7:17.12
1,0,7:18.14
2,0,7:18.12
-4,1,7:18.12
-3,1,7:18.14
-2,1,7:18.12
1,1,7:18.12
-4,2,7:18.6
-2,2,7:18.6
-1,2,7:17.12
0,2,7:18.14
1,2,7:18.12
-2,3,7:18.6
-1,3,7:18.4
-1,4,7:18.4
-4,-4,8:18.14
-2,-4,8:18.12
-3,-3,8:18.4
1,-3,8:188.0
2,-3,8:18.14
-4,-2,8:18.12
-3,-2,8:18.12
-2,-2,8:18.12
-1,-2,8:17.12
0,-2,8:18.14
1,-2,8:188.0
2,-2,8:18.12
3,-2,8:18.12
-3,-1,8:17.12
-1,-1,8:188.0
0,-1,8:18.14
1,-1,8:17.12
2,-1,8:17.12
3,-1,8:18.14
-4,0,8:18.14
-3,0,8:188.0
-1,0,8:18.12
0,0,8:18.14
1,0,8:18.14
2,0,8:18.14
-4,1,8:18.14
-2,1,8:188.0
-1,1,8:18.12
0,1,8:18.14
1,1,8:18.12
2,1,8:18.12
-5,2,8:18.4
-3,2,8:17.12
-2,2,8:17.12
-1,2,8:18.12
0,2,8:17.12
1,2,8:17.12
2,2,8:18.14
-4,3,8:18.6
-3,3,8:18.6
-1,3,8:18.4
0,3,8:17.12
1,3,8:18.4
4,3,8:18.4
-2,4,8:18.6
1,4,8:18.4
3,4,8:18.4
0,5,8:18.4
1,5,8:18.6
1,-5,9:18.12
-4,-4,9:18.12
-3,-4,9:18.12
-2,-4,9:188.0
0,-4,9:18.12
1,-4,9:18.14
-4,-3,9:18.12
-3,-3,9:18.4
-2,-3,9:17.12
-1,-3,9:18.14
0,-3,9:18.14
1,-3,9:188.0
2,-3,9:18.12
-4,-2,9:18.12
-3,-2,9:188.0
-1,-2,9:18.14
2,-2,9:18.12
-3,-1,9:18.14
-2,-1,9:18.12
-1,-1,9:18.12
1,-1,9:18.12
2,-1,9:18.14
3,-1,9:18.12
4,-1,9:18.12
-5,0,9:18.12
-3,0,9:18.12
-1,0,9:18.12
1,0,9:18.14
2,0,9:18.14
-4,1,9:18.12
-2,1,9:18.14
0,1,9:18.14
3,1,9:18.14
4,1,9:18.14
-5,2,9:18.6
-4,2,9:17.12
1,2,9:18.14
2,2,9:18.12
3,2,9:188.0
-5,3,9:18.4
-3,3,9:18.4
-2,3,9:17.12
-1,3,9:18.6
0,3,9:188.0
1,3,9:18.4
2,3,9:17.12
3,3,9:17.12
4,3,9:18.4
-3,4,9:18.6
-1,4,9:18.4
0,4,9:17.12
1,4,9:18.4
2,4,9:18.6
3,4,9:18.4
-1,5,9:18.4
0,5,9:18.6
-2,-4,10:18.14
0,-4,10:18.12
-4,-3,10:18.14
-3,-3,10:18.4
-2,-3,10:18.12
-1,-3,10:18.14
1,-3,10:18.12
-4,-2,10:18.14
-3,-2,10:18.12
-2,-2,10:18.14
-1,-2,10:18.12
-2,-1,10:18.12
0,-1,10:18.12
3,-1,10:18.12
-1,0,10:18.12
0,0,10:18.14
1,0,10:18.12
2,0,10:18.12
-5,1,10:18.12
-4,1,10:18.12
-3,1,10:18.14
-1,1,10:18.12
0,1,10:18.12
2,1,10:18.12
4,1,10:18.12
-5,2,10:18.6
-3,2,10:18.6
-2,2,10:18.6
1,2,10:18.12
3,2,10:18.14
4,2,10:18.14
-3,3,10:17.12
-2,3,10:18.6
-1,3,10:18.4
0,3,10:18.4
1,3,10:18.6
2,3,10:18.4
4,3,10:18.4
-4,4,10:18.6
-3,4,10:18.6
-1,4,10:18.4
0,4,10:18.6
1,4,10:18.6
3,4,10:18.4
0,5,10:18.4
2,5,10:18.4
-3,-2,11:18.12
-1,-2,11:18.14
-2,-1,11:18.14
-1,-1,11:18.14
0,-1,11:18.12
1,-1,11:18.12
-1,0,11:18.12
0,0,11:18.12
1,0,11:18.12
2,0,11:18.12
-3,1,11:18.12
0,1,11:18.14
1,1,11:18.14
2,1,11:18.14
-3,2,11:18.6
1,2,11:18.14
-4,3,11:18.6
-3,3,11:18.4
-2,3,11:18.4
0,3,11:18.6
-3,4,11:18.6
