[META]
version=2.0
spawnOnBlockType=2
spawnSunlight=True
spawnDarkness=True
spawnWater=False
spawnLava=False
underFill=False
randomRotation=True
dig=True
tree=False
branch=False
needsFoundation=True
rarity=100
collisionPercentage=20
spawnElevationMin=0
spawnElevationMax=200
spawnInBiome=Custom
[DATA]
-1,-1,0:17.13
1,-1,0:191.0
2,-1,0:191.0
-1,0,0:191.0
1,0,0:191.0
1,1,0:17.13
0,2,0:191.0
1,2,0:191.0
0,0,1:17.13
0,0,2:17.13
0,0,3:17.13
0,0,4:17.13
-1,1,4:18.6
-2,-1,5:18.4
-1,-1,5:18.4
0,-1,5:18.6
-1,0,5:191.0
0,0,5:17.13
0,1,5:18.6
2,-3,6:18.6
2,-2,6:18.6
-2,0,6:18.4
0,0,6:17.13
-1,1,6:18.6
0,1,6:17.13
0,2,6:18.4
1,2,6:18.4
3,-5,7:18.6
2,-4,7:18.6
3,-4,7:18.6
4,-4,7:18.6
-2,-3,7:18.6
1,-3,7:18.4
3,-3,7:18.6
-2,-2,7:18.6
2,-2,7:17.13
1,-1,7:17.13
2,-1,7:18.4
-1,0,7:17.13
0,0,7:17.13
1,2,7:17.13
2,2,7:17.13
4,2,7:18.4
0,3,7:18.4
1,3,7:17.13
3,3,7:18.6
2,4,7:18.6
1,5,7:18.6
-5,-5,8:18.6
2,-5,8:18.6
4,-5,8:18.4
-1,-4,8:18.4
3,-4,8:17.13
-3,-3,8:18.6
-2,-3,8:18.4
1,-3,8:191.0
2,-3,8:17.13
4,-3,8:18.4
-3,-1,8:17.13
0,-1,8:18.6
-5,0,8:18.6
-4,0,8:18.4
-2,0,8:17.13
0,0,8:17.13
-6,1,8:18.6
-5,1,8:18.6
-2,1,8:191.0
1,1,8:18.4
2,1,8:18.4
3,1,8:18.6
-5,2,8:18.6
-3,2,8:18.6
-2,2,8:18.4
0,2,8:18.4
3,2,8:17.13
-2,3,8:18.4
1,3,8:18.6
2,3,8:18.4
4,3,8:18.4
-2,4,8:18.4
0,4,8:191.0
1,4,8:17.13
-2,5,8:18.6
0,5,8:18.4
1,5,8:18.4
2,5,8:18.6
-3,-6,9:18.6
1,-6,9:18.4
-4,-5,9:18.4
2,-5,9:18.6
3,-5,9:18.6
-1,-4,9:18.4
0,-4,9:18.6
2,-4,9:18.4
3,-4,9:18.6
4,-4,9:18.6
3,-3,9:18.6
-5,-2,9:18.4
-4,-2,9:191.0
-3,-2,9:18.4
-2,-2,9:18.4
-6,-1,9:18.4
-5,-1,9:18.6
-4,-1,9:17.13
-2,-1,9:18.6
4,-1,9:18.4
-6,0,9:18.4
-4,0,9:17.13
-2,0,9:18.6
-1,0,9:18.4
0,0,9:17.13
-4,1,9:18.6
-3,1,9:18.6
-2,1,9:18.4
2,1,9:18.6
-5,2,9:18.6
2,2,9:18.6
3,2,9:18.4
4,2,9:18.4
2,3,9:18.4
3,3,9:18.4
-2,4,9:18.6
-1,4,9:18.6
0,4,9:18.4
1,4,9:18.4
-2,5,9:18.6
-1,5,9:18.6
-1,-6,10:18.6
0,-6,10:18.4
2,-6,10:18.4
-2,-5,10:18.6
2,-4,10:18.6
-3,-3,10:18.6
-2,-3,10:18.4
2,-3,10:18.6
-5,-2,10:18.6
-1,-2,10:17.13
-6,-1,10:18.4
-5,-1,10:17.13
-4,-1,10:18.6
0,-1,10:17.13
2,-1,10:18.6
-6,0,10:18.6
-5,0,10:18.4
-4,0,10:18.4
-3,0,10:18.4
0,0,10:17.13
1,0,10:17.13
3,0,10:18.4
-4,1,10:17.13
-3,1,10:18.4
-5,2,10:18.6
-4,2,10:18.6
-3,2,10:18.6
-2,3,10:18.6
3,3,10:18.4
-1,4,10:18.4
0,4,10:18.6
1,4,10:18.4
-1,5,10:18.6
1,6,10:18.6
-1,-6,11:18.4
-3,-5,11:18.6
-2,-5,11:18.6
0,-5,11:18.4
2,-5,11:18.6
3,-5,11:18.4
-4,-4,11:18.4
-3,-4,11:18.6
-1,-4,11:17.13
2,-4,11:18.6
3,-4,11:18.4
-3,-3,11:191.0
-2,-3,11:17.13
-1,-3,11:17.13
-5,-2,11:18.6
-3,-2,11:18.4
-2,-2,11:18.4
-6,-1,11:18.6
-5,-1,11:18.4
-4,-1,11:18.4
4,-1,11:18.6
-4,0,11:18.4
0,0,11:17.13
1,0,11:17.13
3,0,11:18.4
-5,1,11:18.6
-4,1,11:18.6
-3,1,11:18.6
-1,1,11:17.13
2,1,11:18.4
3,1,11:18.6
5,1,11:18.6
6,1,11:18.6
-3,2,11:18.6
-4,3,11:18.4
-2,3,11:18.6
-1,4,11:18.6
-3,-6,12:18.4
-2,-6,12:18.6
-1,-6,12:18.6
0,-6,12:18.4
2,-6,12:18.4
-5,-5,12:18.6
-2,-5,12:191.0
-1,-5,12:17.13
0,-5,12:18.4
1,-5,12:18.6
3,-5,12:18.4
-3,-4,12:18.4
-3,-3,12:17.13
-2,-3,12:18.6
0,-3,12:18.4
-3,-2,12:18.4
2,-2,12:18.4
-5,-1,12:18.6
-5,0,12:18.6
0,0,12:17.13
2,0,12:17.13
6,0,12:18.4
-4,1,12:18.4
5,1,12:18.6
-5,2,12:18.6
-4,2,12:18.6
-1,2,12:17.13
5,2,12:18.6
-5,3,12:18.6
-3,3,12:191.0
-2,3,12:17.13
0,3,12:17.13
1,3,12:191.0
-4,4,12:18.6
-1,4,12:18.4
0,4,12:18.4
2,4,12:18.4
3,4,12:18.6
-2,5,12:18.4
-1,5,12:18.4
-1,-6,13:18.4
-1,-5,13:18.6
0,-5,13:18.4
-4,-4,13:18.6
-3,-4,13:18.6
-2,-4,13:18.4
-1,-4,13:18.4
0,-4,13:18.4
1,-4,13:18.4
2,-4,13:18.6
4,-4,13:18.4
-4,-3,13:18.4
-3,-3,13:18.4
1,-3,13:18.6
2,-3,13:18.6
3,-3,13:18.4
5,-3,13:18.6
-4,-2,13:18.4
-3,-2,13:18.4
-1,-2,13:18.4
4,-2,13:18.4
5,-2,13:18.6
-3,-1,13:18.4
0,-1,13:18.6
-5,0,13:18.4
0,0,13:17.13
3,0,13:18.6
5,0,13:18.4
2,1,13:17.13
5,1,13:18.6
-5,2,13:18.6
3,2,13:18.4
-3,3,13:18.4
-2,3,13:18.6
0,3,13:18.4
1,3,13:18.4
2,3,13:18.6
-2,4,13:17.13
0,4,13:17.13
1,4,13:18.6
4,4,13:18.6
-4,5,13:18.6
-3,5,13:18.4
-2,5,13:18.6
-1,5,13:18.6
0,5,13:18.4
1,5,13:18.4
-3,6,13:18.6
-2,-5,14:18.6
-1,-5,14:18.4
-4,-4,14:18.4
-1,-4,14:18.6
0,-4,14:18.4
2,-4,14:18.6
4,-4,14:18.6
6,-4,14:18.4
-3,-3,14:18.6
1,-3,14:18.6
2,-3,14:18.4
5,-1,14:18.6
-1,0,14:17.13
-4,1,14:18.6
0,1,14:17.13
1,1,14:18.6
3,1,14:17.13
5,1,14:18.6
-4,2,14:18.6
-2,2,14:18.4
-1,2,14:18.4
2,2,14:18.4
3,2,14:17.13
-5,3,14:18.6
-4,3,14:18.6
3,3,14:18.4
4,3,14:18.4
-6,4,14:18.4
-4,4,14:18.4
-3,4,14:18.6
-2,4,14:18.4
-1,4,14:18.6
2,4,14:18.6
-4,5,14:18.6
-3,5,14:17.13
-2,5,14:18.6
0,5,14:18.4
-3,6,14:18.4
-2,6,14:18.6
-2,-6,15:18.4
1,-6,15:18.4
-2,-5,15:18.4
-1,-4,15:18.6
3,-4,15:18.4
2,-3,15:18.6
3,-3,15:18.4
5,-3,15:18.4
6,-3,15:18.6
0,-1,15:18.4
-1,0,15:17.13
1,0,15:18.6
3,0,15:191.0
5,0,15:18.4
-5,1,15:18.6
-4,1,15:18.6
0,1,15:17.13
3,1,15:17.13
5,1,15:18.6
-4,2,15:18.4
4,2,15:18.6
3,3,15:17.13
4,3,15:18.6
5,3,15:18.4
-3,4,15:18.6
3,4,15:18.6
-2,5,15:18.4
0,5,15:18.6
-4,6,15:18.6
1,-6,16:18.4
-2,-5,16:18.4
-1,-5,16:18.6
1,-5,16:18.6
2,-5,16:18.4
-3,-4,16:18.4
0,-4,16:18.4
1,-4,16:18.6
2,-4,16:18.6
-1,-3,16:18.4
0,-3,16:18.4
5,-3,16:18.6
-2,-2,16:18.6
-2,-1,16:18.6
-5,0,16:18.6
-4,0,16:18.4
-1,0,16:17.13
0,0,16:18.6
-5,1,16:18.6
0,1,16:191.0
3,1,16:18.6
4,1,16:17.13
-5,2,16:18.6
-3,2,16:18.4
0,2,16:17.13
1,2,16:18.4
3,2,16:18.4
-5,3,16:18.6
-3,3,16:18.4
-2,3,16:18.4
2,3,16:18.6
3,3,16:18.4
4,3,16:18.6
-2,4,16:18.4
1,4,16:18.4
2,4,16:18.6
3,4,16:18.6
-4,5,16:18.6
-4,6,16:18.4
0,-5,17:18.6
-2,-4,17:18.4
1,-4,17:18.4
3,-4,17:18.6
4,-4,17:18.4
5,-4,17:18.6
-2,-3,17:18.4
2,-3,17:18.6
3,-3,17:18.6
5,-3,17:18.4
-3,-2,17:18.4
3,-2,17:18.4
4,-2,17:18.6
5,-2,17:18.4
-4,-1,17:18.6
-1,-1,17:17.13
4,-1,17:18.4
-1,0,17:17.13
0,0,17:18.4
1,0,17:18.6
4,0,17:18.6
5,0,17:18.6
0,1,17:18.4
2,1,17:18.4
3,1,17:18.6
4,1,17:17.13
-5,2,17:18.4
-2,2,17:18.6
0,2,17:17.13
3,2,17:18.6
4,2,17:18.6
5,2,17:18.6
-3,3,17:18.6
-2,3,17:18.6
5,3,17:18.6
-1,4,17:18.4
0,4,17:18.6
1,4,17:18.4
4,4,17:18.6
-1,-5,18:18.4
-2,-4,18:18.6
0,-4,18:18.4
2,-4,18:18.4
-2,-3,18:191.0
-1,-3,18:17.13
0,-3,18:18.6
2,-3,18:18.6
5,-3,18:18.6
-3,-2,18:18.4
-1,-2,18:17.13
0,-2,18:191.0
3,-2,18:18.4
4,-2,18:18.4
-3,0,18:18.4
-2,0,18:17.13
-1,0,18:18.4
0,0,18:18.4
4,0,18:18.6
-2,1,18:18.6
3,1,18:18.6
4,1,18:18.6
-4,2,18:18.4
0,2,18:18.4
4,2,18:18.4
-3,3,18:18.6
-1,3,18:18.6
0,3,18:17.13
1,3,18:191.0
3,3,18:18.6
-2,4,18:18.6
0,4,18:18.6
1,4,18:18.6
0,-5,19:18.6
-1,-4,19:17.13
0,-4,19:18.6
0,-3,19:18.4
2,-3,19:18.6
3,-3,19:18.6
4,-3,19:18.4
-1,-2,19:18.4
1,-2,19:18.6
5,-2,19:18.6
-3,-1,19:18.4
-1,-1,19:18.6
-2,0,19:17.13
-1,0,19:18.4
0,0,19:18.4
4,0,19:18.4
-3,1,19:18.6
-2,1,19:18.6
-1,1,19:18.4
-2,2,19:18.6
-1,2,19:18.4
0,3,19:17.13
1,3,19:18.6
2,3,19:18.6
-3,4,19:18.4
-1,4,19:18.4
0,4,19:18.6
1,4,19:18.6
-2,-4,20:18.6
-1,-4,20:18.6
0,-4,20:18.6
-2,-1,20:18.4
0,-1,20:18.6
-3,0,20:18.4
-2,0,20:18.6
-1,0,20:18.4
0,0,20:18.4
3,0,20:18.4
-2,1,20:18.4
0,1,20:18.6
2,1,20:18.6
0,2,20:18.4
2,2,20:18.4
0,3,20:18.4
