[META]
version=2.0
spawnOnBlockType=2
spawnSunlight=True
spawnDarkness=True
spawnWater=False
spawnLava=False
underFill=False
randomRotation=True
dig=True
tree=False
branch=False
needsFoundation=True
rarity=100
collisionPercentage=20
spawnElevationMin=0
spawnElevationMax=200
spawnInBiome=Custom
[DATA]
0,-3,0:17.14
3,-1,0:17.14
-1,1,0:17.14
0,-3,1:17.14
2,-1,1:17.14
-1,0,1:17.14
0,0,1:17.14
0,-2,2:17.14
0,-1,2:17.14
0,0,2:17.14
1,0,2:17.14
0,0,3:17.2
-2,-2,4:18.6
-1,-2,4:18.6
0,-2,4:18.6
2,-2,4:18.6
1,-1,4:18.6
2,-1,4:18.6
0,0,4:17.2
1,0,4:18.6
2,2,4:18.6
-1,-3,5:18.6
0,-3,5:18.6
1,-3,5:18.6
-1,-2,5:18.6
1,-2,5:18.6
2,-2,5:18.6
2,-1,5:18.6
3,-1,5:18.6
0,0,5:17.2
2,0,5:18.6
3,0,5:18.6
2,1,5:18.6
1,2,5:18.6
2,2,5:18.6
1,3,5:18.6
-1,-2,6:18.6
0,-2,6:18.6
1,-2,6:18.6
2,-2,6:18.6
2,-1,6:18.6
0,0,6:17.14
1,2,6:18.6
2,2,6:18.6
1,3,6:18.6
-1,-3,7:18.6
0,-3,7:18.6
-2,-2,7:18.6
0,-2,7:18.6
1,-2,7:18.6
2,-2,7:18.6
1,-1,7:189.0
-2,0,7:18.6
0,0,7:17.14
1,0,7:17.14
2,1,7:18.6
3,1,7:18.6
-2,2,7:18.6
1,2,7:18.6
0,-2,8:18.6
0,0,8:17.14
2,0,8:18.6
-3,1,8:18.6
-2,1,8:18.6
0,1,8:17.14
1,1,8:18.6
-2,2,8:18.6
-1,2,8:18.6
0,2,8:18.6
2,2,8:18.6
-1,3,8:18.6
0,3,8:18.6
0,-2,9:18.6
-2,-1,9:18.6
-3,0,9:18.6
-2,0,9:189.0
-1,0,9:17.14
0,0,9:17.14
1,0,9:189.0
-3,1,9:18.6
-2,1,9:18.6
-1,1,9:18.6
0,1,9:18.6
-2,2,9:18.6
-1,2,9:18.6
0,3,9:18.6
-1,-2,10:18.6
0,-2,10:18.6
1,-2,10:18.6
-3,0,10:18.6
-2,0,10:18.6
-1,0,10:18.6
0,0,10:17.14
2,0,10:18.6
-3,1,10:18.6
-2,2,10:18.6
-1,2,10:18.6
0,2,10:18.6
-1,3,10:18.6
0,-1,11:18.6
2,-1,11:18.6
0,0,11:17.14
1,0,11:189.0
-2,1,11:18.6
2,1,11:18.6
-2,2,11:18.6
-1,2,11:18.6
0,-1,12:17.14
1,-1,12:18.6
-1,0,12:18.6
0,0,12:17.14
-1,1,12:18.6
-1,2,12:18.6
0,2,12:18.6
-2,-1,13:18.6
-1,-1,13:18.6
0,-1,13:189.0
1,-1,13:18.6
-2,0,13:18.6
-1,0,13:18.6
0,0,13:17.14
1,0,13:18.6
-2,1,13:18.6
0,1,13:189.0
1,1,13:18.6
-2,-1,14:18.6
-2,0,14:18.6
0,0,14:17.14
1,0,14:18.6
-1,2,14:18.6
0,2,14:18.6
-1,-1,15:18.6
0,0,15:17.14
-1,-1,16:18.6
0,-1,16:18.6
-1,0,16:18.6
0,0,16:17.14
-1,1,16:18.6
0,1,16:18.6
-1,0,17:18.6
0,1,17:18.6
