[META]
version=2.0
spawnOnBlockType=2
spawnSunlight=True
spawnDarkness=True
spawnWater=False
spawnLava=False
underFill=False
randomRotation=True
dig=True
tree=False
branch=False
needsFoundation=True
rarity=100
collisionPercentage=20
spawnElevationMin=0
spawnElevationMax=200
spawnInBiome=Custom
[DATA]
1,0,0:188.0
-1,-2,1:18.4
0,-2,1:18.4
-2,-1,1:18.15
-1,-1,1:18.12
0,-1,1:18.4
2,-1,1:18.4
-1,0,1:188.0
0,0,1:18.4
1,0,1:188.0
2,0,1:18.7
-1,1,1:18.15
0,1,1:18.7
1,1,1:18.7
-1,-1,2:18.15
0,-1,2:18.4
1,-1,2:18.7
-2,0,2:18.15
0,0,2:18.7
2,0,2:18.4
-1,1,2:18.12
1,1,2:18.4
0,-2,3:18.4
-1,0,3:18.4
0,0,3:18.4
1,0,3:18.7
0,1,3:18.7
0,-1,3:38.3
0,1,2:38.3
1,0,2:38.3
-1,0,2:38.3
0,-2,2:38.3
