[META]
version=2.0
spawnOnBlockType=2
spawnSunlight=True
spawnDarkness=True
spawnWater=False
spawnLava=False
underFill=False
randomRotation=True
dig=True
tree=False
branch=False
needsFoundation=True
rarity=100
collisionPercentage=20
spawnElevationMin=0
spawnElevationMax=200
spawnInBiome=Custom
[DATA]
-4,-4,0:17.13
5,-4,0:17.13
6,-4,0:17.13
4,-3,0:17.13
0,0,0:17.13
4,0,0:17.13
5,0,0:17.13
-1,1,0:17.13
0,1,0:17.13
6,1,0:17.13
7,1,0:17.13
2,3,0:17.13
-4,4,0:17.13
3,4,0:17.13
4,5,0:17.13
5,6,0:17.13
-3,-3,1:17.13
-2,-2,1:17.13
3,-2,1:17.13
-2,-1,1:17.13
1,-1,1:17.13
2,-1,1:17.13
3,-1,1:17.13
-1,0,1:17.13
0,0,1:17.13
-1,1,1:17.13
0,1,1:17.13
-2,2,1:17.13
1,2,1:17.13
-3,3,1:17.13
-1,1,2:17.13
0,1,2:17.13
-2,2,2:191.0
-1,0,3:18.7
0,0,3:17.13
-2,1,3:17.13
0,1,3:17.13
1,1,3:191.0
-2,2,3:18.7
-1,3,3:18.7
-2,-1,4:18.7
-2,0,4:17.13
0,0,4:17.13
-3,1,4:18.7
-2,1,4:18.7
-1,1,4:18.15
0,1,4:18.15
1,1,4:17.13
-2,2,4:18.7
-1,3,4:18.15
-2,0,5:17.13
0,0,5:17.13
-3,1,5:18.7
1,1,5:17.13
-3,2,5:18.7
0,2,5:18.15
1,3,5:18.15
2,3,5:18.15
2,5,5:18.7
1,-2,6:191.0
-3,-1,6:191.0
0,-1,6:18.7
1,-1,6:17.13
-3,0,6:17.13
-2,0,6:191.0
-1,1,6:18.7
0,2,6:18.15
1,2,6:17.13
2,2,6:17.13
3,2,6:18.15
-1,3,6:18.15
0,3,6:18.15
0,4,6:18.15
0,6,6:18.7
-2,-6,7:18.15
0,-5,7:18.7
2,-5,7:18.7
4,-5,7:18.7
-4,-4,7:18.7
1,-4,7:18.15
2,-4,7:18.15
4,-4,7:18.7
2,-3,7:18.15
3,-3,7:18.15
4,-3,7:18.7
-4,-2,7:18.15
-1,-2,7:18.7
0,-2,7:18.7
-3,-1,7:18.15
1,-1,7:17.13
-4,0,7:18.15
-3,0,7:17.13
1,0,7:17.13
3,0,7:18.15
4,0,7:18.15
-2,1,7:18.7
2,1,7:18.7
4,1,7:18.15
-5,2,7:18.7
-3,2,7:18.15
-2,2,7:18.15
0,2,7:18.15
1,2,7:17.13
3,2,7:18.15
-5,3,7:18.7
2,3,7:18.7
5,3,7:18.7
-6,4,7:18.7
-4,4,7:18.7
-3,4,7:18.7
5,4,7:18.7
-6,5,7:18.15
-4,5,7:18.15
0,5,7:18.7
0,6,7:18.7
1,6,7:18.7
2,6,7:18.7
3,6,7:18.7
-3,-6,8:18.7
-1,-6,8:18.7
0,-6,8:18.7
1,-6,8:18.7
1,-5,8:18.7
-2,-4,8:18.7
-5,-3,8:18.15
5,-3,8:18.7
-7,-1,8:18.15
-6,-1,8:18.15
-4,-1,8:191.0
-3,-1,8:17.13
1,-1,8:17.13
2,-1,8:18.7
-6,0,8:18.7
-3,0,8:18.7
-4,1,8:18.7
-3,1,8:18.7
-2,1,8:18.7
-7,2,8:18.7
2,2,8:17.13
5,2,8:18.7
-6,3,8:18.7
-1,3,8:18.7
0,3,8:18.7
1,3,8:18.7
5,3,8:18.7
-6,4,8:18.7
-1,4,8:18.15
1,4,8:18.7
2,4,8:18.7
4,4,8:18.7
-3,5,8:18.7
-2,5,8:18.7
-1,5,8:18.7
5,5,8:18.7
-5,6,8:18.7
-4,6,8:18.7
0,6,8:18.7
3,6,8:18.15
-2,-7,9:18.7
2,-6,9:18.7
3,-6,9:18.7
4,-6,9:18.7
-4,-5,9:18.7
-3,-5,9:18.7
-1,-5,9:18.7
4,-5,9:18.7
2,-4,9:18.15
-3,-3,9:18.7
0,-3,9:18.7
2,-3,9:18.7
3,-3,9:18.7
-3,-2,9:18.7
-2,-2,9:18.7
-1,-2,9:191.0
0,-2,9:17.13
1,-2,9:17.13
2,-2,9:191.0
-6,-1,9:18.7
-5,-1,9:18.15
-4,-1,9:18.15
-3,-1,9:17.13
-2,-1,9:18.7
3,-1,9:18.7
-7,0,9:18.7
-3,0,9:17.13
1,0,9:18.7
-3,1,9:18.7
1,1,9:18.7
5,1,9:18.7
-5,2,9:18.7
2,2,9:17.13
3,2,9:18.7
-1,3,9:18.15
4,3,9:18.7
5,3,9:18.7
6,3,9:18.7
-7,4,9:18.15
-6,4,9:18.15
-5,4,9:18.7
-1,4,9:18.7
-6,5,9:18.7
-1,5,9:18.15
2,5,9:18.15
3,5,9:18.15
5,5,9:18.7
-7,6,9:18.7
-4,6,9:18.15
4,6,9:18.15
-5,7,9:18.7
-2,-7,10:18.7
1,-7,10:18.7
2,-6,10:18.15
3,-6,10:18.15
4,-6,10:18.7
-5,-5,10:18.7
-4,-5,10:18.7
-3,-5,10:18.7
-3,-4,10:18.15
2,-4,10:18.7
3,-4,10:18.7
5,-4,10:18.7
-4,-3,10:18.7
-2,-2,10:191.0
-1,-2,10:191.0
1,-2,10:17.13
4,-2,10:18.7
-5,-1,10:17.13
-4,-1,10:17.13
-5,0,10:18.7
-4,0,10:18.7
-3,0,10:18.7
-1,0,10:18.7
5,0,10:18.15
-4,1,10:18.7
-3,1,10:18.7
2,1,10:18.7
4,1,10:18.7
5,1,10:18.7
-2,2,10:18.15
-1,2,10:18.15
0,2,10:191.0
1,2,10:191.0
2,2,10:17.13
3,2,10:18.7
5,2,10:18.7
-5,3,10:18.7
-2,3,10:18.7
3,3,10:18.7
-5,4,10:18.7
-3,4,10:18.7
-1,4,10:18.7
2,4,10:18.7
3,4,10:18.7
-6,5,10:18.7
-4,5,10:18.15
3,5,10:18.15
5,5,10:18.7
-5,6,10:18.15
-3,6,10:18.7
5,6,10:18.15
-1,7,10:18.7
1,7,10:18.7
4,7,10:18.7
-4,-7,11:18.7
-1,-6,11:18.7
-2,-5,11:18.7
3,-5,11:18.7
4,-5,11:18.7
-4,-4,11:18.7
-2,-4,11:18.15
-4,-3,11:18.7
1,-3,11:17.13
2,-3,11:191.0
-4,-2,11:191.0
-2,-2,11:191.0
-5,-1,11:18.7
-4,-1,11:17.13
0,-1,11:18.7
-6,0,11:18.7
-3,0,11:18.7
2,1,11:17.13
4,1,11:18.7
-4,2,11:18.15
-3,2,11:18.15
-1,2,11:191.0
0,2,11:191.0
2,2,11:17.13
-4,3,11:18.7
-2,3,11:18.7
2,3,11:18.7
5,3,11:18.7
-3,4,11:18.7
-1,4,11:18.7
0,4,11:18.7
2,4,11:18.7
3,4,11:18.7
5,4,11:18.7
-6,5,11:18.7
-4,5,11:18.15
-1,5,11:18.15
0,5,11:18.15
-6,6,11:18.7
2,6,11:18.7
-4,-7,12:18.7
-5,-6,12:18.7
-4,-6,12:18.7
-3,-6,12:18.7
-2,-6,12:18.7
1,-5,12:18.7
1,-3,12:17.13
-4,-2,12:17.13
-2,-2,12:191.0
-1,-2,12:18.7
-5,-1,12:191.0
-4,-1,12:17.13
3,-1,12:18.15
3,0,12:18.7
-1,1,12:18.7
4,1,12:18.7
-2,2,12:191.0
-1,2,12:191.0
3,2,12:17.13
3,3,12:191.0
-5,-7,13:18.7
-3,-6,13:17.13
-4,-4,13:18.15
0,-4,13:18.15
1,-4,13:18.7
2,-4,13:17.13
-7,-2,13:18.15
-6,-1,13:18.15
-5,-1,13:17.13
-2,2,13:191.0
3,2,13:17.13
-3,-8,14:18.7
-2,-8,14:18.7
-1,-7,14:18.7
3,-7,14:18.7
-3,-6,14:18.15
1,-5,14:18.7
3,-5,14:18.7
-1,-4,14:18.7
0,-4,14:18.7
2,-4,14:17.13
-7,-2,14:18.15
-5,-1,14:17.13
-3,-1,14:18.7
-5,0,14:191.0
-4,0,14:18.7
-7,1,14:18.7
-4,1,14:18.7
-6,2,14:18.7
-2,2,14:191.0
2,3,14:18.15
3,3,14:17.13
-5,4,14:18.7
-4,4,14:18.15
-3,4,14:18.15
0,4,14:18.7
2,4,14:18.7
-4,5,14:18.15
-3,5,14:18.15
3,5,14:18.7
4,5,14:18.7
5,5,14:18.7
-5,6,14:18.7
-2,6,14:18.15
2,6,14:18.7
3,6,14:18.7
-2,-7,15:18.7
1,-7,15:18.7
2,-7,15:18.7
-2,-6,15:18.15
1,-6,15:18.7
3,-6,15:18.7
4,-6,15:18.7
-2,-5,15:18.7
0,-5,15:18.7
1,-5,15:18.7
2,-5,15:17.13
4,-5,15:18.7
0,-4,15:18.7
1,-4,15:18.7
3,-4,15:18.7
-6,-3,15:18.7
-4,-3,15:18.7
1,-3,15:18.7
2,-3,15:18.7
-6,-2,15:18.15
-5,-2,15:18.15
-1,-2,15:18.7
2,-2,15:18.7
3,-2,15:18.7
-6,-1,15:17.13
2,-1,15:18.7
-7,0,15:18.15
-5,0,15:18.7
-5,1,15:18.7
-4,1,15:18.7
-3,1,15:18.7
-2,2,15:191.0
-5,3,15:18.7
-4,3,15:18.7
-3,3,15:18.7
-2,3,15:18.7
3,3,15:17.13
-5,4,15:18.7
-3,4,15:18.7
-2,4,15:18.7
3,4,15:17.13
-3,5,15:17.13
5,5,15:18.7
-5,6,15:18.7
-3,6,15:18.7
4,6,15:18.7
-3,7,15:18.7
-2,7,15:18.7
2,-6,16:18.7
3,-6,16:18.7
4,-6,16:18.7
1,-4,16:18.15
2,-4,16:18.15
-7,-3,16:18.7
-3,-3,16:18.7
2,-3,16:18.15
-5,-2,16:18.7
-2,-2,16:18.7
-8,-1,16:18.7
-6,-1,16:18.7
2,-1,16:18.7
-6,1,16:18.15
-5,1,16:18.7
-5,2,16:18.7
-2,2,16:191.0
2,2,16:18.15
-6,3,16:18.7
-4,3,16:18.7
-3,3,16:18.7
2,3,16:18.15
4,3,16:17.13
-5,4,16:18.7
-4,4,16:18.7
-2,4,16:18.7
1,4,16:18.15
-3,5,16:18.7
-1,5,16:18.7
0,5,16:18.7
-5,6,16:18.7
-4,6,16:18.7
-2,6,16:18.7
-1,6,16:18.7
2,6,16:18.15
2,-5,17:18.7
1,-4,17:18.15
-5,-3,17:18.7
-4,-3,17:18.7
-3,-3,17:18.7
-7,-2,17:18.7
3,-2,17:18.7
-4,-1,17:18.7
-2,-1,17:18.7
1,-1,17:18.15
3,-1,17:18.7
5,1,17:18.7
-7,2,17:18.7
2,2,17:18.7
-5,3,17:18.7
2,3,17:18.15
3,3,17:18.15
4,3,17:17.13
5,3,17:18.7
-4,4,17:18.7
0,4,17:18.7
1,4,17:18.7
2,4,17:18.7
3,4,17:18.7
4,4,17:18.7
1,5,17:18.15
2,5,17:18.15
3,5,17:18.15
4,5,17:18.7
1,-2,18:18.15
-5,-1,18:18.7
-1,-1,18:18.7
2,-1,18:18.7
3,-1,18:18.7
-4,0,18:18.15
-5,1,18:18.7
-1,1,18:18.7
3,1,18:18.7
-5,2,18:18.7
-1,2,18:18.15
2,2,18:18.7
3,2,18:18.7
2,3,18:18.7
3,3,18:18.7
4,3,18:17.13
5,3,18:18.7
2,4,18:18.7
0,5,18:18.7
