[META]
version=2.0
spawnOnBlockType=2
spawnSunlight=True
spawnDarkness=True
spawnWater=False
spawnLava=False
underFill=False
randomRotation=True
dig=True
tree=True
branch=False
needsFoundation=True
rarity=100
collisionPercentage=20
spawnElevationMin=0
spawnElevationMax=200
spawnInBiome=Custom
[DATA]
0,1,0:17.14
1,1,0:17.14
0,2,0:17.14
0,1,1:17.14
-1,1,2:189.0
0,1,2:17.14
-1,0,3:18.7
0,0,3:18.7
-1,1,3:17.14
0,1,3:17.14
0,2,3:17.14
1,0,4:17.14
-2,1,4:17.14
-2,2,4:18.7
0,2,4:17.14
0,0,5:18.7
1,0,5:17.14
-2,1,5:189.0
0,1,5:18.7
-3,2,5:18.7
0,3,5:17.14
2,3,5:18.15
-2,-1,6:18.7
0,-1,6:18.7
1,-1,6:18.7
-1,0,6:18.7
1,0,6:17.14
-4,1,6:18.7
-1,1,6:18.15
-3,2,6:18.15
-4,3,6:18.7
-1,3,6:17.14
0,3,6:17.14
1,3,6:189.0
1,4,6:18.15
1,-4,7:18.7
1,-3,7:18.7
2,-3,7:18.7
-2,-2,7:18.7
-1,-2,7:18.7
0,-2,7:18.7
-1,-1,7:18.7
1,-1,7:17.14
-2,0,7:18.7
1,0,7:18.7
2,0,7:18.7
-3,1,7:189.0
0,1,7:18.15
-5,2,7:18.7
-2,2,7:17.14
-1,2,7:189.0
-5,3,7:18.7
-4,3,7:18.7
1,3,7:18.15
-4,4,7:18.7
0,4,7:17.14
1,4,7:18.15
0,5,7:18.15
1,6,7:189.0
-1,-3,8:18.7
0,-3,8:189.0
-2,-2,8:18.7
-1,-1,8:18.7
1,-1,8:17.14
-3,0,8:18.7
-2,0,8:18.7
2,0,8:18.7
-5,1,8:18.7
-1,1,8:18.15
0,1,8:189.0
-5,2,8:18.7
-3,2,8:17.14
-3,3,8:18.7
-2,3,8:18.15
2,3,8:18.7
-5,4,8:18.7
-4,4,8:18.7
-3,4,8:18.7
0,4,8:17.14
3,4,8:18.7
-1,5,8:18.15
1,5,8:18.7
2,5,8:18.7
0,6,8:18.7
1,-4,9:18.7
1,-3,9:18.7
2,-3,9:18.7
0,-2,9:18.7
2,-2,9:18.7
-2,-1,9:18.7
-1,-1,9:18.7
1,-1,9:18.7
-4,0,9:18.7
-1,0,9:18.7
0,0,9:18.7
2,0,9:18.7
-5,1,9:18.7
-4,1,9:18.7
-3,1,9:18.7
-2,1,9:189.0
0,1,9:18.15
-5,3,9:18.7
-4,3,9:18.7
-3,3,9:18.7
-2,3,9:189.0
0,3,9:18.15
2,3,9:18.7
0,4,9:18.15
1,4,9:18.7
2,4,9:18.7
3,4,9:18.7
0,5,9:18.15
2,5,9:18.7
-1,0,10:18.7
-1,1,10:18.7
0,1,10:18.7
-2,2,10:18.7
