[META]
version=2.0
spawnOnBlockType=2
spawnSunlight=True
spawnDarkness=True
spawnWater=False
spawnLava=False
underFill=False
randomRotation=True
dig=True
tree=True
branch=False
needsFoundation=True
rarity=100
collisionPercentage=20
spawnElevationMin=0
spawnElevationMax=200
spawnInBiome=Custom
[DATA]
0,-6,0:17.14
1,-5,0:17.14
2,-5,0:17.14
1,-4,0:17.14
1,-5,1:17.14
1,-5,2:17.14
1,-5,3:17.14
1,-5,4:17.14
1,-4,5:17.14
1,-5,6:18.7
1,-4,6:17.14
2,-4,6:189.0
1,-3,6:17.14
0,-4,7:189.0
1,-4,7:17.14
-2,-3,7:18.7
2,-3,7:18.7
-3,-2,7:18.7
-2,-2,7:189.0
-1,-2,7:18.7
0,-2,7:17.14
2,-2,7:17.14
-4,-1,7:18.7
-1,-1,7:18.7
0,-1,7:18.7
-1,0,7:18.7
0,0,7:18.7
-4,1,7:18.7
-3,1,7:18.7
-1,1,7:18.7
0,1,7:18.7
-3,2,7:18.7
0,-4,8:17.14
-3,-3,8:18.7
-2,-3,8:18.7
1,-3,8:189.0
-4,-2,8:18.7
0,-2,8:18.7
2,-2,8:18.7
-4,-1,8:18.7
-2,-1,8:18.7
-1,-1,8:17.14
0,-1,8:189.0
2,-1,8:17.14
-4,0,8:18.7
-2,0,8:17.14
3,0,8:18.7
-3,1,8:18.7
-2,1,8:18.7
-1,1,8:18.7
4,1,8:18.7
-4,2,8:18.7
0,-4,9:17.14
-2,-3,9:18.7
3,-3,9:18.7
4,-3,9:18.7
5,-3,9:18.7
-3,-2,9:18.7
-2,-2,9:18.7
2,-2,9:18.7
4,-1,9:18.7
-2,0,9:18.7
0,0,9:18.15
2,0,9:18.15
3,0,9:17.14
4,0,9:189.0
5,0,9:18.7
-4,1,9:18.7
0,1,9:18.15
1,1,9:189.0
3,1,9:18.7
5,1,9:18.7
-3,2,9:18.7
4,2,9:18.7
4,3,9:18.7
0,-4,10:17.14
3,-4,10:18.7
5,-4,10:18.7
2,-3,10:18.7
6,-3,10:18.7
-3,-2,10:18.7
5,-2,10:18.7
-3,-1,10:18.7
0,-1,10:18.7
4,-1,10:18.7
5,-1,10:18.7
6,-1,10:18.7
2,0,10:18.15
3,1,10:17.14
4,1,10:18.7
5,2,10:18.7
3,3,10:18.7
4,3,10:18.7
5,3,10:18.7
0,-3,11:17.14
3,-3,11:18.7
5,-3,11:18.7
2,-2,11:18.7
3,-2,11:18.7
4,-2,11:18.7
6,-2,11:18.7
1,-1,11:18.7
2,-1,11:18.7
3,-1,11:18.7
4,1,11:18.7
3,2,11:18.15
5,2,11:18.7
0,-2,12:17.14
2,-2,12:18.15
-1,-1,12:189.0
0,-1,12:17.14
5,1,12:18.7
1,-3,13:18.7
1,-2,13:17.14
-2,0,13:18.7
0,0,13:17.14
-4,1,13:18.15
-2,1,13:18.7
-1,1,13:17.14
-5,2,13:18.15
-3,2,13:18.15
-1,2,13:18.7
-3,3,13:18.15
-2,3,13:18.7
-3,4,13:18.7
3,-4,14:18.15
4,-3,14:18.15
2,-2,14:18.15
-2,-1,14:18.7
0,-1,14:18.7
1,-1,14:17.14
3,-1,14:18.15
-4,0,14:18.7
-2,0,14:18.7
-1,0,14:18.7
1,0,14:18.7
3,0,14:18.7
4,0,14:18.7
-4,1,14:18.7
0,1,14:18.7
-5,2,14:18.7
-4,2,14:18.7
-3,2,14:18.7
-2,2,14:18.7
-1,2,14:17.14
-4,3,14:18.7
-2,3,14:18.7
-1,3,14:18.7
3,-4,15:18.7
1,-3,15:18.7
2,-3,15:18.7
3,-2,15:18.7
-2,-1,15:18.7
1,-1,15:17.14
4,-1,15:18.7
-1,0,15:18.7
2,0,15:18.7
4,0,15:18.7
-3,1,15:18.7
-2,1,15:18.7
0,1,15:18.7
4,1,15:18.7
-4,2,15:18.7
-3,2,15:18.7
-2,2,15:18.7
-1,2,15:18.7
1,2,15:18.7
3,2,15:18.7
-1,3,15:18.7
-3,4,15:18.7
4,-3,16:18.7
2,-2,16:18.7
3,0,16:18.7
4,0,16:18.7
0,1,16:18.7
1,2,16:18.7
