[META]
version=2.0
spawnOnBlockType=2
spawnSunlight=True
spawnDarkness=True
spawnWater=False
spawnLava=False
underFill=False
randomRotation=True
dig=True
tree=True
branch=False
needsFoundation=True
rarity=100
collisionPercentage=20
spawnElevationMin=0
spawnElevationMax=200
spawnInBiome=Custom
[DATA]
-1,0,0:17.14
-1,1,0:17.14
-1,1,1:17.14
-1,1,2:17.14
-1,0,3:17.14
-2,1,3:18.7
-1,1,3:189.0
0,1,3:18.15
-2,2,3:17.14
-1,2,3:18.15
-1,-1,4:18.7
0,-1,4:18.7
-1,0,4:17.14
0,0,4:189.0
-1,1,4:18.7
0,1,4:18.7
-3,2,4:18.15
-2,2,4:17.14
-3,3,4:18.15
-2,3,4:18.15
-1,3,4:18.7
-1,-2,5:18.7
-2,-1,5:18.7
-1,-1,5:17.14
0,-1,5:18.7
-2,0,5:18.7
-1,0,5:18.15
0,0,5:18.15
-2,1,5:18.7
-1,1,5:18.15
-3,2,5:18.15
-2,2,5:18.15
-1,2,5:18.15
-1,-1,6:17.14
0,-1,6:18.7
1,-1,6:18.7
-2,0,6:18.7
0,0,6:18.7
-1,-2,7:18.7
0,-1,7:18.7
-1,0,7:18.7
