[META]
version=2.0
spawnOnBlockType=2
spawnSunlight=True
spawnDarkness=True
spawnWater=False
spawnLava=False
underFill=False
randomRotation=True
dig=True
tree=True
branch=False
needsFoundation=True
rarity=100
collisionPercentage=20
spawnElevationMin=0
spawnElevationMax=200
spawnInBiome=Custom
[DATA]
0,-1,0:17.14
1,-1,0:17.14
2,-1,0:17.14
1,0,0:17.14
1,-1,1:17.14
1,-1,2:17.14
1,-1,3:17.14
0,-1,4:17.14
1,-1,4:17.14
1,0,4:189.0
2,-2,5:17.14
0,-1,5:17.14
1,0,5:18.7
2,0,5:18.7
2,-2,6:17.14
0,-1,6:17.14
-1,0,6:17.14
-1,1,6:189.0
2,-2,7:17.14
0,-1,7:17.14
2,-1,7:189.0
4,-1,7:18.15
4,0,7:18.15
3,1,7:18.7
4,1,7:18.7
4,2,7:189.0
2,-3,8:18.7
2,-2,8:17.14
3,-2,8:18.15
-2,-1,8:18.7
-1,-1,8:17.14
0,-1,8:18.15
3,-1,8:17.14
4,-1,8:18.15
3,0,8:189.0
4,0,8:17.14
0,1,8:18.7
2,1,8:18.15
3,1,8:18.15
4,1,8:18.7
3,2,8:18.15
3,-3,9:18.15
-4,-2,9:18.7
-2,-2,9:18.7
1,-2,9:189.0
2,-2,9:17.14
-2,-1,9:18.7
-1,-1,9:17.14
0,-1,9:18.15
2,-1,9:18.15
3,-1,9:18.15
-5,0,9:18.7
-2,0,9:18.7
2,0,9:18.15
5,0,9:18.15
-4,1,9:18.7
-2,1,9:18.7
-1,1,9:189.0
0,1,9:18.7
2,1,9:18.15
3,1,9:18.15
-4,2,9:18.7
-3,2,9:18.7
-2,2,9:18.7
-1,2,9:18.15
3,2,9:18.15
4,2,9:18.7
-2,3,9:18.7
-4,-3,10:18.7
-2,-3,10:18.7
-1,-3,10:18.15
-6,-2,10:18.7
1,-2,10:18.15
2,-2,10:17.14
5,-2,10:18.7
-4,-1,10:18.7
-3,-1,10:18.7
0,-1,10:18.15
1,-1,10:18.15
-5,0,10:18.7
-4,0,10:18.7
-2,0,10:18.7
-1,0,10:17.14
1,0,10:18.15
-4,1,10:18.7
3,1,10:18.7
2,2,10:18.7
-2,3,10:18.15
-1,3,10:18.15
-4,-3,11:18.7
-3,-3,11:18.7
-2,-3,11:18.15
-2,-2,11:18.7
-1,-2,11:18.15
2,-2,11:17.14
4,-2,11:18.7
-5,-1,11:18.7
-4,-1,11:18.15
-1,-1,11:17.14
4,-1,11:18.7
-5,0,11:18.15
-2,0,11:17.14
-1,0,11:18.7
0,0,11:18.7
1,0,11:18.7
-5,1,11:18.15
-1,1,11:18.7
3,1,11:18.7
-4,2,11:18.15
-3,2,11:18.15
-2,2,11:18.15
-1,2,11:18.7
-2,3,11:18.15
3,-3,12:17.14
-1,-2,12:18.7
-2,-1,12:18.7
-1,-1,12:17.14
4,0,12:18.7
-3,1,12:189.0
-2,1,12:17.14
-4,2,12:189.0
-2,2,12:18.7
6,-6,13:18.7
7,-5,13:18.7
6,-4,13:18.7
2,-3,13:18.7
3,-3,13:17.14
6,-3,13:18.15
-1,-2,13:17.14
3,-2,13:18.7
6,-2,13:18.15
5,-1,13:18.7
6,-1,13:18.15
-3,0,13:18.15
-1,0,13:18.15
6,0,13:18.15
-4,1,13:18.15
-3,1,13:18.15
-2,1,13:17.14
0,1,13:18.15
5,1,13:18.7
-4,2,13:18.7
-3,2,13:18.15
-2,2,13:18.7
-1,2,13:18.7
0,2,13:18.15
-4,3,13:18.7
-3,3,13:18.7
-2,3,13:18.7
-1,3,13:18.7
-5,4,13:18.7
-4,4,13:18.7
-3,4,13:18.7
-2,4,13:18.7
-3,-7,14:18.7
-1,-7,14:18.7
-4,-6,14:18.7
-3,-6,14:18.15
-1,-6,14:18.15
0,-6,14:18.15
5,-6,14:18.7
-2,-5,14:18.15
-1,-5,14:18.15
5,-5,14:18.7
6,-5,14:18.7
-2,-4,14:18.7
0,-4,14:18.15
3,-4,14:18.7
4,-4,14:18.7
6,-4,14:18.7
7,-4,14:189.0
-1,-3,14:18.15
0,-3,14:18.15
2,-3,14:18.7
3,-3,14:17.14
4,-3,14:17.14
6,-3,14:18.7
7,-3,14:189.0
-4,-2,14:18.15
-2,-2,14:18.15
-1,-2,14:17.14
3,-2,14:18.15
4,-2,14:18.7
5,-2,14:17.14
6,-2,14:18.7
-3,-1,14:18.15
2,-1,14:18.15
4,-1,14:18.7
7,-1,14:18.7
-4,0,14:18.15
-3,0,14:18.15
-1,0,14:18.15
0,0,14:18.15
2,0,14:18.15
-4,1,14:18.15
-2,1,14:18.7
0,1,14:18.15
5,1,14:18.7
6,1,14:18.7
-4,2,14:18.7
-3,2,14:17.14
-2,2,14:189.0
0,2,14:18.7
-4,3,14:18.7
-3,3,14:18.7
-2,3,14:18.7
-1,3,14:18.7
-5,4,14:18.7
-4,4,14:18.7
-3,4,14:18.7
-2,4,14:18.7
-4,5,14:189.0
-3,5,14:18.7
-3,-7,15:18.7
-2,-7,15:18.7
-4,-6,15:18.7
-1,-6,15:18.7
0,-6,15:18.7
0,-5,15:18.7
1,-5,15:18.7
-2,-4,15:18.7
-1,-4,15:18.7
0,-4,15:18.7
1,-4,15:18.7
2,-4,15:18.7
3,-4,15:18.7
4,-4,15:18.7
5,-4,15:18.7
6,-4,15:18.7
7,-4,15:18.7
-3,-3,15:18.15
-1,-3,15:17.14
0,-3,15:18.7
3,-3,15:17.14
-4,-2,15:18.15
-3,-2,15:18.15
-1,-2,15:18.7
3,-2,15:18.7
4,-2,15:18.7
5,-2,15:18.7
-4,-1,15:18.15
-3,-1,15:18.15
3,-1,15:18.7
4,-1,15:18.7
6,-1,15:189.0
7,-1,15:18.7
-3,0,15:18.15
-1,0,15:18.15
2,0,15:18.15
4,0,15:18.7
6,0,15:18.7
-4,1,15:18.7
-3,1,15:18.7
-2,1,15:18.7
0,1,15:18.15
2,1,15:18.7
5,1,15:18.7
-3,2,15:17.14
-5,3,15:18.7
-2,3,15:189.0
-4,4,15:18.7
-3,4,15:18.7
-3,-7,16:18.7
-3,-6,16:18.7
-1,-6,16:18.7
0,-6,16:18.7
-2,-5,16:18.7
1,-5,16:18.7
4,-5,16:18.7
-4,-4,16:18.7
-2,-4,16:189.0
-1,-4,16:18.7
0,-4,16:18.7
1,-4,16:18.7
3,-4,16:18.7
4,-4,16:18.7
5,-4,16:18.7
-2,-3,16:18.7
0,-3,16:18.7
-4,-2,16:18.7
2,-2,16:18.7
3,0,16:18.7
-3,1,16:18.7
-3,2,16:18.7
-2,2,16:18.7
-3,3,16:18.7
