[META]
version=2.0
spawnOnBlockType=2
spawnSunlight=True
spawnDarkness=True
spawnWater=False
spawnLava=False
underFill=False
randomRotation=True
dig=True
tree=False
branch=False
needsFoundation=True
rarity=100
collisionPercentage=20
spawnElevationMin=0
spawnElevationMax=200
spawnInBiome=Custom
[DATA]
0,-1,0:183.4
-1,0,0:183.7
0,0,0:17.3
1,0,0:183.5
0,1,0:183.6
0,-1,1:183.4
1,-1,1:143.0
-1,0,1:183.15
0,0,1:17.3
1,0,1:183.5
0,1,1:183.6
0,-1,2:183.4
1,-1,2:103.0
-1,0,2:183.15
0,0,2:17.3
1,0,2:183.5
-1,1,2:143.0
0,1,2:183.6
0,-1,3:183.4
1,-1,3:190.0
-1,0,3:18.12
0,0,3:17.3
1,0,3:18.12
-1,1,3:103.0
0,1,3:18.4
-1,-1,4:18.15
0,-1,4:18.12
1,-1,4:190.0
2,-1,4:18.12
-3,0,4:18.15
-2,0,4:18.15
-1,0,4:183.7
0,0,4:17.3
1,0,4:18.12
-1,1,4:190.0
0,1,4:183.6
1,2,4:18.15
0,-3,5:18.15
4,-3,5:18.15
-2,-2,5:18.15
0,-2,5:18.15
3,-2,5:18.15
-4,-1,5:18.15
0,0,5:18.7
2,0,5:18.15
0,1,5:18.15
2,3,5:18.15
0,-4,6:18.15
-1,0,6:18.15
2,0,6:18.15
0,1,6:18.12
2,3,6:18.7
-2,0,7:18.15
3,0,7:18.15
4,0,7:18.7
0,2,7:18.15
