[META]
version=2.0
spawnOnBlockType=2
spawnSunlight=True
spawnDarkness=True
spawnWater=False
spawnLava=False
underFill=False
randomRotation=True
dig=True
tree=False
branch=False
needsFoundation=True
rarity=100
collisionPercentage=20
spawnElevationMin=0
spawnElevationMax=200
spawnInBiome=Custom
[DATA]
0,0,0:17.0
0,0,1:17.0
0,0,2:17.0
0,0,3:17.0
0,-1,4:18.13
-1,0,4:18.5
0,0,4:17.0
1,0,4:18.13
0,1,4:18.13
0,-1,5:18.13
-1,0,5:18.13
0,0,5:17.0
1,0,5:18.13
0,1,5:18.13
-1,-1,6:18.13
0,-1,6:18.13
1,-1,6:18.13
-1,0,6:18.13
0,0,6:17.0
1,0,6:18.13
-1,1,6:18.13
0,1,6:18.13
1,1,6:18.13
-1,-1,7:18.13
0,-1,7:18.13
1,-1,7:18.5
-1,0,7:18.13
0,0,7:17.0
1,0,7:18.13
0,-1,8:18.13
1,-1,8:18.5
-1,0,8:18.13
0,0,8:17.0
1,0,8:18.13
-1,1,8:18.13
0,1,8:18.13
1,1,8:18.13
-1,-1,9:18.13
0,-1,9:18.13
1,-1,9:18.13
-1,0,9:18.13
0,0,9:17.0
1,0,9:18.13
-1,1,9:18.5
0,1,9:18.5
1,1,9:18.5
-1,-1,10:18.5
0,-1,10:18.13
-1,0,10:18.13
0,0,10:17.0
1,0,10:18.13
-1,1,10:18.13
0,1,10:18.13
1,1,10:18.5
-1,-1,11:18.5
0,-1,11:18.13
1,-1,11:18.13
-1,0,11:18.13
0,0,11:17.0
1,0,11:18.13
0,1,11:18.13
1,1,11:18.13
-1,-1,12:18.13
0,-1,12:18.13
1,-1,12:18.5
-1,0,12:18.13
0,0,12:17.0
1,0,12:18.13
-1,1,12:18.13
0,1,12:18.13
0,-1,13:18.13
1,-1,13:18.13
-1,0,13:18.13
0,0,13:17.0
1,0,13:18.13
-1,1,13:18.5
0,1,13:18.13
1,1,13:18.13
-1,-1,14:18.13
0,-1,14:18.13
-1,0,14:18.13
0,0,14:17.0
1,0,14:18.13
-1,1,14:18.5
0,1,14:18.13
1,1,14:18.13
-1,-1,15:18.5
0,-1,15:18.13
1,-1,15:18.13
-1,0,15:18.5
0,0,15:17.0
1,0,15:18.13
-1,1,15:18.5
0,1,15:18.13
-1,-1,16:18.5
0,-1,16:18.5
1,-1,16:18.5
-1,0,16:18.13
0,0,16:17.0
1,0,16:18.13
-1,1,16:18.13
0,1,16:18.13
1,1,16:18.13
-1,-1,17:18.13
0,-1,17:18.13
1,-1,17:18.5
-1,0,17:18.13
0,0,17:17.0
1,0,17:18.5
0,1,17:18.13
1,1,17:18.5
0,-1,18:18.13
1,-1,18:18.5
-1,0,18:18.13
0,0,18:17.0
1,0,18:18.5
-1,1,18:18.13
0,1,18:18.13
1,1,18:18.5
-1,-1,19:18.13
0,-1,19:18.13
1,-1,19:18.13
-1,0,19:18.13
0,0,19:17.0
1,0,19:18.13
-1,1,19:18.5
0,1,19:18.13
1,1,19:18.13
-1,-1,20:18.5
0,-1,20:18.13
-1,0,20:18.13
0,0,20:17.0
1,0,20:18.13
-1,1,20:18.13
0,1,20:18.13
-1,-1,21:18.5
0,-1,21:18.13
1,-1,21:18.13
-1,0,21:18.13
0,0,21:17.0
1,0,21:18.13
-1,1,21:18.13
0,1,21:18.13
1,1,21:18.13
-1,-1,22:18.13
0,-1,22:18.13
1,-1,22:18.5
-1,0,22:18.13
0,0,22:17.0
1,0,22:18.5
0,1,22:18.13
1,1,22:18.5
0,-1,23:18.13
1,-1,23:18.5
-1,0,23:18.13
0,0,23:17.0
1,0,23:18.5
-1,1,23:18.13
0,1,23:18.13
1,1,23:18.5
-1,-1,24:18.13
0,-1,24:18.13
1,-1,24:18.13
-1,0,24:18.13
0,0,24:17.0
1,0,24:18.13
-1,1,24:18.13
0,1,24:18.13
1,1,24:18.13
0,-1,25:18.13
-1,0,25:18.13
0,0,25:17.0
1,0,25:18.13
0,1,25:18.13
0,-1,26:18.13
-1,0,26:18.13
0,0,26:17.0
1,0,26:18.13
0,1,26:18.13
0,-1,27:18.13
-1,0,27:18.13
0,0,27:17.0
1,0,27:18.5
0,1,27:18.5
0,-1,28:18.13
-1,0,28:18.13
0,0,28:17.0
1,0,28:18.5
0,1,28:18.13
0,0,29:18.13
0,0,30:18.13
0,0,31:18.13
