[META]
version=2.0
spawnOnBlockType=2
spawnSunlight=True
spawnDarkness=True
spawnWater=False
spawnLava=False
underFill=False
randomRotation=True
dig=True
tree=False
branch=False
needsFoundation=True
rarity=100
collisionPercentage=20
spawnElevationMin=0
spawnElevationMax=200
spawnInBiome=Custom
[DATA]
0,0,0:17.0
0,0,1:17.0
0,-1,2:18.5
-1,0,2:18.13
0,0,2:17.0
1,0,2:18.13
0,1,2:18.13
-1,-1,3:18.5
0,-1,3:18.5
1,-1,3:18.5
-1,0,3:18.13
0,0,3:17.0
1,0,3:18.13
-1,1,3:18.13
0,1,3:18.13
-1,-1,4:18.13
0,-1,4:18.13
1,-1,4:18.5
-1,0,4:18.13
0,0,4:17.0
1,0,4:18.13
-1,1,4:18.13
0,1,4:18.13
1,1,4:18.13
0,-1,5:18.13
1,-1,5:18.5
-1,0,5:18.13
0,0,5:17.0
1,0,5:18.5
0,1,5:18.13
1,1,5:18.13
-1,-1,6:18.13
0,-1,6:18.13
1,-1,6:18.13
-1,0,6:18.13
0,0,6:17.0
1,0,6:18.13
-1,1,6:18.13
0,1,6:18.13
1,1,6:18.13
-1,-1,7:18.13
0,-1,7:18.13
-1,0,7:18.13
0,0,7:17.0
1,0,7:18.13
-1,1,7:18.13
0,1,7:18.13
1,1,7:18.13
0,-1,8:18.13
-1,0,8:18.13
0,0,8:17.0
1,0,8:18.13
0,1,8:18.13
0,-1,9:18.13
-1,0,9:18.5
0,0,9:17.0
1,0,9:18.5
0,1,9:18.13
0,0,10:18.13
