[META]
version=2.0
spawnOnBlockType=2
spawnSunlight=True
spawnDarkness=True
spawnWater=False
spawnLava=False
underFill=False
randomRotation=True
dig=True
tree=True
branch=False
needsFoundation=True
rarity=100
collisionPercentage=20
spawnElevationMin=0
spawnElevationMax=200
spawnInBiome=Custom
[DATA]
-1,-4,0:17.13
0,-3,0:17.13
0,-2,0:17.9
-3,-1,0:17.13
-2,-1,0:17.13
-1,-1,0:17.13
0,-1,0:17.13
-4,0,0:17.13
-1,0,0:17.13
0,0,0:17.13
1,0,0:17.13
2,0,0:17.13
0,1,0:17.13
0,2,0:17.13
-1,-1,1:17.13
0,-1,1:17.13
-1,0,1:17.13
0,0,1:17.13
-1,-1,2:17.13
0,-1,2:17.13
-1,0,2:17.13
0,0,2:17.13
-5,-6,3:18.13
-1,-6,3:18.13
0,-6,3:17.13
1,-6,3:18.13
-6,-5,3:18.5
-5,-5,3:17.13
-4,-5,3:18.13
-2,-5,3:18.13
-1,-5,3:18.13
0,-5,3:17.13
1,-5,3:18.13
4,-5,3:18.13
-5,-4,3:18.13
-4,-4,3:17.13
-2,-4,3:18.13
-1,-4,3:18.13
0,-4,3:17.13
1,-4,3:18.13
3,-4,3:18.13
4,-4,3:17.13
5,-4,3:18.13
-4,-3,3:18.13
3,-3,3:17.13
4,-3,3:18.13
-6,-1,3:18.13
-5,-1,3:18.13
-4,-1,3:18.13
-1,-1,3:17.13
0,-1,3:17.13
4,-1,3:18.13
5,-1,3:18.13
-6,0,3:17.13
-5,0,3:17.13
-4,0,3:17.13
-1,0,3:17.13
0,0,3:17.13
3,0,3:17.13
4,0,3:17.13
5,0,3:17.13
-6,1,3:18.13
-5,1,3:18.13
-4,1,3:18.13
3,1,3:18.13
4,1,3:18.13
5,1,3:18.13
3,2,3:17.13
4,2,3:18.13
-2,3,3:18.13
-1,3,3:18.13
0,3,3:18.13
3,3,3:18.13
4,3,3:17.13
5,3,3:18.13
-2,4,3:18.13
-1,4,3:18.13
0,4,3:18.13
3,4,3:18.13
4,4,3:18.13
-2,5,3:18.13
-1,5,3:18.13
0,5,3:18.13
-6,-7,4:18.13
-1,-7,4:18.13
0,-7,4:17.13
1,-7,4:18.13
-7,-6,4:18.13
-6,-6,4:17.13
-5,-6,4:18.13
-4,-6,4:18.13
-2,-6,4:18.13
0,-6,4:18.13
2,-6,4:18.13
5,-6,4:18.13
-6,-5,4:18.13
-5,-5,4:18.13
-4,-5,4:18.13
-3,-5,4:18.13
-2,-5,4:18.13
0,-5,4:18.13
2,-5,4:18.13
3,-5,4:18.13
4,-5,4:18.13
5,-5,4:188.0
6,-5,4:18.13
-4,-4,4:18.13
-3,-4,4:18.13
0,-4,4:18.13
2,-4,4:18.13
3,-4,4:18.13
4,-4,4:18.13
5,-4,4:18.13
-5,-3,4:18.13
-4,-3,4:18.13
-3,-3,4:17.13
-2,-3,4:18.13
-1,-3,4:18.13
0,-3,4:17.13
1,-3,4:18.13
2,-3,4:18.13
3,-3,4:18.13
4,-3,4:18.13
5,-3,4:18.13
-5,-2,4:18.13
-4,-2,4:18.13
-3,-2,4:18.13
-2,-2,4:17.13
-1,-2,4:18.13
0,-2,4:17.13
1,-2,4:18.13
2,-2,4:17.13
3,-2,4:18.13
5,-2,4:18.13
6,-2,4:18.13
-7,-1,4:18.13
-3,-1,4:18.13
-2,-1,4:18.13
-1,-1,4:17.13
0,-1,4:17.13
1,-1,4:17.13
2,-1,4:18.13
3,-1,4:18.13
5,-1,4:18.13
6,-1,4:18.13
-7,0,4:17.13
-6,0,4:18.13
-5,0,4:18.13
-4,0,4:18.13
-3,0,4:17.13
-2,0,4:17.13
-1,0,4:17.13
0,0,4:17.13
1,0,4:17.13
2,0,4:17.13
3,0,4:18.13
4,0,4:18.13
5,0,4:18.13
6,0,4:188.0
-7,1,4:18.13
-5,1,4:18.13
-4,1,4:18.13
-3,1,4:18.13
-1,1,4:17.13
0,1,4:18.13
1,1,4:18.13
2,1,4:17.13
3,1,4:18.13
6,1,4:18.13
-6,2,4:18.13
-5,2,4:18.13
-3,2,4:18.13
-1,2,4:17.13
0,2,4:18.13
2,2,4:18.13
3,2,4:18.13
5,2,4:18.13
-5,3,4:18.13
-4,3,4:17.13
-1,3,4:18.13
0,3,4:18.13
2,3,4:18.13
4,3,4:18.13
5,3,4:18.13
-6,4,4:18.13
-5,4,4:17.13
-4,4,4:18.13
-3,4,4:18.13
-1,4,4:18.13
0,4,4:18.13
1,4,4:18.13
4,4,4:18.13
5,4,4:188.0
6,4,4:18.13
-5,5,4:18.13
-3,5,4:18.13
-1,5,4:18.13
3,5,4:18.13
4,5,4:18.13
5,5,4:18.13
-2,6,4:18.13
-1,6,4:18.13
0,6,4:18.13
0,-9,5:18.13
-7,-8,5:18.13
-1,-8,5:18.13
0,-8,5:17.13
1,-8,5:18.13
-8,-7,5:18.13
-7,-7,5:17.13
-6,-7,5:18.13
0,-7,5:18.13
6,-7,5:18.13
-7,-6,5:18.5
-6,-6,5:18.13
-4,-6,5:18.13
-3,-6,5:18.13
1,-6,5:18.13
5,-6,5:18.13
6,-6,5:188.0
7,-6,5:18.13
-7,-5,5:18.13
0,-5,5:18.13
3,-5,5:18.13
5,-5,5:18.13
6,-5,5:18.13
-5,-4,5:18.5
2,-4,5:18.13
-6,-3,5:18.13
-5,-3,5:18.13
-3,-3,5:18.13
0,-3,5:18.13
3,-3,5:18.13
5,-3,5:18.13
-6,-2,5:18.13
-5,-2,5:18.13
-2,-2,5:18.5
-1,-2,5:18.13
0,-2,5:18.13
2,-2,5:18.13
-8,-1,5:18.13
-1,-1,5:17.13
0,-1,5:17.13
1,-1,5:18.13
6,-1,5:18.13
7,-1,5:18.13
-9,0,5:18.13
-8,0,5:17.13
-7,0,5:18.13
-3,0,5:18.13
-2,0,5:18.13
-1,0,5:17.13
0,0,5:17.13
1,0,5:18.13
2,0,5:18.13
6,0,5:18.13
7,0,5:188.0
8,0,5:18.13
-8,1,5:18.13
-4,1,5:18.13
-3,1,5:18.13
-2,1,5:17.13
-1,1,5:18.13
2,1,5:18.13
7,1,5:18.13
-6,2,5:18.13
-4,2,5:18.13
-3,2,5:17.13
-2,2,5:18.13
-1,2,5:18.13
1,2,5:18.13
6,2,5:18.13
-6,3,5:18.13
-4,3,5:18.13
-3,3,5:18.13
4,3,5:18.13
-6,4,5:18.13
-5,4,5:18.13
-3,4,5:18.13
1,4,5:18.13
2,4,5:18.13
5,4,5:18.13
6,4,5:18.13
-7,5,5:18.13
-6,5,5:17.13
-5,5,5:18.13
-4,5,5:18.13
-3,5,5:18.13
1,5,5:18.13
5,5,5:18.13
6,5,5:188.0
7,5,5:18.13
-6,6,5:18.13
-1,6,5:18.13
5,6,5:18.13
6,6,5:18.13
-2,7,5:18.13
-1,7,5:188.0
0,7,5:18.13
-1,8,5:18.13
-8,-8,6:18.13
0,-8,6:18.13
-7,-7,6:18.13
7,-7,6:18.13
6,-6,6:18.13
2,-4,6:18.13
-6,-3,6:18.5
-3,-3,6:18.5
3,-3,6:18.13
-1,-2,6:18.13
-1,-1,6:17.13
0,-1,6:17.13
-8,0,6:18.13
-1,0,6:17.13
0,0,6:17.13
4,0,6:18.13
7,0,6:18.13
-2,1,6:18.13
-3,2,6:18.13
-6,5,6:18.13
6,5,6:18.13
-7,6,6:18.13
7,6,6:18.13
-1,7,6:18.13
3,-5,7:18.13
-5,-4,7:18.13
-4,-4,7:18.13
-3,-4,7:18.13
2,-4,7:18.13
3,-4,7:188.0
4,-4,7:18.13
-6,-3,7:18.13
-5,-3,7:17.13
-4,-3,7:17.13
-3,-3,7:17.13
-2,-3,7:18.13
1,-3,7:18.13
2,-3,7:17.13
3,-3,7:18.13
-5,-2,7:18.13
-4,-2,7:18.13
-3,-2,7:18.13
2,-2,7:18.13
-4,-1,7:18.13
-1,-1,7:17.13
0,-1,7:17.13
-6,0,7:18.13
-5,0,7:18.13
-4,0,7:17.13
-1,0,7:17.13
0,0,7:17.13
3,0,7:18.13
4,0,7:18.13
-7,1,7:18.13
-6,1,7:17.13
-5,1,7:17.13
-4,1,7:18.13
2,1,7:18.13
3,1,7:17.13
4,1,7:17.13
-6,2,7:18.13
-5,2,7:18.13
3,2,7:18.13
4,2,7:18.13
5,2,7:18.13
-4,3,7:18.13
-3,3,7:17.13
-2,3,7:18.13
1,3,7:17.13
2,3,7:18.13
-4,4,7:18.13
-3,4,7:17.13
-2,4,7:18.13
0,4,7:18.13
1,4,7:17.13
2,4,7:18.13
1,5,7:18.13
4,-6,8:18.13
-6,-5,8:18.13
-4,-5,8:18.13
2,-5,8:18.13
3,-5,8:18.13
4,-5,8:188.0
5,-5,8:18.13
-7,-4,8:18.13
-6,-4,8:17.13
-5,-4,8:18.13
1,-4,8:18.13
3,-4,8:18.13
4,-4,8:18.13
-6,-3,8:18.13
-5,-3,8:18.13
-4,-3,8:18.13
-3,-3,8:18.13
-2,-3,8:18.13
1,-3,8:18.13
2,-3,8:18.13
4,-3,8:18.13
-6,-2,8:18.13
-3,-2,8:18.13
-2,-2,8:17.13
-1,-2,8:18.13
0,-2,8:18.13
1,-2,8:17.13
2,-2,8:18.13
3,-2,8:18.13
-5,-1,8:18.13
-3,-1,8:18.13
-2,-1,8:18.13
-1,-1,8:17.13
0,-1,8:17.13
1,-1,8:18.13
2,-1,8:18.13
4,-1,8:18.13
-4,0,8:18.13
-3,0,8:17.13
-2,0,8:17.13
-1,0,8:17.13
0,0,8:17.13
1,0,8:17.13
2,0,8:17.13
3,0,8:18.13
5,0,8:18.13
-7,1,8:18.13
-6,1,8:18.13
-5,1,8:18.13
-3,1,8:18.13
-2,1,8:17.13
0,1,8:17.13
1,1,8:18.13
2,1,8:18.13
3,1,8:18.13
4,1,8:18.13
5,1,8:188.0
-8,2,8:18.13
-7,2,8:188.0
-6,2,8:18.13
-3,2,8:18.13
-2,2,8:17.13
-1,2,8:18.13
0,2,8:17.13
1,2,8:18.13
3,2,8:18.13
5,2,8:18.13
-7,3,8:18.13
-3,3,8:18.13
-2,3,8:18.13
-1,3,8:18.13
0,3,8:18.13
1,3,8:18.13
4,3,8:18.13
-4,4,8:18.13
-3,4,8:18.13
1,4,8:18.13
2,4,8:18.13
-5,5,8:18.13
-4,5,8:188.0
-3,5,8:18.13
-2,5,8:18.13
1,5,8:18.13
2,5,8:188.0
3,5,8:18.13
2,6,8:18.13
5,-7,9:18.13
4,-6,9:18.13
5,-6,9:188.0
6,-6,9:18.13
-7,-5,9:18.13
4,-5,9:18.13
5,-5,9:18.13
-6,-4,9:18.13
-2,-2,9:18.13
1,-2,9:18.13
-1,-1,9:17.13
0,-1,9:17.13
-3,0,9:18.13
-1,0,9:17.13
0,0,9:17.13
1,0,9:18.13
2,0,9:18.13
6,0,9:18.13
-2,1,9:18.13
0,1,9:18.13
5,1,9:18.13
6,1,9:188.0
7,1,9:18.13
-7,2,9:18.13
-2,2,9:18.13
0,2,9:18.13
6,2,9:18.13
-8,3,9:18.13
-4,3,9:18.13
2,3,9:18.13
-5,4,9:18.13
-1,4,9:18.13
3,4,9:18.13
-4,5,9:18.13
0,5,9:18.13
2,5,9:18.13
3,5,9:18.13
-5,6,9:18.13
-4,6,9:188.0
-3,6,9:18.13
1,6,9:18.13
2,6,9:18.13
3,6,9:188.0
4,6,9:18.13
-4,7,9:18.13
3,7,9:18.13
6,-7,10:18.13
5,-6,10:18.13
1,-4,10:18.13
-1,-3,10:18.13
-2,-2,10:18.13
-1,-1,10:17.13
0,-1,10:17.13
-1,0,10:17.13
0,0,10:17.13
6,1,10:18.13
1,3,10:18.13
2,3,10:18.13
-2,4,10:18.13
-4,6,10:18.13
3,6,10:18.13
4,7,10:18.13
-3,-5,11:18.13
-1,-5,11:18.13
0,-5,11:188.0
1,-5,11:18.13
-4,-4,11:18.13
-3,-4,11:188.0
-2,-4,11:18.13
-1,-4,11:18.13
0,-4,11:17.13
1,-4,11:18.13
-3,-3,11:18.13
-2,-3,11:188.0
-1,-3,11:18.13
0,-3,11:17.13
1,-3,11:18.13
-2,-2,11:18.13
-2,-1,11:18.13
-1,-1,11:17.13
0,-1,11:17.13
-1,0,11:17.13
0,0,11:17.13
-2,2,11:18.13
-1,2,11:17.13
0,2,11:18.13
2,2,11:18.13
-2,3,11:18.13
-1,3,11:17.13
0,3,11:18.13
1,3,11:18.13
2,3,11:17.13
3,3,11:18.13
-2,4,11:18.13
-1,4,11:188.0
0,4,11:18.13
2,4,11:18.13
0,6,11:18.13
0,-7,12:18.13
-4,-6,12:18.13
-1,-6,12:18.13
0,-6,12:188.0
1,-6,12:18.13
-5,-5,12:18.13
-4,-5,12:188.0
-3,-5,12:18.13
-2,-5,12:18.13
0,-5,12:18.13
-4,-4,12:18.13
-3,-4,12:18.13
0,-4,12:18.13
2,-4,12:18.13
3,-4,12:18.13
-2,-3,12:18.13
-1,-3,12:18.13
0,-3,12:18.13
1,-3,12:18.13
2,-3,12:18.13
3,-3,12:188.0
4,-3,12:18.13
-5,-2,12:18.13
-4,-2,12:18.13
-3,-2,12:18.13
-2,-2,12:18.13
-1,-2,12:17.13
0,-2,12:188.0
1,-2,12:18.13
2,-2,12:188.0
3,-2,12:18.13
-5,-1,12:188.0
-4,-1,12:17.13
-3,-1,12:17.13
-1,-1,12:17.13
0,-1,12:17.13
2,-1,12:18.13
3,-1,12:18.13
4,-1,12:18.13
-5,0,12:18.13
-4,0,12:18.13
-3,0,12:18.13
-1,0,12:17.13
2,0,12:17.13
3,0,12:17.13
4,0,12:188.0
-3,1,12:18.13
-1,1,12:17.13
0,1,12:17.13
1,1,12:18.13
2,1,12:18.13
3,1,12:18.13
4,1,12:18.13
-4,2,12:18.13
-3,2,12:188.0
-2,2,12:18.13
-1,2,12:18.13
0,2,12:18.13
1,2,12:18.13
-5,3,12:18.13
-4,3,12:188.0
-3,3,12:18.13
-1,3,12:18.13
2,3,12:18.13
3,3,12:18.13
-4,4,12:18.13
-1,4,12:18.13
1,4,12:18.13
2,4,12:18.13
3,4,12:188.0
4,4,12:18.13
-2,5,12:18.13
-1,5,12:188.0
0,5,12:18.13
3,5,12:18.13
-1,6,12:18.13
0,6,12:18.13
-5,-6,13:18.13
0,-6,13:18.13
-4,-5,13:18.13
4,-5,13:18.13
3,-4,13:18.13
4,-4,13:188.0
5,-4,13:18.13
-5,-3,13:18.13
-4,-3,13:18.13
3,-3,13:18.13
4,-3,13:18.13
-6,-2,13:18.13
-2,-2,13:18.13
-1,-2,13:18.13
0,-2,13:18.13
2,-2,13:18.13
4,-2,13:18.13
-7,-1,13:18.13
-6,-1,13:188.0
-5,-1,13:18.13
-4,-1,13:18.13
-3,-1,13:18.13
-2,-1,13:17.13
-1,-1,13:17.13
0,-1,13:17.13
1,-1,13:17.13
2,-1,13:18.13
5,-1,13:18.13
-6,0,13:18.13
-2,0,13:18.13
-1,0,13:17.13
1,0,13:17.13
2,0,13:18.13
3,0,13:18.13
4,0,13:18.13
5,0,13:188.0
6,0,13:18.13
-4,1,13:18.13
-3,1,13:18.13
-2,1,13:17.13
-1,1,13:18.13
0,1,13:18.13
1,1,13:18.13
2,1,13:18.13
5,1,13:18.13
-3,2,13:18.13
-2,2,13:18.13
2,2,13:18.13
3,2,13:18.13
-5,3,13:18.13
-4,3,13:18.13
-2,3,13:18.13
-6,4,13:18.13
-5,4,13:188.0
-4,4,13:18.13
-3,4,13:18.13
3,4,13:18.13
-5,5,13:18.13
-1,5,13:18.13
4,5,13:18.13
5,-5,14:18.13
4,-4,14:18.13
2,-3,14:18.13
-3,-2,14:18.13
-6,-1,14:18.13
-2,-1,14:18.13
-1,-1,14:17.13
0,-1,14:17.13
1,-1,14:18.13
3,-1,14:18.13
-1,0,14:17.13
1,0,14:18.13
5,0,14:18.13
-2,1,14:18.13
-1,1,14:18.13
-5,4,14:18.13
-6,5,14:18.13
2,-5,15:18.13
1,-4,15:18.13
2,-4,15:188.0
3,-4,15:18.13
1,-3,15:188.0
2,-3,15:18.13
-4,-2,15:18.13
-3,-2,15:18.13
-4,-1,15:188.0
-3,-1,15:17.13
-1,-1,15:17.13
0,-1,15:17.13
-4,0,15:18.13
-3,0,15:18.13
-1,0,15:17.13
-4,1,15:18.13
1,3,15:18.13
3,-6,16:18.13
-2,-5,16:18.13
2,-5,16:18.13
3,-5,16:188.0
4,-5,16:18.13
-3,-4,16:18.13
-2,-4,16:188.0
-1,-4,16:18.13
0,-4,16:18.13
2,-4,16:18.13
3,-4,16:18.13
-2,-3,16:18.13
-1,-3,16:188.0
0,-3,16:18.13
1,-3,16:18.13
3,-3,16:18.13
-5,-2,16:18.13
0,-2,16:17.13
1,-2,16:18.13
2,-2,16:18.13
-6,-1,16:18.13
-5,-1,16:188.0
-4,-1,16:18.13
-3,-1,16:18.13
-2,-1,16:17.13
-1,-1,16:17.13
0,-1,16:18.13
1,-1,16:18.13
2,-1,16:18.13
-5,0,16:18.13
-2,0,16:18.13
-1,0,16:17.13
1,0,16:17.13
2,0,16:17.13
3,0,16:18.13
-4,1,16:18.13
-3,1,16:17.13
0,1,16:18.13
2,1,16:18.13
-4,2,16:18.13
-3,2,16:188.0
-2,2,16:18.13
-1,2,16:18.13
0,2,16:17.9
1,2,16:18.13
-3,3,16:18.13
-1,3,16:18.13
0,3,16:188.0
1,3,16:18.13
0,4,16:18.13
-3,-6,17:18.13
4,-6,17:18.13
-4,-5,17:18.13
-3,-5,17:188.0
-2,-5,17:18.13
0,-5,17:18.13
3,-5,17:18.13
-4,-4,17:18.13
-3,-4,17:18.13
-2,-4,17:18.13
-1,-4,17:18.13
-4,-3,17:18.13
-3,-3,17:18.13
-1,-3,17:18.13
-2,-2,17:18.13
-1,-2,17:17.13
0,-2,17:18.13
-5,-1,17:18.13
-2,-1,17:18.13
-1,-1,17:17.13
3,-1,17:18.13
-3,0,17:18.13
-2,0,17:17.13
-1,0,17:17.13
0,0,17:17.13
1,0,17:18.13
2,0,17:18.13
3,0,17:18.13
-5,1,17:18.13
-3,1,17:18.13
-2,1,17:18.13
-1,1,17:17.13
0,1,17:18.13
1,1,17:18.13
2,1,17:18.13
3,1,17:188.0
4,1,17:18.13
-4,2,17:18.13
-3,2,17:18.13
-1,2,17:18.13
0,2,17:18.13
3,2,17:18.13
-5,3,17:18.13
-4,3,17:188.0
-2,3,17:18.13
0,3,17:18.13
1,3,17:18.13
2,3,17:18.13
-4,4,17:18.13
-1,4,17:18.13
0,4,17:18.13
1,4,17:188.0
2,4,17:18.13
1,5,17:18.13
-4,-6,18:18.13
-3,-5,18:18.13
1,-3,18:18.13
-1,-2,18:18.13
-1,-1,18:17.13
-3,0,18:18.13
-2,0,18:18.13
-1,0,18:17.13
0,0,18:18.13
-4,1,18:18.13
-1,1,18:18.13
3,1,18:18.13
4,2,18:18.13
-4,3,18:18.13
-5,4,18:18.13
1,4,18:18.13
2,5,18:18.13
-3,-4,19:18.13
-4,-3,19:18.13
-3,-3,19:18.13
-2,-3,19:18.13
-4,-2,19:18.13
-3,-2,19:18.13
-1,-1,19:17.13
1,-1,19:18.13
2,-1,19:18.13
-4,0,19:18.13
-3,0,19:18.13
-1,0,19:17.13
-5,1,19:18.13
-4,1,19:18.13
-3,1,19:18.13
-4,2,19:18.13
-2,2,19:18.13
-1,2,19:18.13
0,2,19:18.13
-2,3,19:18.13
0,-5,20:18.13
-4,-4,20:18.13
-1,-4,20:18.13
0,-4,20:18.13
1,-4,20:18.13
-1,-3,20:18.13
0,-3,20:18.13
-3,-2,20:18.13
-2,-2,20:18.13
-1,-2,20:18.13
-2,-1,20:18.13
-1,-1,20:17.13
1,-1,20:18.13
2,-1,20:18.13
3,-1,20:18.13
-3,0,20:18.13
-2,0,20:18.13
-1,0,20:18.13
1,0,20:18.13
3,0,20:18.13
-1,1,20:18.13
0,1,20:18.13
2,1,20:18.13
-5,2,20:18.13
-2,2,20:18.13
-1,2,20:18.13
0,2,20:18.13
-2,3,20:18.13
-1,3,20:18.13
0,3,20:18.13
-1,4,20:18.13
1,-5,21:18.13
-1,-2,21:18.13
1,-2,21:18.13
-2,-1,21:18.13
-1,-1,21:17.13
0,-1,21:18.13
1,-1,21:18.13
2,-1,21:18.13
-1,0,21:18.13
0,0,21:18.13
1,0,21:18.13
4,0,21:18.13
-1,4,21:18.13
-3,-3,22:18.13
-2,-3,22:18.13
-1,-1,22:17.13
0,-1,22:18.13
-3,0,22:18.5
-2,0,22:18.5
-2,1,22:18.5
0,1,22:18.13
-1,-3,23:18.13
-2,-2,23:18.13
-1,-2,23:18.13
0,-2,23:18.13
1,-2,23:18.13
-3,-1,23:18.5
-2,-1,23:18.5
-1,-1,23:17.13
0,-1,23:18.5
-2,0,23:18.5
-1,0,23:18.13
0,0,23:18.13
-1,1,23:18.5
-1,-2,24:18.13
0,-2,24:18.13
-2,-1,24:18.13
-1,-1,24:17.13
0,-1,24:18.13
1,-1,24:18.13
-1,0,24:18.13
-1,-2,25:18.13
-1,-1,25:17.13
-1,0,25:18.13
-1,-1,26:18.13
