[META]
version=2.0
spawnOnBlockType=2
spawnSunlight=True
spawnDarkness=True
spawnWater=False
spawnLava=False
underFill=False
randomRotation=True
dig=True
tree=True
branch=False
needsFoundation=True
rarity=100
collisionPercentage=20
spawnElevationMin=0
spawnElevationMax=200
spawnInBiome=Custom
[DATA]
-2,-3,0:162.12
-2,-1,0:162.12
0,-1,0:162.12
-2,-3,1:162.12
-1,-2,1:162.12
-2,-2,2:18.7
-1,-2,2:162.12
1,-2,2:18.7
0,-1,2:18.7
3,-1,2:18.7
-1,0,2:18.7
-1,1,2:18.7
0,1,2:18.7
4,1,2:18.7
4,-7,3:18.7
4,-5,3:18.15
5,-5,3:189.0
-1,-4,3:18.7
0,-4,3:18.7
1,-4,3:18.7
6,-4,3:18.7
1,-3,3:162.12
4,-3,3:18.7
6,-3,3:18.7
7,-3,3:18.7
-1,-2,3:162.12
0,-2,3:162.12
6,-2,3:18.7
1,-1,3:18.7
-3,0,3:18.7
2,0,3:18.7
3,0,3:18.7
-3,1,3:18.7
1,1,3:18.7
4,1,3:18.7
-2,2,3:18.7
-2,3,3:18.7
1,3,3:18.7
3,3,3:18.7
2,4,3:18.7
4,-7,4:18.7
5,-6,4:18.15
-2,-5,4:18.15
0,-5,4:18.15
2,-5,4:18.7
3,-5,4:18.7
4,-5,4:18.7
5,-5,4:18.7
6,-5,4:18.7
-2,-4,4:18.15
-1,-4,4:18.15
0,-4,4:18.15
3,-4,4:18.7
4,-4,4:162.12
5,-4,4:162.12
-1,-3,4:18.7
2,-3,4:162.12
3,-3,4:162.12
4,-3,4:18.7
5,-3,4:18.7
6,-3,4:18.7
-3,-2,4:18.7
-2,-2,4:162.12
-1,-2,4:162.12
2,-2,4:18.7
7,-2,4:18.7
-1,-1,4:18.7
0,-1,4:162.12
1,-1,4:18.7
4,-1,4:18.7
-4,0,4:18.7
-3,0,4:18.7
-2,0,4:18.7
0,0,4:162.12
2,0,4:18.7
-1,1,4:162.12
-3,2,4:18.7
-2,2,4:18.7
-1,2,4:18.7
0,2,4:18.7
-3,3,4:18.7
-1,3,4:18.7
0,3,4:18.7
1,3,4:18.7
3,3,4:18.7
-3,4,4:18.7
-1,4,4:18.7
-3,5,4:18.7
-2,5,4:18.7
-1,5,4:18.7
-2,-6,5:18.7
3,-6,5:18.7
4,-6,5:18.7
5,-6,5:18.7
1,-5,5:18.7
2,-5,5:18.7
3,-5,5:18.7
-6,-4,5:18.7
-1,-4,5:189.0
0,-4,5:18.7
3,-4,5:18.7
5,-4,5:18.7
6,-4,5:18.7
-4,-3,5:162.12
-3,-3,5:162.12
1,-3,5:18.7
4,-3,5:18.7
-1,-2,5:162.12
3,-2,5:18.15
6,-2,5:18.7
-3,1,5:18.7
-1,1,5:18.7
0,1,5:18.7
1,1,5:162.12
2,1,5:18.7
-4,2,5:18.7
-3,2,5:18.7
-2,2,5:18.7
-1,2,5:162.12
0,2,5:18.7
1,2,5:162.12
2,2,5:18.7
-2,3,5:162.12
2,3,5:162.12
4,3,5:18.7
-2,5,5:18.7
-1,5,5:18.7
-4,-6,6:18.7
-1,-6,6:18.7
0,-6,6:18.7
-4,-5,6:18.7
-6,-4,6:18.7
-5,-4,6:162.12
-4,-4,6:18.7
-3,-4,6:18.15
-6,-3,6:18.7
-3,-3,6:18.15
-2,-3,6:189.0
5,-3,6:18.7
-6,-2,6:18.7
-4,-2,6:18.7
-1,-2,6:162.12
0,-2,6:18.7
-6,-1,6:18.7
-5,-1,6:18.7
2,-1,6:189.0
3,-1,6:18.7
4,-1,6:18.7
2,0,6:18.7
3,0,6:18.7
-2,1,6:18.7
2,1,6:18.7
4,1,6:18.7
-2,2,6:18.15
2,2,6:18.7
-2,3,6:18.15
-1,3,6:18.15
0,3,6:18.15
1,3,6:18.7
2,3,6:18.7
0,4,6:18.7
1,4,6:18.7
0,5,6:18.7
0,-7,7:18.7
-3,-6,7:18.7
-1,-6,7:18.7
0,-6,7:18.7
1,-6,7:18.7
-4,-5,7:18.7
1,-5,7:18.7
4,-5,7:18.7
-4,-4,7:18.7
0,-4,7:162.12
1,-4,7:18.7
3,-4,7:18.7
4,-4,7:18.7
-4,-3,7:18.7
-3,-3,7:18.7
-1,-3,7:162.12
0,-3,7:18.7
4,-3,7:18.7
-5,-2,7:18.7
-4,-2,7:18.7
0,-2,7:162.12
4,-2,7:18.7
-2,-1,7:162.12
0,-1,7:18.7
1,-1,7:162.12
-5,0,7:18.7
-4,0,7:18.7
-3,0,7:18.7
-1,0,7:18.7
4,0,7:18.7
-1,1,7:18.7
4,1,7:18.7
6,1,7:18.7
-5,2,7:18.7
-2,2,7:18.15
-1,2,7:18.15
2,2,7:18.15
3,2,7:18.7
4,2,7:18.7
-5,3,7:18.7
-2,3,7:18.15
-1,3,7:189.0
2,3,7:18.15
-1,4,7:18.7
-1,5,7:18.7
1,-7,8:18.7
0,-6,8:162.12
1,-6,8:18.7
3,-6,8:18.7
-4,-5,8:18.7
-3,-5,8:18.7
0,-5,8:162.12
2,-5,8:18.7
3,-5,8:18.7
0,-4,8:18.7
5,-4,8:18.7
1,-3,8:18.7
2,-3,8:18.7
5,-3,8:18.7
-3,-2,8:18.7
-2,-2,8:18.7
-1,-2,8:18.7
3,-2,8:18.7
4,-2,8:18.7
-5,-1,8:18.7
-3,-1,8:18.7
-2,-1,8:162.12
-1,-1,8:18.7
2,-1,8:162.12
3,-1,8:162.12
4,-1,8:18.7
-3,0,8:162.12
-2,0,8:18.7
6,0,8:18.7
-5,1,8:18.15
-4,1,8:162.12
-3,1,8:18.7
-1,1,8:18.7
2,1,8:18.7
4,1,8:18.7
6,1,8:18.7
-4,2,8:18.7
-2,2,8:18.15
0,2,8:18.15
5,2,8:18.7
-5,3,8:18.7
-2,3,8:18.7
0,3,8:18.15
1,3,8:189.0
2,3,8:18.7
-4,4,8:18.7
-2,5,8:18.7
0,-7,9:18.15
2,-7,9:18.15
1,-6,9:18.15
4,-6,9:18.7
-2,-5,9:18.7
3,-5,9:18.7
-3,-4,9:18.7
2,-3,9:18.7
-5,-2,9:18.7
-2,-2,9:18.15
5,-2,9:18.7
-2,-1,9:162.12
-1,-1,9:162.12
0,-1,9:18.7
-4,0,9:18.15
-1,0,9:18.7
5,0,9:18.7
-5,1,9:189.0
4,1,9:18.7
5,1,9:18.7
6,1,9:18.7
-5,2,9:18.7
-3,2,9:18.7
0,2,9:18.15
1,2,9:18.15
2,2,9:18.15
-5,3,9:18.7
-4,3,9:18.7
0,3,9:18.7
2,3,9:18.7
-4,4,9:18.7
1,4,9:18.7
3,-7,10:18.7
1,-6,10:189.0
3,-6,10:18.7
4,-6,10:18.7
1,-5,10:18.7
2,-5,10:18.7
5,-5,10:18.7
0,-4,10:18.15
3,-4,10:18.7
-3,-3,10:18.15
-1,-3,10:18.15
3,-3,10:18.7
-4,-2,10:18.15
-3,-2,10:189.0
-2,-2,10:18.15
3,-2,10:18.7
-2,-1,10:162.12
0,-1,10:162.12
-2,0,10:162.12
-1,0,10:18.7
1,0,10:162.12
3,0,10:18.15
-3,1,10:162.12
1,1,10:18.7
2,1,10:18.7
-3,2,10:18.7
0,2,10:18.7
1,2,10:18.7
2,2,10:18.7
-2,3,10:18.7
-1,3,10:18.7
1,4,10:18.7
0,-5,11:18.7
1,-5,11:18.7
2,-5,11:18.7
-3,-4,11:18.7
-2,-4,11:18.7
-1,-3,11:18.15
0,-3,11:189.0
-2,-2,11:189.0
-1,-2,11:18.7
-2,-1,11:162.12
-1,-1,11:18.7
-3,0,11:18.15
-2,0,11:18.15
0,0,11:18.7
2,0,11:162.12
3,0,11:189.0
5,0,11:18.7
6,0,11:18.7
-3,1,11:189.0
3,1,11:18.7
-3,2,11:162.12
-1,2,11:18.7
0,2,11:18.7
3,2,11:18.7
4,2,11:18.7
5,2,11:18.7
-3,3,11:18.7
0,-4,12:18.15
-2,-3,12:18.15
0,-3,12:18.7
2,-3,12:18.7
-3,-2,12:18.7
-1,-2,12:18.7
0,-2,12:18.7
2,-1,12:18.15
-3,0,12:18.15
2,0,12:18.7
-5,1,12:18.7
-4,1,12:18.7
-2,1,12:18.7
1,1,12:18.7
2,1,12:18.7
4,1,12:18.7
6,1,12:18.7
-4,2,12:18.7
-2,2,12:18.7
-1,2,12:18.7
3,2,12:18.7
-5,3,12:18.7
-4,3,12:18.7
-1,3,12:18.7
1,-3,13:18.7
1,-1,13:18.7
-5,2,13:18.7
-4,2,13:18.7
-4,3,13:18.7
