[META]
version=2.0
spawnOnBlockType=2
spawnSunlight=True
spawnDarkness=True
spawnWater=False
spawnLava=False
underFill=False
randomRotation=True
dig=True
tree=True
branch=False
needsFoundation=True
rarity=100
collisionPercentage=20
spawnElevationMin=0
spawnElevationMax=200
spawnInBiome=Custom
[DATA]
0,-1,0:162.12
2,-1,0:162.12
2,1,0:162.12
0,0,1:162.12
1,0,1:162.12
2,1,1:162.12
1,0,2:162.12
-1,-6,3:18.15
-4,-5,3:18.15
-2,-5,3:18.15
-4,-3,3:18.15
-5,-2,3:18.15
1,0,3:162.12
-4,4,3:18.15
-3,5,3:18.15
-2,5,3:18.15
0,5,3:18.15
-2,-6,4:18.15
-3,-5,4:18.15
1,-5,4:18.15
-6,-4,4:18.15
-5,-4,4:18.15
0,-4,4:18.15
-6,-3,4:18.15
-4,-3,4:18.15
-2,-3,4:18.15
-3,-2,4:18.15
-2,-2,4:18.15
2,-2,4:18.15
2,-1,4:162.12
0,0,4:162.12
1,0,4:162.12
-1,1,4:162.12
3,1,4:18.15
4,1,4:18.15
6,1,4:18.15
-3,2,4:18.15
1,2,4:18.15
-7,3,4:18.15
-6,4,4:18.15
0,4,4:18.15
-3,6,4:18.15
1,6,4:18.15
-1,-8,5:18.15
0,-8,5:18.15
-3,-6,5:18.15
-3,-5,5:18.15
2,-5,5:18.15
-3,-4,5:18.15
0,-4,5:18.15
1,-3,5:18.15
4,-3,5:18.15
-2,-2,5:18.15
3,-2,5:162.12
4,-2,5:162.12
-1,-1,5:18.15
2,-1,5:18.15
-2,0,5:18.15
-1,0,5:18.15
1,0,5:162.12
-2,1,5:162.12
0,1,5:18.15
4,1,5:18.15
5,1,5:18.15
-7,2,5:18.15
-4,2,5:18.15
-3,2,5:162.12
5,2,5:18.15
6,2,5:18.15
-8,3,5:18.15
3,3,5:18.15
5,3,5:18.15
-7,4,5:18.15
1,4,5:18.15
7,4,5:18.15
-4,5,5:18.15
-3,5,5:18.15
-2,6,5:18.15
4,-7,6:18.15
-5,-5,6:18.15
1,-5,6:18.15
2,-5,6:18.15
3,-5,6:18.15
0,-4,6:18.15
6,-4,6:18.15
-2,-3,6:18.15
5,-3,6:162.12
-6,-2,6:18.15
-4,-2,6:18.15
0,-2,6:162.12
0,-1,6:162.12
3,-1,6:18.15
-4,0,6:18.15
1,0,6:162.12
5,0,6:18.15
1,1,6:162.12
2,1,6:18.15
4,1,6:18.15
5,1,6:18.15
7,1,6:18.15
-7,2,6:18.15
-6,2,6:18.15
-5,2,6:18.15
-4,2,6:162.12
-2,2,6:18.15
2,2,6:18.15
3,2,6:18.15
5,2,6:18.15
6,2,6:18.15
7,2,6:18.15
1,3,6:18.15
3,3,6:18.15
4,3,6:18.15
5,3,6:18.15
-5,4,6:18.15
-1,4,6:18.15
0,4,6:18.15
5,4,6:18.15
7,4,6:18.15
5,5,6:18.15
6,5,6:18.15
2,-7,7:18.15
-1,-6,7:18.15
1,-6,7:18.15
4,-6,7:18.15
6,-6,7:18.15
0,-5,7:18.15
4,-5,7:18.15
7,-5,7:18.15
8,-5,7:18.15
0,-4,7:18.15
4,-4,7:18.15
6,-4,7:162.12
-1,-3,7:162.12
1,-3,7:18.15
2,-3,7:18.15
5,-3,7:18.15
-7,-2,7:18.15
-5,-2,7:18.15
-7,-1,7:18.15
-4,-1,7:18.15
5,-1,7:18.15
-7,0,7:18.15
-3,0,7:18.15
0,0,7:18.15
1,0,7:162.12
3,0,7:18.15
3,1,7:18.15
4,1,7:18.15
7,1,7:18.15
-5,2,7:162.12
1,2,7:162.12
3,2,7:18.15
4,2,7:18.15
5,2,7:18.15
-7,3,7:18.15
1,3,7:162.12
2,3,7:18.15
5,3,7:18.15
-4,4,7:18.15
0,4,7:18.15
3,4,7:18.15
6,4,7:18.15
7,4,7:18.15
1,5,7:18.15
6,5,7:18.15
-6,6,7:18.15
-3,-8,8:18.15
-1,-8,8:18.15
0,-7,8:18.15
6,-7,8:18.15
4,-6,8:18.15
-4,-5,8:18.15
-2,-5,8:162.12
0,-5,8:18.15
7,-5,8:162.12
-1,-4,8:162.12
4,-4,8:18.15
7,-4,8:18.15
7,-3,8:162.12
-2,-2,8:18.15
4,-2,8:18.15
5,-2,8:18.15
6,-2,8:18.15
7,-2,8:18.15
7,-1,8:18.15
1,0,8:162.12
4,0,8:18.15
-8,1,8:18.15
5,1,8:189.0
-6,3,8:18.15
4,3,8:18.15
-5,4,8:18.15
1,4,8:162.12
2,4,8:162.12
0,5,8:162.12
0,6,8:18.15
4,6,8:18.15
0,-8,9:18.15
-3,-7,9:18.15
-1,-7,9:18.15
-5,-6,9:18.15
-2,-6,9:18.15
-1,-6,9:18.15
-5,-5,9:18.15
1,-5,9:18.15
5,-5,9:18.15
7,-5,9:18.15
-5,-4,9:18.15
-3,-4,9:18.15
2,-4,9:18.15
4,-4,9:18.15
-5,-3,9:18.15
8,-3,9:18.15
-3,-2,9:18.15
0,-2,9:18.15
-2,-1,9:18.15
-7,0,9:18.15
-4,0,9:18.15
-3,0,9:18.15
1,0,9:162.12
6,0,9:18.15
8,0,9:18.15
3,1,9:18.15
-8,2,9:18.15
-6,2,9:18.15
4,2,9:18.15
6,2,9:18.15
-6,3,9:18.15
1,3,9:18.15
-6,4,9:18.15
1,4,9:18.15
-8,5,9:18.15
3,5,9:162.12
5,5,9:18.15
5,6,9:18.15
-5,7,9:189.0
1,7,9:18.15
3,7,9:18.15
-1,-8,10:18.15
-1,-7,10:18.15
6,-7,10:18.15
-3,-6,10:18.15
0,-6,10:18.15
2,-6,10:18.15
4,-6,10:18.15
-7,-5,10:18.7
-4,-5,10:18.15
-1,-5,10:18.15
-6,-4,10:18.15
4,-4,10:18.15
7,-4,10:18.15
-7,-3,10:18.7
-4,-3,10:18.15
6,-3,10:18.15
1,-2,10:162.12
-7,-1,10:18.15
1,-1,10:162.12
3,-1,10:18.15
4,-1,10:18.15
-4,0,10:18.15
1,0,10:162.12
2,0,10:162.12
-7,1,10:18.15
-5,1,10:18.15
0,1,10:162.12
1,1,10:18.15
-6,2,10:18.15
-1,2,10:18.15
-6,3,10:18.15
-5,3,10:18.15
3,3,10:18.15
8,3,10:18.15
-7,4,10:18.15
-6,4,10:18.15
-4,4,10:18.15
5,4,10:18.15
7,4,10:18.15
-1,5,10:18.15
0,5,10:18.15
2,5,10:18.15
4,5,10:18.15
5,5,10:18.15
-3,6,10:18.15
-1,6,10:18.15
-3,7,10:18.15
-1,7,10:18.15
1,7,10:18.15
3,7,10:18.15
4,7,10:18.15
-3,8,10:18.15
1,8,10:18.15
3,8,10:18.15
-2,9,10:18.15
0,9,10:18.15
0,-8,11:18.15
2,-8,11:18.15
2,-7,11:18.15
-6,-6,11:18.15
-5,-6,11:18.15
-2,-6,11:18.15
6,-5,11:18.15
-7,-4,11:18.7
1,-4,11:162.12
0,-3,11:18.15
1,-3,11:162.12
-7,-2,11:18.15
-3,-2,11:18.15
-5,-1,11:18.15
-4,-1,11:18.15
1,-1,11:18.15
2,-1,11:18.15
-7,0,11:18.15
-4,0,11:18.15
1,0,11:162.12
2,0,11:18.15
3,0,11:162.12
-6,1,11:18.15
-5,1,11:18.15
-4,1,11:18.15
-3,1,11:18.15
6,1,11:18.15
-6,2,11:18.15
-2,2,11:18.15
-1,2,11:162.12
0,2,11:18.15
-7,3,11:18.15
-2,3,11:162.12
6,3,11:18.15
5,4,11:18.15
6,4,11:18.15
5,5,11:18.15
7,5,11:18.15
-1,6,11:18.15
4,6,11:18.15
5,6,11:18.15
-3,7,11:18.15
-2,7,11:18.15
4,7,11:18.15
7,7,11:18.15
-2,8,11:18.15
-1,8,11:18.15
5,8,11:18.15
1,-9,12:18.15
6,-8,12:18.15
-5,-6,12:18.15
5,-6,12:18.15
-1,-5,12:18.15
0,-5,12:162.12
2,-5,12:162.12
-3,-4,12:18.15
6,-4,12:18.15
8,-3,12:18.15
-6,-2,12:18.15
-5,-2,12:18.15
8,-2,12:18.15
-4,-1,12:18.15
-1,-1,12:18.15
0,-1,12:18.15
6,-1,12:18.15
-6,0,12:18.15
-5,0,12:18.15
1,0,12:162.12
4,0,12:162.12
-7,1,12:18.7
-6,1,12:18.15
7,1,12:18.15
-3,2,12:18.15
-7,3,12:18.7
6,3,12:18.15
-5,4,12:18.15
-5,5,12:18.15
-4,5,12:18.15
3,5,12:18.15
4,5,12:18.15
5,5,12:18.15
-5,6,12:18.15
-4,6,12:18.15
-3,6,12:18.15
3,6,12:18.15
4,6,12:18.15
7,6,12:18.15
-6,7,12:18.15
-4,7,12:18.15
1,8,12:18.15
4,-8,13:18.15
-1,-7,13:18.15
-3,-6,13:18.15
-1,-6,13:18.15
2,-6,13:18.15
5,-6,13:18.15
7,-6,13:18.15
0,-5,13:18.15
-6,-3,13:18.15
5,-3,13:18.15
-5,-2,13:18.15
7,-2,13:18.15
-7,-1,13:18.7
-2,-1,13:18.15
5,-1,13:162.12
2,0,13:18.15
7,0,13:18.15
8,0,13:18.15
1,1,13:162.12
5,1,13:162.12
6,1,13:18.15
7,1,13:18.15
-1,2,13:18.15
1,2,13:18.15
6,2,13:18.15
-4,3,13:18.15
-3,4,13:18.15
1,5,13:18.15
-7,6,13:18.7
-5,6,13:18.15
-3,6,13:18.15
0,6,13:18.15
-4,7,13:18.15
5,7,13:18.15
-5,8,13:18.7
-4,8,13:18.7
0,8,13:18.15
6,8,13:18.15
-2,-8,14:18.15
0,-8,14:18.15
2,-8,14:18.15
4,-8,14:18.15
6,-8,14:18.15
-3,-7,14:18.15
-2,-7,14:18.15
4,-7,14:18.15
1,-6,14:18.15
4,-6,14:18.15
7,-6,14:18.15
-3,-5,14:18.15
-1,-5,14:18.15
0,-5,14:18.15
1,-5,14:18.15
-6,-4,14:18.7
-5,-4,14:18.15
-3,-4,14:18.15
-7,-3,14:18.7
-6,-3,14:18.7
-4,-3,14:18.15
-2,-3,14:18.15
-1,-3,14:18.15
-4,-2,14:18.15
-1,-2,14:18.15
9,-2,14:18.15
-7,-1,14:18.7
-6,-1,14:18.15
-4,-1,14:18.15
-3,-1,14:18.15
2,-1,14:18.15
6,-1,14:162.12
-6,0,14:18.15
-5,0,14:18.15
6,0,14:18.15
1,1,14:162.12
6,1,14:162.12
8,1,14:18.15
-5,3,14:189.0
-1,3,14:18.15
4,3,14:189.0
7,3,14:18.15
-7,4,14:18.7
-2,4,14:18.15
6,4,14:18.15
-4,5,14:18.15
-3,5,14:18.15
-4,6,14:18.15
-3,6,14:18.15
-1,6,14:18.15
0,6,14:18.15
2,6,14:18.15
-6,7,14:18.15
-1,7,14:18.15
7,7,14:18.15
4,8,14:18.7
-1,9,14:18.7
1,9,14:18.7
-4,-7,15:18.15
0,-7,15:18.15
4,-7,15:18.15
-1,-6,15:18.15
5,-6,15:18.15
-3,-5,15:18.15
-1,-5,15:18.15
4,-5,15:18.15
7,-5,15:18.15
-2,-4,15:18.15
-6,-3,15:18.7
-4,-3,15:18.15
-3,-3,15:18.15
6,-3,15:18.15
8,-3,15:18.15
-8,-2,15:18.7
-1,-2,15:18.15
7,-2,15:18.15
-4,-1,15:18.15
8,-1,15:18.15
-9,0,15:18.7
-7,0,15:18.7
-6,0,15:18.15
-5,0,15:18.15
1,0,15:162.12
-6,1,15:18.15
-5,1,15:18.15
-4,1,15:18.15
1,1,15:162.12
2,1,15:18.15
7,1,15:18.15
2,2,15:162.12
0,3,15:18.15
2,3,15:18.15
8,3,15:18.15
-8,4,15:18.7
-3,4,15:18.15
-3,6,15:18.15
-1,6,15:18.15
4,6,15:18.15
8,6,15:18.15
-3,7,15:18.15
3,8,15:18.15
5,8,15:18.7
-2,-7,16:18.15
0,-7,16:18.15
4,-7,16:18.15
-4,-6,16:18.15
5,-6,16:18.15
-1,-5,16:18.15
0,-5,16:18.15
2,-5,16:18.15
5,-5,16:18.15
-5,-4,16:18.15
-4,-4,16:18.15
-2,-4,16:18.15
2,-4,16:18.15
-5,-3,16:18.15
2,-2,16:162.12
9,-2,16:18.15
2,-1,16:162.12
8,-1,16:18.15
-8,0,16:18.7
-7,0,16:18.7
0,0,16:18.15
6,0,16:18.15
-6,1,16:18.15
-4,1,16:18.15
0,1,16:162.12
1,1,16:162.12
7,1,16:18.15
3,2,16:162.12
7,2,16:18.15
-7,3,16:18.7
-6,3,16:18.15
-5,3,16:18.15
-1,3,16:18.15
-5,4,16:18.15
-3,4,16:18.15
-7,5,16:18.7
-5,5,16:18.15
-2,5,16:18.15
-1,5,16:18.15
1,5,16:18.15
2,5,16:18.15
6,5,16:18.15
8,6,16:18.15
-3,7,16:18.15
4,7,16:18.15
6,7,16:18.15
7,7,16:18.15
0,8,16:18.7
-4,-7,17:18.15
-5,-6,17:18.7
3,-6,17:18.15
-3,-5,17:18.15
3,-5,17:18.15
-6,-3,17:18.15
3,-3,17:162.12
5,-3,17:18.15
5,-1,17:18.15
6,-1,17:18.15
-7,0,17:18.15
5,0,17:18.15
-7,1,17:18.15
-4,1,17:18.15
0,1,17:162.12
1,1,17:162.12
6,1,17:18.15
-6,2,17:18.15
7,2,17:18.15
-4,3,17:18.15
0,3,17:18.15
1,3,17:18.15
3,3,17:162.12
5,3,17:18.15
-4,4,17:18.15
0,4,17:18.15
2,4,17:18.15
4,4,17:18.15
7,4,17:18.15
-8,5,17:18.7
-4,5,17:18.15
0,5,17:18.15
6,5,17:18.15
-2,6,17:18.15
0,6,17:18.15
1,6,17:18.15
6,6,17:18.15
1,8,17:18.7
0,-6,18:18.15
-6,-4,18:18.15
-3,-4,18:18.15
0,-4,18:18.15
1,-4,18:18.15
3,-4,18:18.15
4,-4,18:18.15
-4,-3,18:18.15
2,-3,18:18.15
3,-3,18:18.15
5,-3,18:18.15
7,-3,18:18.15
6,-2,18:18.15
-8,0,18:18.15
-7,0,18:18.15
-1,0,18:162.12
7,0,18:18.15
-4,1,18:18.15
1,1,18:162.12
9,1,18:18.15
8,2,18:18.15
-5,3,18:18.15
0,3,18:18.15
4,3,18:162.12
-6,4,18:18.15
-3,4,18:18.15
0,4,18:18.15
1,4,18:18.15
7,4,18:18.15
-2,5,18:18.15
0,5,18:18.15
2,5,18:18.15
4,5,18:18.15
-3,6,18:18.15
-2,6,18:18.15
1,6,18:18.15
2,-7,19:18.15
-1,-6,19:18.15
2,-6,19:18.15
4,-6,19:18.15
5,-6,19:18.15
-6,-5,19:18.7
0,-5,19:18.15
2,-5,19:18.15
3,-5,19:18.15
5,-5,19:18.15
-4,-4,19:18.15
0,-4,19:18.15
1,-4,19:18.15
-7,-3,19:18.15
-4,-3,19:18.15
1,-3,19:18.15
4,-3,19:18.15
5,-3,19:18.15
-5,-2,19:18.15
-4,-2,19:18.15
-3,-2,19:18.15
-2,-2,19:18.15
2,-2,19:18.15
7,-2,19:18.15
-6,-1,19:18.15
-4,-1,19:18.15
-7,0,19:18.15
-6,0,19:18.15
-5,0,19:18.15
-1,0,19:162.12
8,0,19:18.15
-7,1,19:18.15
-6,1,19:18.15
-5,1,19:18.15
1,1,19:162.12
6,1,19:18.15
-4,2,19:18.15
0,2,19:18.15
-4,3,19:18.15
-1,3,19:18.15
0,3,19:18.15
7,3,19:18.15
-7,4,19:18.15
-2,4,19:18.15
-1,4,19:18.15
0,4,19:18.15
3,4,19:18.15
-5,5,19:18.15
-4,5,19:18.15
-3,5,19:18.15
0,5,19:18.15
7,5,19:18.15
-6,6,19:18.15
-5,6,19:18.15
-3,6,19:18.15
-2,6,19:18.15
-1,6,19:18.15
4,6,19:18.15
5,6,19:18.15
-4,7,19:18.15
-3,7,19:18.15
0,8,19:18.15
-1,-7,20:18.15
-6,-6,20:18.7
5,-6,20:18.15
-7,-4,20:18.15
-6,-4,20:18.15
-5,-4,20:18.15
4,-4,20:18.15
-8,-3,20:18.15
-7,-3,20:18.15
-5,-3,20:18.15
-4,-3,20:18.15
2,-3,20:18.15
3,-3,20:18.15
-4,-2,20:18.15
-4,-1,20:18.15
-3,-1,20:18.15
-2,-1,20:18.15
-2,0,20:162.12
1,0,20:162.12
-5,1,20:18.15
-5,2,20:18.15
0,2,20:18.15
1,2,20:162.12
6,2,20:18.15
2,3,20:18.15
-5,4,20:18.15
-1,4,20:18.15
6,5,20:18.15
-5,6,20:18.15
-4,6,20:18.15
-3,6,20:18.15
3,6,20:18.15
6,6,20:18.15
-5,7,20:18.15
-4,7,20:18.15
-2,7,20:18.15
2,7,20:18.15
4,-6,21:18.15
-4,-5,21:18.7
-5,-4,21:18.15
-1,-2,21:18.15
6,-2,21:18.15
2,-1,21:162.12
5,-1,21:18.15
-5,0,21:18.15
-4,0,21:18.15
-3,0,21:162.12
1,0,21:162.12
-5,1,21:18.15
-2,1,21:162.12
-6,2,21:18.15
2,2,21:162.12
8,2,21:18.15
-5,3,21:18.15
2,3,21:18.15
6,3,21:18.15
7,3,21:18.15
2,4,21:18.15
7,4,21:18.15
-4,5,21:18.15
-3,6,21:18.15
-2,6,21:18.15
0,6,21:18.15
1,6,21:18.15
-2,7,21:18.15
4,7,21:18.15
0,-6,22:18.15
2,-6,22:18.15
2,-5,22:18.15
4,-5,22:18.15
-5,-3,22:18.15
-1,-3,22:18.15
-7,-2,22:18.7
-6,-2,22:18.7
-2,-2,22:18.15
2,-2,22:162.12
-7,-1,22:18.7
-6,-1,22:18.7
0,-1,22:18.15
-8,0,22:18.7
-7,0,22:18.7
-6,0,22:18.15
-4,0,22:162.12
1,0,22:162.12
-6,2,22:18.15
-5,2,22:18.15
-2,2,22:162.12
0,2,22:18.15
-4,3,22:18.15
2,3,22:162.12
5,3,22:18.15
-3,5,22:18.15
1,6,22:18.15
1,-6,23:18.15
3,-6,23:18.15
4,-6,23:18.15
2,-5,23:18.15
-4,-4,23:18.15
2,-3,23:18.15
3,-3,23:18.15
3,-2,23:162.12
-6,-1,23:18.15
-5,-1,23:18.15
1,0,23:162.12
3,0,23:18.15
4,0,23:18.15
7,0,23:18.15
-6,1,23:18.15
7,1,23:18.15
-3,2,23:18.15
-7,3,23:18.15
-4,3,23:18.15
-3,3,23:162.12
-1,3,23:18.15
6,3,23:18.15
-7,4,23:18.7
-6,4,23:18.15
2,4,23:162.12
7,4,23:18.7
-7,5,23:18.15
-6,5,23:18.15
2,5,23:18.15
2,6,23:18.15
1,7,23:18.15
2,9,23:18.7
0,-6,24:18.15
-3,-5,24:18.7
3,-4,24:18.15
5,-4,24:18.15
-4,-3,24:18.15
-1,-3,24:18.15
0,-3,24:18.15
7,-3,24:18.15
-4,-2,24:18.15
6,-2,24:18.15
0,-1,24:18.15
4,-1,24:18.15
5,-1,24:18.15
-7,0,24:18.15
0,0,24:18.15
1,0,24:18.15
5,0,24:18.15
7,0,24:18.15
-2,1,24:18.15
5,2,24:18.15
-6,3,24:18.15
2,3,24:18.15
4,3,24:18.15
5,3,24:18.15
6,3,24:18.15
-6,4,24:18.15
-3,4,24:18.15
4,4,24:18.15
5,4,24:18.15
-7,5,24:18.15
-6,5,24:18.15
1,5,24:18.15
3,5,24:18.15
-4,6,24:18.15
-3,6,24:18.15
1,6,24:18.15
3,6,24:18.15
1,7,24:18.15
3,8,24:18.15
2,-6,25:18.15
4,-6,25:18.15
2,-5,25:18.15
5,-5,25:18.15
2,-4,25:18.15
3,-4,25:18.15
4,-4,25:18.15
5,-4,25:18.15
7,-4,25:18.15
-2,-3,25:18.15
5,-3,25:18.15
7,-3,25:18.15
7,-2,25:18.15
-4,-1,25:18.15
4,-1,25:18.15
-1,0,25:18.15
0,0,25:18.15
-4,1,25:18.15
7,1,25:18.15
5,2,25:18.15
7,2,25:18.15
4,3,25:18.15
5,3,25:18.15
-4,4,25:18.15
-3,4,25:18.15
0,4,25:18.15
2,4,25:18.15
3,4,25:18.15
-7,5,25:18.15
1,5,25:18.15
0,6,25:18.15
5,6,25:18.15
1,7,25:18.15
2,8,25:18.15
5,-6,26:18.15
2,-5,26:18.15
4,-5,26:18.15
-2,-4,26:18.15
5,-4,26:18.15
5,-3,26:18.15
7,-3,26:18.15
-1,-2,26:18.15
6,-2,26:18.15
6,-1,26:18.15
-2,0,26:18.15
-1,0,26:18.15
0,0,26:18.15
1,0,26:18.15
4,0,26:18.15
1,1,26:18.15
2,1,26:18.15
5,1,26:18.15
5,2,26:18.15
6,2,26:18.15
5,3,26:18.15
6,3,26:18.15
6,4,26:18.15
6,5,26:18.15
2,-2,27:18.15
-1,-1,27:18.15
-2,0,27:18.15
6,0,27:18.15
0,1,27:18.15
2,1,27:18.15
1,2,27:18.15
7,2,27:18.15
7,3,27:18.7
