[META]
version=2.0
spawnOnBlockType=2
spawnSunlight=True
spawnDarkness=True
spawnWater=False
spawnLava=False
underFill=False
randomRotation=True
dig=True
tree=True
branch=False
needsFoundation=True
rarity=100
collisionPercentage=20
spawnElevationMin=0
spawnElevationMax=200
spawnInBiome=Custom
[DATA]
-2,-2,0:17.13
-3,-1,0:17.13
-2,-1,0:17.13
-1,-1,0:17.13
0,-1,0:17.13
-4,0,0:17.13
-1,0,0:17.13
-1,1,0:17.13
-1,-1,1:17.13
-1,0,1:17.13
-1,-1,2:17.13
-1,0,2:17.13
-3,-7,3:18.13
-4,-6,3:18.13
-3,-6,3:18.13
-2,-6,3:18.13
-3,-5,3:18.13
-2,-5,3:18.13
-1,-5,3:18.13
-3,-4,3:18.13
-2,-4,3:18.13
-1,-4,3:18.13
-2,-3,3:18.13
-6,-2,3:18.13
-5,-2,3:18.13
-4,-2,3:18.13
-1,-1,3:17.13
-6,0,3:18.13
-5,0,3:18.13
-4,0,3:18.13
-1,0,3:17.13
3,2,3:18.13
-1,3,3:18.13
1,3,3:18.13
4,3,3:18.13
-1,4,3:18.13
1,4,3:18.13
3,4,3:18.13
4,4,3:18.13
5,4,3:18.13
-1,5,3:18.13
1,5,3:18.13
4,5,3:18.13
-4,-8,4:18.13
-5,-7,4:18.13
-4,-7,4:18.13
-3,-7,4:18.13
-4,-6,4:18.13
-3,-6,4:18.13
-1,-6,4:18.13
3,-6,4:18.13
-4,-5,4:18.13
-3,-5,4:18.13
-2,-5,4:18.13
2,-5,4:18.13
3,-5,4:18.13
4,-5,4:18.13
-3,-4,4:18.13
-2,-4,4:18.13
-1,-4,4:18.13
1,-4,4:18.13
2,-4,4:17.13
3,-4,4:18.13
-5,-3,4:18.13
-4,-3,4:18.13
-2,-3,4:18.13
2,-3,4:18.13
-7,-2,4:18.13
-5,-2,4:18.13
-3,-2,4:18.13
-2,-2,4:18.13
3,-2,4:18.13
4,-2,4:18.13
5,-2,4:18.13
-8,-1,4:18.13
-7,-1,4:18.13
-6,-1,4:18.13
-5,-1,4:18.13
-4,-1,4:18.13
-1,-1,4:17.13
-7,0,4:18.13
-3,0,4:18.13
-1,0,4:17.13
3,0,4:18.13
4,0,4:18.13
5,0,4:18.13
-1,1,4:18.13
2,1,4:18.13
-1,2,4:18.13
1,2,4:18.13
3,2,4:18.13
4,2,4:18.13
-5,3,4:18.13
-4,3,4:18.13
-2,3,4:18.13
0,3,4:18.13
2,3,4:18.13
3,3,4:18.13
4,3,4:18.13
5,3,4:18.13
-6,4,4:18.13
-5,4,4:18.13
-4,4,4:18.13
-2,4,4:18.13
-1,4,4:18.13
0,4,4:18.13
1,4,4:18.13
2,4,4:18.13
4,4,4:18.13
5,4,4:18.13
-5,5,4:18.13
0,5,4:18.13
3,5,4:18.13
4,5,4:18.13
5,5,4:18.13
6,5,4:18.13
-1,6,4:18.13
0,6,4:18.13
1,6,4:18.13
5,6,4:18.13
0,7,4:18.13
-5,-8,5:18.13
-4,-7,5:18.13
4,-7,5:18.13
3,-6,5:18.13
4,-6,5:18.13
5,-6,5:18.13
3,-5,5:18.13
4,-5,5:18.13
-4,-4,5:18.13
1,-4,5:18.13
2,-4,5:18.13
3,-4,5:18.13
-1,-3,5:18.13
0,-3,5:18.13
1,-3,5:18.13
2,-3,5:18.13
4,-3,5:18.13
5,-3,5:18.13
-5,-2,5:18.13
-1,-2,5:18.13
0,-2,5:18.13
1,-2,5:18.13
2,-2,5:18.13
4,-2,5:18.13
6,-2,5:18.13
-7,-1,5:18.13
-3,-1,5:18.13
-1,-1,5:17.13
0,-1,5:18.13
1,-1,5:18.13
2,-1,5:18.13
3,-1,5:18.13
4,-1,5:18.13
5,-1,5:18.13
6,-1,5:17.13
7,-1,5:18.13
-1,0,5:17.13
0,0,5:18.13
2,0,5:18.13
4,0,5:18.13
6,0,5:18.13
-3,1,5:18.13
-2,1,5:17.13
0,1,5:18.13
1,1,5:18.13
4,1,5:18.13
5,1,5:18.13
-5,2,5:18.13
-4,2,5:18.13
-3,2,5:18.13
-2,2,5:18.13
0,2,5:18.13
2,2,5:18.13
-6,3,5:18.13
-4,3,5:18.13
-3,3,5:18.13
4,3,5:18.13
-6,4,5:18.13
-5,4,5:18.13
-3,4,5:18.13
-7,5,5:18.13
-6,5,5:18.13
-5,5,5:18.13
5,5,5:18.13
-6,6,5:18.13
0,6,5:18.13
6,6,5:18.13
4,-6,6:18.13
1,-5,6:18.13
2,-5,6:18.13
1,-3,6:18.13
-4,-1,6:18.13
-1,-1,6:17.13
0,-1,6:17.13
2,-1,6:18.13
6,-1,6:18.13
-5,0,6:18.13
-4,0,6:17.13
-1,0,6:17.13
0,0,6:18.5
-6,1,6:18.13
-5,1,6:18.13
-4,1,6:18.13
-5,2,6:18.13
-3,2,6:18.13
-3,3,6:18.13
-2,3,6:17.13
-1,3,6:18.13
3,3,6:18.13
-3,4,6:18.13
-2,4,6:18.13
-1,4,6:18.13
1,4,6:18.13
-6,5,6:18.13
-2,5,6:18.13
-7,6,6:18.13
0,-6,7:18.13
-4,-5,7:18.13
-3,-5,7:18.13
-1,-5,7:18.13
0,-5,7:18.13
1,-5,7:18.13
-5,-4,7:18.13
-4,-4,7:17.13
-3,-4,7:18.13
-1,-4,7:18.13
0,-4,7:18.13
1,-4,7:18.13
-5,-3,7:18.13
-4,-3,7:17.13
-3,-3,7:18.13
-4,-2,7:18.13
-3,-1,7:18.13
-1,-1,7:17.13
0,-1,7:17.13
1,-1,7:18.13
3,-1,7:18.13
-4,0,7:18.13
-3,0,7:17.13
-2,0,7:17.13
-1,0,7:17.13
2,0,7:17.13
3,0,7:17.13
4,0,7:18.13
-6,1,7:18.13
-5,1,7:18.13
-3,1,7:18.13
-1,1,7:17.13
1,1,7:18.13
2,1,7:18.13
4,1,7:18.13
-7,2,7:18.13
-6,2,7:18.13
-5,2,7:18.13
-2,2,7:18.13
-1,2,7:17.13
0,2,7:18.13
1,2,7:17.13
2,2,7:18.13
4,2,7:18.13
-6,3,7:18.13
-5,3,7:18.13
-4,3,7:18.13
-2,3,7:18.13
-1,3,7:18.13
1,3,7:18.13
2,3,7:18.13
3,3,7:18.13
-3,4,7:18.13
-2,4,7:18.13
0,4,7:18.13
1,4,7:18.13
2,4,7:18.13
3,4,7:18.13
-4,5,7:18.13
-3,5,7:17.13
-2,5,7:18.13
-1,5,7:18.13
1,5,7:18.13
2,5,7:18.13
-3,6,7:18.13
1,-7,8:18.13
-5,-6,8:18.13
0,-6,8:18.13
1,-6,8:18.13
2,-6,8:18.13
-6,-5,8:18.13
-5,-5,8:17.13
-4,-5,8:18.13
0,-5,8:18.13
1,-5,8:18.13
2,-5,8:18.13
-5,-4,8:18.13
-4,-4,8:18.13
-2,-4,8:18.13
-1,-4,8:18.13
0,-4,8:18.13
2,-4,8:18.13
-4,-3,8:18.13
-3,-3,8:18.13
-1,-3,8:18.13
0,-3,8:17.13
1,-3,8:18.13
2,-3,8:18.13
-5,-2,8:18.13
-4,-2,8:18.13
-3,-2,8:17.13
-2,-2,8:18.13
-1,-2,8:18.13
0,-2,8:17.13
1,-2,8:18.13
-3,-1,8:18.13
-2,-1,8:17.13
-1,-1,8:17.13
0,-1,8:17.13
2,-1,8:18.13
4,-1,8:18.13
-3,0,8:18.13
-1,0,8:17.13
0,0,8:17.13
1,0,8:17.13
2,0,8:17.13
3,0,8:18.13
5,0,8:18.13
0,1,8:17.13
1,1,8:18.13
2,1,8:18.13
3,1,8:18.13
4,1,8:18.13
5,1,8:17.13
6,1,8:18.13
-6,2,8:18.13
-1,2,8:18.13
1,2,8:18.13
5,2,8:18.13
-7,3,8:18.13
2,3,8:18.13
4,3,8:18.13
2,4,8:18.13
3,4,8:18.13
-3,5,8:18.13
2,5,8:18.13
3,5,8:18.13
4,5,8:18.13
-4,6,8:18.13
3,6,8:18.13
-6,-6,9:18.13
1,-6,9:18.13
-5,-5,9:18.13
3,-4,9:18.13
0,-3,9:18.13
2,-3,9:18.13
3,-3,9:17.13
4,-3,9:18.13
-3,-2,9:18.13
0,-2,9:18.13
1,-2,9:18.13
2,-2,9:17.13
3,-2,9:18.13
-2,-1,9:18.13
-1,-1,9:17.13
0,-1,9:17.13
2,-1,9:18.13
-1,0,9:17.13
2,0,9:18.13
-2,1,9:18.13
0,1,9:18.13
5,1,9:18.13
-3,2,9:18.13
-2,2,9:17.13
-1,2,9:18.13
-4,3,9:18.13
-3,3,9:17.13
-2,3,9:18.13
-3,4,9:18.13
3,5,9:18.13
4,6,9:18.13
-2,-5,10:18.13
4,-5,10:18.13
-3,-4,10:18.13
-2,-4,10:17.13
-1,-4,10:18.13
3,-4,10:18.13
4,-4,10:17.13
5,-4,10:18.13
-3,-3,10:18.13
-2,-3,10:17.13
-1,-3,10:18.13
1,-3,10:18.13
3,-3,10:18.13
4,-3,10:18.13
1,-2,10:18.13
2,-2,10:18.13
4,-2,10:18.13
-5,-1,10:18.13
-4,-1,10:18.13
-3,-1,10:18.13
-1,-1,10:17.13
0,-1,10:17.13
1,-1,10:17.13
2,-1,10:18.13
3,-1,10:18.13
-4,0,10:17.13
-3,0,10:17.13
-1,0,10:17.13
1,0,10:18.13
-4,1,10:18.13
-3,1,10:18.13
-2,1,10:18.13
-1,1,10:17.13
0,1,10:18.13
1,1,10:17.13
2,1,10:18.13
-4,2,10:18.13
-2,2,10:18.13
-1,2,10:18.13
1,2,10:18.13
2,2,10:17.13
3,2,10:18.13
-4,3,10:18.13
-3,3,10:18.13
1,3,10:18.13
-5,4,10:18.13
-4,4,10:17.13
-3,4,10:18.13
-2,4,10:18.13
-4,5,10:18.13
-3,-6,11:18.13
-4,-5,11:18.13
-3,-5,11:17.13
-2,-5,11:18.13
5,-5,11:18.13
-3,-4,11:18.13
-2,-4,11:18.13
4,-4,11:18.13
-2,-3,11:18.13
-1,-3,11:18.13
-4,-2,11:18.13
-1,-2,11:17.13
0,-2,11:18.13
-5,-1,11:18.13
-2,-1,11:18.13
-1,-1,11:17.13
1,-1,11:18.13
-6,0,11:18.13
-5,0,11:17.13
-4,0,11:18.13
-3,0,11:18.13
-2,0,11:17.13
-1,0,11:17.13
0,0,11:17.13
1,0,11:18.13
-5,1,11:18.13
-4,1,11:18.13
-2,1,11:18.13
-1,1,11:18.13
1,1,11:18.13
2,2,11:18.13
1,3,11:18.13
2,3,11:17.13
3,3,11:18.13
-4,4,11:18.13
2,4,11:18.13
-4,-6,12:18.13
-3,-5,12:18.13
2,-4,12:18.13
-2,-3,12:18.13
-1,-3,12:17.13
0,-3,12:18.13
1,-3,12:18.13
2,-3,12:17.13
3,-3,12:18.13
0,-2,12:18.13
1,-2,12:17.13
2,-2,12:18.13
-1,-1,12:17.13
0,-1,12:18.13
1,-1,12:18.5
2,-1,12:18.5
-5,0,12:18.13
-2,0,12:18.13
-1,0,12:17.13
0,2,12:18.13
2,3,12:18.13
3,4,12:18.13
-1,-5,13:18.13
-2,-4,13:18.13
-1,-4,13:17.13
0,-4,13:18.13
1,-4,13:18.13
3,-4,13:18.13
-3,-3,13:18.13
-1,-3,13:18.13
1,-3,13:18.5
2,-3,13:18.13
3,-3,13:17.13
4,-3,13:18.13
-3,-2,13:18.13
-2,-2,13:18.13
-1,-2,13:17.13
0,-2,13:18.13
1,-2,13:18.13
3,-2,13:18.13
-4,-1,13:18.13
-3,-1,13:17.13
-1,-1,13:17.13
0,-1,13:17.13
1,-1,13:18.13
2,-1,13:18.13
-3,0,13:18.13
-1,0,13:17.13
1,0,13:17.13
1,1,13:18.13
-2,2,13:18.13
-1,2,13:17.13
0,2,13:18.13
-1,3,13:18.13
0,3,13:17.13
1,3,13:18.13
0,4,13:18.13
-1,-4,14:18.13
4,-4,14:18.13
-4,-3,14:18.13
1,-3,14:18.5
-5,-2,14:18.13
-4,-2,14:18.13
-3,-2,14:18.13
-2,-2,14:18.13
-1,-2,14:18.13
-4,-1,14:18.13
-3,-1,14:18.13
-2,-1,14:17.13
-1,-1,14:17.13
0,-1,14:18.13
2,-1,14:18.5
-3,0,14:18.13
-2,0,14:17.13
-1,0,14:17.13
0,0,14:17.13
1,0,14:18.13
2,0,14:17.13
3,0,14:18.13
-4,1,14:18.13
-3,1,14:17.13
-2,1,14:18.13
-1,1,14:17.13
0,1,14:18.13
2,1,14:18.13
-3,2,14:18.13
-1,2,14:18.13
0,3,14:18.13
1,3,14:18.13
-1,4,14:18.13
0,4,14:18.13
1,4,14:18.13
2,4,14:18.13
1,5,14:18.13
-5,-3,15:18.13
-2,-1,15:18.13
-1,-1,15:17.13
-2,0,15:18.13
-1,0,15:17.13
0,0,15:18.13
2,0,15:18.13
-4,1,15:18.13
-3,1,15:18.13
-1,1,15:18.13
-5,2,15:18.13
-4,2,15:18.13
-3,2,15:18.13
-2,2,15:18.13
-4,3,15:18.13
2,5,15:18.13
0,-3,16:18.13
-1,-2,16:18.13
0,-2,16:18.13
1,-2,16:18.13
-1,-1,16:17.13
-1,0,16:18.13
-5,3,16:18.13
-2,-4,17:18.13
-3,-3,17:18.13
-2,-3,17:18.13
-1,-3,17:18.13
1,-3,17:18.13
-2,-2,17:18.13
-1,-2,17:18.13
0,-2,17:18.13
-3,-1,17:18.13
-2,-1,17:18.13
-1,-1,17:17.13
0,-1,17:18.13
2,-1,17:18.13
-3,0,17:18.13
-2,0,17:18.13
-1,0,17:18.13
0,0,17:18.13
1,0,17:18.13
2,0,17:18.13
-2,1,17:18.13
1,1,17:18.13
-2,-4,18:18.13
-1,-2,18:18.13
-4,-1,18:18.13
-2,-1,18:18.13
-1,-1,18:17.13
0,-1,18:18.13
-1,0,18:18.13
-3,1,18:18.13
2,1,18:18.13
-3,-3,19:18.13
-2,-2,19:18.13
-1,-2,19:18.13
-2,-1,19:18.13
-1,-1,19:17.13
0,-1,19:18.13
-1,0,19:18.13
1,0,19:18.13
-1,1,19:18.13
-2,-2,20:18.13
-1,-2,20:18.5
-2,-1,20:18.13
-1,-1,20:17.13
0,-1,20:18.13
-1,0,20:18.13
-1,-1,21:18.13
