[META]
version=2.0
spawnOnBlockType=2
spawnSunlight=True
spawnDarkness=True
spawnWater=False
spawnLava=False
underFill=False
randomRotation=True
dig=True
tree=True
branch=False
needsFoundation=True
rarity=100
collisionPercentage=20
spawnElevationMin=0
spawnElevationMax=200
spawnInBiome=Custom
[DATA]
-1,-2,0:162.12
-1,1,0:162.12
-1,-1,1:162.12
0,0,1:162.12
0,0,2:162.12
-2,-4,3:18.7
1,-4,3:18.7
-3,-3,3:18.7
2,-3,3:18.15
3,-3,3:18.15
2,-2,3:18.15
3,-2,3:18.15
1,-1,3:162.12
4,-1,3:18.7
-1,0,3:18.15
0,0,3:162.12
1,0,3:18.15
2,0,3:18.15
4,0,3:18.7
-4,1,3:18.7
0,1,3:18.7
1,1,3:162.12
-1,2,3:18.7
1,2,3:18.7
2,2,3:162.12
-2,3,3:18.7
-1,3,3:18.7
1,3,3:18.7
3,3,3:18.15
2,4,3:18.15
-2,-5,4:18.7
0,-4,4:18.15
1,-4,4:18.15
-1,-3,4:18.7
0,-3,4:18.7
2,-3,4:162.12
3,-3,4:18.15
4,-3,4:18.15
-4,-2,4:18.7
-2,-2,4:18.7
0,-2,4:18.7
1,-2,4:162.12
3,-2,4:189.0
5,-2,4:18.15
-3,-1,4:18.7
-1,-1,4:162.12
1,-1,4:18.15
5,-1,4:18.7
-1,0,4:189.0
0,0,4:162.12
1,0,4:18.15
-4,1,4:18.15
-3,1,4:18.15
-1,1,4:162.12
0,1,4:18.15
2,1,4:18.15
-4,2,4:18.15
-2,2,4:162.12
-1,2,4:18.15
0,2,4:18.15
2,2,4:18.15
-4,3,4:18.15
-4,4,4:18.7
-2,4,4:18.15
0,4,4:18.15
0,-5,5:18.15
1,-5,5:189.0
-2,-4,5:18.7
-1,-4,5:18.15
0,-4,5:189.0
3,-3,5:18.15
-4,-2,5:18.7
-2,-2,5:162.12
4,-2,5:189.0
5,-2,5:18.7
4,-1,5:18.7
-5,0,5:18.15
0,0,5:162.12
2,0,5:18.15
-5,1,5:18.15
-3,1,5:18.15
0,1,5:162.12
1,1,5:162.12
2,1,5:162.12
4,1,5:18.7
-3,2,5:18.15
1,2,5:18.7
2,2,5:18.15
3,2,5:18.15
5,2,5:18.15
-3,3,5:162.12
3,3,5:18.15
4,3,5:18.15
-4,4,5:18.7
1,4,5:18.15
2,4,5:18.15
-4,5,5:18.7
-2,5,5:18.7
-4,-4,6:18.7
-3,-4,6:18.7
-2,-4,6:18.7
-1,-4,6:18.7
1,-4,6:18.7
-3,-3,6:162.12
-4,-2,6:18.7
-3,-2,6:18.7
-2,-2,6:18.15
-1,-2,6:18.15
1,-2,6:18.7
2,-2,6:18.7
4,-2,6:18.7
5,-2,6:18.7
-2,-1,6:18.15
0,-1,6:18.15
1,-1,6:162.12
2,-1,6:18.7
4,-1,6:18.7
-2,0,6:18.7
3,0,6:18.7
5,0,6:18.7
-5,1,6:189.0
0,1,6:162.12
1,1,6:18.7
4,1,6:18.7
5,1,6:18.7
-5,2,6:18.15
3,2,6:162.12
4,2,6:162.12
-4,3,6:18.15
-2,3,6:18.15
0,3,6:18.15
2,3,6:18.7
4,3,6:189.0
-4,4,6:18.15
4,4,6:18.7
-2,5,6:18.15
-1,5,6:18.15
0,5,6:18.15
1,5,6:18.15
-3,-4,7:18.7
2,-3,7:18.7
-3,-2,7:18.15
-1,-2,7:18.15
-3,-1,7:18.7
-2,-1,7:18.15
-1,-1,7:189.0
1,-1,7:162.12
2,-1,7:162.12
3,-1,7:18.7
4,-1,7:18.7
5,-1,7:18.7
-4,0,7:18.15
-3,0,7:18.7
3,0,7:18.7
5,0,7:18.7
-3,1,7:18.15
-1,1,7:18.7
0,1,7:162.12
1,1,7:18.7
4,1,7:18.7
5,1,7:18.7
-4,2,7:18.15
2,2,7:18.7
5,2,7:18.15
-2,3,7:18.15
-1,3,7:18.15
2,3,7:18.7
3,3,7:18.7
-4,4,7:18.15
0,4,7:18.15
1,4,7:18.7
2,4,7:18.7
3,4,7:18.7
-3,5,7:18.15
-1,5,7:18.15
1,5,7:18.7
-1,-3,8:18.15
-2,-2,8:189.0
1,-2,8:18.7
4,-2,8:18.15
1,-1,8:162.12
3,-1,8:162.12
-4,0,8:18.7
-1,0,8:18.7
0,0,8:18.15
1,0,8:18.15
3,0,8:18.7
0,1,8:162.12
-3,2,8:18.15
2,2,8:18.7
3,2,8:18.7
1,3,8:18.7
-3,4,8:18.15
-2,4,8:18.7
0,4,8:18.15
2,4,8:18.7
1,-2,9:18.15
3,-2,9:18.15
-3,-1,9:18.15
-2,-1,9:18.7
0,-1,9:18.15
1,-1,9:162.12
4,-1,9:189.0
0,0,9:18.15
1,0,9:18.15
2,0,9:18.15
3,0,9:18.7
-3,1,9:18.7
-2,1,9:18.15
-1,1,9:18.15
1,1,9:189.0
4,1,9:18.7
0,2,9:18.15
-2,3,9:18.15
0,3,9:18.15
0,-2,10:18.15
1,-2,10:18.15
2,-2,10:18.7
-1,-1,10:18.15
0,-1,10:18.7
2,-1,10:18.7
3,-1,10:18.7
0,0,10:18.15
4,0,10:18.7
-2,2,10:18.7
-1,2,10:18.15
