[META]
version=2.0
spawnOnBlockType=2
spawnSunlight=True
spawnDarkness=True
spawnWater=False
spawnLava=False
underFill=False
randomRotation=True
dig=True
tree=False
branch=False
needsFoundation=True
rarity=100
collisionPercentage=20
spawnElevationMin=0
spawnElevationMax=200
spawnInBiome=Custom
[DATA]
3,-2,0:162.12
2,0,0:162.12
2,-1,1:162.12
2,0,1:162.12
2,-1,2:162.12
-2,-4,3:18.7
-1,-4,3:18.7
2,-4,3:18.7
-3,-3,3:18.15
1,-3,3:18.7
2,-3,3:18.7
-2,-2,3:18.15
3,-2,3:18.15
-2,-1,3:18.15
2,-1,3:162.12
3,-1,3:18.15
4,-1,3:18.15
-1,0,3:18.15
-3,-5,4:18.15
-2,-5,4:18.15
-2,-4,4:18.15
1,-4,4:18.7
2,-4,4:18.7
3,-4,4:18.7
-1,-3,4:18.15
1,-3,4:18.7
4,-3,4:18.15
-3,-2,4:18.15
2,-2,4:162.12
4,-2,4:18.15
-3,-1,4:18.15
-2,-1,4:18.15
-1,-1,4:18.15
1,-1,4:162.12
2,-1,4:18.15
3,-1,4:162.12
-3,0,4:18.15
-2,0,4:18.15
0,0,4:162.12
4,0,4:18.15
0,1,4:18.15
2,1,4:18.15
2,2,4:18.15
3,2,4:18.15
-1,-4,5:18.7
2,-4,5:18.7
-3,-3,5:18.15
-2,-3,5:18.7
0,-3,5:18.7
2,-3,5:18.15
3,-3,5:18.15
1,-2,5:18.15
2,-2,5:162.12
4,-2,5:18.15
-2,-1,5:18.15
-1,-1,5:18.15
2,-1,5:18.15
3,-1,5:162.12
4,-1,5:18.15
-2,0,5:162.12
-1,0,5:162.12
3,0,5:18.15
4,0,5:18.15
-2,1,5:18.15
4,1,5:18.15
2,3,5:18.15
3,3,5:18.15
-1,-4,6:18.7
1,-3,6:162.12
2,-2,6:18.15
3,-2,6:162.12
-4,-1,6:18.15
-3,-1,6:18.15
2,-1,6:18.15
-3,0,6:18.15
-1,0,6:18.15
0,0,6:18.15
2,0,6:162.12
3,0,6:162.12
-2,1,6:18.15
2,1,6:18.15
1,2,6:18.15
4,2,6:18.15
1,-5,7:189.0
0,-4,7:189.0
1,-4,7:18.7
2,-4,7:18.7
-1,-3,7:189.0
1,-3,7:162.12
3,-3,7:18.15
-2,-2,7:18.15
3,-2,7:162.12
-3,-1,7:18.15
-1,-1,7:189.0
0,-1,7:18.15
1,-1,7:18.15
3,0,7:162.12
6,0,7:18.15
-2,1,7:18.15
-1,1,7:18.15
1,1,7:162.12
3,1,7:18.15
4,1,7:18.15
0,2,7:18.15
4,2,7:18.15
2,-5,8:18.15
0,-4,8:18.7
1,-4,8:162.12
3,-4,8:18.7
4,-4,8:18.7
0,-3,8:18.15
3,-3,8:18.7
4,-3,8:162.12
5,-3,8:18.7
-3,-2,8:18.15
3,-2,8:18.15
-1,-1,8:18.15
0,-1,8:18.15
3,-1,8:18.15
-2,0,8:18.15
0,0,8:18.15
1,0,8:18.15
3,0,8:18.15
4,0,8:162.12
-3,1,8:18.15
0,1,8:162.12
1,1,8:18.15
5,1,8:18.15
0,-5,9:18.15
2,-5,9:18.15
-2,-4,9:18.7
0,-4,9:18.7
-2,-3,9:18.15
3,-3,9:18.15
4,-2,9:18.15
5,-2,9:18.15
-2,-1,9:18.15
0,-1,9:18.15
1,-1,9:18.15
2,-1,9:18.15
4,-1,9:18.15
-3,0,9:18.15
-2,0,9:18.15
-1,0,9:18.15
1,0,9:18.15
3,0,9:18.15
5,0,9:18.15
-3,1,9:18.15
0,1,9:18.15
1,1,9:18.15
2,1,9:18.15
3,1,9:18.15
4,1,9:18.15
-1,2,9:18.15
1,-4,10:18.7
1,-3,10:18.7
4,-3,10:189.0
-2,-2,10:18.15
0,-2,10:18.15
1,-2,10:18.15
2,-2,10:18.15
4,-2,10:18.15
-1,-1,10:18.15
-2,0,10:18.15
3,0,10:18.15
-1,1,10:18.15
0,1,10:18.15
3,1,10:18.15
3,-3,11:18.15
