[META]
version=2.0
spawnOnBlockType=2
spawnSunlight=True
spawnDarkness=True
spawnWater=False
spawnLava=False
underFill=False
randomRotation=True
dig=True
tree=False
branch=False
needsFoundation=True
rarity=100
collisionPercentage=20
spawnElevationMin=0
spawnElevationMax=200
spawnInBiome=Custom
[DATA]
1,-4,0:162.12
-1,-3,0:162.12
1,-2,0:162.12
1,-4,1:162.12
0,-3,1:162.12
0,-3,2:162.12
0,-8,3:18.15
-1,-6,3:18.15
0,-6,3:18.15
-1,-2,3:18.15
0,-2,3:162.12
3,-2,3:18.15
4,-2,3:18.15
-3,-1,3:18.7
-1,-1,3:18.7
1,-1,3:162.12
2,-1,3:18.7
3,0,3:18.7
4,0,3:18.7
-2,-9,4:18.15
-1,-9,4:18.15
-3,-8,4:18.15
-2,-8,4:18.7
-2,-7,4:18.15
-1,-7,4:18.15
-1,-6,4:18.15
1,-6,4:18.7
-1,-5,4:162.12
1,-5,4:18.15
-5,-4,4:18.15
-2,-4,4:18.15
-1,-4,4:162.12
1,-4,4:18.15
0,-3,4:162.12
4,-3,4:18.15
0,-2,4:162.12
1,-2,4:18.15
2,-2,4:18.15
4,-2,4:18.15
-3,-1,4:18.7
-1,-1,4:162.12
-4,0,4:18.7
-3,0,4:18.7
-2,0,4:162.12
-1,0,4:18.7
0,0,4:18.7
2,0,4:162.12
4,0,4:18.7
5,0,4:18.7
3,1,4:162.12
-6,2,4:18.7
-2,2,4:18.15
1,2,4:18.7
3,2,4:162.12
-5,3,4:18.7
3,4,4:18.7
4,4,4:18.15
0,-9,5:18.15
-4,-7,5:18.15
-3,-7,5:18.15
-1,-7,5:162.12
3,-7,5:18.15
-4,-6,5:18.15
-1,-6,5:162.12
3,-6,5:18.15
-1,-5,5:18.15
2,-5,5:18.15
-4,-4,5:18.15
-3,-4,5:18.15
0,-4,5:162.12
3,-4,5:18.15
4,-3,5:18.15
-4,-2,5:18.7
0,-2,5:162.12
1,-2,5:18.15
4,-2,5:18.15
2,-1,5:18.7
6,-1,5:18.7
-1,0,5:18.7
0,0,5:18.7
-7,1,5:18.7
-6,1,5:18.7
-5,1,5:18.7
-4,1,5:18.7
-3,1,5:18.15
-2,1,5:162.12
-1,1,5:18.15
2,1,5:18.7
-5,2,5:18.7
-3,2,5:162.12
2,2,5:18.7
3,2,5:18.7
4,2,5:18.15
-6,3,5:18.7
-4,3,5:162.12
-1,3,5:18.7
0,3,5:18.7
1,3,5:18.7
3,3,5:18.15
4,3,5:162.12
-5,4,5:18.7
-4,4,5:18.7
2,4,5:18.7
3,4,5:18.15
-1,-9,6:18.15
-3,-8,6:18.15
4,-8,6:18.15
-1,-7,6:18.15
3,-6,6:18.15
1,-5,6:162.12
2,-5,6:162.12
3,-5,6:18.15
4,-5,6:18.15
-4,-4,6:18.15
-3,-4,6:18.15
-2,-4,6:18.15
0,-4,6:18.15
1,-4,6:18.15
-4,-3,6:18.7
-5,-2,6:18.7
-1,-2,6:162.12
1,-2,6:18.15
5,-2,6:18.15
6,-2,6:18.15
-5,-1,6:18.7
-1,-1,6:18.7
2,-1,6:18.7
4,-1,6:18.7
-3,1,6:18.15
-2,1,6:18.15
-7,2,6:18.7
-6,2,6:18.7
-4,2,6:18.7
1,2,6:18.7
4,2,6:18.15
5,2,6:18.15
-6,3,6:18.7
5,3,6:18.15
-4,4,6:189.0
0,-9,7:18.15
1,-9,7:18.15
2,-8,7:18.15
-2,-7,7:18.15
-5,-6,7:18.15
2,-6,7:18.15
4,-5,7:18.15
5,-5,7:18.15
-6,-4,7:18.15
-4,-4,7:18.15
2,-4,7:18.15
5,-4,7:18.15
-4,-3,7:18.7
-2,-3,7:18.7
3,-3,7:18.15
4,-3,7:18.15
-4,-2,7:18.7
-3,-2,7:18.7
-2,-2,7:162.12
2,-2,7:18.15
3,-2,7:18.15
5,-2,7:18.15
7,-2,7:18.15
-1,-1,7:162.12
0,-1,7:162.12
-6,0,7:18.7
-3,0,7:18.7
-7,1,7:18.7
-6,1,7:18.7
-2,1,7:18.15
2,1,7:18.7
4,1,7:18.15
1,2,7:189.0
3,2,7:18.7
4,2,7:18.7
-4,3,7:18.7
-1,3,7:18.7
4,3,7:18.15
6,3,7:18.7
-1,4,7:18.7
1,4,7:18.7
3,4,7:18.7
5,4,7:18.7
-1,-9,8:18.15
1,-9,8:18.15
4,-8,8:18.15
0,-7,8:18.15
-4,-6,8:18.15
-2,-6,8:18.15
-3,-5,8:18.15
-2,-5,8:18.15
-6,-4,8:18.15
-5,-4,8:18.15
-4,-4,8:18.15
1,-4,8:18.15
3,-4,8:18.15
-6,-3,8:18.7
-4,-3,8:162.12
-3,-3,8:162.12
-1,-3,8:18.15
2,-2,8:162.12
7,-2,8:18.15
-1,-1,8:162.12
1,-1,8:162.12
2,-1,8:18.7
3,-1,8:18.15
4,-1,8:18.15
2,0,8:18.7
-6,1,8:18.7
-5,1,8:18.7
-4,1,8:18.7
1,1,8:18.7
3,1,8:18.7
-2,2,8:18.7
0,3,8:18.7
1,3,8:18.7
-1,4,8:18.7
1,4,8:18.7
3,4,8:18.15
5,4,8:18.15
6,4,8:18.7
-2,-9,9:18.15
1,-9,9:18.15
0,-8,9:18.15
-2,-7,9:18.15
-4,-6,9:18.15
-2,-6,9:18.15
2,-6,9:18.15
3,-6,9:18.15
5,-6,9:18.15
-2,-5,9:18.15
-5,-4,9:162.12
0,-4,9:18.15
3,-4,9:18.15
-7,-3,9:18.15
-6,-3,9:18.15
1,-3,9:18.15
2,-3,9:18.15
-3,-2,9:18.7
1,-2,9:18.15
2,-2,9:18.15
3,-2,9:162.12
4,-2,9:162.12
-3,-1,9:162.12
-2,-1,9:162.12
-1,-1,9:162.12
0,-1,9:18.7
-7,0,9:18.7
-6,0,9:18.15
-1,0,9:162.12
0,0,9:18.15
2,0,9:18.7
5,0,9:18.7
-5,1,9:18.7
-4,1,9:18.7
-2,1,9:18.15
3,1,9:18.7
5,1,9:18.7
6,1,9:18.7
-5,2,9:18.7
-4,2,9:18.7
0,2,9:18.7
-3,3,9:18.7
-2,3,9:18.7
0,3,9:18.7
5,3,9:18.7
3,4,9:18.15
6,4,9:18.7
0,5,9:18.15
-2,-8,10:18.15
-1,-8,10:18.15
1,-8,10:18.15
2,-8,10:18.15
4,-8,10:18.15
2,-7,10:18.15
2,-6,10:18.15
3,-6,10:18.15
4,-6,10:18.15
6,-6,10:18.15
-5,-5,10:18.7
-4,-4,10:18.15
-3,-4,10:18.15
4,-4,10:162.12
-6,-3,10:18.15
3,-3,10:18.15
4,-3,10:162.12
5,-3,10:189.0
-5,-2,10:18.15
-1,-2,10:162.12
3,-2,10:18.15
4,-2,10:18.15
5,-2,10:18.15
7,-2,10:18.15
-5,-1,10:18.15
-1,-1,10:162.12
2,-1,10:18.7
5,-1,10:162.12
7,-1,10:18.15
-6,0,10:162.12
-5,0,10:162.12
-4,0,10:162.12
2,0,10:18.7
6,0,10:18.15
-6,1,10:18.15
-5,1,10:18.15
-4,1,10:18.7
-1,1,10:162.12
5,1,10:18.7
-2,2,10:18.7
-1,2,10:162.12
4,2,10:18.7
-5,3,10:18.7
-1,3,10:162.12
0,3,10:18.7
-1,4,10:162.12
3,4,10:18.15
-4,5,10:18.7
-1,6,10:18.7
-1,-7,11:18.15
2,-7,11:18.15
3,-7,11:18.15
4,-7,11:18.15
-5,-6,11:18.7
5,-6,11:162.12
1,-5,11:18.15
2,-5,11:18.15
5,-5,11:162.12
-2,-4,11:18.15
-1,-4,11:162.12
-1,-3,11:162.12
7,-3,11:18.15
-7,-2,11:18.15
-5,-1,11:18.7
-4,-1,11:18.7
-1,-1,11:162.12
2,-1,11:18.15
4,-1,11:18.7
8,-1,11:18.15
-6,0,11:18.7
-5,0,11:18.7
-3,0,11:18.15
6,0,11:162.12
-3,1,11:18.15
2,1,11:18.7
3,1,11:18.7
9,1,11:18.7
-4,2,11:18.15
-3,2,11:18.15
-2,2,11:18.15
3,2,11:18.7
6,2,11:18.15
8,2,11:18.15
-1,3,11:18.7
1,3,11:18.15
-2,4,11:18.15
-1,4,11:18.15
3,4,11:18.7
-4,5,11:18.7
-1,5,11:162.12
0,5,11:18.15
1,5,11:18.7
-1,6,11:18.15
0,6,11:18.15
0,-8,12:18.15
2,-8,12:18.15
-2,-7,12:18.15
0,-7,12:18.15
1,-7,12:18.15
2,-7,12:18.15
4,-7,12:18.15
-4,-6,12:18.15
-3,-6,12:18.15
0,-6,12:162.12
1,-6,12:18.15
3,-6,12:18.15
6,-6,12:18.15
-5,-5,12:18.7
-2,-5,12:18.15
0,-5,12:162.12
4,-5,12:18.15
3,-4,12:18.15
-8,-2,12:18.7
-2,-2,12:18.7
-6,-1,12:18.7
-5,-1,12:18.7
-2,-1,12:162.12
-1,-1,12:162.12
0,-1,12:18.15
1,-1,12:18.15
5,-1,12:18.7
8,0,12:18.7
9,0,12:18.7
-7,1,12:18.15
-4,1,12:18.15
-2,1,12:18.7
-1,1,12:18.7
1,1,12:18.7
3,1,12:18.7
9,1,12:18.7
0,2,12:18.7
4,2,12:18.7
5,2,12:18.7
6,2,12:18.15
-1,3,12:18.7
-6,4,12:18.7
-2,4,12:18.15
0,4,12:18.15
2,4,12:18.7
1,5,12:18.7
3,5,12:18.7
0,6,12:18.7
2,6,12:18.7
0,-8,13:18.15
-4,-7,13:18.15
-1,-7,13:18.15
0,-7,13:18.15
4,-7,13:18.15
-1,-6,13:18.15
0,-6,13:18.15
3,-6,13:18.15
-3,-5,13:18.15
-6,-3,13:18.7
-4,-3,13:18.15
2,-3,13:18.15
-3,-2,13:162.12
1,-2,13:18.7
6,-2,13:18.7
7,-2,13:18.15
8,-2,13:18.15
-8,-1,13:18.15
-6,-1,13:18.7
-1,-1,13:162.12
0,-1,13:162.12
2,-1,13:18.15
3,-1,13:18.15
-8,0,13:18.15
-5,0,13:18.15
-3,0,13:162.12
-2,0,13:162.12
1,0,13:162.12
4,0,13:18.15
5,0,13:18.7
6,0,13:18.7
0,1,13:18.7
4,1,13:18.7
7,1,13:18.7
9,1,13:18.7
-6,2,13:18.7
0,2,13:18.7
1,2,13:18.7
2,2,13:18.7
8,2,13:18.7
-3,3,13:18.7
3,3,13:18.7
0,4,13:18.15
3,4,13:18.7
3,5,13:18.7
5,5,13:18.7
1,6,13:18.7
-2,-8,14:18.15
-1,-8,14:18.15
-3,-7,14:18.15
1,-7,14:18.15
2,-7,14:18.15
-3,-6,14:18.15
-2,-6,14:18.15
1,-6,14:18.15
-6,-5,14:18.7
-5,-4,14:18.7
1,-4,14:18.15
2,-4,14:18.15
4,-4,14:18.15
-5,-3,14:18.7
0,-3,14:18.15
-6,-2,14:18.7
-4,-2,14:162.12
-1,-2,14:18.7
0,-2,14:18.7
4,-2,14:18.7
-8,-1,14:18.15
-1,-1,14:162.12
3,-1,14:18.15
-4,0,14:18.15
2,0,14:162.12
5,0,14:18.7
7,0,14:18.7
8,0,14:18.7
-8,1,14:18.15
-4,1,14:162.12
-3,1,14:18.7
-2,1,14:18.7
3,1,14:162.12
6,1,14:18.7
-5,2,14:162.12
-1,2,14:18.7
4,2,14:18.7
5,2,14:18.7
-5,3,14:18.7
-4,3,14:18.7
-2,3,14:18.7
4,3,14:18.7
6,3,14:18.15
2,4,14:18.7
6,4,14:18.15
7,4,14:18.15
8,4,14:18.15
-6,5,14:18.15
-5,5,14:18.7
2,5,14:18.7
7,5,14:18.7
-4,6,14:18.7
-2,-8,15:18.15
-1,-8,15:18.15
0,-8,15:18.15
-4,-7,15:18.15
-2,-6,15:18.15
-6,-5,15:18.7
2,-5,15:18.15
-7,-4,15:18.7
-4,-4,15:18.15
1,-4,15:18.15
2,-4,15:18.15
-7,-3,15:18.15
-6,-3,15:18.15
-5,-3,15:162.12
-2,-3,15:18.15
4,-3,15:18.15
5,-3,15:18.15
-7,-2,15:18.15
-6,-2,15:18.15
-5,-2,15:18.7
-2,-2,15:18.7
0,-2,15:162.12
6,-2,15:18.7
-6,-1,15:18.15
-5,-1,15:18.15
-2,-1,15:18.7
-1,-1,15:18.7
2,-1,15:18.15
3,-1,15:162.12
4,-1,15:162.12
-4,0,15:18.7
-2,0,15:18.7
-1,0,15:162.12
4,1,15:162.12
7,1,15:18.7
-6,2,15:162.12
-4,2,15:18.7
3,2,15:18.7
5,2,15:162.12
6,2,15:18.7
-5,3,15:18.15
-3,3,15:18.7
0,3,15:18.15
7,3,15:18.15
-3,4,15:18.15
-2,4,15:18.15
-1,4,15:18.7
4,4,15:18.7
5,4,15:18.7
6,4,15:18.15
4,5,15:18.7
5,5,15:18.7
6,5,15:18.7
8,5,15:18.7
-4,6,15:18.7
-1,-8,16:18.15
-3,-7,16:18.15
-1,-7,16:18.15
0,-7,16:189.0
2,-7,16:18.15
-1,-6,16:18.15
2,-6,16:18.15
3,-6,16:18.15
-3,-5,16:18.15
-4,-4,16:18.15
1,-4,16:162.12
-7,-3,16:18.15
-6,-3,16:162.12
-5,-3,16:18.7
-4,-3,16:18.15
1,-3,16:162.12
-6,-2,16:18.15
-5,-2,16:18.15
-2,-2,16:18.7
-1,-2,16:18.7
0,-2,16:162.12
2,-2,16:18.7
5,-2,16:162.12
2,-1,16:18.7
5,-1,16:18.7
6,-1,16:18.7
0,0,16:162.12
2,0,16:18.7
3,0,16:18.7
-6,1,16:18.15
-4,1,16:18.7
0,1,16:18.15
1,1,16:18.15
7,1,16:18.7
-2,2,16:18.15
2,2,16:18.15
6,2,16:18.7
-4,3,16:18.15
-3,3,16:18.7
1,3,16:18.7
2,3,16:18.7
3,3,16:18.7
6,3,16:18.15
-6,4,16:18.15
-5,4,16:18.15
-4,4,16:189.0
0,4,16:18.7
-4,5,16:18.15
-2,5,16:18.7
7,5,16:18.7
-1,-7,17:18.15
0,-7,17:18.15
2,-7,17:18.15
3,-7,17:18.15
2,-6,17:162.12
3,-6,17:18.15
-6,-5,17:18.7
-4,-5,17:18.15
-1,-5,17:18.15
1,-5,17:18.15
2,-5,17:162.12
-6,-4,17:18.7
-5,-4,17:18.7
1,-4,17:18.15
3,-4,17:18.15
-4,-3,17:18.15
-1,-3,17:162.12
-4,-2,17:18.15
0,-2,17:162.12
7,-2,17:18.7
-8,-1,17:18.15
-6,-1,17:18.15
-5,-1,17:18.15
-2,-1,17:18.7
-1,-1,17:18.7
-5,0,17:18.7
1,0,17:18.7
-8,1,17:18.7
-6,1,17:18.7
0,1,17:162.12
3,1,17:18.7
7,1,17:18.15
-3,2,17:18.7
-2,2,17:18.15
-1,2,17:18.15
7,2,17:18.15
4,3,17:18.7
-3,4,17:18.15
3,4,17:18.7
5,4,17:18.15
-5,5,17:18.15
-2,5,17:18.7
3,5,17:18.7
-4,6,17:18.7
-2,6,17:18.7
-1,-6,18:18.7
2,-6,18:18.7
3,-6,18:18.7
2,-5,18:18.7
-7,-4,18:18.7
-4,-4,18:18.7
-3,-4,18:18.7
1,-4,18:18.15
2,-4,18:18.15
-7,-3,18:18.7
-5,-3,18:18.7
-4,-3,18:18.7
-2,-3,18:162.12
4,-3,18:18.15
5,-3,18:18.15
6,-3,18:18.15
-4,-2,18:18.15
-3,-2,18:18.15
0,-2,18:162.12
5,-2,18:18.7
-7,-1,18:18.7
0,-1,18:18.7
3,-1,18:18.7
-7,0,18:18.7
4,0,18:18.7
5,0,18:18.7
-3,1,18:18.7
-2,1,18:18.7
5,1,18:18.15
-3,2,18:18.7
0,2,18:162.12
5,2,18:18.15
-6,3,18:18.15
3,3,18:18.7
-6,4,18:18.15
0,4,18:18.7
2,4,18:18.7
7,4,18:18.7
-2,5,18:18.7
-1,5,18:18.7
2,5,18:18.7
5,5,18:18.7
-3,6,18:18.7
-2,-6,19:18.7
1,-6,19:18.7
-2,-5,19:18.7
-3,-4,19:162.12
1,-4,19:18.7
2,-4,19:18.7
3,-4,19:18.7
4,-4,19:18.7
-7,-3,19:18.7
-5,-3,19:18.7
4,-3,19:18.15
-6,-2,19:18.7
-2,-2,19:18.7
0,-2,19:162.12
1,-2,19:162.12
3,-2,19:18.15
-7,-1,19:18.7
-2,-1,19:18.7
0,-1,19:18.7
2,-1,19:18.7
1,0,19:18.7
3,0,19:18.7
4,0,19:18.7
5,0,19:18.7
4,1,19:18.7
1,2,19:18.7
4,2,19:18.7
6,2,19:18.15
-2,3,19:162.12
-1,3,19:162.12
1,3,19:18.7
-2,4,19:18.7
2,4,19:18.7
-2,5,19:18.7
-2,6,19:18.7
-4,-6,20:18.7
-3,-6,20:18.7
1,-6,20:18.7
1,-5,20:18.7
3,-5,20:18.7
-3,-4,20:162.12
0,-4,20:18.7
1,-4,20:18.15
1,-3,20:18.15
3,-3,20:162.12
5,-3,20:18.7
0,-2,20:162.12
2,-2,20:162.12
5,-2,20:18.7
-6,-1,20:18.7
-3,-1,20:18.7
4,-1,20:18.7
5,-1,20:18.7
-6,0,20:18.7
-2,0,20:18.7
1,0,20:18.7
5,0,20:18.7
-4,1,20:18.7
-2,1,20:18.7
1,1,20:18.7
3,1,20:18.7
4,1,20:18.7
4,2,20:18.7
-4,3,20:18.7
-3,3,20:162.12
-2,3,20:18.7
2,3,20:18.7
5,4,20:18.7
2,5,20:18.7
-4,-6,21:18.7
-3,-5,21:162.12
-6,-4,21:18.7
-5,-4,21:18.15
-2,-4,21:18.7
-1,-4,21:18.7
2,-4,21:18.15
4,-4,21:18.7
5,-4,21:18.7
0,-3,21:18.7
1,-3,21:18.15
4,-3,21:162.12
-6,-2,21:18.15
1,-2,21:18.7
5,-2,21:18.7
-5,-1,21:18.7
-3,-1,21:18.15
-2,-1,21:162.12
-1,-1,21:162.12
1,-1,21:18.7
3,-1,21:18.7
-4,0,21:18.7
1,0,21:18.7
2,0,21:18.15
3,0,21:18.15
4,0,21:18.15
6,0,21:18.7
-1,1,21:18.15
3,1,21:18.15
4,1,21:18.15
0,2,21:18.7
4,2,21:18.7
-3,3,21:18.7
-1,3,21:18.7
0,3,21:18.7
-3,5,21:18.7
0,5,21:18.7
-2,6,21:18.7
-1,6,21:18.7
-6,-5,22:18.7
-3,-5,22:162.12
-1,-5,22:18.7
-4,-4,22:18.7
-5,-3,22:18.15
-4,-3,22:18.15
-1,-3,22:18.7
-3,-2,22:18.7
1,-2,22:18.15
2,-2,22:18.15
-3,-1,22:18.15
1,-1,22:18.15
3,-1,22:18.7
-3,0,22:162.12
-1,0,22:18.15
1,0,22:18.7
4,0,22:18.15
-4,1,22:18.7
-3,1,22:18.15
-1,1,22:18.7
-1,2,22:18.7
2,2,22:18.7
1,3,22:18.7
0,4,22:18.7
2,5,22:18.7
0,6,22:18.7
1,6,22:18.7
-3,-6,23:18.7
-5,-5,23:18.7
-5,-4,23:18.7
-4,-4,23:18.7
-3,-4,23:18.7
-3,-3,23:18.7
-2,-3,23:18.7
-5,-2,23:18.15
0,-1,23:18.15
3,-1,23:18.7
1,0,23:18.15
-3,1,23:18.7
-2,1,23:18.7
1,1,23:18.15
0,3,23:18.15
0,4,23:18.15
0,5,23:18.7
