[META]
version=2.0
spawnOnBlockType=2
spawnSunlight=True
spawnDarkness=True
spawnWater=False
spawnLava=False
underFill=False
randomRotation=True
dig=True
tree=True
branch=False
needsFoundation=True
rarity=100
collisionPercentage=20
spawnElevationMin=0
spawnElevationMax=200
spawnInBiome=Custom
[DATA]
-1,-4,0:17.12
0,-3,0:17.12
-4,-2,0:17.12
2,-1,0:17.12
-3,0,0:17.12
0,2,0:17.12
-1,-3,1:17.12
2,-2,1:17.12
-3,-1,1:17.12
0,1,1:17.12
-1,-3,2:17.12
2,-2,2:17.12
-2,-1,2:17.12
0,1,2:17.12
-1,-3,3:17.12
0,-3,3:17.12
1,-2,3:17.12
-2,-1,3:17.12
0,0,3:17.12
-1,-2,4:17.12
1,-2,4:17.12
0,0,4:17.12
0,-2,5:17.12
1,-2,5:17.12
0,-1,5:17.12
0,-3,6:143.4
1,-3,6:188.0
0,-2,6:17.12
1,-2,6:17.12
0,-1,6:17.12
0,0,6:143.3
0,-2,7:17.12
1,-2,7:17.12
0,-1,7:17.12
1,-2,8:17.12
-3,-1,8:188.0
-2,-1,8:188.0
-1,-1,8:17.12
0,-1,8:17.12
0,0,8:17.12
1,0,8:188.0
6,-9,9:18.14
5,-8,9:18.14
6,-7,9:18.14
8,-7,9:18.14
7,-6,9:18.14
8,-6,9:18.14
9,-6,9:18.6
8,-5,9:18.14
1,-3,9:188.0
1,-2,9:17.12
-3,-1,9:188.0
-2,-1,9:18.14
-1,-1,9:17.12
0,-1,9:17.12
0,0,9:17.12
0,1,9:17.12
1,1,9:143.1
0,2,9:17.12
0,3,9:17.12
-7,8,9:18.14
5,-10,10:18.14
-3,-9,10:18.14
5,-9,10:18.14
7,-9,10:18.14
5,-8,10:18.14
6,-8,10:18.14
7,-8,10:18.14
8,-8,10:18.14
-3,-7,10:18.14
-1,-7,10:18.14
6,-7,10:18.14
7,-7,10:18.14
8,-7,10:18.14
9,-7,10:18.6
2,-6,10:188.0
3,-6,10:17.12
6,-6,10:18.14
7,-6,10:18.14
8,-6,10:18.14
-7,-5,10:18.14
2,-5,10:17.12
6,-5,10:18.14
8,-5,10:18.14
-9,-4,10:18.14
-8,-4,10:18.14
0,-4,10:17.12
2,-4,10:17.12
3,-4,10:188.0
4,-4,10:188.0
5,-4,10:18.14
7,-4,10:18.14
-9,-3,10:18.14
-8,-3,10:18.14
-5,-3,10:18.14
-1,-3,10:188.0
0,-3,10:188.0
1,-3,10:17.12
6,-3,10:18.14
-6,-2,10:18.14
-5,-2,10:18.14
-3,-2,10:18.14
-11,-1,10:18.14
-10,-1,10:18.14
-9,-1,10:18.14
-5,-1,10:18.14
-3,-1,10:18.14
-1,-1,10:17.12
0,-1,10:17.12
-11,0,10:18.14
-10,0,10:17.12
-9,0,10:17.12
-8,0,10:18.14
-2,0,10:17.12
-1,0,10:17.12
-9,2,10:18.14
-8,2,10:188.0
-7,2,10:18.14
-8,3,10:188.0
-2,3,10:188.0
-1,3,10:188.0
0,3,10:17.12
1,3,10:188.0
2,3,10:188.0
-9,4,10:18.14
-8,4,10:18.14
-7,4,10:18.14
0,4,10:17.12
-4,5,10:188.0
0,5,10:17.12
-6,6,10:18.14
-4,6,10:188.0
-3,6,10:188.0
-6,7,10:17.12
-4,7,10:18.14
-3,7,10:188.0
-2,7,10:18.14
-6,8,10:17.12
-4,8,10:18.14
-7,9,10:18.14
0,-10,11:18.14
4,-10,11:18.14
5,-10,11:18.14
-5,-9,11:18.14
-4,-9,11:18.14
1,-9,11:18.14
5,-9,11:18.14
6,-9,11:18.14
7,-9,11:18.14
-4,-8,11:18.14
-2,-8,11:18.14
-1,-8,11:18.14
0,-8,11:18.14
3,-8,11:18.14
4,-8,11:18.14
5,-8,11:18.14
6,-8,11:18.14
7,-8,11:18.14
-3,-7,11:18.14
-2,-7,11:17.12
-1,-7,11:18.14
0,-7,11:18.14
1,-7,11:188.0
2,-7,11:18.14
3,-7,11:17.12
8,-7,11:18.14
-9,-6,11:18.14
-7,-6,11:18.14
-2,-6,11:18.14
-1,-6,11:17.12
1,-6,11:188.0
2,-6,11:188.0
3,-6,11:17.12
4,-6,11:18.14
6,-6,11:18.14
9,-6,11:18.6
-9,-5,11:18.6
-8,-5,11:18.14
-7,-5,11:18.14
-6,-5,11:18.14
-4,-5,11:18.14
-3,-5,11:188.0
-2,-5,11:188.0
-1,-5,11:17.12
5,-5,11:18.14
6,-5,11:18.14
7,-5,11:18.14
8,-5,11:18.14
-10,-4,11:18.14
-9,-4,11:18.14
-8,-4,11:18.14
0,-4,11:17.12
4,-4,11:188.0
5,-4,11:188.0
6,-4,11:18.14
7,-4,11:18.14
-8,-3,11:18.14
-5,-3,11:18.14
-4,-3,11:18.14
-1,-3,11:188.0
5,-3,11:18.14
7,-3,11:18.14
-10,-2,11:18.14
-9,-2,11:18.14
-5,-2,11:188.0
-4,-2,11:18.14
-11,-1,11:18.14
-9,-1,11:18.14
-8,-1,11:18.14
-7,-1,11:188.0
-5,-1,11:188.0
-4,-1,11:18.14
0,-1,11:17.12
-11,0,11:175.2
-10,0,11:18.14
-9,0,11:17.12
-8,0,11:17.12
-7,0,11:17.12
-2,0,11:17.12
-1,0,11:17.12
-10,1,11:18.14
-8,1,11:188.0
-6,1,11:17.12
-1,1,11:17.12
-11,2,11:18.14
-10,2,11:18.14
-9,2,11:188.0
-8,2,11:188.0
-10,3,11:18.14
-9,3,11:18.14
-8,3,11:18.14
-7,3,11:18.14
-5,3,11:17.12
-2,3,11:188.0
2,3,11:188.0
3,3,11:188.0
4,3,11:18.14
-8,4,11:175.2
-6,4,11:17.12
-5,4,11:17.12
-4,4,11:188.0
-2,4,11:188.0
3,4,11:188.0
4,4,11:18.14
-7,5,11:188.0
-6,5,11:17.12
-4,5,11:188.0
1,5,11:17.12
-8,6,11:188.0
-7,6,11:188.0
-6,6,11:17.12
-5,6,11:18.14
1,6,11:17.12
-8,7,11:18.14
-6,7,11:18.14
-2,7,11:18.14
2,7,11:18.14
-8,8,11:18.14
-7,8,11:18.14
-6,8,11:18.14
-3,8,11:18.14
-1,8,11:18.14
1,8,11:18.14
-7,9,11:175.2
-6,9,11:18.14
-3,9,11:18.14
-2,9,11:18.14
1,9,11:18.14
-1,10,11:18.14
-3,-11,12:18.14
-2,-11,12:18.14
-2,-10,12:18.14
1,-10,12:18.14
3,-10,12:18.14
-5,-9,12:18.14
-4,-9,12:17.12
-2,-9,12:18.14
0,-9,12:18.14
3,-9,12:18.14
4,-9,12:17.12
5,-9,12:18.14
6,-9,12:18.14
-5,-8,12:18.14
-3,-8,12:17.12
-2,-8,12:18.14
0,-8,12:188.0
1,-8,12:188.0
2,-8,12:18.14
3,-8,12:18.14
4,-8,12:17.12
7,-8,12:18.14
-7,-7,12:18.14
-2,-7,12:17.12
-1,-7,12:18.14
0,-7,12:18.14
1,-7,12:188.0
2,-7,12:18.14
3,-7,12:17.12
4,-7,12:18.14
-9,-6,12:18.14
-2,-6,12:18.14
0,-6,12:18.14
1,-6,12:18.14
2,-6,12:18.14
4,-6,12:175.2
6,-6,12:18.14
7,-6,12:18.14
-10,-5,12:18.6
-8,-5,12:18.14
-7,-5,12:18.14
-5,-5,12:188.0
-4,-5,12:188.0
-3,-5,12:188.0
6,-5,12:188.0
7,-5,12:18.14
8,-5,12:18.14
-10,-4,12:18.14
-6,-4,12:18.14
-5,-4,12:18.14
5,-4,12:188.0
6,-4,12:188.0
8,-4,12:18.14
-11,-3,12:18.14
-8,-3,12:18.14
-5,-3,12:18.14
-2,-3,12:188.0
-1,-3,12:188.0
6,-3,12:18.14
-10,-2,12:18.14
-9,-2,12:18.14
-8,-2,12:188.0
-7,-2,12:188.0
-5,-2,12:18.14
-4,-2,12:18.14
-11,-1,12:18.14
-8,-1,12:18.14
-7,-1,12:188.0
-5,-1,12:188.0
0,-1,12:17.12
1,-1,12:143.1
-10,0,12:18.14
-9,0,12:18.14
-5,0,12:188.0
-2,0,12:17.12
-1,0,12:17.12
0,0,12:17.12
1,0,12:17.12
-10,1,12:18.14
-9,1,12:18.14
-6,1,12:17.12
-5,1,12:17.12
-1,1,12:17.12
-11,2,12:175.2
-8,2,12:18.14
-5,2,12:17.12
-10,3,12:18.14
-9,3,12:175.2
-7,3,12:175.2
-2,4,12:188.0
3,4,12:188.0
4,4,12:188.0
-7,5,12:18.14
-6,5,12:18.14
-3,5,12:18.14
-1,5,12:18.14
2,5,12:18.14
3,5,12:18.14
4,5,12:18.14
5,5,12:18.14
-8,6,12:188.0
-7,6,12:18.14
-6,6,12:18.14
-5,6,12:18.14
-1,6,12:188.0
0,6,12:188.0
1,6,12:17.12
2,6,12:188.0
3,6,12:188.0
-8,7,12:188.0
-7,7,12:18.14
-6,7,12:18.14
-5,7,12:18.14
-3,7,12:18.14
-2,7,12:18.14
1,7,12:17.12
2,7,12:18.14
3,7,12:18.14
4,7,12:18.14
5,7,12:18.14
-7,8,12:18.14
-2,8,12:18.14
-1,8,12:18.14
0,8,12:18.14
1,8,12:17.12
2,8,12:18.14
3,8,12:18.14
-3,9,12:18.14
-2,9,12:18.14
-1,9,12:18.14
0,9,12:18.14
1,9,12:18.14
2,9,12:18.14
3,9,12:18.14
-2,10,12:18.14
-1,10,12:175.2
0,10,12:18.14
-2,-11,13:18.14
-6,-10,13:18.14
-5,-10,13:175.2
-4,-10,13:18.14
-3,-10,13:18.14
-2,-10,13:18.14
0,-10,13:18.14
1,-10,13:175.2
3,-10,13:175.2
4,-10,13:18.14
-6,-9,13:18.14
-5,-9,13:18.14
3,-9,13:18.14
4,-9,13:18.14
-5,-8,13:18.14
-3,-8,13:18.14
0,-8,13:188.0
2,-8,13:18.14
5,-8,13:18.14
-8,-7,13:18.14
-2,-7,13:18.14
-1,-7,13:18.14
0,-7,13:18.14
1,-7,13:18.14
-9,-6,13:175.2
-8,-6,13:18.14
-2,-6,13:18.14
-1,-6,13:18.14
0,-6,13:18.14
1,-6,13:18.14
7,-6,13:175.2
-10,-5,13:18.6
-8,-5,13:175.2
-4,-5,13:18.14
5,-5,13:18.14
6,-5,13:188.0
8,-5,13:175.2
-11,-4,13:18.14
-10,-4,13:18.14
-9,-4,13:18.14
-8,-4,13:18.14
-6,-4,13:175.2
-5,-4,13:18.14
-4,-4,13:18.14
-3,-4,13:188.0
-2,-4,13:18.14
-11,-3,13:175.2
-9,-3,13:18.14
-8,-3,13:188.0
-5,-3,13:175.2
-3,-3,13:188.0
-2,-3,13:188.0
4,-3,13:18.14
-10,-2,13:175.2
-9,-2,13:18.14
-8,-2,13:188.0
-4,-2,13:175.2
4,-2,13:18.14
-11,-1,13:175.2
-10,-1,13:18.14
-11,0,13:18.14
-10,0,13:18.14
-2,0,13:17.12
-1,0,13:17.12
1,0,13:17.12
-9,1,13:175.2
-4,1,13:17.12
-3,1,13:17.12
-2,1,13:17.12
-1,1,13:17.12
2,1,13:17.12
-8,2,13:175.2
-10,3,13:175.2
-8,3,13:18.14
-9,4,13:18.14
-8,4,13:18.14
-7,4,13:18.14
2,4,13:18.14
3,4,13:18.14
4,4,13:18.14
5,4,13:18.14
-8,5,13:18.14
-5,5,13:18.14
2,5,13:18.14
3,5,13:18.14
4,5,13:18.14
5,5,13:175.2
-8,6,13:18.14
-7,6,13:18.14
-6,6,13:18.14
-5,6,13:18.14
-1,6,13:188.0
1,6,13:18.14
2,6,13:18.14
3,6,13:188.0
4,6,13:18.14
-9,7,13:18.14
-8,7,13:18.14
-7,7,13:18.14
-5,7,13:18.14
-2,7,13:188.0
-1,7,13:188.0
2,7,13:18.14
3,7,13:188.0
4,7,13:188.0
5,7,13:18.14
-8,8,13:18.14
-7,8,13:175.2
-6,8,13:18.14
-2,8,13:18.14
-1,8,13:18.14
0,8,13:18.14
2,8,13:18.14
3,8,13:18.14
4,8,13:18.14
-3,9,13:175.2
-2,9,13:18.14
0,9,13:18.14
1,9,13:17.12
-2,10,13:175.2
0,10,13:18.14
1,10,13:18.14
-6,-10,14:175.2
-2,-10,14:175.2
0,-10,14:18.14
3,-10,14:18.14
4,-10,14:175.2
-6,-9,14:18.14
-5,-9,14:175.2
-4,-9,14:18.14
2,-9,14:18.14
3,-9,14:18.14
4,-9,14:18.14
5,-9,14:18.14
6,-9,14:18.14
-3,-8,14:18.14
-1,-8,14:18.14
0,-8,14:18.14
2,-8,14:18.14
4,-8,14:18.14
-2,-7,14:18.14
1,-7,14:18.14
3,-7,14:18.14
5,-7,14:18.14
6,-7,14:18.14
7,-7,14:18.14
-9,-6,14:18.6
-8,-6,14:18.14
-1,-6,14:18.14
1,-6,14:18.14
3,-6,14:18.14
5,-6,14:18.14
6,-6,14:18.14
-10,-5,14:175.2
-4,-5,14:18.14
-2,-5,14:18.14
2,-5,14:18.14
4,-5,14:18.14
5,-5,14:18.14
7,-5,14:18.14
-11,-4,14:175.2
-10,-4,14:18.14
-9,-4,14:18.14
-8,-4,14:18.14
-7,-4,14:18.14
-5,-4,14:175.2
-3,-4,14:188.0
1,-4,14:18.14
6,-4,14:175.2
-11,-3,14:18.14
-8,-3,14:188.0
-3,-3,14:18.14
0,-3,14:18.14
1,-3,14:18.14
2,-3,14:18.14
3,-3,14:18.14
4,-3,14:18.14
5,-3,14:18.14
-11,-2,14:18.14
-9,-2,14:175.2
-7,-2,14:18.14
-1,-2,14:188.0
0,-2,14:188.0
3,-2,14:18.14
4,-2,14:18.14
5,-2,14:175.2
-12,-1,14:18.14
-8,-1,14:175.2
-3,-1,14:17.12
-1,-1,14:188.0
3,-1,14:188.0
4,-1,14:18.14
5,-1,14:18.14
-11,0,14:175.2
-10,0,14:18.14
-2,0,14:17.12
-1,0,14:17.12
2,0,14:188.0
3,0,14:188.0
-10,1,14:18.14
-3,1,14:17.12
-2,1,14:17.12
2,1,14:17.12
-11,2,14:18.14
-10,2,14:18.14
3,2,14:17.12
-9,3,14:18.14
-8,3,14:18.14
-9,4,14:18.14
3,4,14:175.2
5,4,14:175.2
-9,5,14:18.14
-8,5,14:18.14
-7,5,14:18.14
-6,5,14:18.14
2,5,14:18.14
3,5,14:18.14
4,5,14:18.14
-7,6,14:18.14
-6,6,14:18.14
-5,6,14:18.14
2,6,14:18.14
-9,7,14:175.2
-7,7,14:175.2
-5,7,14:18.14
-3,7,14:18.14
-2,7,14:188.0
4,7,14:18.14
5,7,14:175.2
-8,8,14:175.2
-2,8,14:18.14
0,8,14:18.14
1,8,14:18.14
-1,9,14:18.14
0,9,14:18.14
1,9,14:18.14
2,9,14:18.14
3,9,14:18.14
-2,10,14:18.14
0,10,14:175.2
-4,-10,15:18.14
0,-10,15:175.2
3,-10,15:175.2
-6,-9,15:175.2
-4,-9,15:175.2
0,-9,15:18.14
2,-9,15:175.2
4,-9,15:175.2
6,-9,15:175.2
-3,-8,15:18.14
-1,-8,15:18.14
0,-8,15:18.14
3,-8,15:18.14
5,-8,15:18.14
-9,-7,15:18.6
-8,-7,15:18.14
-7,-7,15:18.14
-6,-7,15:18.14
-1,-7,15:18.14
2,-7,15:18.14
5,-7,15:175.2
7,-7,15:175.2
-9,-6,15:18.14
-7,-6,15:18.14
-2,-6,15:18.14
0,-6,15:18.14
1,-6,15:18.14
6,-6,15:18.14
-10,-5,15:18.6
-8,-5,15:18.14
-7,-5,15:18.14
-2,-5,15:18.14
5,-5,15:18.14
6,-5,15:18.14
7,-5,15:175.2
-9,-4,15:18.14
-8,-4,15:18.14
-4,-4,15:18.14
-3,-4,15:18.14
-2,-4,15:18.14
1,-4,15:188.0
2,-4,15:18.14
-12,-3,15:18.14
-10,-3,15:175.2
-9,-3,15:18.14
0,-3,15:188.0
1,-3,15:188.0
2,-3,15:18.14
3,-3,15:175.2
5,-3,15:175.2
-11,-2,15:18.14
-6,-2,15:188.0
-5,-2,15:188.0
0,-2,15:188.0
2,-2,15:18.14
4,-2,15:18.14
5,-2,15:18.14
-12,-1,15:175.2
-10,-1,15:18.14
-5,-1,15:188.0
-4,-1,15:188.0
-3,-1,15:17.12
3,-1,15:188.0
4,-1,15:188.0
5,-1,15:18.14
3,0,15:18.14
4,0,15:18.14
6,0,15:18.14
-11,1,15:18.14
-10,1,15:18.14
-9,1,15:18.14
-4,1,15:17.12
-3,1,15:17.12
-2,1,15:17.12
5,1,15:18.14
-11,2,15:175.2
-4,2,15:17.12
3,2,15:17.12
4,2,15:188.0
5,2,15:188.0
-9,3,15:175.2
2,3,15:188.0
3,3,15:188.0
4,3,15:17.12
6,3,15:18.14
8,3,15:18.14
9,3,15:18.14
-9,4,15:18.14
8,4,15:18.14
-9,5,15:175.2
-8,5,15:18.14
-7,5,15:18.14
2,5,15:175.2
4,5,15:175.2
9,5,15:18.14
-7,6,15:175.2
-6,7,15:18.14
-5,7,15:18.14
-2,7,15:18.14
2,7,15:18.14
4,7,15:18.14
-6,8,15:18.14
0,8,15:18.14
1,8,15:18.14
2,8,15:18.14
3,8,15:18.14
4,8,15:18.14
-6,9,15:18.14
-1,9,15:18.14
1,9,15:175.2
2,9,15:18.14
4,9,15:18.14
-1,10,15:18.14
-3,-10,16:175.2
0,-9,16:175.2
3,-9,16:18.14
5,-9,16:175.2
-9,-8,16:18.14
-7,-8,16:18.14
-3,-8,16:175.2
-1,-8,16:175.2
3,-8,16:175.2
4,-8,16:18.14
-9,-7,16:18.14
-8,-7,16:175.2
-7,-7,16:18.14
-6,-7,16:18.14
4,-7,16:18.14
5,-7,16:18.14
-8,-6,16:18.14
-6,-6,16:18.14
0,-6,16:18.14
1,-6,16:18.14
2,-6,16:18.14
5,-6,16:175.2
-8,-5,16:18.14
-3,-5,16:18.14
1,-5,16:18.14
2,-5,16:188.0
6,-5,16:175.2
-9,-4,16:175.2
1,-4,16:188.0
2,-4,16:188.0
-12,-3,16:175.2
-7,-3,16:18.14
-6,-3,16:18.14
-2,-3,16:188.0
0,-3,16:18.14
1,-3,16:18.14
2,-3,16:18.14
-11,-2,16:18.14
-6,-2,16:188.0
-5,-2,16:18.14
-3,-2,16:188.0
-2,-2,16:188.0
1,-2,16:18.14
2,-2,16:18.14
-11,-1,16:18.14
-10,-1,16:175.2
-7,-1,16:18.14
-3,-1,16:17.12
3,-1,16:18.14
4,-1,16:188.0
5,-1,16:188.0
6,-1,16:18.14
-11,0,16:18.14
-9,0,16:18.14
6,0,16:18.14
-10,1,16:18.14
5,1,16:18.14
6,1,16:18.14
7,1,16:18.14
8,1,16:18.14
-8,2,16:18.14
-4,2,16:17.12
-3,2,16:17.12
-2,2,16:17.12
4,2,16:18.14
5,2,16:188.0
6,2,16:188.0
7,2,16:18.14
8,2,16:18.14
9,2,16:18.14
-9,3,16:18.14
-8,3,16:188.0
-7,3,16:188.0
-6,3,16:188.0
-5,3,16:17.12
2,3,16:188.0
5,3,16:17.12
7,3,16:18.14
8,3,16:175.2
-9,4,16:18.14
1,4,16:188.0
2,4,16:188.0
5,4,16:17.12
6,4,16:18.14
8,4,16:18.14
9,4,16:18.14
-9,5,16:18.14
-7,5,16:18.14
9,5,16:175.2
-9,6,16:18.14
-7,6,16:18.14
3,6,16:18.14
-9,7,16:18.14
-5,7,16:18.14
3,7,16:18.14
4,7,16:175.2
-6,8,16:18.14
-3,8,16:18.14
-2,8,16:18.14
-1,8,16:18.14
0,8,16:18.14
1,8,16:175.2
2,8,16:18.14
3,8,16:18.14
-2,9,16:18.14
-1,9,16:18.14
0,9,16:18.14
2,9,16:18.14
4,9,16:175.2
-2,10,16:18.14
0,10,16:18.14
4,10,16:18.14
3,-9,17:175.2
-9,-8,17:175.2
-7,-8,17:18.6
-6,-8,17:175.2
-2,-8,17:175.2
4,-8,17:175.2
-7,-7,17:18.14
-6,-7,17:18.14
-2,-7,17:18.14
-1,-7,17:18.14
1,-7,17:18.14
2,-7,17:175.2
5,-7,17:175.2
-9,-6,17:18.14
-8,-6,17:175.2
-2,-6,17:18.14
0,-6,17:18.14
1,-6,17:18.14
2,-6,17:18.14
3,-6,17:18.14
-3,-5,17:18.14
-2,-5,17:18.14
4,-5,17:175.2
-8,-4,17:175.2
-7,-4,17:18.14
2,-4,17:18.14
3,-4,17:18.14
-8,-3,17:18.14
-6,-3,17:18.14
-2,-3,17:188.0
-1,-3,17:188.0
-11,-2,17:175.2
-7,-2,17:18.14
-5,-2,17:18.14
-4,-2,17:17.12
6,-2,17:18.14
3,-1,17:18.14
5,-1,17:188.0
-12,0,17:18.6
-11,0,17:175.2
-8,0,17:188.0
3,0,17:18.14
7,0,17:175.2
-10,1,17:175.2
-9,1,17:18.14
-8,1,17:188.0
7,1,17:18.14
8,1,17:18.14
-9,2,17:188.0
-8,2,17:188.0
-4,2,17:17.12
-2,2,17:17.12
4,2,17:18.14
5,2,17:18.14
6,2,17:188.0
7,2,17:188.0
8,2,17:18.14
9,2,17:175.2
-9,3,17:18.14
-8,3,17:188.0
-7,3,17:18.14
-5,3,17:17.12
-2,3,17:17.12
4,3,17:18.14
5,3,17:18.14
6,3,17:18.14
7,3,17:18.14
8,3,17:18.14
9,3,17:18.14
-9,4,17:175.2
-5,4,17:188.0
-2,4,17:17.12
1,4,17:188.0
2,4,17:18.14
5,4,17:18.14
6,4,17:17.12
9,4,17:175.2
-8,5,17:18.14
-7,5,17:18.14
-5,5,17:188.0
-2,5,17:188.0
1,5,17:18.14
2,5,17:18.14
6,5,17:18.14
-9,6,17:175.2
-7,6,17:18.14
-2,6,17:188.0
3,6,17:175.2
-9,7,17:18.14
-8,7,17:18.14
-7,7,17:18.14
-3,8,17:175.2
-2,8,17:18.14
0,8,17:175.2
3,8,17:175.2
4,8,17:18.14
-1,9,17:18.14
1,9,17:18.14
2,9,17:18.14
-2,10,17:175.2
0,10,17:175.2
1,10,17:18.14
-7,-8,18:175.2
-1,-8,18:18.6
-6,-7,18:175.2
-2,-7,18:18.14
-1,-7,18:175.2
-3,-6,18:18.14
-2,-6,18:18.14
-1,-6,18:18.14
1,-6,18:175.2
3,-6,18:18.14
-6,-5,18:18.14
-2,-5,18:18.14
-8,-4,18:18.14
-7,-4,18:18.14
-5,-4,18:18.14
-4,-4,18:18.14
2,-4,18:175.2
-6,-3,18:18.14
-5,-3,18:18.14
-1,-3,18:188.0
1,-3,18:18.14
4,-3,18:18.14
-8,-2,18:18.14
-7,-2,18:18.14
-6,-2,18:18.14
-4,-2,18:17.12
-3,-2,18:188.0
0,-2,18:18.14
3,-2,18:18.14
4,-2,18:18.14
6,-2,18:175.2
-4,-1,18:188.0
-3,-1,18:188.0
-2,-1,18:188.0
3,-1,18:18.14
5,-1,18:18.14
6,-1,18:18.14
-8,0,18:188.0
-4,0,18:188.0
-2,0,18:188.0
-1,0,18:188.0
3,0,18:18.14
4,0,18:18.14
-10,1,18:18.14
-9,1,18:18.14
6,1,18:18.14
8,1,18:18.14
-10,2,18:18.14
-9,2,18:188.0
-7,2,18:18.14
-6,2,18:188.0
5,2,18:18.14
7,2,18:188.0
-7,3,18:18.14
-6,3,18:17.12
9,3,18:175.2
-7,4,18:17.12
-2,4,18:17.12
-1,4,18:188.0
0,4,18:188.0
4,4,18:18.14
5,4,18:18.14
6,4,18:17.12
7,4,18:18.14
8,4,18:18.14
-10,5,18:18.14
-8,5,18:18.14
-7,5,18:18.14
-5,5,18:188.0
5,5,18:18.14
7,5,18:18.14
-10,6,18:18.14
-9,6,18:18.14
-5,6,18:188.0
-2,6,18:188.0
-9,7,18:18.14
-8,7,18:18.14
-7,7,18:175.2
-6,7,18:18.14
-5,7,18:18.14
-3,7,18:188.0
-2,7,18:188.0
-5,8,18:18.14
-1,9,18:175.2
2,9,18:175.2
-3,10,18:18.14
1,10,18:175.2
-5,-7,19:18.14
-2,-7,19:175.2
-8,-6,19:18.14
-7,-6,19:18.14
-6,-6,19:18.14
-5,-6,19:18.14
-3,-6,19:175.2
-1,-6,19:175.2
4,-6,19:18.14
-8,-5,19:18.14
-6,-5,19:18.14
-5,-5,19:18.14
-4,-5,19:18.14
-2,-5,19:18.14
3,-5,19:175.2
-7,-4,19:18.14
-6,-4,19:18.14
-5,-4,19:18.14
-3,-4,19:18.14
-2,-4,19:18.14
-1,-4,19:18.14
1,-4,19:18.14
-8,-3,19:18.14
-5,-3,19:18.14
-4,-3,19:18.14
-3,-3,19:18.14
-1,-3,19:188.0
0,-3,19:188.0
1,-3,19:18.14
4,-3,19:18.14
-9,-2,19:18.14
-8,-2,19:18.14
-5,-2,19:17.12
-4,-2,19:17.12
-1,-2,19:18.14
3,-2,19:18.14
4,-2,19:18.14
-9,-1,19:18.14
-8,-1,19:188.0
-7,-1,19:18.14
-6,-1,19:18.14
-5,-1,19:18.14
-4,-1,19:18.14
-2,-1,19:18.14
-1,-1,19:18.14
0,-1,19:18.14
3,-1,19:18.14
4,-1,19:18.14
6,-1,19:175.2
-9,0,19:18.14
-8,0,19:188.0
-7,0,19:18.14
-5,0,19:188.0
-4,0,19:188.0
-2,0,19:18.14
-1,0,19:188.0
0,0,19:18.14
5,0,19:18.14
6,0,19:18.14
-9,1,19:18.14
-7,1,19:18.14
-6,1,19:18.14
-5,1,19:188.0
-4,1,19:18.14
2,1,19:18.14
3,1,19:18.14
4,1,19:18.14
5,1,19:18.14
6,1,19:18.14
7,1,19:18.14
8,1,19:175.2
-9,2,19:188.0
-7,2,19:18.14
-5,2,19:188.0
3,2,19:18.14
4,2,19:18.14
6,2,19:18.14
7,2,19:18.14
8,2,19:18.14
-10,3,19:18.14
-9,3,19:18.14
-7,3,19:18.14
-6,3,19:18.14
7,3,19:18.14
8,3,19:18.14
-10,4,19:18.14
-9,4,19:18.14
-8,4,19:18.14
-7,4,19:17.12
-3,4,19:188.0
-2,4,19:17.12
0,4,19:188.0
4,4,19:175.2
7,4,19:18.14
-10,5,19:175.2
-9,5,19:18.14
-8,5,19:18.14
-3,5,19:188.0
-1,5,19:17.12
4,5,19:18.14
5,5,19:18.14
6,5,19:18.14
7,5,19:175.2
8,5,19:18.14
-9,6,19:18.14
-7,6,19:18.14
-5,6,19:188.0
-4,6,19:18.14
-8,7,19:175.2
-5,7,19:188.0
-4,7,19:18.14
-3,7,19:188.0
-6,8,19:18.14
-4,8,19:18.14
-3,8,19:188.0
-5,9,19:18.14
-6,-7,20:18.14
-5,-7,20:18.14
-9,-6,20:18.14
-7,-6,20:175.2
-5,-6,20:18.14
-3,-6,20:18.14
-8,-5,20:18.14
-7,-5,20:18.14
-6,-5,20:175.2
-5,-5,20:18.14
-4,-5,20:18.14
-1,-5,20:18.14
0,-5,20:18.14
1,-5,20:18.14
-8,-4,20:18.14
-7,-4,20:18.14
-6,-4,20:18.14
-5,-4,20:18.14
-2,-4,20:175.2
-1,-4,20:18.14
0,-4,20:18.14
1,-4,20:18.14
-8,-3,20:18.14
-7,-3,20:18.14
-5,-3,20:17.12
-3,-3,20:18.14
-2,-3,20:18.14
-1,-3,20:18.14
0,-3,20:18.14
1,-3,20:18.14
3,-3,20:18.14
5,-3,20:18.6
-9,-2,20:175.2
-8,-2,20:18.14
-7,-2,20:18.14
-6,-2,20:18.14
-5,-2,20:18.14
-3,-2,20:18.14
-2,-2,20:18.14
0,-2,20:18.14
4,-2,20:18.14
5,-2,20:18.14
-9,-1,20:18.14
-8,-1,20:18.14
-6,-1,20:18.14
-5,-1,20:18.14
-3,-1,20:18.14
-2,-1,20:18.14
0,-1,20:18.14
3,-1,20:18.14
4,-1,20:18.14
5,-1,20:18.14
-6,0,20:18.14
-5,0,20:188.0
-4,0,20:18.14
-3,0,20:18.14
-1,0,20:188.0
3,0,20:18.14
6,0,20:175.2
-9,1,20:18.14
-7,1,20:175.2
-5,1,20:18.14
-2,1,20:18.14
-1,1,20:188.0
0,1,20:188.0
1,1,20:18.14
2,1,20:18.14
3,1,20:18.14
4,1,20:18.14
5,1,20:175.2
7,1,20:175.2
8,1,20:18.14
-11,2,20:18.14
-5,2,20:188.0
-3,2,20:18.14
-1,2,20:18.14
0,2,20:18.14
2,2,20:18.14
3,2,20:18.14
5,2,20:18.14
8,2,20:175.2
-10,3,20:175.2
-9,3,20:18.14
-8,3,20:18.14
-7,3,20:175.2
-6,3,20:18.14
-4,3,20:18.14
-2,3,20:18.14
4,3,20:18.14
6,3,20:18.14
7,3,20:18.14
9,3,20:18.14
-9,4,20:18.14
-8,4,20:18.14
-7,4,20:18.14
0,4,20:188.0
1,4,20:188.0
5,4,20:18.14
6,4,20:18.14
7,4,20:175.2
-10,5,20:18.14
-9,5,20:18.14
-8,5,20:18.14
-7,5,20:18.14
-4,5,20:188.0
-3,5,20:188.0
-1,5,20:17.12
4,5,20:175.2
5,5,20:18.14
7,5,20:18.14
8,5,20:175.2
9,5,20:18.14
-9,6,20:175.2
-7,6,20:18.14
-5,6,20:18.14
-1,6,20:17.12
0,6,20:188.0
1,6,20:188.0
-9,7,20:18.14
-5,7,20:18.14
-2,7,20:18.14
-9,8,20:18.14
-6,8,20:18.14
-3,8,20:188.0
-1,8,20:18.14
0,8,20:18.14
2,8,20:18.14
3,8,20:18.14
-5,9,20:18.14
-4,9,20:18.14
-3,9,20:18.14
-2,9,20:18.14
-6,-7,21:175.2
-7,-6,21:18.14
-5,-6,21:18.14
-3,-6,21:175.2
-9,-5,21:188.0
-8,-5,21:188.0
-7,-5,21:18.14
-6,-5,21:18.14
-5,-5,21:18.14
-4,-5,21:18.14
-3,-5,21:18.14
-2,-5,21:18.14
-1,-5,21:175.2
0,-5,21:18.14
1,-5,21:175.2
-8,-4,21:188.0
-7,-4,21:188.0
-5,-4,21:18.14
-3,-4,21:18.14
-2,-4,21:18.14
0,-4,21:175.2
1,-4,21:18.6
-7,-3,21:188.0
-6,-3,21:17.12
-5,-3,21:18.14
-3,-3,21:18.14
-2,-3,21:18.14
0,-3,21:18.14
4,-3,21:18.14
5,-3,21:175.2
-6,-2,21:18.14
-4,-2,21:18.14
-1,-2,21:18.14
3,-2,21:18.6
4,-2,21:18.6
5,-2,21:18.14
-9,-1,21:18.14
-8,-1,21:18.14
-7,-1,21:18.14
-6,-1,21:18.14
-3,-1,21:18.14
-2,-1,21:18.14
-1,-1,21:18.14
0,-1,21:18.14
3,-1,21:18.6
4,-1,21:18.6
-6,0,21:188.0
-5,0,21:188.0
-4,0,21:18.14
-3,0,21:18.14
-2,0,21:18.14
0,0,21:18.14
1,0,21:18.14
2,0,21:18.14
3,0,21:18.14
4,0,21:18.14
-5,1,21:18.14
-3,1,21:18.14
-1,1,21:18.14
0,1,21:188.0
3,1,21:18.14
4,1,21:18.14
-6,2,21:18.14
-5,2,21:188.0
-4,2,21:18.14
-3,2,21:18.14
-1,2,21:18.14
1,2,21:18.14
3,2,21:18.14
4,2,21:18.14
-9,3,21:175.2
-5,3,21:188.0
-3,3,21:18.14
-2,3,21:18.14
3,3,21:175.2
4,3,21:18.14
7,3,21:175.2
-8,4,21:175.2
-5,4,21:18.14
1,4,21:188.0
5,4,21:18.14
6,4,21:175.2
-9,5,21:175.2
-7,5,21:175.2
-4,5,21:188.0
5,5,21:175.2
7,5,21:175.2
-8,6,21:18.14
-4,6,21:188.0
-1,6,21:17.12
0,6,21:18.14
1,6,21:188.0
2,6,21:18.14
-9,7,21:18.14
-8,7,21:18.14
-7,7,21:18.14
-2,7,21:18.14
0,7,21:18.14
1,7,21:188.0
3,7,21:18.14
-9,8,21:175.2
-8,8,21:18.14
-5,8,21:18.14
-3,8,21:18.14
-2,8,21:18.14
-1,8,21:18.14
0,8,21:18.14
1,8,21:18.14
-5,9,21:18.14
-4,9,21:18.14
-3,9,21:18.14
-2,9,21:175.2
1,9,21:18.14
-3,10,21:18.14
-5,-7,22:175.2
-9,-6,22:18.14
-7,-6,22:18.14
-6,-6,22:18.14
-5,-6,22:18.14
-9,-5,22:188.0
-8,-5,22:18.14
-6,-5,22:18.14
-5,-5,22:18.14
-4,-5,22:175.2
-3,-5,22:18.14
-2,-5,22:18.14
0,-5,22:175.2
-8,-4,22:18.14
-6,-4,22:18.14
-5,-4,22:18.14
-4,-4,22:18.14
-3,-4,22:18.14
-2,-4,22:18.14
-1,-4,22:175.2
1,-4,22:175.2
-8,-3,22:18.14
-7,-3,22:18.14
-4,-3,22:18.14
-3,-3,22:18.14
0,-3,22:175.2
-5,-2,22:18.14
-4,-2,22:18.14
-2,-2,22:18.14
4,-2,22:175.2
-8,-1,22:175.2
-6,-1,22:18.14
-4,-1,22:18.14
-3,-1,22:18.14
-2,-1,22:18.14
-1,-1,22:18.14
0,-1,22:18.14
1,-1,22:18.14
3,-1,22:18.6
-6,0,22:18.14
-2,0,22:18.14
-1,0,22:18.14
2,0,22:18.14
3,0,22:18.14
4,0,22:18.14
-6,1,22:18.14
-5,1,22:18.14
-1,1,22:18.14
1,1,22:18.14
4,1,22:175.2
-5,2,22:18.14
-1,2,22:18.14
0,2,22:18.14
1,2,22:18.14
3,2,22:175.2
5,2,22:175.2
6,2,22:18.14
-6,3,22:18.14
-5,3,22:18.14
2,3,22:18.14
1,4,22:188.0
2,4,22:188.0
5,4,22:175.2
2,5,22:18.14
-8,6,22:175.2
-5,6,22:18.14
-4,6,22:188.0
1,6,22:18.14
2,6,22:18.14
-9,7,22:175.2
-7,7,22:175.2
-4,7,22:18.14
-2,7,22:18.14
-1,7,22:17.12
1,7,22:188.0
2,7,22:188.0
-8,8,22:175.2
-5,8,22:175.2
-1,8,22:18.14
0,8,22:175.2
2,8,22:18.14
-4,9,22:18.14
1,9,22:18.14
-3,10,22:18.14
-10,-6,23:18.14
-9,-6,23:175.2
-7,-6,23:175.2
-5,-6,23:175.2
-9,-5,23:18.14
-8,-5,23:175.2
-7,-5,23:18.14
-6,-5,23:175.2
-3,-5,23:18.14
-2,-5,23:175.2
-6,-4,23:18.14
-5,-4,23:175.2
-2,-4,23:18.14
-8,-3,23:175.2
-6,-3,23:18.14
-4,-3,23:175.2
-3,-3,23:18.14
-2,-3,23:18.14
-1,-3,23:175.2
-2,-2,23:175.2
-6,-1,23:18.14
-5,-1,23:18.14
-4,-1,23:18.14
-3,-1,23:175.2
-2,-1,23:18.14
-5,0,23:18.14
-4,0,23:18.14
-3,0,23:18.14
1,0,23:18.14
3,0,23:175.2
-6,1,23:175.2
-4,1,23:18.14
-1,1,23:18.14
0,1,23:18.14
-5,2,23:175.2
-3,2,23:18.14
0,2,23:18.14
-6,3,23:18.14
-4,3,23:18.14
-3,3,23:18.14
1,3,23:18.14
-7,4,23:18.14
-6,4,23:18.14
-4,4,23:18.14
-3,4,23:18.14
-2,4,23:18.14
-1,4,23:18.14
2,4,23:188.0
3,4,23:18.14
-6,5,23:18.14
-5,5,23:18.14
-4,5,23:18.14
0,5,23:18.14
1,5,23:18.14
2,5,23:18.14
3,5,23:18.14
-5,6,23:18.14
0,6,23:18.14
1,6,23:18.14
2,6,23:18.14
-7,7,23:18.14
-6,7,23:18.14
-5,7,23:18.14
-4,7,23:18.14
-3,7,23:18.14
-1,7,23:18.14
0,7,23:18.14
2,7,23:188.0
-5,8,23:18.14
-4,8,23:18.14
-3,8,23:188.0
-2,8,23:188.0
-1,8,23:17.12
3,8,23:18.14
-6,9,23:18.14
-5,9,23:18.14
-3,9,23:188.0
1,9,23:18.14
2,9,23:18.14
-1,10,23:18.14
-5,11,23:18.14
-7,-5,24:175.2
-8,-4,24:18.14
-6,-4,24:18.14
-2,-4,24:175.2
-6,-2,24:18.14
-5,-2,24:18.14
-4,-2,24:18.14
-3,-2,24:18.14
-4,-1,24:18.14
-2,-1,24:175.2
0,-1,24:18.14
2,-1,24:18.14
-5,0,24:175.2
-3,0,24:175.2
1,0,24:175.2
-1,1,24:175.2
-5,2,24:18.14
-4,2,24:18.14
-3,2,24:18.14
0,2,24:175.2
-7,3,24:18.14
-6,3,24:18.14
2,3,24:18.14
-7,4,24:18.14
-2,4,24:18.14
1,4,24:18.14
3,4,24:18.14
-7,5,24:18.14
-4,5,24:18.14
-3,5,24:18.14
0,5,24:18.14
-7,6,24:18.6
-5,6,24:18.14
-4,6,24:18.14
0,6,24:18.14
-6,7,24:18.14
-5,7,24:18.14
-2,7,24:18.14
0,7,24:18.14
-7,8,24:18.6
-6,8,24:18.6
-5,8,24:18.14
-2,8,24:18.14
0,8,24:18.14
-6,9,24:18.14
-5,9,24:18.14
-4,9,24:188.0
-3,9,24:188.0
-1,9,24:18.14
1,9,24:18.14
2,9,24:18.14
-6,10,24:18.14
-5,10,24:188.0
-4,10,24:188.0
-2,10,24:18.14
-1,10,24:18.14
-4,11,24:18.14
-2,-3,25:18.14
-5,-2,25:175.2
-3,-2,25:175.2
-7,-1,25:18.14
-6,-1,25:175.2
-4,-1,25:175.2
2,-1,25:175.2
-4,2,25:18.14
-6,3,25:18.14
-3,3,25:18.14
-2,3,25:18.14
2,3,25:175.2
-7,4,25:18.14
-3,4,25:18.14
-1,4,25:18.14
1,4,25:18.14
3,4,25:175.2
-6,5,25:18.6
-2,5,25:18.14
0,5,25:18.14
-5,6,25:18.14
-3,6,25:18.14
-2,6,25:18.14
1,6,25:18.14
-7,7,25:18.6
-6,7,25:18.14
-3,7,25:18.14
-2,7,25:18.14
-6,8,25:18.6
-5,8,25:18.14
-4,8,25:18.14
-3,8,25:18.14
-2,8,25:18.14
0,8,25:175.2
-6,9,25:18.6
-5,9,25:18.14
-2,9,25:18.14
2,9,25:175.2
-6,10,25:18.14
-5,10,25:18.14
-4,10,25:18.14
-2,10,25:18.14
1,10,25:18.14
-5,11,25:18.14
-4,11,25:18.14
-5,1,26:18.6
-3,1,26:18.14
-7,2,26:18.6
-4,2,26:175.2
-2,2,26:18.6
-6,3,26:175.2
-2,3,26:175.2
-7,4,26:175.2
-4,4,26:175.2
0,4,26:18.14
1,4,26:175.2
-6,5,26:175.2
-3,5,26:18.14
-2,5,26:18.14
-1,5,26:18.14
0,5,26:18.14
1,5,26:18.14
-5,6,26:175.2
-2,6,26:18.14
0,6,26:18.14
-7,7,26:175.2
1,7,26:18.14
-6,8,26:175.2
-4,8,26:175.2
-2,8,26:18.14
-5,9,26:18.14
-4,9,26:18.14
-3,9,26:18.14
-2,9,26:18.14
-6,10,26:18.14
-5,10,26:18.14
-3,12,26:18.14
-5,1,27:175.2
-3,1,27:175.2
-2,2,27:175.2
0,4,27:175.2
-3,5,27:175.2
-1,5,27:175.2
1,5,27:175.2
0,6,27:175.2
0,7,27:18.14
-4,9,27:175.2
-2,9,27:175.2
-6,10,27:175.2
-1,10,27:18.14
