[META]
version=2.0
spawnOnBlockType=2
spawnSunlight=True
spawnDarkness=True
spawnWater=False
spawnLava=False
underFill=False
randomRotation=True
dig=True
tree=True
branch=False
needsFoundation=True
rarity=100
collisionPercentage=20
spawnElevationMin=0
spawnElevationMax=200
spawnInBiome=Custom
[DATA]
-2,-1,0:17.12
-3,0,0:17.12
-1,1,0:17.12
-3,2,0:17.12
-3,0,1:17.12
-1,1,1:17.12
-3,2,1:17.12
-2,0,2:17.12
-2,1,2:17.12
-2,1,3:17.12
-3,1,4:143.2
-2,1,4:17.12
-4,-4,5:18.14
-1,-4,5:18.14
-5,-3,5:18.14
-4,-3,5:18.14
-3,-3,5:18.14
-2,-3,5:18.14
-1,-3,5:18.14
-4,-2,5:18.14
-2,-2,5:18.14
-1,-2,5:18.14
-2,1,5:17.12
-2,2,5:17.12
-2,3,5:143.3
1,7,5:18.14
-4,-4,6:175.2
-3,-4,6:18.14
-1,-4,6:175.2
0,-4,6:18.14
-6,-3,6:18.14
-5,-3,6:18.14
-2,-3,6:175.2
-1,-3,6:18.14
1,-3,6:18.14
-5,-2,6:18.14
-4,-2,6:18.14
-1,-2,6:18.14
0,-2,6:18.14
1,-2,6:18.14
1,-1,6:18.14
0,0,6:18.14
1,0,6:18.14
-2,1,6:17.12
2,1,6:18.14
3,1,6:18.14
-2,2,6:17.12
0,2,6:18.14
1,2,6:18.14
2,2,6:18.14
0,3,6:18.14
1,3,6:18.14
3,3,6:18.14
-2,5,6:18.14
-1,5,6:18.14
1,5,6:18.14
2,5,6:18.14
-1,6,6:18.14
0,6,6:18.14
1,6,6:18.14
2,6,6:18.14
3,6,6:18.14
-2,7,6:18.14
1,7,6:175.2
2,7,6:18.14
-3,8,6:18.14
-2,-6,7:18.14
-5,-5,7:18.14
-4,-5,7:18.14
-3,-5,7:18.14
0,-5,7:18.14
-8,-4,7:18.14
-6,-4,7:18.14
-4,-4,7:18.14
-2,-4,7:18.14
0,-4,7:175.2
-8,-3,7:18.14
-6,-3,7:18.14
-5,-3,7:18.14
-4,-3,7:18.14
-1,-3,7:175.2
0,-3,7:18.14
1,-3,7:175.2
2,-3,7:18.14
-7,-2,7:18.6
-6,-2,7:18.14
-5,-2,7:18.14
-4,-2,7:18.14
1,-2,7:18.14
-5,-1,7:188.0
-4,-1,7:188.0
-3,-1,7:17.12
2,-1,7:18.14
3,-1,7:18.14
-2,0,7:17.12
1,0,7:18.14
2,0,7:18.14
3,0,7:18.14
-2,1,7:17.12
-1,1,7:143.1
2,1,7:18.14
3,1,7:175.2
-3,2,7:17.12
-2,2,7:17.12
-1,2,7:188.0
0,2,7:188.0
2,2,7:18.14
-8,3,7:18.14
-2,3,7:17.12
-1,3,7:18.14
0,3,7:18.14
2,3,7:18.14
3,3,7:175.2
-5,4,7:188.0
-4,4,7:188.0
-3,4,7:17.12
-7,5,7:18.6
-5,5,7:188.0
-1,5,7:18.14
0,5,7:18.14
2,5,7:175.2
3,5,7:18.14
-4,6,7:18.14
-3,6,7:18.14
-1,6,7:175.2
1,6,7:175.2
2,6,7:18.14
-4,7,7:18.14
-2,7,7:18.14
1,7,7:18.14
4,7,7:18.14
-5,8,7:18.14
-4,8,7:18.14
-2,8,7:18.6
0,8,7:18.14
3,8,7:18.14
1,9,7:18.14
-3,-6,8:18.14
-2,-6,8:175.2
-7,-5,8:18.6
-5,-5,8:18.6
-4,-5,8:175.2
-3,-5,8:18.14
-2,-5,8:18.14
-1,-5,8:18.14
0,-5,8:175.2
-8,-4,8:18.14
-7,-4,8:18.14
-5,-4,8:18.14
-4,-4,8:18.14
-3,-4,8:18.14
-2,-4,8:18.14
2,-4,8:18.14
-8,-3,8:175.2
-7,-3,8:18.14
-6,-3,8:18.14
-4,-3,8:18.14
-3,-3,8:17.12
-2,-3,8:18.14
-1,-3,8:188.0
0,-3,8:18.14
2,-3,8:18.14
-7,-2,8:175.2
-6,-2,8:188.0
-5,-2,8:188.0
-3,-2,8:17.12
-2,-2,8:188.0
-1,-2,8:188.0
1,-2,8:175.2
-7,-1,8:18.6
-5,-1,8:188.0
-4,-1,8:18.6
1,-1,8:18.14
3,-1,8:175.2
-6,0,8:188.0
-5,0,8:188.0
-1,0,8:17.12
1,0,8:18.14
2,0,8:175.2
-7,1,8:18.14
-3,1,8:17.12
-2,1,8:17.12
1,1,8:18.14
2,1,8:18.14
-4,2,8:17.12
-3,2,8:17.12
-2,2,8:17.12
0,2,8:188.0
1,2,8:188.0
2,2,8:18.14
-8,3,8:18.14
-7,3,8:18.14
2,3,8:18.14
3,3,8:18.14
2,4,8:18.14
-7,5,8:18.14
-6,5,8:188.0
-5,5,8:188.0
-3,5,8:17.12
-2,5,8:188.0
-1,5,8:188.0
0,5,8:18.14
3,5,8:175.2
-6,6,8:188.0
-3,6,8:17.12
-1,6,8:18.14
2,6,8:175.2
3,6,8:18.14
4,6,8:18.6
-4,7,8:18.14
-2,7,8:175.2
0,7,8:18.6
1,7,8:18.14
4,7,8:18.14
-5,8,8:175.2
-4,8,8:18.14
0,8,8:18.14
1,8,8:18.14
2,8,8:18.14
3,8,8:18.14
-3,9,8:18.14
0,9,8:18.14
1,9,8:175.2
-3,-6,9:175.2
-2,-6,9:18.14
-8,-5,9:18.14
-7,-5,9:18.14
-6,-5,9:18.14
-5,-5,9:175.2
-4,-5,9:17.12
-3,-5,9:18.14
-2,-5,9:18.14
-1,-5,9:175.2
0,-5,9:18.14
1,-5,9:18.14
-7,-4,9:175.2
-5,-4,9:18.14
-4,-4,9:17.12
-2,-4,9:18.14
-1,-4,9:188.0
0,-4,9:188.0
1,-4,9:18.14
-7,-3,9:18.14
-4,-3,9:18.14
-3,-3,9:17.12
-1,-3,9:188.0
0,-3,9:175.2
3,-3,9:18.14
-8,-2,9:18.6
-7,-2,9:188.0
-6,-2,9:188.0
-5,-2,9:18.14
-4,-2,9:18.14
-1,-2,9:18.14
1,-2,9:18.14
3,-2,9:18.14
-8,-1,9:18.6
-5,-1,9:18.6
1,-1,9:18.14
3,-1,9:18.14
-8,0,9:18.14
-7,0,9:188.0
-6,0,9:188.0
-1,0,9:17.12
2,0,9:18.14
-7,1,9:18.14
-6,1,9:18.6
-3,1,9:17.12
2,1,9:18.14
3,1,9:18.14
4,1,9:18.14
-7,2,9:18.14
-5,2,9:17.12
-3,2,9:17.12
-2,2,9:17.12
1,2,9:188.0
2,2,9:188.0
3,2,9:188.0
4,2,9:18.14
-8,3,9:18.14
-7,3,9:18.14
2,3,9:18.14
4,3,9:18.14
-7,4,9:18.14
-7,5,9:18.14
-6,5,9:18.14
-5,5,9:18.14
-1,5,9:188.0
0,5,9:188.0
1,5,9:18.14
2,5,9:18.14
-7,6,9:18.14
-6,6,9:188.0
-4,6,9:18.14
-3,6,9:17.12
-2,6,9:18.14
-1,6,9:18.14
0,6,9:188.0
1,6,9:18.14
2,6,9:18.14
3,6,9:175.2
-6,7,9:18.6
-5,7,9:18.6
-4,7,9:17.12
-2,7,9:18.6
0,7,9:18.14
1,7,9:18.14
3,7,9:18.14
4,7,9:18.14
-5,8,9:18.6
-4,8,9:17.12
-3,8,9:18.6
-2,8,9:18.6
-1,8,9:18.14
0,8,9:18.14
1,8,9:175.2
3,8,9:175.2
-5,9,9:18.14
-3,9,9:18.14
-2,9,9:18.14
1,9,9:18.14
-5,10,9:18.14
-2,-7,10:18.14
-5,-6,10:18.6
-4,-6,10:18.6
-8,-5,10:175.2
-7,-5,10:18.14
-6,-5,10:175.2
-5,-5,10:18.6
-4,-5,10:18.6
-3,-5,10:18.14
-2,-5,10:175.2
0,-5,10:18.14
1,-5,10:18.14
-8,-4,10:18.14
-5,-4,10:18.14
-2,-4,10:18.14
-1,-4,10:18.14
0,-4,10:188.0
1,-4,10:175.2
-8,-3,10:18.14
-4,-3,10:18.14
-1,-3,10:18.14
3,-3,10:18.14
-8,-2,10:18.6
-7,-2,10:18.6
-6,-2,10:18.14
-4,-2,10:18.14
0,-2,10:18.14
2,-2,10:18.14
3,-2,10:18.14
-8,-1,10:175.2
-6,-1,10:18.6
0,-1,10:17.12
2,-1,10:18.14
3,-1,10:175.2
-8,0,10:18.14
-7,0,10:18.14
-5,0,10:18.6
-1,0,10:17.12
0,0,10:188.0
2,0,10:18.14
-7,1,10:175.2
-6,1,10:18.6
-3,1,10:17.12
1,1,10:18.14
2,1,10:18.14
4,1,10:175.2
-8,2,10:18.14
-6,2,10:17.12
-5,2,10:17.12
-3,2,10:17.12
-2,2,10:17.12
2,2,10:18.14
4,2,10:18.14
-7,3,10:175.2
-4,3,10:17.12
-1,3,10:17.12
2,3,10:175.2
4,3,10:175.2
-8,5,10:18.14
-7,5,10:175.2
-6,5,10:18.14
-5,5,10:175.2
-2,5,10:18.6
1,5,10:18.14
2,5,10:18.14
-7,6,10:18.14
-4,6,10:175.2
-3,6,10:18.14
-2,6,10:18.14
-1,6,10:18.14
0,6,10:18.14
1,6,10:175.2
3,6,10:18.14
-6,7,10:18.6
-5,7,10:18.6
-3,7,10:18.6
0,7,10:175.2
2,7,10:18.14
3,7,10:18.14
4,7,10:175.2
-6,8,10:18.6
-4,8,10:18.14
-3,8,10:18.14
-2,8,10:18.14
-1,8,10:175.2
-5,9,10:175.2
-4,9,10:18.14
-2,9,10:175.2
0,9,10:18.14
1,9,10:175.2
-4,10,10:18.14
-2,10,10:18.14
-2,-7,11:175.2
-5,-6,11:175.2
-7,-5,11:175.2
-4,-5,11:175.2
0,-5,11:175.2
2,-5,11:18.14
-8,-4,11:18.14
-6,-4,11:18.14
-5,-4,11:175.2
-2,-4,11:18.14
-1,-4,11:175.2
-8,-3,11:175.2
-6,-3,11:18.14
-4,-3,11:175.2
3,-3,11:175.2
-8,-2,11:18.14
-6,-2,11:175.2
-1,-2,11:18.14
0,-2,11:17.12
1,-2,11:17.12
2,-2,11:175.2
-7,-1,11:18.14
-6,-1,11:18.14
1,-1,11:18.14
2,-1,11:18.14
-8,0,11:175.2
-7,0,11:18.14
-6,0,11:188.0
0,0,11:188.0
1,0,11:188.0
3,0,11:18.14
-6,1,11:188.0
-5,1,11:18.6
1,1,11:188.0
2,1,11:188.0
3,1,11:18.14
-8,2,11:175.2
-6,2,11:17.12
-3,2,11:17.12
-1,2,11:143.4
1,2,11:18.14
2,2,11:175.2
4,2,11:175.2
-6,3,11:188.0
-5,3,11:143.2
-4,3,11:17.12
-1,3,11:17.12
-6,4,11:188.0
0,4,11:17.12
1,4,11:17.12
2,4,11:18.14
3,4,11:18.14
-8,5,11:175.2
-6,5,11:175.2
-3,5,11:18.6
0,5,11:18.14
2,5,11:18.14
-7,6,11:175.2
-3,6,11:18.6
-2,6,11:18.6
0,6,11:18.14
1,6,11:18.14
2,6,11:18.14
3,6,11:18.14
-7,7,11:18.6
-6,7,11:175.2
-5,7,11:18.6
-3,7,11:18.6
-2,7,11:18.14
-1,7,11:18.14
0,7,11:18.14
1,7,11:18.14
2,7,11:175.2
-5,8,11:18.6
-4,8,11:18.14
-3,8,11:18.14
-2,8,11:18.14
-4,9,11:175.2
0,9,11:175.2
-5,-6,12:18.14
-4,-6,12:18.14
-8,-5,12:18.14
-6,-5,12:18.14
-5,-5,12:18.14
-3,-5,12:18.14
2,-5,12:175.2
-8,-4,12:175.2
-7,-4,12:18.14
-2,-4,12:175.2
-6,-3,12:175.2
-5,-3,12:18.14
1,-3,12:18.14
2,-3,12:18.14
-8,-2,12:175.2
-5,-2,12:18.6
-2,-2,12:18.14
0,-2,12:18.14
2,-2,12:18.14
-8,-1,12:18.14
-7,-1,12:175.2
-6,-1,12:188.0
-1,-1,12:18.14
-6,0,12:188.0
-5,0,12:18.14
0,0,12:18.14
1,0,12:18.14
2,0,12:18.14
3,0,12:18.14
-8,1,12:18.14
-6,1,12:18.14
-5,1,12:175.2
-1,1,12:18.14
0,1,12:18.14
1,1,12:18.14
2,1,12:18.14
3,1,12:18.14
-8,2,12:18.14
-7,2,12:17.12
0,2,12:18.14
1,2,12:18.14
-8,3,12:18.14
-4,3,12:17.12
1,3,12:18.6
-8,4,12:18.14
-7,4,12:188.0
-6,4,12:188.0
-5,4,12:18.14
-4,4,12:188.0
-3,4,12:188.0
1,4,12:17.12
2,4,12:18.14
-4,5,12:18.6
-3,5,12:188.0
-2,5,12:18.6
-1,5,12:18.6
2,5,12:17.12
-4,6,12:18.6
-3,6,12:18.6
-2,6,12:18.6
0,6,12:18.6
1,6,12:18.14
2,6,12:175.2
3,6,12:18.14
-5,7,12:175.2
-4,7,12:18.6
-3,7,12:18.6
-1,7,12:175.2
1,7,12:175.2
-4,8,12:18.14
-2,8,12:175.2
-1,8,12:18.14
2,8,12:18.14
-3,9,12:18.14
-5,-6,13:175.2
-4,-6,13:18.14
-8,-5,13:175.2
-6,-5,13:18.14
-5,-5,13:18.14
-4,-5,13:18.14
-3,-5,13:175.2
-7,-4,13:175.2
-6,-4,13:18.14
-5,-3,13:18.14
-4,-3,13:18.14
-1,-3,13:18.14
0,-3,13:18.14
1,-3,13:175.2
-8,-2,13:18.14
-7,-2,13:18.14
-6,-2,13:18.6
-2,-2,13:18.14
1,-2,13:18.14
2,-2,13:175.2
3,-2,13:18.14
-8,-1,13:175.2
-7,-1,13:188.0
-6,-1,13:188.0
-8,0,13:18.14
-7,0,13:18.14
-6,0,13:18.14
-5,0,13:175.2
0,0,13:18.14
3,0,13:18.14
-9,1,13:18.14
-8,1,13:18.14
-6,1,13:175.2
0,1,13:18.14
1,1,13:175.2
2,1,13:18.14
3,1,13:175.2
-9,2,13:18.14
-8,2,13:17.12
-5,2,13:18.14
-4,2,13:18.14
-1,2,13:18.14
0,2,13:18.14
-9,3,13:18.14
-8,3,13:18.14
-7,3,13:18.14
-6,3,13:18.14
-4,3,13:17.12
-3,3,13:18.14
0,3,13:18.14
1,3,13:18.14
-8,4,13:18.14
-7,4,13:188.0
-5,4,13:175.2
-3,4,13:18.14
-2,4,13:18.14
2,4,13:18.14
-8,5,13:18.14
-7,5,13:18.14
-4,5,13:175.2
-3,5,13:188.0
-2,5,13:188.0
-1,5,13:188.0
0,5,13:18.6
1,5,13:18.14
2,5,13:175.2
3,5,13:18.14
-4,6,13:18.14
-3,6,13:188.0
-2,6,13:175.2
0,6,13:175.2
2,6,13:18.14
3,6,13:175.2
-4,7,13:18.6
-3,7,13:18.6
-4,8,13:175.2
-3,8,13:18.6
-1,8,13:175.2
-3,9,13:175.2
-5,-6,14:18.14
-4,-6,14:175.2
-5,-5,14:175.2
-2,-5,14:18.14
-7,-4,14:18.14
-5,-4,14:18.14
-1,-4,14:18.14
-2,-3,14:18.14
-1,-3,14:18.14
0,-3,14:18.14
-8,-2,14:175.2
-7,-2,14:18.14
-6,-2,14:18.14
-3,-2,14:18.14
0,-2,14:18.14
1,-2,14:175.2
-8,-1,14:18.14
-7,-1,14:175.2
-6,-1,14:18.14
-5,-1,14:18.6
-4,-1,14:18.14
-1,-1,14:18.14
1,-1,14:18.14
-7,0,14:18.14
-6,0,14:175.2
-3,0,14:18.14
3,0,14:175.2
-9,1,14:18.14
-6,1,14:18.14
-1,1,14:18.14
0,1,14:18.14
1,1,14:18.14
-9,2,14:175.2
-8,2,14:18.14
-7,2,14:18.14
-6,2,14:18.14
-5,2,14:18.14
-3,2,14:18.14
0,2,14:18.14
2,2,14:18.14
-9,3,14:18.14
-8,3,14:18.14
-5,3,14:18.14
-4,3,14:17.12
1,3,14:175.2
-8,4,14:175.2
-7,4,14:18.14
-6,4,14:18.14
-5,4,14:18.14
-4,4,14:18.14
-3,4,14:18.14
-1,4,14:18.14
2,4,14:175.2
3,4,14:18.14
-9,5,14:18.14
-7,5,14:18.14
-6,5,14:18.14
-3,5,14:18.14
-2,5,14:18.14
-1,5,14:188.0
0,5,14:18.14
1,5,14:175.2
3,5,14:175.2
-6,6,14:18.14
-3,6,14:188.0
-1,6,14:18.14
0,6,14:18.14
2,6,14:175.2
-6,7,14:18.14
-3,7,14:188.0
-2,7,14:18.14
2,7,14:18.14
-4,8,14:18.14
-3,8,14:175.2
-2,8,14:18.14
-5,-6,15:175.2
-2,-6,15:18.14
-2,-5,15:175.2
-5,-4,15:175.2
0,-4,15:18.14
-5,-3,15:18.14
-3,-3,15:18.14
-1,-3,15:175.2
1,-3,15:18.14
-7,-2,15:175.2
-6,-2,15:18.14
-4,-2,15:18.14
0,-2,15:175.2
-8,-1,15:175.2
-5,-1,15:175.2
-4,-1,15:18.6
-3,-1,15:18.14
-2,-1,15:18.14
-1,-1,15:18.14
1,-1,15:175.2
2,-1,15:18.14
-7,0,15:175.2
-3,0,15:18.14
-2,0,15:18.14
-9,1,15:175.2
-8,1,15:18.14
-6,1,15:18.14
-3,1,15:18.14
-1,1,15:175.2
1,1,15:175.2
-9,2,15:18.14
-8,2,15:175.2
-7,2,15:18.14
-6,2,15:175.2
-3,2,15:18.14
-2,2,15:18.14
0,2,15:175.2
2,2,15:175.2
-9,3,15:175.2
-7,3,15:18.14
-5,3,15:175.2
-3,3,15:18.14
-2,3,15:18.14
2,3,15:18.14
-6,4,15:18.14
-4,4,15:175.2
-2,4,15:18.6
-1,4,15:175.2
3,4,15:175.2
-7,5,15:175.2
-5,5,15:18.14
-3,5,15:18.14
-2,5,15:175.2
-1,5,15:18.14
0,5,15:18.14
-6,6,15:18.14
-3,6,15:175.2
-1,6,15:175.2
-5,7,15:18.14
-4,7,15:18.14
-3,7,15:18.14
-2,7,15:18.14
2,7,15:175.2
-4,8,15:175.2
-2,8,15:175.2
-3,-4,16:18.14
-7,-3,16:18.14
-5,-3,16:175.2
-3,-3,16:175.2
-6,-2,16:175.2
-5,-2,16:18.14
-4,-2,16:175.2
-3,-2,16:18.6
-3,-1,16:175.2
-1,-1,16:175.2
-3,0,16:18.14
-2,0,16:175.2
-1,0,16:18.14
-8,1,16:175.2
-6,1,16:175.2
-9,2,16:175.2
-7,2,16:18.14
-3,2,16:175.2
-1,2,16:18.14
-8,3,16:18.14
-7,3,16:175.2
-3,3,16:18.14
-2,3,16:18.14
2,3,16:175.2
-6,4,16:175.2
-2,4,16:175.2
-5,5,16:175.2
-3,5,16:175.2
-1,5,16:175.2
1,5,16:18.14
-7,6,16:18.14
-6,6,16:175.2
-1,6,16:18.14
-4,7,16:175.2
-2,7,16:175.2
-5,8,16:18.14
-3,8,16:18.14
-5,-2,17:175.2
-3,-2,17:175.2
-3,0,17:175.2
-1,2,17:175.2
-2,3,17:175.2
