[META]
version=2.0
spawnOnBlockType=2
spawnSunlight=True
spawnDarkness=True
spawnWater=False
spawnLava=False
underFill=False
randomRotation=True
dig=True
tree=True
branch=False
needsFoundation=True
rarity=100
collisionPercentage=20
spawnElevationMin=0
spawnElevationMax=200
spawnInBiome=Custom
[DATA]
-1,-1,0:17.12
-1,0,0:17.12
-1,1,0:17.12
-1,0,1:17.12
-2,0,2:143.2
-1,0,2:17.12
-1,-1,3:143.4
-1,0,3:17.12
-3,-5,4:18.14
-4,-4,4:18.14
-1,-4,4:18.14
1,-4,4:18.14
-4,-3,4:18.14
-2,-3,4:18.14
0,-3,4:18.14
1,-3,4:18.14
-4,-2,4:18.14
-3,-2,4:18.14
1,-2,4:18.14
-5,-1,4:18.14
1,-1,4:18.14
2,-1,4:18.14
-5,0,4:18.14
-1,0,4:17.12
0,0,4:17.12
2,0,4:18.14
-1,1,4:143.3
0,1,4:188.0
3,1,4:18.6
0,2,4:188.0
-3,-5,5:18.14
-2,-5,5:18.14
-4,-4,5:18.14
0,-4,5:18.14
1,-4,5:175.2
-5,-3,5:18.14
-3,-3,5:18.14
-2,-3,5:18.14
-1,-3,5:18.14
0,-3,5:18.14
2,-3,5:18.14
3,-3,5:18.14
-5,-2,5:18.14
-2,-2,5:18.14
1,-2,5:18.14
3,-2,5:18.6
-5,-1,5:18.14
-4,-1,5:188.0
-3,-1,5:188.0
-2,-1,5:17.12
1,-1,5:18.14
2,-1,5:18.14
3,-1,5:18.14
4,-1,5:18.14
-5,0,5:175.2
-4,0,5:18.14
-3,0,5:18.14
0,0,5:17.12
1,0,5:18.14
3,0,5:18.14
-5,1,5:18.14
-4,1,5:18.14
-3,1,5:18.14
-2,1,5:17.12
2,1,5:18.14
4,1,5:18.14
-3,2,5:18.14
-2,2,5:188.0
0,2,5:188.0
1,2,5:188.0
2,2,5:188.0
-4,3,5:18.14
-2,3,5:188.0
0,3,5:188.0
1,3,5:18.14
2,3,5:188.0
-3,4,5:18.14
-1,4,5:18.14
1,4,5:18.6
-2,-5,6:18.14
-2,-4,6:18.14
0,-4,6:18.14
1,-4,6:18.14
-5,-3,6:18.14
-4,-3,6:18.14
-3,-3,6:17.12
-2,-3,6:18.14
0,-3,6:188.0
1,-3,6:18.14
3,-3,6:175.2
-5,-2,6:175.2
-4,-2,6:18.14
-3,-2,6:18.14
-2,-2,6:17.12
0,-2,6:188.0
2,-2,6:18.14
3,-2,6:18.14
-5,-1,6:18.14
-4,-1,6:188.0
0,-1,6:17.12
1,-1,6:18.14
2,-1,6:18.14
3,-1,6:18.14
4,-1,6:175.2
-5,0,6:18.14
-4,0,6:18.14
-3,0,6:175.2
2,0,6:18.14
3,0,6:18.14
4,0,6:18.14
-5,1,6:18.14
-4,1,6:18.14
-3,1,6:17.12
2,1,6:18.14
3,1,6:18.14
4,1,6:175.2
-5,2,6:18.14
-3,2,6:175.2
-2,2,6:18.14
2,2,6:18.14
3,2,6:18.14
4,2,6:18.14
-4,3,6:175.2
-3,3,6:188.0
-2,3,6:188.0
-1,3,6:18.14
0,3,6:188.0
1,3,6:18.14
2,3,6:188.0
3,3,6:188.0
4,3,6:18.6
-3,4,6:18.14
-2,4,6:18.14
-1,4,6:18.14
0,4,6:188.0
2,4,6:18.6
3,4,6:18.6
4,4,6:18.6
-1,5,6:18.14
0,5,6:18.6
1,5,6:18.6
-3,-5,7:175.2
-1,-5,7:18.14
0,-5,7:18.14
-4,-4,7:18.6
-3,-4,7:18.14
-2,-4,7:175.2
-1,-4,7:18.14
0,-4,7:18.14
1,-4,7:18.14
-5,-3,7:175.2
-1,-3,7:18.14
0,-3,7:188.0
1,-3,7:175.2
-5,-2,7:18.14
-4,-2,7:18.14
-3,-2,7:18.14
-1,-2,7:18.14
2,-2,7:175.2
-5,-1,7:18.14
-4,-1,7:188.0
0,-1,7:17.12
1,-1,7:18.14
2,-1,7:18.14
3,-1,7:175.2
-5,0,7:175.2
3,0,7:18.14
-5,1,7:18.14
-3,1,7:18.14
-2,1,7:18.14
2,1,7:175.2
-5,2,7:18.14
-4,2,7:17.12
-1,2,7:18.14
3,2,7:175.2
-5,3,7:18.14
-4,3,7:18.14
-3,3,7:18.14
-2,3,7:18.14
-1,3,7:18.14
3,3,7:18.14
4,3,7:175.2
-3,4,7:18.14
-1,4,7:175.2
0,4,7:188.0
1,4,7:18.14
2,4,7:18.14
3,4,7:18.14
-1,5,7:18.14
0,5,7:18.6
1,5,7:175.2
-3,-5,8:18.14
-2,-5,8:175.2
-1,-5,8:18.14
0,-5,8:175.2
-4,-4,8:175.2
-3,-4,8:18.14
-1,-4,8:175.2
1,-4,8:175.2
-4,-3,8:18.14
-3,-3,8:18.14
-1,-3,8:18.14
0,-3,8:175.2
1,-3,8:18.14
2,-3,8:18.14
-5,-2,8:175.2
-4,-2,8:18.14
0,-2,8:18.14
2,-2,8:18.6
-4,-1,8:18.14
-3,-1,8:18.14
0,-1,8:18.14
1,-1,8:17.12
2,-1,8:18.14
0,0,8:18.14
1,0,8:18.6
3,0,8:18.6
-5,1,8:18.14
-4,1,8:18.14
-3,1,8:18.14
-1,1,8:18.14
1,1,8:18.14
-5,2,8:175.2
-3,2,8:18.14
-1,2,8:18.14
0,2,8:18.14
2,2,8:18.14
-5,3,8:18.14
-4,3,8:18.14
-2,3,8:18.14
2,3,8:18.14
-3,4,8:175.2
0,4,8:18.6
1,4,8:175.2
3,4,8:175.2
-1,5,8:175.2
0,5,8:18.6
-4,-5,9:18.14
-3,-5,9:175.2
-2,-5,9:18.14
-4,-4,9:18.14
-3,-4,9:18.14
-2,-4,9:18.14
-1,-4,9:18.14
-4,-3,9:18.14
-1,-3,9:18.14
1,-3,9:18.6
-4,-2,9:175.2
-3,-2,9:18.14
-1,-2,9:18.14
0,-2,9:18.14
1,-2,9:18.6
2,-2,9:18.6
-3,-1,9:175.2
-2,-1,9:18.14
-1,-1,9:18.14
0,-1,9:18.14
1,-1,9:175.2
2,-1,9:18.6
-3,0,9:18.14
-2,0,9:18.14
-1,0,9:18.14
0,0,9:18.14
1,0,9:18.14
2,0,9:18.14
3,0,9:175.2
-4,1,9:175.2
-1,1,9:18.14
0,1,9:18.14
1,1,9:18.14
-3,2,9:175.2
1,2,9:18.14
-4,3,9:175.2
-2,3,9:175.2
1,3,9:18.14
2,3,9:175.2
0,4,9:18.6
0,5,9:175.2
-2,-5,10:175.2
-4,-4,10:18.14
-3,-4,10:175.2
-1,-4,10:175.2
-4,-3,10:175.2
-3,-3,10:18.14
1,-3,10:175.2
-3,-2,10:18.14
-1,-2,10:18.14
0,-2,10:175.2
2,-2,10:175.2
-3,-1,10:18.14
-1,-1,10:18.14
-2,0,10:175.2
0,0,10:18.14
2,0,10:175.2
-3,1,10:18.14
-1,1,10:175.2
1,1,10:175.2
0,2,10:18.14
1,3,10:175.2
0,4,10:175.2
-2,-3,11:18.14
-3,-2,11:175.2
-2,-2,11:18.14
-1,-2,11:18.14
-1,-1,11:175.2
0,0,11:175.2
-2,-3,12:175.2
-1,-2,12:175.2
