[META]
version=2.0
spawnOnBlockType=2
spawnSunlight=True
spawnDarkness=True
spawnWater=False
spawnLava=False
underFill=False
randomRotation=True
dig=True
tree=True
branch=False
needsFoundation=True
rarity=100
collisionPercentage=20
spawnElevationMin=0
spawnElevationMax=200
spawnInBiome=Custom
[DATA]
-1,1,0:17.12
-3,2,0:17.12
0,2,0:17.12
-1,3,0:17.12
-1,1,1:17.12
-2,2,1:17.12
-1,3,1:17.12
-1,2,2:17.12
-2,2,3:143.2
-1,2,3:17.12
-1,2,4:17.12
-1,1,5:17.12
-1,2,5:17.12
-2,-6,6:18.14
-1,-5,6:18.14
2,-5,6:18.14
-2,-4,6:18.6
-1,-4,6:18.6
0,-4,6:18.14
2,-4,6:18.14
3,-4,6:18.14
2,-3,6:18.14
3,-2,6:18.14
-1,-1,6:143.4
1,-1,6:18.6
2,-1,6:18.14
4,-1,6:18.14
-1,0,6:17.12
-1,1,6:17.12
4,1,6:18.14
-2,2,6:17.12
-1,2,6:17.12
0,2,6:143.1
-2,3,6:17.12
-4,7,6:18.14
-1,7,6:18.14
-3,8,6:18.14
-2,-7,7:18.14
-4,-6,7:18.14
-3,-6,7:18.14
-2,-6,7:18.14
-1,-6,7:18.14
-6,-5,7:18.6
-5,-5,7:18.14
-2,-5,7:18.14
-1,-5,7:175.2
2,-5,7:18.14
-6,-4,7:18.6
-4,-4,7:18.6
-2,-4,7:18.6
0,-4,7:18.14
3,-4,7:175.2
-6,-3,7:18.6
2,-3,7:175.2
3,-3,7:18.14
-5,-2,7:18.14
-4,-2,7:18.14
-3,-2,7:18.6
-1,-2,7:17.12
0,-2,7:18.6
1,-2,7:18.6
3,-2,7:18.14
4,-2,7:18.14
5,-2,7:18.6
-7,-1,7:18.6
-6,-1,7:18.14
-4,-1,7:18.14
-1,-1,7:17.12
0,-1,7:188.0
1,-1,7:188.0
2,-1,7:18.14
3,-1,7:18.14
4,-1,7:18.14
5,-1,7:18.14
1,0,7:18.14
2,0,7:18.14
5,0,7:18.6
-2,1,7:17.12
4,1,7:175.2
-8,2,7:18.14
-7,2,7:18.14
-6,2,7:18.14
-2,2,7:17.12
-1,2,7:17.12
1,2,7:18.6
3,2,7:18.6
1,3,7:18.6
4,3,7:18.6
-7,4,7:18.14
-6,4,7:18.14
-4,4,7:188.0
-3,4,7:188.0
-2,4,7:17.12
1,4,7:18.6
3,4,7:18.6
-5,5,7:18.14
-2,5,7:17.12
-1,5,7:188.0
0,5,7:18.14
-7,6,7:18.14
-5,6,7:18.14
-4,6,7:18.14
-3,6,7:17.12
-1,6,7:188.0
0,6,7:18.6
-4,7,7:175.2
-3,7,7:18.14
-2,7,7:18.14
-1,7,7:18.14
0,7,7:18.14
1,7,7:18.6
-4,8,7:18.14
-3,8,7:18.14
0,8,7:18.6
1,8,7:18.6
2,8,7:18.6
-5,9,7:18.14
-3,9,7:18.6
-1,9,7:18.6
1,9,7:18.6
-2,-7,8:18.14
-1,-7,8:18.14
-4,-6,8:175.2
-3,-6,8:18.14
-1,-6,8:175.2
1,-6,8:18.14
-6,-5,8:175.2
-5,-5,8:18.14
-2,-5,8:175.2
2,-5,8:18.14
-6,-4,8:18.14
-4,-4,8:18.6
-3,-4,8:18.14
-2,-4,8:17.12
-1,-4,8:18.14
0,-4,8:188.0
1,-4,8:18.14
2,-4,8:18.14
3,-4,8:18.14
-5,-3,8:18.14
-2,-3,8:17.12
-1,-3,8:188.0
0,-3,8:188.0
1,-3,8:18.14
4,-3,8:18.6
-8,-2,8:18.14
-6,-2,8:18.14
-5,-2,8:18.14
-4,-2,8:188.0
1,-2,8:18.6
2,-2,8:188.0
3,-2,8:18.6
4,-2,8:18.6
5,-2,8:175.2
-7,-1,8:175.2
-6,-1,8:18.14
-4,-1,8:188.0
-3,-1,8:18.14
0,-1,8:18.6
1,-1,8:188.0
2,-1,8:188.0
5,-1,8:18.6
-6,0,8:18.6
-5,0,8:188.0
-4,0,8:188.0
5,0,8:18.14
-8,1,8:18.14
-7,1,8:18.14
-6,1,8:18.6
-4,1,8:188.0
-3,1,8:188.0
-2,1,8:17.12
2,1,8:18.6
4,1,8:18.14
-6,2,8:175.2
-3,2,8:143.2
-2,2,8:17.12
0,2,8:18.6
1,2,8:18.6
2,2,8:18.6
3,2,8:18.6
4,2,8:18.14
-8,3,8:18.14
0,3,8:17.12
1,3,8:188.0
2,3,8:188.0
4,3,8:18.6
-8,4,8:18.6
-7,4,8:18.14
-5,4,8:188.0
-4,4,8:188.0
0,4,8:17.12
1,4,8:18.6
2,4,8:18.14
3,4,8:18.14
-8,5,8:18.6
-7,5,8:18.14
-5,5,8:188.0
2,5,8:18.14
4,5,8:18.14
-7,6,8:175.2
-6,6,8:188.0
-5,6,8:188.0
-4,6,8:175.2
-3,6,8:17.12
-2,6,8:18.14
-1,6,8:188.0
1,6,8:18.14
3,6,8:18.14
-6,7,8:18.6
-5,7,8:18.14
-3,7,8:17.12
-1,7,8:188.0
0,7,8:188.0
1,7,8:18.14
-5,8,8:18.14
-3,8,8:17.12
-2,8,8:18.14
-1,8,8:18.14
0,8,8:188.0
2,8,8:18.6
-5,9,8:175.2
-3,9,8:175.2
-2,9,8:18.6
-1,9,8:18.14
2,9,8:18.6
-2,-7,9:175.2
-1,-7,9:18.14
0,-7,9:18.14
-5,-6,9:18.14
-4,-6,9:18.14
-3,-6,9:175.2
-2,-6,9:17.12
1,-6,9:18.14
-7,-5,9:18.14
-5,-5,9:188.0
-4,-5,9:18.14
-3,-5,9:18.14
-2,-5,9:17.12
0,-5,9:188.0
1,-5,9:188.0
2,-5,9:18.14
-7,-4,9:18.14
-6,-4,9:18.14
-5,-4,9:188.0
-4,-4,9:188.0
-3,-4,9:18.14
-1,-4,9:175.2
0,-4,9:188.0
1,-4,9:18.14
2,-4,9:18.14
3,-4,9:175.2
-8,-3,9:18.14
-5,-3,9:18.14
-4,-3,9:188.0
4,-3,9:18.6
-8,-2,9:175.2
-7,-2,9:18.14
-5,-2,9:18.14
-4,-2,9:188.0
2,-2,9:188.0
3,-2,9:188.0
4,-2,9:188.0
5,-2,9:18.14
-7,-1,9:188.0
-6,-1,9:188.0
2,-1,9:18.14
4,-1,9:18.14
-8,0,9:18.6
-6,0,9:188.0
-5,0,9:188.0
4,0,9:18.14
5,0,9:175.2
-8,1,9:175.2
-7,1,9:18.14
-6,1,9:175.2
-2,1,9:17.12
2,1,9:175.2
4,1,9:175.2
5,1,9:18.14
-8,2,9:18.14
-2,2,9:17.12
2,2,9:188.0
3,2,9:188.0
-8,3,9:18.14
-6,3,9:18.14
-3,3,9:17.12
2,3,9:188.0
3,3,9:18.6
4,3,9:18.6
-8,4,9:18.6
-7,4,9:18.6
-6,4,9:18.6
0,4,9:17.12
1,4,9:18.14
2,4,9:175.2
4,4,9:18.14
-8,5,9:175.2
-6,5,9:18.14
-5,5,9:18.14
1,5,9:17.12
2,5,9:18.14
4,5,9:175.2
-7,6,9:18.14
1,6,9:17.12
3,6,9:175.2
-6,7,9:175.2
-5,7,9:18.14
1,7,9:18.14
2,7,9:18.14
3,7,9:18.14
-5,8,9:175.2
-4,8,9:18.6
-3,8,9:18.14
2,8,9:18.14
-2,9,9:18.6
-1,9,9:18.14
1,9,9:18.6
2,9,9:175.2
-2,-7,10:18.6
-1,-7,10:18.6
0,-7,10:18.6
-5,-6,10:18.14
-4,-6,10:18.14
-3,-6,10:18.6
1,-6,10:18.6
-7,-5,10:175.2
-3,-5,10:18.14
-2,-5,10:18.14
0,-5,10:175.2
1,-5,10:188.0
2,-5,10:18.14
-7,-4,10:18.14
-4,-4,10:18.14
-3,-4,10:18.6
0,-4,10:18.6
1,-4,10:18.6
2,-4,10:175.2
-8,-3,10:18.14
-6,-3,10:18.14
-5,-3,10:18.14
4,-3,10:18.14
-8,-2,10:18.14
-6,-2,10:18.6
2,-2,10:18.14
4,-2,10:188.0
5,-2,10:18.14
-8,-1,10:18.6
2,-1,10:18.14
4,-1,10:18.14
-8,0,10:175.2
-6,0,10:18.14
-2,0,10:17.12
2,0,10:18.14
3,0,10:18.14
4,0,10:18.14
-7,1,10:18.6
-6,1,10:18.6
-5,1,10:18.6
-2,1,10:17.12
-1,1,10:143.1
3,1,10:18.6
4,1,10:18.14
5,1,10:175.2
-6,2,10:188.0
-5,2,10:188.0
2,2,10:18.14
3,2,10:188.0
4,2,10:188.0
-8,3,10:175.2
-6,3,10:18.14
-5,3,10:188.0
-4,3,10:17.12
3,3,10:18.14
4,3,10:175.2
-7,4,10:175.2
-5,4,10:17.12
2,4,10:18.14
3,4,10:18.14
4,4,10:18.14
-6,5,10:175.2
-5,5,10:188.0
3,5,10:18.14
-7,6,10:175.2
-5,6,10:188.0
0,6,10:18.14
1,6,10:17.12
3,6,10:18.14
-5,7,10:18.14
2,7,10:17.12
3,7,10:18.14
-4,8,10:175.2
-3,8,10:18.14
-2,8,10:18.14
-1,8,10:18.14
0,8,10:18.14
2,8,10:175.2
-2,9,10:18.6
0,9,10:18.6
1,9,10:175.2
-2,-7,11:18.14
0,-7,11:175.2
1,-7,11:18.6
-4,-6,11:175.2
-3,-6,11:18.6
1,-6,11:175.2
-5,-5,11:18.14
-4,-5,11:18.14
-3,-5,11:18.14
-2,-5,11:18.6
2,-5,11:175.2
3,-5,11:18.14
-8,-4,11:18.14
-7,-4,11:175.2
-6,-4,11:18.14
-4,-4,11:18.14
1,-4,11:175.2
-8,-3,11:175.2
-7,-3,11:18.14
-6,-3,11:18.14
-5,-3,11:175.2
4,-3,11:175.2
-6,-2,11:18.14
2,-2,11:175.2
3,-2,11:18.14
4,-2,11:18.14
5,-2,11:175.2
-8,-1,11:175.2
2,-1,11:18.14
4,-1,11:175.2
-6,0,11:175.2
-2,0,11:17.12
2,0,11:18.14
3,0,11:175.2
-8,1,11:18.6
-7,1,11:18.14
-5,1,11:175.2
-3,1,11:17.12
-2,1,11:17.12
2,1,11:18.6
3,1,11:18.6
4,1,11:175.2
-6,2,11:188.0
-5,2,11:18.14
3,2,11:18.14
5,2,11:18.6
-7,3,11:18.14
-6,3,11:18.14
4,3,11:18.6
-6,4,11:17.12
-5,4,11:17.12
2,4,11:18.14
4,4,11:175.2
-7,5,11:18.14
-6,5,11:18.14
-5,5,11:18.14
-4,5,11:18.14
0,5,11:18.6
3,5,11:18.14
-5,6,11:188.0
-4,6,11:18.14
-1,6,11:18.14
0,6,11:18.14
1,6,11:18.14
2,6,11:18.14
3,6,11:175.2
-6,7,11:18.14
-5,7,11:188.0
-4,7,11:18.14
-2,7,11:18.14
1,7,11:18.14
2,7,11:18.14
3,7,11:18.14
-3,8,11:175.2
-2,8,11:18.14
-1,8,11:175.2
0,8,11:18.14
1,8,11:18.14
-2,9,11:175.2
0,9,11:175.2
-2,-7,12:175.2
1,-7,12:175.2
-5,-6,12:18.14
-3,-6,12:175.2
1,-6,12:18.14
-4,-5,12:175.2
-2,-5,12:175.2
3,-5,12:175.2
-8,-4,12:175.2
-6,-4,12:175.2
-2,-4,12:18.6
-7,-3,12:175.2
-6,-3,12:18.14
-3,-3,12:18.6
-7,-2,12:18.14
-6,-2,12:18.14
-5,-2,12:18.14
-3,-2,12:188.0
3,-2,12:18.14
4,-2,12:175.2
-3,-1,12:188.0
2,-1,12:18.6
4,-1,12:18.14
-7,0,12:18.14
-3,0,12:17.12
-1,0,12:17.12
2,0,12:18.6
-8,1,12:18.14
-7,1,12:18.14
-6,1,12:18.14
-4,1,12:18.6
-3,1,12:17.12
-1,1,12:188.0
0,1,12:188.0
4,1,12:18.6
-8,2,12:18.14
-5,2,12:18.6
-3,2,12:188.0
1,2,12:18.14
2,2,12:18.14
5,2,12:175.2
-7,3,12:175.2
-4,3,12:18.6
-3,3,12:188.0
-2,3,12:18.6
4,3,12:18.14
-8,4,12:18.14
-7,4,12:18.14
-6,4,12:18.14
2,4,12:18.14
3,4,12:18.14
-7,5,12:17.12
-5,5,12:18.14
1,5,12:18.6
3,5,12:175.2
-8,6,12:18.14
-4,6,12:18.6
-1,6,12:18.14
0,6,12:175.2
2,6,12:18.14
3,6,12:18.14
-6,7,12:18.14
-5,7,12:188.0
-4,7,12:18.14
-3,7,12:18.14
-1,7,12:18.14
0,7,12:18.14
1,7,12:175.2
2,7,12:18.14
3,7,12:175.2
4,7,12:18.14
-6,8,12:18.6
-5,8,12:18.6
-4,8,12:18.6
-3,8,12:18.14
-2,8,12:175.2
0,8,12:175.2
-2,9,12:18.14
-4,-5,13:18.14
-3,-5,13:18.14
0,-5,13:18.14
1,-5,13:18.14
-5,-4,13:18.14
-3,-4,13:188.0
-2,-4,13:18.14
-1,-4,13:18.14
0,-4,13:18.14
-6,-3,13:18.14
-5,-3,13:18.6
-3,-3,13:188.0
-1,-3,13:18.6
1,-3,13:18.6
2,-3,13:18.14
-7,-2,13:175.2
-5,-2,13:18.14
-4,-2,13:18.6
-3,-2,13:188.0
-1,-2,13:188.0
3,-2,13:175.2
-8,-1,13:18.6
-7,-1,13:18.14
-5,-1,13:18.14
-1,-1,13:188.0
0,-1,13:17.12
4,-1,13:175.2
-7,0,13:18.6
-5,0,13:188.0
-4,0,13:188.0
-3,0,13:17.12
-8,1,13:18.14
-7,1,13:175.2
-5,1,13:18.14
-3,1,13:18.14
0,1,13:188.0
3,1,13:18.14
4,1,13:175.2
-8,2,13:175.2
-7,2,13:18.14
-5,2,13:18.6
-3,2,13:18.6
3,2,13:18.14
-3,3,13:188.0
2,3,13:18.6
3,3,13:18.14
4,3,13:175.2
-8,4,13:175.2
-7,4,13:18.14
-2,4,13:18.6
2,4,13:18.14
3,4,13:18.14
-7,5,13:18.14
-4,5,13:18.14
0,5,13:18.6
1,5,13:18.14
2,5,13:18.14
-7,6,13:18.14
-6,6,13:18.6
-4,6,13:18.6
-1,6,13:18.14
2,6,13:175.2
-6,7,13:175.2
-4,7,13:175.2
-1,7,13:175.2
0,7,13:18.14
4,7,13:175.2
-5,8,13:175.2
-3,8,13:175.2
2,8,13:18.14
-5,-5,14:18.14
-4,-5,14:18.14
-3,-5,14:175.2
-2,-5,14:18.14
-1,-5,14:18.14
0,-5,14:175.2
1,-5,14:18.14
2,-5,14:18.14
-5,-4,14:18.14
-3,-4,14:188.0
-2,-4,14:18.14
-1,-4,14:18.14
1,-4,14:18.14
-6,-3,14:18.6
-1,-3,14:18.14
3,-3,14:18.14
-8,-2,14:18.14
-7,-2,14:18.14
-6,-2,14:18.14
-5,-2,14:18.14
-4,-2,14:18.6
-2,-2,14:188.0
-1,-2,14:188.0
0,-2,14:18.14
1,-2,14:18.14
2,-2,14:18.14
-8,-1,14:18.14
-7,-1,14:18.14
-4,-1,14:17.12
-2,-1,14:18.6
0,-1,14:17.12
-7,0,14:175.2
-6,0,14:188.0
-5,0,14:188.0
-3,0,14:18.14
-2,0,14:18.14
-5,1,14:175.2
-3,1,14:18.14
0,1,14:188.0
1,1,14:18.6
3,1,14:18.14
-8,2,14:18.14
-7,2,14:175.2
-6,2,14:18.6
-5,2,14:18.6
-4,2,14:18.6
-3,2,14:18.6
-2,2,14:18.6
0,2,14:188.0
1,2,14:188.0
2,2,14:18.6
3,2,14:18.14
4,2,14:18.14
-5,3,14:18.14
-4,3,14:18.14
-3,3,14:188.0
-2,3,14:18.6
0,3,14:188.0
1,3,14:18.6
2,3,14:175.2
-7,4,14:175.2
-4,4,14:18.14
-3,4,14:188.0
-2,4,14:18.6
-1,4,14:18.14
0,4,14:188.0
2,4,14:18.14
3,4,14:18.14
-8,5,14:18.14
-4,5,14:18.14
-2,5,14:18.14
0,5,14:175.2
2,5,14:18.14
-7,6,14:175.2
-6,6,14:18.6
-5,6,14:18.6
-4,6,14:175.2
-1,6,14:175.2
-5,7,14:18.6
-2,7,14:18.14
0,7,14:175.2
0,8,14:18.14
2,8,14:175.2
-4,-5,15:18.14
-3,-5,15:18.14
0,-5,15:18.14
2,-5,15:175.2
3,-5,15:18.14
-5,-4,15:175.2
-4,-4,15:18.14
-2,-4,15:18.14
-1,-4,15:18.14
1,-4,15:18.14
-6,-3,15:18.14
-4,-3,15:18.14
-2,-3,15:18.14
0,-3,15:18.14
1,-3,15:18.6
3,-3,15:175.2
-8,-2,15:175.2
-5,-2,15:18.14
-4,-2,15:18.14
-3,-2,15:18.6
-2,-2,15:188.0
0,-2,15:18.14
1,-2,15:17.12
3,-2,15:18.14
-7,-1,15:175.2
-6,-1,15:18.14
-5,-1,15:18.14
-4,-1,15:17.12
-2,-1,15:18.14
2,-1,15:18.14
-7,0,15:18.6
-4,0,15:18.14
-3,0,15:18.14
-1,0,15:18.6
3,0,15:18.14
-2,1,15:18.6
0,1,15:18.6
1,1,15:18.6
3,1,15:175.2
4,1,15:18.14
-6,2,15:175.2
-5,2,15:18.6
-4,2,15:18.6
-2,2,15:175.2
0,2,15:18.6
1,2,15:188.0
2,2,15:175.2
4,2,15:175.2
-4,3,15:18.14
-3,3,15:175.2
0,3,15:18.14
1,3,15:175.2
-4,4,15:18.14
-3,4,15:18.6
-2,4,15:18.14
0,4,15:188.0
3,4,15:175.2
-4,5,15:175.2
-3,5,15:18.6
-1,5,15:18.14
2,5,15:175.2
3,5,15:18.14
-6,6,15:175.2
2,6,15:18.14
-5,7,15:175.2
-3,-6,16:18.14
0,-6,16:18.14
-5,-5,16:18.14
0,-5,16:175.2
-4,-4,16:18.14
-1,-4,16:175.2
1,-4,16:175.2
-6,-3,16:175.2
-4,-3,16:175.2
-2,-3,16:18.14
-1,-3,16:18.14
0,-3,16:18.14
1,-3,16:18.14
-5,-2,16:175.2
-4,-2,16:18.14
-3,-2,16:18.14
-2,-2,16:18.14
-1,-2,16:18.14
0,-2,16:175.2
1,-2,16:18.14
2,-2,16:18.14
3,-2,16:175.2
-6,-1,16:175.2
-5,-1,16:18.14
-4,-1,16:175.2
-3,-1,16:18.14
0,-1,16:18.6
2,-1,16:175.2
-7,0,16:175.2
-6,0,16:18.14
-3,0,16:175.2
-2,0,16:18.14
-1,0,16:18.6
3,0,16:175.2
-5,1,16:18.6
-4,1,16:18.6
-3,1,16:18.6
-2,1,16:175.2
1,1,16:18.6
-4,2,16:175.2
0,2,16:175.2
1,2,16:18.6
2,2,16:18.6
0,3,16:18.14
1,3,16:18.14
-5,4,16:18.14
-4,4,16:175.2
-3,5,16:175.2
-1,5,16:175.2
0,5,16:18.14
-4,-4,17:175.2
-2,-4,17:18.14
-1,-3,17:175.2
0,-3,17:18.14
1,-3,17:175.2
-4,-2,17:18.14
-2,-2,17:175.2
2,-2,17:175.2
-5,-1,17:18.14
-3,-1,17:175.2
0,-1,17:175.2
-6,0,17:175.2
-5,0,17:18.14
-1,0,17:18.6
-5,1,17:175.2
-3,1,17:175.2
1,1,17:175.2
2,2,17:175.2
1,3,17:175.2
0,4,17:18.14
-4,-3,18:18.14
-6,-1,18:18.14
-5,0,18:175.2
-1,0,18:175.2
