[META]
version=2.0
spawnOnBlockType=2
spawnSunlight=True
spawnDarkness=True
spawnWater=False
spawnLava=False
underFill=False
randomRotation=True
dig=True
tree=False
branch=False
needsFoundation=True
rarity=100
collisionPercentage=20
spawnElevationMin=0
spawnElevationMax=200
spawnInBiome=Custom
[DATA]
0,-2,0:17.13
-2,-1,0:17.13
-1,-1,0:17.13
0,-1,0:17.13
1,-1,0:17.13
-1,0,0:17.13
0,0,0:17.13
0,1,0:17.13
-1,-1,1:17.13
0,-1,1:17.13
-1,0,1:17.13
0,0,1:17.13
-1,-1,2:17.13
0,-1,2:17.13
-1,0,2:17.13
0,0,2:17.13
-1,-1,3:17.13
0,-1,3:17.13
-1,0,3:17.13
0,0,3:17.13
-4,-6,4:18.13
-1,-6,4:18.13
0,-6,4:188.0
1,-6,4:18.13
3,-6,4:18.13
-5,-5,4:18.13
-4,-5,4:188.0
-3,-5,4:18.13
-1,-5,4:18.13
0,-5,4:17.13
1,-5,4:18.13
2,-5,4:18.13
3,-5,4:188.0
4,-5,4:18.13
-4,-4,4:18.13
-3,-4,4:188.0
0,-4,4:17.13
1,-4,4:18.13
2,-4,4:188.0
3,-4,4:18.13
4,-4,4:18.13
-6,-2,4:18.13
-5,-2,4:18.13
-4,-2,4:18.13
-6,-1,4:188.0
-5,-1,4:17.13
-4,-1,4:17.13
-1,-1,4:17.13
0,-1,4:17.13
3,-1,4:18.13
4,-1,4:18.13
5,-1,4:18.13
-6,0,4:18.13
-5,0,4:18.13
-4,0,4:18.13
-1,0,4:17.13
0,0,4:17.13
3,0,4:17.13
4,0,4:17.13
5,0,4:188.0
-5,1,4:18.13
-4,1,4:18.13
3,1,4:18.13
4,1,4:18.13
5,1,4:18.13
-5,3,4:18.13
-4,3,4:17.13
-3,3,4:18.13
-1,3,4:18.13
0,3,4:17.13
1,3,4:18.13
-6,4,4:18.13
-5,4,4:17.13
-4,4,4:18.13
-1,4,4:18.13
0,4,4:17.13
1,4,4:18.13
-5,5,4:18.5
-1,5,4:18.13
0,5,4:188.0
1,5,4:18.13
-5,-7,5:18.13
-2,-7,5:18.13
-1,-7,5:18.13
0,-7,5:188.0
1,-7,5:18.13
4,-7,5:18.13
-6,-6,5:18.13
-5,-6,5:188.0
-4,-6,5:18.13
-3,-6,5:18.13
-2,-6,5:18.13
-1,-6,5:18.13
0,-6,5:18.13
2,-6,5:18.13
3,-6,5:18.13
4,-6,5:188.0
5,-6,5:18.13
-5,-5,5:18.13
-4,-5,5:18.13
-3,-5,5:18.13
0,-5,5:18.13
3,-5,5:18.13
4,-5,5:18.13
5,-5,5:18.13
-5,-4,5:18.13
-4,-4,5:18.13
-3,-4,5:18.13
-2,-4,5:18.13
-1,-4,5:18.13
0,-4,5:18.13
1,-4,5:18.13
2,-4,5:18.13
5,-4,5:18.13
-6,-3,5:18.13
-5,-3,5:18.13
-4,-3,5:18.13
-3,-3,5:18.13
-2,-3,5:17.13
-1,-3,5:18.13
0,-3,5:17.13
1,-3,5:17.13
2,-3,5:18.13
3,-3,5:18.13
-7,-2,5:18.13
-3,-2,5:18.13
-2,-2,5:18.13
-1,-2,5:17.13
0,-2,5:17.13
1,-2,5:18.13
4,-2,5:18.13
-7,-1,5:188.0
-6,-1,5:18.13
-5,-1,5:18.13
-4,-1,5:18.13
-3,-1,5:17.13
-2,-1,5:17.13
-1,-1,5:17.13
0,-1,5:17.13
1,-1,5:18.13
2,-1,5:18.13
3,-1,5:18.13
4,-1,5:18.13
6,-1,5:18.13
-7,0,5:18.13
-3,0,5:18.13
-2,0,5:18.13
-1,0,5:17.13
0,0,5:17.13
1,0,5:17.13
2,0,5:17.13
3,0,5:18.13
4,0,5:18.13
5,0,5:18.13
6,0,5:188.0
-6,1,5:18.13
-5,1,5:18.13
-3,1,5:18.13
-2,1,5:17.13
-1,1,5:18.13
0,1,5:17.13
6,1,5:18.13
-5,2,5:18.13
-4,2,5:18.13
-3,2,5:17.13
-2,2,5:18.13
-1,2,5:18.13
0,2,5:17.13
1,2,5:18.13
2,2,5:18.13
4,2,5:18.13
5,2,5:18.13
-6,3,5:18.13
-5,3,5:18.13
-4,3,5:18.13
-3,3,5:18.13
-2,3,5:18.13
0,3,5:18.13
1,3,5:18.13
3,3,5:188.0
4,3,5:18.13
-6,4,5:18.13
-5,4,5:18.13
-3,4,5:18.13
-2,4,5:18.13
0,4,5:18.13
1,4,5:18.13
2,4,5:18.13
3,4,5:18.13
4,4,5:188.0
5,4,5:18.13
-7,5,5:18.13
-6,5,5:17.13
-5,5,5:18.13
0,5,5:18.13
2,5,5:18.13
4,5,5:18.13
-6,6,5:18.13
-1,6,5:18.13
0,6,5:188.0
1,6,5:18.13
0,-9,6:18.2
-6,-8,6:18.13
-1,-8,6:18.13
0,-8,6:188.0
1,-8,6:18.13
5,-8,6:18.13
-7,-7,6:18.13
-6,-7,6:188.0
-5,-7,6:18.13
-1,-7,6:18.13
0,-7,6:18.13
2,-7,6:18.13
4,-7,6:18.13
5,-7,6:188.0
6,-7,6:18.13
-6,-6,6:18.13
-5,-6,6:18.13
-3,-6,6:18.13
4,-6,6:18.13
5,-6,6:18.13
6,-6,6:18.13
3,-5,6:18.13
-5,-4,6:18.13
-3,-4,6:18.13
1,-4,6:18.13
2,-4,6:18.13
-4,-3,6:18.13
-2,-3,6:18.13
0,-3,6:18.13
1,-3,6:18.13
2,-3,6:18.13
4,-3,6:18.13
-8,-2,6:18.13
-6,-2,6:18.13
-1,-2,6:18.13
0,-2,6:18.13
2,-2,6:18.13
4,-2,6:18.13
5,-2,6:18.13
-9,-1,6:18.13
-8,-1,6:188.0
-7,-1,6:18.13
-5,-1,6:18.13
-3,-1,6:18.13
-2,-1,6:18.13
-1,-1,6:17.13
0,-1,6:17.13
3,-1,6:18.13
4,-1,6:18.13
7,-1,6:18.13
-8,0,6:18.13
-2,0,6:18.13
-1,0,6:17.13
0,0,6:17.13
1,0,6:18.13
2,0,6:18.13
4,0,6:18.13
6,0,6:18.13
7,0,6:188.0
8,0,6:18.13
-2,1,6:18.13
0,1,6:18.13
1,1,6:17.13
2,1,6:18.13
7,1,6:18.13
-6,2,6:18.13
-3,2,6:18.13
0,2,6:18.13
1,2,6:18.13
2,2,6:17.13
3,2,6:18.13
4,2,6:18.13
5,2,6:18.13
-6,3,6:18.13
1,3,6:18.13
2,3,6:18.13
3,3,6:18.13
5,3,6:18.13
-4,4,6:18.13
-3,4,6:18.13
-2,4,6:18.13
4,4,6:18.13
5,4,6:18.13
-7,5,6:18.13
-6,5,6:18.13
-3,5,6:18.13
-2,5,6:18.13
2,5,6:18.13
3,5,6:18.13
4,5,6:18.13
5,5,6:188.0
6,5,6:18.13
-8,6,6:18.13
-7,6,6:17.13
-6,6,6:18.5
-5,6,6:18.13
0,6,6:18.13
5,6,6:18.13
-7,7,6:18.13
-1,7,6:18.13
0,7,6:188.0
1,7,6:18.13
0,8,6:18.13
-7,-8,7:18.13
0,-8,7:18.13
6,-8,7:18.13
-6,-7,7:18.13
5,-7,7:18.13
0,-5,7:18.13
-3,-4,7:18.13
2,-4,7:18.13
3,-4,7:18.13
-4,-3,7:18.13
2,-3,7:18.13
-8,-1,7:18.13
-1,-1,7:17.13
0,-1,7:17.13
-2,0,7:18.13
-1,0,7:17.13
0,0,7:17.13
1,0,7:18.13
2,0,7:18.13
7,0,7:18.13
1,1,7:18.13
-3,2,7:18.13
2,2,7:18.13
-3,5,7:18.13
5,5,7:18.13
-7,6,7:18.13
6,6,7:18.13
-8,7,7:18.13
0,7,7:18.13
2,-6,8:18.13
-4,-5,8:18.13
0,-5,8:18.13
1,-5,8:17.13
2,-5,8:18.13
-5,-4,8:18.13
-4,-4,8:17.13
-3,-4,8:18.13
0,-4,8:18.13
1,-4,8:17.13
2,-4,8:18.13
-4,-3,8:18.13
-3,-3,8:17.13
-2,-3,8:18.13
1,-3,8:18.13
3,-3,8:18.13
4,-3,8:18.13
-3,-2,8:18.13
3,-2,8:17.13
4,-2,8:17.13
5,-2,8:18.13
-1,-1,8:17.13
0,-1,8:17.13
1,-1,8:18.13
2,-1,8:18.13
4,-1,8:18.13
-1,0,8:17.13
0,0,8:17.13
-3,1,8:18.13
3,1,8:18.13
4,1,8:18.13
-4,2,8:18.13
-3,2,8:17.13
-2,2,8:18.13
3,2,8:17.13
4,2,8:188.0
-4,3,8:18.13
-3,3,8:17.13
-2,3,8:18.13
-1,3,8:18.13
0,3,8:17.13
1,3,8:18.13
3,3,8:18.13
4,3,8:18.13
-4,4,8:18.13
-3,4,8:17.13
-2,4,8:18.13
0,4,8:18.13
1,4,8:17.13
2,4,8:18.13
-3,5,8:18.13
0,5,8:18.13
1,5,8:17.13
2,5,8:18.13
1,6,8:18.13
-5,-6,9:18.13
0,-6,9:18.13
1,-6,9:17.13
2,-6,9:18.13
-6,-5,9:18.13
-5,-5,9:17.13
-4,-5,9:18.13
-3,-5,9:18.13
-1,-5,9:18.13
1,-5,9:18.13
3,-5,9:18.13
-5,-4,9:18.13
-4,-4,9:18.13
-2,-4,9:18.13
0,-4,9:18.13
1,-4,9:18.13
2,-4,9:18.13
5,-4,9:18.13
-5,-3,9:18.13
-3,-3,9:18.13
-2,-3,9:18.13
-1,-3,9:18.13
0,-3,9:17.13
1,-3,9:18.13
4,-3,9:18.13
5,-3,9:17.13
6,-3,9:18.13
-4,-2,9:18.13
-3,-2,9:18.13
-2,-2,9:17.13
-1,-2,9:18.13
0,-2,9:17.13
1,-2,9:18.13
2,-2,9:18.13
3,-2,9:18.13
4,-2,9:18.13
5,-2,9:18.13
-2,-1,9:18.13
-1,-1,9:17.13
0,-1,9:17.13
1,-1,9:17.13
2,-1,9:17.13
3,-1,9:18.13
-2,0,9:18.13
-1,0,9:17.13
0,0,9:17.13
2,0,9:18.13
3,0,9:18.13
-3,1,9:18.13
-2,1,9:17.13
-1,1,9:18.13
0,1,9:17.13
1,1,9:17.13
2,1,9:17.13
3,1,9:18.13
5,1,9:18.13
-3,2,9:18.13
-2,2,9:18.13
-1,2,9:18.13
0,2,9:17.13
1,2,9:18.13
2,2,9:18.13
3,2,9:18.13
4,2,9:18.13
5,2,9:18.13
-5,3,9:18.13
-3,3,9:18.13
-2,3,9:18.13
-1,3,9:18.13
0,3,9:18.13
4,3,9:18.13
5,3,9:188.0
-4,4,9:18.13
-3,4,9:18.13
-1,4,9:18.13
1,4,9:18.13
5,4,9:18.13
-5,5,9:18.13
-4,5,9:17.13
-3,5,9:18.13
-2,5,9:18.13
1,5,9:18.13
2,5,9:18.13
-4,6,9:18.13
1,6,9:18.13
2,6,9:188.0
3,6,9:18.13
2,7,9:18.13
1,-8,10:18.13
-6,-7,10:18.13
0,-7,10:18.13
1,-7,10:17.13
2,-7,10:18.13
-7,-6,10:18.13
-6,-6,10:17.13
-5,-6,10:18.13
1,-6,10:18.13
-6,-5,10:18.13
-5,-5,10:18.13
6,-5,10:18.13
4,-4,10:18.13
5,-4,10:18.13
6,-4,10:17.13
7,-4,10:18.13
0,-3,10:18.13
3,-3,10:18.13
5,-3,10:18.13
6,-3,10:18.13
-2,-2,10:18.13
0,-2,10:18.13
6,-2,10:18.13
-4,-1,10:18.13
-1,-1,10:17.13
0,-1,10:17.13
1,-1,10:18.13
2,-1,10:18.13
5,-1,10:18.13
-1,0,10:17.13
0,0,10:17.13
4,0,10:18.13
-4,1,10:18.13
-2,1,10:18.13
1,1,10:18.13
2,1,10:18.13
-2,2,10:18.13
0,2,10:18.13
6,2,10:18.13
-3,3,10:18.13
0,3,10:18.13
3,3,10:18.13
5,3,10:18.13
6,3,10:188.0
7,3,10:18.13
0,4,10:18.13
4,4,10:18.13
6,4,10:18.13
-4,5,10:18.13
-5,6,10:18.13
2,6,10:18.13
3,7,10:18.13
-7,-7,11:18.13
1,-7,11:18.13
-6,-6,11:18.13
7,-5,11:18.13
6,-4,11:18.13
3,-3,11:18.13
-4,-2,11:18.13
3,-2,11:18.13
-1,-1,11:17.13
0,-1,11:17.13
-3,0,11:18.13
-1,0,11:17.13
0,0,11:17.13
-2,1,11:18.13
0,1,11:18.13
4,1,11:18.13
0,2,11:18.13
2,2,11:18.13
6,3,11:18.13
3,-4,12:18.13
2,-3,12:18.13
3,-3,12:17.13
4,-3,12:18.13
-5,-2,12:18.13
-4,-2,12:18.13
-3,-2,12:18.13
2,-2,12:17.13
3,-2,12:18.13
-5,-1,12:188.0
-4,-1,12:17.13
-3,-1,12:17.13
-1,-1,12:17.13
0,-1,12:17.13
2,-1,12:18.13
3,-1,12:18.13
4,-1,12:18.13
6,-1,12:18.13
-5,0,12:18.13
-4,0,12:18.13
-3,0,12:18.13
-1,0,12:17.13
0,0,12:17.13
2,0,12:17.13
3,0,12:17.13
4,0,12:188.0
-4,1,12:18.13
-3,1,12:188.0
-2,1,12:18.13
-1,1,12:18.13
2,1,12:18.13
3,1,12:18.13
4,1,12:18.13
-5,2,12:18.13
-4,2,12:188.0
-3,2,12:18.13
-4,3,12:18.13
-1,3,12:188.0
1,3,12:18.13
-3,-5,13:18.13
-1,-5,13:18.13
0,-5,13:188.0
1,-5,13:18.13
4,-5,13:18.13
-4,-4,13:18.13
-3,-4,13:188.0
-2,-4,13:18.13
-1,-4,13:18.13
0,-4,13:17.13
1,-4,13:18.13
3,-4,13:18.13
4,-4,13:17.13
5,-4,13:18.13
-4,-3,13:18.13
-3,-3,13:18.13
-2,-3,13:17.13
-1,-3,13:18.13
0,-3,13:17.13
1,-3,13:18.13
3,-3,13:18.13
4,-3,13:18.13
-6,-2,13:18.13
-3,-2,13:18.13
-2,-2,13:18.13
1,-2,13:18.13
2,-2,13:18.13
4,-2,13:18.13
-7,-1,13:18.13
-6,-1,13:188.0
-5,-1,13:18.13
-4,-1,13:18.13
-3,-1,13:18.13
-2,-1,13:17.13
-1,-1,13:17.13
1,-1,13:17.13
2,-1,13:18.13
5,-1,13:18.13
6,-1,13:18.13
-6,0,13:18.13
-3,0,13:18.13
-2,0,13:17.13
-1,0,13:17.13
0,0,13:17.13
1,0,13:17.13
2,0,13:18.13
3,0,13:18.13
4,0,13:18.13
5,0,13:188.0
6,0,13:18.13
-5,1,13:18.13
-3,1,13:18.13
-2,1,13:18.13
2,1,13:18.13
5,1,13:18.13
-5,2,13:18.13
-4,2,13:18.13
-2,2,13:18.13
-1,2,13:17.13
0,2,13:18.13
1,2,13:18.13
2,2,13:188.0
3,2,13:18.13
-6,3,13:18.13
-5,3,13:188.0
-4,3,13:18.13
-2,3,13:18.13
-1,3,13:17.13
0,3,13:18.13
2,3,13:18.13
3,3,13:188.0
4,3,13:18.13
-5,4,13:18.13
-2,4,13:18.13
-1,4,13:188.0
0,4,13:18.13
3,4,13:18.13
0,-7,14:18.13
-4,-6,14:18.13
-1,-6,14:18.13
0,-6,14:188.0
1,-6,14:18.13
-5,-5,14:18.13
-4,-5,14:188.0
-3,-5,14:18.13
-2,-5,14:18.13
0,-5,14:18.13
5,-5,14:18.13
-4,-4,14:18.13
-3,-4,14:18.13
0,-4,14:18.13
2,-4,14:18.13
4,-4,14:18.13
-2,-3,14:18.13
-1,-3,14:18.13
0,-3,14:18.13
1,-3,14:18.13
2,-3,14:18.13
-1,-2,14:17.13
0,-2,14:17.13
1,-2,14:18.13
-6,-1,14:18.13
-2,-1,14:18.13
-1,-1,14:17.13
1,-1,14:18.13
-2,0,14:18.13
-1,0,14:17.13
0,0,14:17.13
1,0,14:18.13
5,0,14:18.13
-2,1,14:18.13
-1,1,14:17.13
0,1,14:18.13
1,1,14:17.13
2,1,14:18.13
3,1,14:18.13
-1,2,14:18.13
1,2,14:18.13
2,2,14:18.13
4,2,14:18.13
-5,3,14:18.13
-3,3,14:18.13
-1,3,14:18.13
1,3,14:18.13
3,3,14:18.13
4,3,14:18.13
-6,4,14:18.13
-3,4,14:18.13
-1,4,14:18.13
3,4,14:18.13
4,4,14:188.0
5,4,14:18.13
-2,5,14:18.13
-1,5,14:188.0
0,5,14:18.13
4,5,14:18.13
-1,6,14:18.13
-5,-6,15:18.13
0,-6,15:18.13
-4,-5,15:18.13
-3,-3,15:18.13
-1,-2,15:18.13
0,-2,15:18.13
-1,-1,15:17.13
-1,0,15:17.13
0,0,15:17.13
1,0,15:18.13
-1,1,15:18.13
1,1,15:18.13
-2,2,15:18.13
4,4,15:18.13
-1,5,15:18.13
5,5,15:18.13
-4,-4,16:18.13
-5,-3,16:18.13
-4,-3,16:188.0
-3,-3,16:18.13
-4,-2,16:18.13
-3,-2,16:188.0
3,-2,16:18.13
-1,-1,16:17.13
-1,0,16:17.13
0,0,16:17.13
-2,2,16:18.13
-1,2,16:17.13
0,2,16:18.13
-2,3,16:18.13
-1,3,16:188.0
0,3,16:18.13
1,3,16:18.13
-5,-5,17:18.13
-6,-4,17:18.13
-5,-4,17:188.0
-4,-4,17:18.13
-3,-4,17:18.13
0,-4,17:18.13
-5,-3,17:18.13
-4,-3,17:18.13
-2,-3,17:18.13
-1,-3,17:18.13
0,-3,17:17.13
1,-3,17:18.13
-3,-2,17:18.13
-2,-2,17:18.13
-1,-2,17:18.13
0,-2,17:17.13
2,-2,17:18.13
3,-2,17:18.13
-4,-1,17:18.13
-3,-1,17:18.13
-2,-1,17:17.13
-1,-1,17:18.13
1,-1,17:18.13
2,-1,17:17.13
3,-1,17:188.0
4,-1,17:18.13
-4,0,17:18.13
-3,0,17:188.0
-1,0,17:17.13
0,0,17:17.13
2,0,17:18.13
3,0,17:18.13
-5,1,17:18.13
-4,1,17:188.0
-3,1,17:18.13
-1,1,17:17.13
0,1,17:18.13
2,1,17:18.13
-4,2,17:18.13
-1,2,17:18.13
1,2,17:17.13
2,2,17:188.0
3,2,17:18.13
-1,3,17:18.13
1,3,17:18.13
2,3,17:18.13
-2,4,17:18.13
-1,4,17:188.0
0,4,17:18.13
-1,5,17:18.13
-6,-5,18:18.13
1,-5,18:18.13
-5,-4,18:18.13
-1,-4,18:18.13
0,-4,18:18.13
1,-4,18:188.0
2,-4,18:18.13
0,-3,18:18.13
1,-3,18:18.13
3,-3,18:18.13
4,-3,18:18.13
0,-2,18:18.13
1,-2,18:18.13
3,-2,18:18.13
4,-2,18:188.0
5,-2,18:18.13
-2,-1,18:18.13
0,-1,18:17.13
1,-1,18:18.13
2,-1,18:18.13
3,-1,18:18.13
4,-1,18:18.13
-4,0,18:18.13
-3,0,18:18.13
-2,0,18:17.13
-1,0,18:17.13
0,0,18:17.13
1,0,18:17.13
2,0,18:18.13
4,0,18:18.13
-5,1,18:18.13
-4,1,18:18.13
-2,1,18:18.13
-1,1,18:18.13
0,1,18:17.13
1,1,18:18.13
3,1,18:18.13
-6,2,18:18.13
-5,2,18:188.0
-4,2,18:18.13
-3,2,18:18.13
0,2,18:18.13
1,2,18:18.13
2,2,18:18.13
-5,3,18:18.13
-4,3,18:18.13
-3,3,18:18.13
2,3,18:18.13
3,3,18:188.0
4,3,18:18.13
-1,4,18:18.13
1,4,18:18.13
3,4,18:18.13
2,-5,19:18.13
1,-4,19:18.13
5,-3,19:18.13
4,-2,19:18.13
0,-1,19:18.13
-2,0,19:18.13
-1,0,19:17.13
0,0,19:17.13
1,0,19:18.13
0,1,19:18.13
-5,2,19:18.13
0,2,19:18.13
-6,3,19:18.13
1,3,19:18.13
3,3,19:18.13
4,4,19:18.13
-1,-3,20:18.13
-1,-2,20:18.13
2,-1,20:18.13
-1,0,20:17.13
0,0,20:17.13
2,0,20:18.13
-3,1,20:18.13
2,1,20:18.13
3,1,20:18.13
-4,2,20:18.13
-3,2,20:18.13
-2,2,20:18.13
0,2,20:18.13
1,2,20:18.13
-3,3,20:18.13
-2,3,20:18.13
0,3,20:18.13
1,3,20:18.13
2,3,20:18.13
1,4,20:18.13
-1,-4,21:18.13
0,-4,21:18.13
-1,-3,21:18.13
1,-3,21:18.13
-4,-2,21:18.13
-1,-2,21:18.13
0,-2,21:18.13
-5,-1,21:18.13
-4,-1,21:18.13
-3,-1,21:18.13
1,-1,21:18.13
2,-1,21:18.13
3,-1,21:18.13
-4,0,21:18.13
-3,0,21:18.13
-2,0,21:18.13
-1,0,21:17.13
0,0,21:18.13
1,0,21:18.13
2,0,21:18.13
3,0,21:18.13
4,0,21:18.13
-2,1,21:18.13
-1,1,21:18.13
0,1,21:18.13
2,1,21:18.13
3,1,21:18.13
-2,2,21:18.13
0,2,21:18.13
-4,3,21:18.13
2,4,21:18.13
0,-5,22:18.13
-1,-3,22:18.13
-5,-2,22:18.13
-2,-2,22:18.13
-1,-2,22:18.13
0,-2,22:18.13
-1,-1,22:18.13
0,-1,22:18.13
-2,0,22:18.13
-1,0,22:17.13
0,0,22:18.13
4,0,22:18.13
-1,-1,23:18.13
1,-1,23:18.13
-1,0,23:17.13
-3,1,23:18.13
0,1,23:18.5
1,1,23:18.5
-3,2,23:18.13
0,2,23:18.5
-2,-2,24:18.13
-2,-1,24:18.13
-1,-1,24:18.5
0,-1,24:18.13
-3,0,24:18.13
-2,0,24:18.13
-1,0,24:17.13
0,0,24:18.13
1,0,24:18.5
-2,1,24:18.13
-1,1,24:18.5
0,1,24:18.5
-1,2,24:18.5
-1,-2,25:18.13
-2,-1,25:18.13
-1,-1,25:18.5
-2,0,25:18.13
-1,0,25:17.13
0,0,25:18.13
-1,1,25:18.5
-1,-1,26:18.5
-2,0,26:18.13
-1,0,26:17.13
0,0,26:18.5
-1,1,26:18.5
-1,0,27:18.13
