[META]
version=2.0
spawnOnBlockType=2
spawnSunlight=True
spawnDarkness=True
spawnWater=False
spawnLava=False
underFill=False
randomRotation=True
dig=True
tree=True
branch=False
needsFoundation=True
rarity=100
collisionPercentage=20
spawnElevationMin=0
spawnElevationMax=200
spawnInBiome=Custom
[DATA]
0,0,0:17.13
-1,1,0:17.13
-1,0,1:162.13
-1,1,1:17.13
-1,0,2:17.13
-1,0,3:17.13
1,-3,4:18.13
0,-1,4:17.13
-2,0,4:143.2
-1,0,4:17.13
2,-5,5:18.13
1,-4,5:18.13
1,-3,5:162.13
4,-3,5:18.13
0,-2,5:17.13
3,-2,5:18.13
4,-2,5:18.13
-5,-1,5:18.13
-4,-1,5:18.13
3,-1,5:18.13
-3,0,5:162.13
-2,0,5:17.13
-1,0,5:17.13
0,0,5:17.13
2,-5,6:162.13
1,-4,6:17.13
1,-3,6:18.13
5,-3,6:18.13
6,-3,6:18.13
3,-2,6:17.13
4,-2,6:17.13
-6,-1,6:18.13
-5,-1,6:17.13
-4,-1,6:162.13
-1,-1,6:18.13
1,-1,6:162.13
2,-1,6:17.13
3,-1,6:17.13
-3,0,6:17.13
-1,0,6:17.13
4,0,6:18.5
5,0,6:18.5
6,0,6:18.5
-1,1,6:17.13
0,1,6:17.13
1,1,6:162.13
4,1,6:18.13
-3,2,6:18.13
0,2,6:17.13
2,2,6:18.13
3,2,6:18.13
0,3,6:18.13
1,4,6:18.13
2,-5,7:18.13
1,-4,7:18.13
-1,-3,7:18.13
5,-3,7:17.13
6,-3,7:162.13
-1,-2,7:17.13
3,-2,7:18.13
4,-2,7:18.13
-6,-1,7:17.13
-5,-1,7:18.13
-4,-1,7:18.13
-1,-1,7:162.13
3,-1,7:18.5
-1,0,7:162.13
4,0,7:17.13
5,0,7:162.13
6,0,7:162.13
-4,2,7:18.13
2,2,7:17.13
3,2,7:162.13
0,3,7:17.13
4,3,7:18.13
5,3,7:18.13
1,4,7:17.13
1,5,7:18.13
-1,-5,8:18.13
-1,-4,8:18.13
-4,-3,8:18.13
-1,-3,8:17.13
5,-3,8:18.13
6,-3,8:18.13
-3,-2,8:18.13
-2,-2,8:17.13
-6,-1,8:18.13
-3,-1,8:191.0
-2,0,8:17.13
-1,0,8:17.13
4,0,8:18.5
5,0,8:18.13
6,0,8:18.5
-4,1,8:18.13
-3,1,8:162.13
1,1,8:18.13
-5,2,8:18.13
-3,2,8:18.13
2,2,8:18.13
3,2,8:18.13
0,3,8:18.13
4,3,8:17.13
5,3,8:17.13
1,4,8:18.13
1,5,8:17.13
-1,-6,9:18.13
-1,-5,9:17.13
4,-5,9:18.13
-1,-4,9:17.13
3,-4,9:18.13
-5,-3,9:18.13
-4,-3,9:17.13
-1,-3,9:18.13
2,-3,9:18.13
3,-3,9:18.13
-3,-2,9:17.13
1,-2,9:162.13
-1,-1,9:18.13
0,-1,9:162.13
2,-1,9:18.13
-1,0,9:162.13
0,0,9:17.13
1,0,9:162.13
2,0,9:162.13
3,0,9:18.13
4,0,9:18.13
-4,1,9:17.13
-2,1,9:162.13
-1,1,9:18.13
2,1,9:18.13
-6,2,9:18.13
-5,2,9:17.13
-3,2,9:162.13
0,2,9:18.13
-3,3,9:18.13
4,3,9:18.13
5,3,9:18.13
-3,4,9:18.13
1,5,9:18.13
-1,-6,10:17.13
-1,-5,10:18.13
4,-5,10:162.13
-1,-4,10:18.13
3,-4,10:162.13
-5,-3,10:17.13
-4,-3,10:18.13
2,-3,10:162.13
-4,-2,10:191.0
-3,-2,10:18.13
-1,0,10:17.13
0,0,10:191.0
2,0,10:17.13
3,0,10:162.13
4,0,10:162.13
5,0,10:18.13
6,0,10:18.13
-4,1,10:18.13
2,1,10:191.0
-6,2,10:17.13
-5,2,10:18.13
-3,2,10:18.13
4,2,10:18.13
5,2,10:191.0
-3,3,10:17.13
-1,3,10:191.0
-3,4,10:17.13
-1,-6,11:18.13
4,-5,11:18.13
3,-4,11:18.13
-5,-3,11:18.13
1,-3,11:18.13
2,-3,11:18.13
-3,-1,11:18.13
2,-1,11:191.0
4,-1,11:18.13
-1,0,11:162.13
3,0,11:18.13
4,0,11:18.13
5,0,11:162.13
6,0,11:162.13
-1,1,11:162.13
2,1,11:18.13
-6,2,11:18.13
-3,3,11:18.13
-3,4,11:18.13
0,-5,12:18.13
1,-5,12:18.13
1,-4,12:18.13
-2,-3,12:18.13
-1,-3,12:18.13
0,-3,12:162.13
0,-2,12:162.13
3,-2,12:18.13
-4,-1,12:18.13
-2,-1,12:191.0
-1,-1,12:162.13
2,-1,12:18.13
-3,0,12:18.13
-2,0,12:162.13
-1,0,12:17.13
2,0,12:17.13
5,0,12:18.13
6,0,12:18.13
0,1,12:17.13
1,1,12:17.13
-2,2,12:162.13
2,2,12:18.13
-3,3,12:18.13
3,3,12:18.13
-3,-5,13:18.13
1,-5,13:162.13
-2,-4,13:18.13
1,-4,13:17.13
4,-4,13:18.13
-2,-3,13:162.13
0,-3,13:18.13
3,-3,13:18.13
-1,-2,13:17.13
3,-2,13:17.13
-5,-1,13:18.13
-4,-1,13:162.13
2,-1,13:162.13
4,-1,13:191.0
-3,0,13:162.13
-1,0,13:162.13
-1,1,13:143.3
-2,2,13:162.13
2,2,13:17.13
-3,3,13:18.13
3,3,13:162.13
4,3,13:18.13
-3,-5,14:17.13
1,-5,14:18.13
-2,-4,14:162.13
1,-4,14:18.13
4,-4,14:17.13
-2,-3,14:18.13
3,-3,14:162.13
3,-2,14:18.13
-5,-1,14:17.13
-4,-1,14:18.13
1,-1,14:191.0
-3,0,14:18.13
-1,0,14:17.13
0,0,14:17.13
2,0,14:18.13
0,1,14:17.13
3,1,14:191.0
-2,2,14:18.13
0,2,14:162.13
2,2,14:18.13
-3,3,14:17.13
1,3,14:18.13
3,3,14:18.13
4,3,14:162.13
1,4,14:18.13
1,-6,15:18.13
-3,-5,15:18.13
0,-5,15:18.13
-2,-4,15:18.13
0,-4,15:191.0
1,-4,15:18.13
2,-4,15:18.13
4,-4,15:18.13
-1,-3,15:191.0
3,-3,15:18.13
-5,-1,15:18.13
-1,-1,15:143.4
3,-1,15:18.13
-3,0,15:18.13
-1,0,15:162.13
1,0,15:17.13
2,0,15:162.13
3,0,15:18.13
4,0,15:18.13
-2,1,15:18.13
2,1,15:18.13
0,2,15:18.13
-3,3,15:18.13
1,3,15:17.13
4,3,15:18.13
1,4,15:17.13
-1,-4,16:18.13
-1,-3,16:18.13
1,-3,16:18.13
2,-3,16:191.0
-3,-2,16:18.13
-1,-2,16:191.0
1,-2,16:18.13
-2,-1,16:162.13
-1,-1,16:162.13
0,-1,16:17.13
-1,0,16:17.13
0,0,16:191.0
2,0,16:18.13
3,0,16:17.13
4,0,16:162.13
-3,1,16:18.13
-1,1,16:191.0
0,1,16:191.0
-3,2,16:191.0
0,2,16:191.0
0,3,16:191.0
1,3,16:18.13
1,4,16:18.13
-1,-4,17:191.0
-4,-3,17:18.13
-2,-3,17:191.0
-1,-3,17:191.0
2,-3,17:18.13
-3,-2,17:17.13
-1,-2,17:191.0
1,-2,17:17.13
-2,-1,17:162.13
-2,0,17:18.13
-1,0,17:17.13
0,0,17:143.1
3,0,17:18.13
4,0,17:18.13
-3,1,17:17.13
-2,1,17:17.13
-1,1,17:18.13
0,1,17:18.13
-4,2,17:18.13
-3,2,17:191.0
-2,2,17:18.13
0,2,17:191.0
1,2,17:191.0
2,2,17:18.13
0,3,17:18.13
-1,-4,18:18.13
-4,-3,18:17.13
-1,-3,18:18.13
2,-3,18:162.13
-3,-2,18:18.13
1,-2,18:18.13
-1,0,18:162.13
-3,1,18:18.13
-1,1,18:17.13
1,1,18:18.13
-4,2,18:162.13
-1,2,18:17.13
1,2,18:18.13
2,2,18:191.0
-1,3,18:18.13
2,3,18:191.0
3,3,18:18.13
-1,4,18:18.13
-4,-3,19:18.13
1,-3,19:18.13
2,-3,19:18.13
2,-1,19:18.13
-2,0,19:143.2
-1,0,19:162.13
0,0,19:162.13
-4,2,19:18.13
-1,2,19:18.13
2,2,19:18.13
-1,3,19:17.13
2,3,19:191.0
3,3,19:191.0
-1,4,19:162.13
-1,-2,20:18.13
-1,-1,20:18.13
2,-1,20:162.13
3,-1,20:18.13
-1,0,20:162.13
1,0,20:162.13
2,2,20:18.13
-1,3,20:18.13
3,3,20:18.13
-1,4,20:18.13
-2,-3,21:18.13
-1,-3,21:18.13
-1,-2,21:162.13
-3,-1,21:18.13
-1,-1,21:162.13
2,-1,21:18.13
3,-1,21:17.13
-1,0,21:17.13
1,0,21:18.13
-2,1,21:18.13
0,1,21:17.13
-2,-3,22:162.13
-1,-2,22:18.13
-4,-1,22:18.13
-3,-1,22:162.13
-1,-1,22:18.13
0,-1,22:18.13
3,-1,22:18.13
-2,0,22:17.13
-1,0,22:17.13
-2,1,22:162.13
0,1,22:162.13
-3,2,22:18.13
1,2,22:18.13
-2,-3,23:18.13
-4,-1,23:162.13
-3,-1,23:18.13
-1,0,23:162.13
-2,1,23:18.13
-1,1,23:191.0
0,1,23:18.13
-3,2,23:17.13
0,2,23:18.13
1,2,23:162.13
-4,-1,24:18.13
-1,-1,24:18.13
-1,0,24:162.13
-3,2,24:18.13
1,2,24:18.13
-1,-2,25:18.13
-3,-1,25:18.13
-2,0,25:18.13
-1,0,25:18.13
0,1,25:18.13
