[META]
version=2.0
spawnOnBlockType=2
spawnSunlight=True
spawnDarkness=True
spawnWater=False
spawnLava=False
underFill=False
randomRotation=True
dig=True
tree=True
branch=False
needsFoundation=True
rarity=100
collisionPercentage=20
spawnElevationMin=0
spawnElevationMax=200
spawnInBiome=Custom
[DATA]
0,-2,0:17.13
2,-2,0:17.13
2,0,0:162.13
0,-2,1:17.13
1,-1,1:162.13
2,0,1:162.13
1,-1,2:162.13
1,-1,3:162.13
1,-1,4:162.13
1,0,4:143.3
-4,-6,5:18.13
-3,-5,5:18.13
0,-5,5:18.13
-2,-4,5:18.13
-1,-4,5:162.13
0,-3,5:162.13
3,-3,5:18.5
1,-2,5:17.13
2,-2,5:17.13
4,-2,5:18.5
-2,-1,5:18.5
0,-1,5:162.13
1,-1,5:162.13
-4,0,5:18.13
-3,0,5:18.13
0,-7,6:18.13
-4,-6,6:17.13
-1,-6,6:18.5
0,-6,6:18.13
3,-6,6:191.0
4,-6,6:18.13
-3,-5,6:17.13
0,-5,6:162.13
2,-5,6:162.13
3,-5,6:18.13
-2,-4,6:162.13
1,-4,6:17.13
0,-3,6:191.0
1,-3,6:162.13
3,-3,6:191.0
4,-3,6:18.5
3,-2,6:17.13
4,-2,6:17.13
5,-2,6:18.13
6,-2,6:18.13
-2,-1,6:162.13
-1,-1,6:17.13
1,-1,6:17.13
3,-1,6:17.13
-6,0,6:18.13
-5,0,6:18.13
-4,0,6:162.13
-3,0,6:162.13
1,0,6:162.13
4,0,6:17.13
4,1,6:18.13
5,2,6:18.13
0,-7,7:17.13
6,-7,7:18.13
-4,-6,7:18.13
-2,-6,7:191.0
-1,-6,7:18.5
0,-6,7:17.13
2,-6,7:18.5
4,-6,7:17.13
5,-6,7:18.13
-3,-5,7:18.13
0,-5,7:18.13
3,-5,7:17.13
-2,-4,7:18.13
4,-2,7:17.13
5,-2,7:17.13
6,-2,7:162.13
7,-2,7:18.13
1,-1,7:162.13
-6,0,7:162.13
-5,0,7:17.13
-4,0,7:18.13
-3,0,7:18.13
0,0,7:17.13
-1,1,7:162.13
1,1,7:162.13
4,1,7:162.13
2,2,7:17.13
5,2,7:162.13
-3,3,7:18.13
1,3,7:18.13
2,3,7:162.13
6,3,7:18.13
2,4,7:18.13
2,5,7:18.13
0,-7,8:18.13
6,-7,8:162.13
0,-6,8:18.13
3,-6,8:18.5
4,-6,8:162.13
5,-6,8:17.13
3,-5,8:18.13
5,-4,8:18.5
3,-3,8:191.0
-3,-2,8:18.13
-1,-2,8:17.13
0,-2,8:162.13
5,-2,8:18.13
6,-2,8:18.13
7,-2,8:17.13
1,-1,8:162.13
-6,0,8:18.13
-5,0,8:18.13
3,0,8:18.5
-2,1,8:18.5
1,1,8:18.13
4,1,8:18.13
7,1,8:191.0
-2,2,8:162.13
4,2,8:191.0
5,2,8:18.13
-3,3,8:17.13
0,3,8:18.13
2,3,8:17.13
3,3,8:191.0
6,3,8:162.13
-4,4,8:18.13
2,4,8:17.13
2,5,8:17.13
6,-7,9:18.13
4,-6,9:18.13
5,-6,9:18.13
-2,-5,9:18.13
2,-5,9:191.0
6,-4,9:18.13
0,-3,9:17.13
4,-3,9:18.13
5,-3,9:18.13
-5,-2,9:18.13
-4,-2,9:18.13
-3,-2,9:162.13
-2,-2,9:17.13
-1,-2,9:162.13
2,-2,9:17.13
3,-2,9:162.13
7,-2,9:18.13
1,-1,9:162.13
4,-1,9:18.13
2,0,9:162.13
-2,2,9:18.13
3,2,9:18.13
-3,3,9:18.13
2,3,9:18.13
6,3,9:18.13
-4,4,9:17.13
1,4,9:191.0
2,4,9:18.13
3,4,9:18.5
2,5,9:18.13
-2,-6,10:18.13
-2,-5,10:162.13
1,-5,10:18.13
-1,-4,10:17.13
1,-4,10:18.13
4,-4,10:191.0
6,-4,10:17.13
1,-3,10:162.13
4,-3,10:162.13
5,-3,10:162.13
-5,-2,10:17.13
-4,-2,10:17.13
-3,-2,10:18.13
-2,-2,10:18.13
0,-2,10:18.5
1,-2,10:17.13
0,-1,10:162.13
1,-1,10:17.13
4,-1,10:162.13
5,-1,10:18.13
-3,0,10:18.13
-2,0,10:18.13
0,0,10:18.13
6,0,10:18.13
2,1,10:17.13
1,2,10:18.13
3,2,10:17.13
0,3,10:18.13
3,3,10:18.13
-4,4,10:18.13
1,-7,11:18.13
-2,-6,11:17.13
1,-6,11:18.13
-2,-5,11:18.13
1,-5,11:17.13
2,-5,11:191.0
-1,-4,11:18.13
1,-4,11:17.13
6,-4,11:18.13
4,-3,11:18.13
5,-3,11:18.13
-5,-2,11:18.13
-4,-2,11:18.13
-3,-2,11:191.0
0,-1,11:17.13
1,-1,11:162.13
4,-1,11:18.13
5,-1,11:162.13
-3,0,11:162.13
-2,0,11:162.13
-1,0,11:162.13
1,0,11:191.0
3,0,11:191.0
6,0,11:162.13
7,0,11:18.13
-5,1,11:18.13
-4,1,11:18.13
1,1,11:191.0
2,1,11:191.0
1,2,11:191.0
3,2,11:18.13
4,2,11:18.5
0,3,11:191.0
1,3,11:191.0
3,3,11:162.13
-1,4,11:18.13
0,4,11:191.0
4,4,11:18.13
1,-7,12:17.13
-2,-6,12:18.13
1,-6,12:17.13
1,-5,12:18.13
1,-4,12:18.13
-3,-3,12:18.13
-2,-3,12:18.5
5,-3,12:18.5
-3,-2,12:18.5
-2,-2,12:18.13
-1,-2,12:17.13
0,-1,12:162.13
1,-1,12:162.13
2,-1,12:143.1
5,-1,12:18.13
-3,0,12:18.13
-2,0,12:18.13
1,0,12:17.13
2,0,12:162.13
6,0,12:18.13
7,0,12:17.13
-5,1,12:17.13
-4,1,12:162.13
4,1,12:18.13
5,1,12:18.5
1,2,12:18.13
0,3,12:18.13
3,3,12:18.13
-1,4,12:191.0
0,4,12:191.0
4,4,12:17.13
1,-7,13:18.13
1,-6,13:18.13
0,-4,13:18.5
-4,-3,13:18.13
-3,-3,13:17.13
3,-3,13:18.5
4,-3,13:18.13
-2,-2,13:162.13
1,-2,13:143.4
2,-2,13:162.13
1,-1,13:162.13
7,0,13:18.13
-5,1,13:18.13
-4,1,13:18.13
-1,1,13:18.13
0,1,13:162.13
1,1,13:17.13
3,1,13:162.13
4,1,13:17.13
1,2,13:18.13
5,2,13:18.13
0,3,13:191.0
-1,4,13:18.13
4,4,13:18.13
0,-5,14:18.13
2,-5,14:18.13
0,-4,14:18.13
1,-4,14:191.0
2,-4,14:18.13
5,-4,14:18.13
-4,-3,14:17.13
-3,-3,14:18.13
1,-3,14:162.13
4,-3,14:17.13
-2,-2,14:18.13
1,-2,14:162.13
3,-2,14:17.13
5,-2,14:191.0
1,-1,14:162.13
-1,0,14:18.13
1,0,14:18.5
-1,1,14:162.13
1,1,14:18.13
3,1,14:18.13
4,1,14:18.13
-2,2,14:18.13
1,2,14:162.13
5,2,14:162.13
1,3,14:18.13
-1,-6,15:18.13
2,-6,15:18.13
0,-5,15:17.13
2,-5,15:162.13
0,-4,15:162.13
2,-4,15:17.13
5,-4,15:17.13
-4,-3,15:18.13
4,-3,15:18.13
-1,-1,15:191.0
1,-1,15:17.13
3,-1,15:18.13
-1,1,15:18.13
-3,2,15:18.13
-2,2,15:17.13
1,2,15:18.13
5,2,15:18.13
1,3,15:162.13
-1,-6,16:162.13
2,-6,16:162.13
0,-5,16:18.13
2,-5,16:18.13
0,-4,16:18.13
2,-4,16:18.13
5,-4,16:18.13
-1,-3,16:18.13
-1,-2,16:191.0
0,-2,16:191.0
3,-2,16:18.5
4,-2,16:18.13
5,-2,16:18.13
0,-1,16:191.0
1,-1,16:162.13
2,-1,16:162.13
3,-1,16:162.13
-2,0,16:18.5
2,0,16:162.13
3,0,16:18.13
4,1,16:18.13
-3,2,16:162.13
-2,2,16:18.13
1,3,16:18.13
-1,-6,17:18.13
2,-6,17:18.13
-2,-4,17:18.13
0,-4,17:18.5
-2,-3,17:191.0
-1,-3,17:191.0
0,-3,17:18.5
1,-3,17:18.13
-2,-2,17:18.5
-1,-2,17:191.0
4,-2,17:17.13
5,-2,17:17.13
1,-1,17:17.13
3,-1,17:18.13
1,0,17:17.13
2,0,17:191.0
3,0,17:191.0
1,1,17:17.13
3,1,17:191.0
4,1,17:191.0
5,1,17:18.13
-3,2,17:18.13
1,2,17:18.13
1,3,17:18.13
1,-5,18:18.13
-2,-4,18:191.0
1,-4,18:18.13
-2,-3,18:191.0
-1,-3,18:18.13
1,-3,18:162.13
1,-2,18:17.13
2,-2,18:18.13
4,-2,18:18.13
5,-2,18:18.13
0,-1,18:143.2
1,-1,18:17.13
0,0,18:18.5
3,0,18:18.13
1,1,18:18.13
4,1,18:18.13
5,1,18:191.0
1,2,18:162.13
1,3,18:17.13
1,-5,19:162.13
-2,-4,19:18.13
1,-4,19:162.13
1,-3,19:18.13
-2,-2,19:18.13
-1,-2,19:18.13
0,-2,19:191.0
2,-2,19:162.13
3,-2,19:18.13
0,-1,19:191.0
1,-1,19:17.13
0,0,19:17.13
-1,1,19:18.13
5,1,19:18.13
1,2,19:18.13
1,3,19:18.13
1,-5,20:18.13
1,-4,20:18.13
4,-3,20:18.13
-2,-2,20:191.0
-1,-2,20:191.0
0,-2,20:191.0
2,-2,20:18.13
3,-2,20:17.13
-1,-1,20:18.5
1,-1,20:162.13
3,-1,20:18.5
0,0,20:162.13
-1,1,20:18.13
2,1,20:18.5
3,1,20:191.0
3,-4,21:18.13
4,-3,21:162.13
-2,-2,21:18.13
-1,-2,21:18.13
3,-2,21:18.13
1,-1,21:17.13
2,-1,21:191.0
0,0,21:18.13
2,0,21:191.0
-2,1,21:18.13
-1,1,21:162.13
3,1,21:18.13
0,-3,22:18.13
2,-3,22:18.13
4,-3,22:18.13
1,-2,22:162.13
1,-1,22:17.13
1,0,22:143.3
2,0,22:191.0
-2,1,22:162.13
-1,1,22:18.13
3,1,22:18.13
0,-3,23:17.13
2,-3,23:18.13
0,-1,23:18.13
1,-1,23:17.13
1,0,23:18.13
2,0,23:18.13
-2,1,23:18.13
3,1,23:191.0
0,-3,24:18.13
-1,-1,24:18.13
1,-1,24:18.13
1,0,24:18.13
3,1,24:18.13
