[META]
version=2.0
spawnOnBlockType=2
spawnSunlight=True
spawnDarkness=True
spawnWater=False
spawnLava=False
underFill=False
randomRotation=True
dig=True
tree=True
branch=False
needsFoundation=True
rarity=100
collisionPercentage=20
spawnElevationMin=0
spawnElevationMax=200
spawnInBiome=Custom
[DATA]
-2,-2,0:17.13
0,-1,0:17.13
-2,-2,1:162.13
-1,-1,1:17.13
-1,-1,2:17.13
-1,-1,3:162.13
0,-1,3:143.1
-2,-5,4:18.13
1,-5,4:18.13
-2,-4,4:18.13
0,-4,4:18.13
-4,-3,4:18.13
-3,-2,4:162.13
-1,-2,4:17.13
-2,-1,4:162.13
-1,-1,4:17.13
0,0,4:17.13
1,1,4:162.13
1,2,4:18.13
2,3,4:18.13
-2,-5,5:17.13
1,-5,5:162.13
-2,-4,5:17.13
0,-4,5:17.13
-4,-3,5:17.13
-1,-3,5:17.13
3,-3,5:18.13
-3,-2,5:18.13
1,-2,5:162.13
2,-2,5:18.13
-1,-1,5:162.13
0,-1,5:162.13
-1,0,5:162.13
0,2,5:18.13
1,2,5:162.13
0,3,5:18.13
2,3,5:162.13
3,4,5:18.13
-2,-5,6:18.13
1,-5,6:18.13
-2,-4,6:18.13
0,-4,6:18.13
-4,-3,6:18.13
3,-3,6:162.13
-5,-2,6:18.13
-4,-2,6:18.13
2,-2,6:17.13
-3,-1,6:162.13
-2,-1,6:17.13
-1,-1,6:17.13
0,-1,6:17.13
-3,0,6:162.13
2,0,6:18.13
-3,1,6:18.13
-1,1,6:17.13
-4,2,6:18.13
0,2,6:17.13
1,2,6:18.13
0,3,6:162.13
2,3,6:18.13
0,4,6:18.13
3,4,6:162.13
3,-3,7:18.13
-5,-2,7:191.0
-4,-2,7:191.0
-3,-2,7:191.0
-1,-2,7:143.4
2,-2,7:18.13
-3,-1,7:191.0
-1,-1,7:17.13
1,-1,7:17.13
2,0,7:17.13
3,0,7:18.13
-3,1,7:162.13
-2,1,7:18.13
-4,2,7:17.13
0,2,7:18.13
0,3,7:18.13
0,4,7:162.13
3,4,7:18.13
-2,-5,8:18.13
-1,-4,8:18.13
1,-4,8:18.13
-1,-3,8:162.13
1,-3,8:18.13
-5,-2,8:18.13
-4,-2,8:18.13
-1,-2,8:162.13
0,-2,8:17.13
-2,-1,8:143.2
-1,-1,8:162.13
-2,0,8:17.13
2,0,8:18.13
3,0,8:17.13
4,0,8:18.13
-3,1,8:18.13
-2,1,8:162.13
-4,2,8:18.13
-3,2,8:18.13
-3,3,8:18.13
0,4,8:18.13
-2,-5,9:162.13
-5,-4,9:18.13
-1,-4,9:162.13
1,-4,9:191.0
-4,-3,9:18.13
1,-3,9:17.13
-3,-2,9:162.13
-2,-2,9:162.13
-1,-1,9:17.13
0,0,9:162.13
3,0,9:18.13
4,0,9:17.13
-2,1,9:18.13
1,1,9:18.13
-3,2,9:162.13
1,2,9:18.13
-3,3,9:162.13
-2,-5,10:18.13
-5,-4,10:17.13
-1,-4,10:18.13
1,-4,10:18.13
-4,-3,10:162.13
1,-3,10:18.13
-3,-2,10:18.13
-1,-2,10:143.4
-1,-1,10:162.13
-3,0,10:18.13
4,0,10:18.13
1,1,10:162.13
-3,2,10:18.13
1,2,10:162.13
-3,3,10:18.13
2,3,10:18.13
-5,-4,11:18.13
-4,-3,11:18.13
-2,-1,11:17.13
-1,-1,11:162.13
1,-1,11:18.13
-4,0,11:18.13
-3,0,11:162.13
1,1,11:18.13
1,2,11:18.13
2,3,11:17.13
-2,-3,12:18.13
-1,-2,12:17.13
-2,-1,12:143.2
-1,-1,12:162.13
0,-1,12:162.13
1,-1,12:17.13
-4,0,12:17.13
-3,0,12:18.13
-1,0,12:17.13
2,0,12:18.13
-1,1,12:18.13
2,3,12:18.13
-2,-3,13:17.13
0,-3,13:18.13
-1,-2,13:18.13
-1,-1,13:162.13
1,-1,13:18.13
-4,0,13:18.13
2,0,13:17.13
-1,1,13:162.13
-2,2,13:18.13
-2,-3,14:18.13
0,-3,14:17.13
0,-2,14:17.13
-2,-1,14:18.13
-1,-1,14:162.13
2,0,14:18.13
-1,1,14:18.13
-2,2,14:17.13
0,-3,15:18.13
-2,-1,15:17.13
-1,-1,15:18.13
0,-1,15:18.13
0,0,15:162.13
-2,2,15:18.13
-2,-1,16:18.13
-1,-1,16:18.13
0,0,16:18.13
