[META]
version=2.0
spawnOnBlockType=2
spawnSunlight=True
spawnDarkness=True
spawnWater=False
spawnLava=False
underFill=False
randomRotation=True
dig=True
tree=True
branch=False
needsFoundation=True
rarity=100
collisionPercentage=20
spawnElevationMin=0
spawnElevationMax=200
spawnInBiome=Custom
[DATA]
0,-1,0:17.13
-2,1,0:17.13
0,1,0:162.13
-1,0,1:17.13
-2,1,1:162.13
-1,0,2:162.13
-1,0,3:162.13
0,0,3:143.1
-3,0,4:18.5
-1,0,4:162.13
-3,4,4:191.0
-2,6,4:18.5
-2,-1,5:17.13
-6,0,5:18.13
-2,0,5:17.13
-1,0,5:17.13
0,1,5:17.13
-3,6,5:18.5
0,6,5:18.5
-4,-7,6:18.13
-3,-6,6:18.13
-3,-4,6:162.13
-3,-3,6:17.13
-9,-2,6:18.13
-2,-2,6:162.13
-8,-1,6:18.13
-7,-1,6:18.13
-6,0,6:162.13
-5,0,6:162.13
-1,0,6:17.13
0,0,6:162.13
-5,1,6:17.13
-4,1,6:162.13
-3,1,6:162.13
-8,2,6:18.13
-7,2,6:18.13
-6,2,6:18.5
1,2,6:162.13
2,2,6:17.13
4,2,6:18.13
2,3,6:17.13
3,4,6:18.13
4,4,6:18.13
-4,5,6:18.5
5,5,6:18.13
-4,-9,7:18.13
-4,-8,7:18.13
-4,-7,7:162.13
-3,-6,7:17.13
-3,-5,7:162.13
-3,-4,7:162.9
-9,-2,7:17.13
6,-2,7:18.13
-8,-1,7:17.13
-7,-1,7:17.13
-4,-1,7:191.0
-3,-1,7:18.5
-1,-1,7:17.13
2,-1,7:17.13
3,-1,7:162.13
5,-1,7:18.13
6,-1,7:18.13
-6,0,7:18.13
-1,0,7:162.13
1,0,7:162.13
-8,2,7:162.13
-7,2,7:17.13
-6,2,7:162.13
-3,2,7:18.5
3,2,7:162.13
4,2,7:162.13
5,2,7:18.13
6,2,7:18.13
-10,3,7:18.13
-9,3,7:18.13
-1,3,7:18.5
2,3,7:17.13
3,4,7:17.13
4,4,7:162.13
5,4,7:18.5
4,5,7:191.0
5,5,7:17.13
6,6,7:18.13
0,7,7:191.0
7,7,7:18.13
-4,-9,8:162.13
-4,-8,8:17.13
-4,-7,8:18.13
-3,-6,8:18.13
0,-6,8:18.13
0,-5,8:18.13
3,-5,8:18.13
4,-5,8:18.13
5,-5,8:18.13
0,-4,8:18.13
-2,-3,8:191.0
-1,-3,8:17.13
-9,-2,8:18.13
-1,-2,8:17.13
6,-2,8:17.13
7,-2,8:18.13
-8,-1,8:18.13
-7,-1,8:18.13
-2,-1,8:162.13
2,-1,8:18.5
4,-1,8:162.13
5,-1,8:17.13
6,-1,8:162.13
-5,0,8:18.5
-1,0,8:162.13
-1,1,8:162.13
0,1,8:18.5
2,1,8:18.5
-8,2,8:18.13
-7,2,8:18.13
4,2,8:18.13
5,2,8:17.13
6,2,8:162.13
-10,3,8:17.13
-9,3,8:17.13
2,3,8:18.5
-2,4,8:191.0
3,4,8:18.13
4,4,8:18.13
-5,5,8:191.0
-1,5,8:18.5
5,5,8:162.13
6,6,8:162.13
7,7,8:17.13
-4,-9,9:18.13
-4,-8,9:18.13
0,-8,9:18.13
0,-7,9:18.13
0,-6,9:17.13
0,-5,9:17.13
3,-5,9:191.0
4,-5,9:191.0
5,-5,9:191.0
-7,-4,9:18.13
-5,-4,9:18.13
0,-4,9:17.13
1,-4,9:191.0
2,-4,9:191.0
3,-4,9:191.0
-6,-3,9:18.13
-4,-2,9:17.13
-2,-2,9:18.5
-1,-2,9:18.5
6,-2,9:18.13
7,-2,9:17.13
-8,-1,9:191.0
-3,-1,9:17.13
5,-1,9:18.13
6,-1,9:18.13
-8,0,9:18.5
-1,0,9:17.13
-1,1,9:17.13
0,1,9:18.5
1,1,9:18.5
-8,2,9:18.5
-7,2,9:18.5
-2,2,9:162.13
-1,2,9:191.0
0,2,9:17.13
5,2,9:18.13
6,2,9:18.13
-10,3,9:18.13
-9,3,9:18.13
-3,3,9:17.13
0,3,9:17.13
-5,4,9:18.13
-3,4,9:17.13
-5,5,9:191.0
-2,5,9:18.5
-1,5,9:18.5
5,5,9:18.13
1,6,9:18.5
6,6,9:18.13
-2,7,9:18.13
0,7,9:18.5
7,7,9:18.13
-2,8,9:18.13
-6,-8,10:18.13
-3,-8,10:18.13
0,-8,10:162.13
-6,-7,10:18.13
-3,-7,10:18.13
0,-7,10:162.13
-6,-6,10:18.13
-2,-6,10:18.13
0,-6,10:18.13
-9,-5,10:18.13
-2,-5,10:18.13
0,-5,10:18.13
3,-5,10:18.13
4,-5,10:18.13
5,-5,10:18.13
-8,-4,10:18.13
-7,-4,10:162.13
-5,-4,10:17.13
-2,-4,10:18.5
0,-4,10:18.13
-6,-3,10:162.13
-5,-3,10:162.13
-5,-2,10:162.13
-4,-2,10:17.13
-2,-2,10:191.0
7,-2,10:18.13
-7,-1,10:18.5
-1,-1,10:191.0
1,-1,10:18.5
-1,0,10:162.13
0,0,10:17.13
2,0,10:18.5
4,0,10:18.13
5,1,10:18.5
-6,2,10:18.5
4,2,10:191.0
-5,3,10:18.5
-5,4,10:162.13
-4,4,10:17.13
1,4,10:17.13
2,4,10:18.5
-6,5,10:18.13
-3,5,10:17.13
1,5,10:162.13
3,5,10:191.0
5,5,10:18.5
-7,6,10:18.13
-3,6,10:162.13
1,6,10:17.13
3,6,10:18.13
-2,7,10:162.13
2,7,10:18.13
-2,8,10:17.13
2,8,10:18.13
-2,9,10:18.13
-2,10,10:18.13
-6,-8,11:162.13
-3,-8,11:162.13
0,-8,11:18.13
-6,-7,11:17.13
-3,-7,11:17.13
0,-7,11:18.13
-6,-6,11:17.13
-2,-6,11:17.13
-9,-5,11:162.13
-5,-5,11:162.13
-2,-5,11:17.13
-8,-4,11:162.13
-7,-4,11:18.13
-5,-4,11:18.13
-2,-4,11:17.13
-7,-3,11:18.5
-6,-3,11:18.13
-2,-3,11:17.13
-1,-2,11:162.13
-6,-1,11:191.0
-1,-1,11:162.13
0,-1,11:143.1
2,-1,11:18.5
4,-1,11:18.5
-1,0,11:17.13
1,0,11:162.13
2,0,11:17.13
3,0,11:17.13
4,0,11:17.13
5,0,11:18.13
6,0,11:18.13
2,1,11:162.13
3,2,11:18.13
-1,3,11:18.5
4,3,11:18.13
-5,4,11:17.13
-2,4,11:191.0
4,4,11:191.0
5,4,11:18.13
-6,5,11:17.13
1,5,11:17.13
2,5,11:17.13
-7,6,11:162.13
1,6,11:17.13
3,6,11:162.13
4,6,11:18.13
-8,7,11:18.13
-2,7,11:18.13
2,7,11:162.13
5,7,11:18.13
-2,8,11:18.13
2,8,11:17.13
-2,9,11:17.13
0,9,11:18.5
3,9,11:18.13
-2,10,11:17.13
3,10,11:18.13
-6,-8,12:18.13
-3,-8,12:18.13
-6,-7,12:18.13
-3,-7,12:18.13
-6,-6,12:18.13
-2,-6,12:18.13
-9,-5,12:18.13
-5,-5,12:18.13
-2,-5,12:18.13
-8,-4,12:18.13
-7,-4,12:18.5
1,-4,12:18.13
0,-2,12:162.13
3,-2,12:18.5
0,-1,12:162.13
-2,0,12:162.13
-1,0,12:162.13
1,0,12:191.0
4,0,12:18.13
5,0,12:162.13
6,0,12:17.13
-1,1,12:17.13
-1,2,12:17.13
3,2,12:17.13
-2,3,12:18.5
4,3,12:162.13
-5,4,12:18.13
5,4,12:162.13
-7,5,12:18.5
-6,5,12:18.13
-4,5,12:191.0
-7,6,12:162.13
-4,6,12:18.5
-3,6,12:18.5
1,6,12:18.13
3,6,12:18.13
4,6,12:17.13
-8,7,12:162.13
-6,7,12:191.0
2,7,12:18.13
5,7,12:17.13
2,8,12:17.13
-2,9,12:18.13
-1,9,12:191.0
3,9,12:17.13
-2,10,12:18.13
3,10,12:162.13
-3,-6,13:18.5
2,-6,13:18.13
2,-5,13:18.13
1,-4,13:17.13
-4,-3,13:18.13
-1,-3,13:18.5
1,-3,13:162.13
2,-3,13:191.0
3,-3,13:191.0
4,-3,13:191.0
5,-3,13:191.0
-3,-2,13:17.13
2,-2,13:191.0
-2,-1,13:162.13
-9,0,13:18.5
-7,0,13:18.13
-6,0,13:18.13
-3,0,13:17.13
-1,0,13:162.13
5,0,13:18.13
6,0,13:18.13
-7,1,13:18.13
-6,1,13:18.13
-5,1,13:17.13
-4,1,13:162.13
-2,1,13:162.13
-8,2,13:18.13
-4,2,13:18.5
-3,2,13:18.5
3,2,13:18.13
-6,3,13:18.5
-3,3,13:18.13
-1,3,13:17.13
4,3,13:18.13
-6,4,13:191.0
-2,4,13:191.0
-1,4,13:17.13
5,4,13:18.13
3,5,13:18.5
-7,6,13:18.13
0,6,13:18.13
4,6,13:18.13
-8,7,13:18.13
5,7,13:18.13
2,8,13:18.13
3,8,13:18.5
3,9,13:18.13
3,10,13:18.13
2,-6,14:17.13
-6,-5,14:18.13
2,-5,14:17.13
-5,-4,14:18.13
1,-4,14:18.13
-4,-3,14:17.13
1,-3,14:18.13
2,-3,14:191.0
3,-3,14:18.13
4,-3,14:18.13
5,-3,14:191.0
-9,-2,14:18.13
-5,-2,14:191.0
-4,-2,14:18.5
4,-2,14:191.0
-8,-1,14:18.13
-1,-1,14:143.4
-7,0,14:162.13
-6,0,14:162.13
-1,0,14:162.13
0,0,14:18.5
1,0,14:18.5
-7,1,14:162.13
-6,1,14:162.13
0,1,14:162.13
-9,2,14:18.13
-8,2,14:162.13
-2,2,14:17.13
2,2,14:18.13
-3,3,14:162.13
-4,4,14:18.5
-3,4,14:18.13
0,4,14:17.13
-4,5,14:18.13
-1,5,14:17.13
0,5,14:162.13
1,5,14:162.13
2,5,14:18.13
-1,6,14:18.13
0,6,14:191.0
3,6,14:18.13
0,7,14:18.13
0,8,14:18.13
-7,-6,15:18.13
-3,-6,15:18.13
2,-6,15:18.13
-6,-5,15:162.13
-3,-5,15:18.13
-1,-5,15:18.13
2,-5,15:18.13
-5,-4,15:17.13
-4,-4,15:162.13
0,-4,15:18.13
3,-4,15:18.5
-4,-3,15:18.13
0,-3,15:18.13
4,-3,15:18.13
5,-3,15:18.13
-9,-2,15:162.13
3,-2,15:18.13
4,-2,15:18.5
-8,-1,15:162.13
-6,-1,15:18.5
-4,-1,15:18.13
-2,-1,15:191.0
0,-1,15:162.13
-7,0,15:18.13
-6,0,15:18.13
-2,0,15:17.13
-1,0,15:17.13
-7,1,15:18.13
-6,1,15:18.13
0,1,15:18.5
1,1,15:162.13
-9,2,15:162.13
-8,2,15:18.13
2,2,15:162.13
3,2,15:18.13
-3,3,15:18.13
4,3,15:18.13
-3,4,15:162.13
-4,5,15:162.13
2,5,15:17.13
-4,6,15:18.13
-2,6,15:18.5
-1,6,15:162.13
0,6,15:18.13
3,6,15:162.13
4,6,15:18.13
-5,7,15:18.13
-2,7,15:18.13
0,7,15:191.0
2,7,15:191.0
0,8,15:191.0
0,9,15:18.13
-3,-7,16:18.13
-7,-6,16:17.13
-3,-6,16:17.13
2,-6,16:18.5
-6,-5,16:18.13
-3,-5,16:162.13
-1,-5,16:162.13
1,-5,16:191.0
-7,-4,16:18.5
-5,-4,16:18.13
-3,-4,16:191.0
0,-4,16:17.13
-4,-3,16:18.5
0,-3,16:162.13
4,-3,16:162.13
5,-3,16:18.13
-9,-2,16:18.13
1,-2,16:17.13
2,-2,16:17.13
3,-2,16:162.13
-8,-1,16:18.13
-7,-1,16:18.5
-6,-1,16:18.13
-5,-1,16:18.13
-4,-1,16:17.13
1,-1,16:162.13
-7,0,16:18.5
-3,0,16:17.13
-1,0,16:17.13
-3,1,16:18.5
-9,2,16:18.13
-4,2,16:18.5
-2,2,16:191.0
2,2,16:18.13
3,2,16:162.13
-6,3,16:18.5
4,3,16:17.13
-3,4,16:18.13
-4,5,16:18.13
2,5,16:18.13
3,5,16:18.5
-4,6,16:162.13
-1,6,16:18.13
3,6,16:18.13
4,6,16:17.13
-5,7,16:17.13
-2,7,16:17.13
0,7,16:18.13
-2,8,16:18.13
0,8,16:18.13
0,9,16:191.0
-3,-7,17:162.13
-7,-6,17:18.13
-3,-6,17:18.13
-3,-5,17:18.13
-1,-5,17:18.13
0,-4,17:18.13
-4,-3,17:18.13
0,-3,17:18.13
4,-3,17:18.13
5,-3,17:17.13
-6,-2,17:18.5
-3,-2,17:18.13
3,-2,17:18.13
-6,-1,17:162.13
-5,-1,17:17.13
-4,-1,17:18.13
-2,-1,17:162.13
-1,0,17:162.13
2,0,17:18.5
-1,1,17:17.13
-5,2,17:18.5
3,2,17:18.13
4,3,17:18.13
-2,4,17:18.13
-2,5,17:18.5
1,5,17:18.13
-4,6,17:18.13
-3,6,17:191.0
1,6,17:18.5
2,6,17:191.0
4,6,17:18.13
-5,7,17:18.13
-2,7,17:18.13
-2,8,17:162.13
-2,9,17:18.13
0,9,17:18.13
-3,-7,18:18.13
-2,-7,18:18.5
1,-5,18:18.5
-5,-4,18:18.13
-4,-4,18:191.0
0,-4,18:18.5
-4,-3,18:17.13
5,-3,18:18.13
-3,-2,18:17.13
-6,-1,18:18.13
-5,-1,18:18.13
-1,-1,18:18.5
-2,0,18:18.5
-1,0,18:162.13
-2,1,18:17.13
1,1,18:18.5
-3,2,18:162.13
-2,2,18:191.0
0,2,18:162.13
-5,3,18:18.13
-2,3,18:191.0
0,3,18:17.13
2,3,18:18.5
-5,4,18:18.5
-2,4,18:191.0
1,4,18:17.13
3,4,18:18.5
-5,5,18:18.5
-2,5,18:18.13
1,5,18:162.13
-5,6,18:18.5
2,6,18:18.13
-1,7,18:18.5
1,7,18:18.5
2,7,18:18.13
-3,8,18:18.5
-2,8,18:18.13
-2,9,18:162.13
-5,-4,19:162.13
2,-4,19:18.13
-4,-3,19:18.13
1,-3,19:18.13
-3,-2,19:18.13
1,-2,19:162.13
0,-1,19:162.13
-6,0,19:18.13
-1,0,19:17.13
0,0,19:17.13
-5,1,19:18.13
-4,1,19:162.13
-5,3,19:162.13
-4,3,19:17.13
-2,3,19:18.13
-6,4,19:18.13
-2,4,19:191.0
2,4,19:162.13
3,4,19:18.13
-7,5,19:18.13
-2,5,19:191.0
1,5,19:18.13
4,5,19:18.13
0,6,19:18.5
2,6,19:162.13
4,6,19:191.0
1,7,19:191.0
2,7,19:162.13
-2,8,19:18.5
-2,9,19:18.13
3,-5,20:18.13
-5,-4,20:18.13
2,-4,20:162.13
1,-3,20:162.13
-8,-1,20:18.13
-7,-1,20:18.13
-6,0,20:162.13
-1,0,20:162.13
3,0,20:18.13
4,0,20:18.13
-5,1,20:162.13
1,1,20:17.13
2,1,20:17.13
-2,2,20:18.5
3,2,20:18.13
4,2,20:18.13
5,2,20:18.5
-5,3,20:18.13
-6,4,20:17.13
-2,4,20:18.13
-1,4,20:18.5
3,4,20:17.13
-7,5,20:17.13
-2,5,20:18.13
4,5,20:162.13
5,5,20:18.13
2,6,20:18.13
0,7,20:191.0
2,7,20:18.13
-2,8,20:18.5
0,9,20:18.5
3,-5,21:162.13
-6,-4,21:18.5
2,-4,21:18.13
-2,-3,21:18.13
1,-3,21:18.13
-8,-2,21:18.5
-8,-1,21:162.13
-7,-1,21:17.13
-1,-1,21:17.13
2,-1,21:18.5
5,-1,21:18.13
-6,0,21:18.13
-1,0,21:17.13
3,0,21:191.0
4,0,21:191.0
5,0,21:191.0
-7,1,21:18.5
-6,1,21:191.0
-5,1,21:18.13
3,1,21:18.13
0,2,21:18.5
1,2,21:191.0
3,2,21:191.0
4,2,21:191.0
5,2,21:191.0
3,3,21:18.5
5,3,21:18.13
-6,4,21:18.13
3,4,21:18.13
-7,5,21:18.13
-2,5,21:191.0
4,5,21:18.13
5,5,21:162.13
-3,6,21:191.0
-3,7,21:18.5
0,-5,22:18.13
3,-5,22:18.13
-3,-4,22:18.13
0,-4,22:18.13
-7,-3,22:18.5
-2,-3,22:17.13
-1,-3,22:17.13
2,-3,22:18.5
-6,-2,22:18.5
-2,-2,22:17.13
-1,-2,22:17.13
-8,-1,22:18.13
-7,-1,22:18.13
-1,-1,22:17.13
5,-1,22:191.0
-4,0,22:18.5
-1,0,22:17.13
0,0,22:18.5
3,0,22:18.13
4,0,22:18.13
5,0,22:191.0
0,1,22:162.13
3,2,22:18.13
4,2,22:18.13
5,2,22:191.0
-2,3,22:18.5
1,3,22:18.13
5,3,22:191.0
0,4,22:18.5
5,5,22:18.13
0,-6,23:18.13
-3,-5,23:18.13
0,-5,23:17.13
-3,-4,23:17.13
0,-4,23:162.13
-2,-3,23:17.13
2,-2,23:18.13
0,-1,23:17.13
1,-1,23:18.13
5,-1,23:18.13
-3,0,23:162.13
-2,0,23:162.13
-1,0,23:162.13
-5,1,23:18.13
-1,1,23:143.3
0,1,23:191.0
0,2,23:162.13
-1,3,23:162.13
1,3,23:162.13
5,3,23:18.13
-4,4,23:191.0
-2,4,23:18.13
-1,4,23:17.13
1,4,23:18.13
-3,5,23:18.13
0,5,23:18.13
2,5,23:18.13
-4,6,23:18.13
0,6,23:18.13
0,7,23:18.13
0,-6,24:162.13
-3,-5,24:162.13
0,-5,24:18.13
-3,-4,24:18.13
0,-4,24:18.13
-2,-3,24:18.13
-1,-3,24:191.0
3,-3,24:18.13
-4,-2,24:18.13
2,-2,24:162.13
-5,-1,24:191.0
-2,-1,24:17.13
1,-1,24:162.13
3,-1,24:17.13
-4,0,24:191.0
-3,0,24:191.0
-1,0,24:162.13
1,0,24:191.0
-7,1,24:18.13
-6,1,24:18.13
-5,1,24:191.0
-4,1,24:191.0
-3,1,24:191.0
-2,1,24:18.5
1,1,24:191.0
4,1,24:18.13
1,3,24:18.13
-2,4,24:162.13
1,4,24:17.13
3,4,24:18.5
-3,5,24:17.13
0,5,24:17.13
2,5,24:17.13
-4,6,24:162.13
0,6,24:17.13
0,7,24:17.13
0,-6,25:18.13
-3,-5,25:18.13
-6,-3,25:18.13
3,-3,25:162.13
-6,-2,25:18.5
-5,-2,25:18.13
-4,-2,25:162.13
-2,-2,25:191.0
2,-2,25:18.13
-3,-1,25:17.13
-1,-1,25:162.13
1,-1,25:18.13
3,-1,25:191.0
-1,0,25:17.13
1,0,25:18.13
3,0,25:17.13
-7,1,25:191.0
-6,1,25:191.0
-5,1,25:18.13
-2,1,25:162.13
1,1,25:191.0
4,1,25:17.13
1,2,25:191.0
4,2,25:18.13
-2,3,25:18.5
5,3,25:18.13
-2,4,25:18.13
1,4,25:18.13
-3,5,25:18.13
0,5,25:18.13
2,5,25:18.13
-4,6,25:18.13
0,6,25:18.13
0,7,25:18.13
-4,-4,26:18.5
-3,-4,26:191.0
-6,-3,26:162.13
3,-3,26:17.13
-5,-2,26:17.13
-4,-2,26:18.13
-1,-2,26:162.13
2,-2,26:18.13
4,-1,26:18.5
-2,0,26:18.5
-1,0,26:162.13
0,0,26:162.13
-7,1,26:18.13
-6,1,26:18.13
-3,1,26:17.13
-1,1,26:17.13
4,1,26:18.13
0,2,26:191.0
4,2,26:17.13
5,3,26:162.13
2,4,26:18.5
-4,-4,27:18.5
-6,-3,27:18.13
-3,-3,27:18.5
3,-3,27:18.13
-5,-2,27:18.13
-1,-2,27:162.13
3,-1,27:18.5
-5,0,27:18.5
-4,0,27:18.5
-1,0,27:17.13
1,0,27:17.13
5,1,27:191.0
-4,2,27:18.13
-3,2,27:17.13
-1,2,27:162.13
0,2,27:17.13
4,2,27:18.13
5,3,27:18.13
-2,4,27:18.13
2,4,27:18.5
-1,-4,28:18.13
-1,-3,28:162.13
0,-3,28:18.5
-2,0,28:162.13
-1,0,28:162.13
2,0,28:17.13
3,0,28:18.13
-1,1,28:18.5
-4,2,28:17.13
-5,3,28:18.13
-4,3,28:191.0
-1,3,28:162.13
0,3,28:162.13
1,3,28:191.0
2,3,28:191.0
3,3,28:18.13
-4,4,28:191.0
-2,4,28:162.13
0,4,28:162.13
2,4,28:18.5
-4,5,28:18.13
-2,5,28:18.13
0,5,28:18.13
-1,-5,29:18.13
-1,-4,29:162.13
-1,-3,29:18.13
3,-2,29:191.0
-2,-1,29:162.13
3,-1,29:191.0
-3,0,29:162.13
-1,0,29:162.13
2,0,29:17.13
3,0,29:162.13
4,0,29:18.13
3,1,29:191.0
-4,2,29:18.13
-6,3,29:18.13
-5,3,29:162.13
2,3,29:191.0
3,3,29:191.0
-4,4,29:18.13
-2,4,29:18.13
0,4,29:17.13
-4,5,29:191.0
-2,5,29:17.13
0,5,29:162.13
-2,6,29:18.13
1,6,29:18.13
-1,-5,30:17.13
-1,-4,30:18.13
-3,-3,30:18.13
-2,-3,30:18.5
-2,-2,30:162.13
-1,-2,30:18.5
1,-2,30:191.0
3,-2,30:191.0
0,-1,30:191.0
1,-1,30:191.0
3,-1,30:18.13
-4,0,30:18.13
-3,0,30:17.13
-1,0,30:162.13
0,0,30:191.0
3,0,30:18.13
4,0,30:17.13
5,0,30:18.13
3,2,30:191.0
-6,3,30:162.13
-5,3,30:18.13
1,3,30:18.5
2,3,30:18.13
3,3,30:18.13
0,4,30:18.13
-4,5,30:18.13
-2,5,30:18.13
0,5,30:18.13
-2,6,30:17.13
1,6,30:162.13
-1,-5,31:18.13
-4,-4,31:18.13
2,-4,31:18.13
-3,-3,31:162.13
1,-3,31:18.13
2,-3,31:18.13
1,-2,31:191.0
3,-2,31:18.13
1,-1,31:191.0
-5,0,31:18.13
-4,0,31:162.13
-1,0,31:162.13
4,0,31:18.13
5,0,31:162.13
-1,1,31:162.13
-2,2,31:18.13
-1,2,31:18.5
1,2,31:191.0
-6,3,31:18.13
-2,3,31:18.13
1,4,31:191.0
-2,6,31:18.13
1,6,31:18.13
-4,-4,32:162.13
-2,-4,32:191.0
2,-4,32:191.0
-3,-3,32:18.13
0,-3,32:18.5
1,-3,32:191.0
2,-3,32:191.0
-4,-2,32:18.5
1,-2,32:191.0
1,-1,32:18.13
-6,0,32:18.13
-5,0,32:17.13
-4,0,32:18.13
-1,0,32:17.13
5,0,32:18.13
0,1,32:17.13
-2,2,32:162.13
0,2,32:18.5
1,2,32:191.0
-2,3,32:17.13
1,3,32:191.0
-3,4,32:18.13
-4,-4,33:18.13
2,-4,33:191.0
-1,-3,33:18.5
1,-3,33:18.13
2,-3,33:18.13
-2,-2,33:18.5
1,-2,33:18.13
-1,-1,33:17.13
-6,0,33:17.13
-5,0,33:18.13
-3,0,33:191.0
-1,0,33:17.13
0,0,33:18.5
-2,1,33:162.13
-2,2,33:191.0
1,2,33:162.13
2,2,33:18.5
-2,3,33:18.13
1,3,33:191.0
2,3,33:18.13
-3,4,33:17.13
2,-4,34:18.13
-1,-3,34:18.13
-1,-2,34:162.13
-3,-1,34:18.5
-6,0,34:18.13
-1,0,34:162.13
0,0,34:17.13
-3,1,34:162.13
-4,2,34:18.13
-3,2,34:191.0
-1,2,34:18.13
1,2,34:18.13
2,3,34:162.13
-3,4,34:18.13
3,4,34:18.13
-1,-3,35:18.13
-4,-2,35:18.5
-1,-2,35:17.13
-2,-1,35:162.13
2,-1,35:18.13
-1,0,35:17.13
1,0,35:162.13
-3,1,35:18.13
-1,1,35:162.13
-5,2,35:18.13
-4,2,35:162.13
-1,2,35:162.13
-1,3,35:18.13
2,3,35:18.13
-1,4,35:18.13
3,4,35:162.13
-1,-4,36:18.13
-1,-3,36:162.13
-3,-2,36:18.13
-1,-2,36:18.13
-3,-1,36:17.13
2,-1,36:162.13
3,-1,36:18.13
-1,0,36:162.13
-5,2,36:162.13
-4,2,36:18.13
-1,2,36:18.13
-1,3,36:162.13
-1,4,36:162.13
3,4,36:18.13
-1,-4,37:17.13
-1,-3,37:18.13
-4,-2,37:18.13
-3,-2,37:162.13
2,-1,37:18.13
3,-1,37:162.13
-1,0,37:162.13
2,0,37:18.13
-5,1,37:18.5
-2,1,37:18.13
-1,1,37:18.13
0,1,37:17.13
-5,2,37:18.13
-2,2,37:18.13
1,2,37:18.13
-1,3,37:18.13
-1,4,37:18.13
-1,-4,38:18.13
-4,-2,38:162.13
-3,-2,38:18.13
-1,-1,38:191.0
0,-1,38:191.0
3,-1,38:18.13
-3,0,38:18.5
-1,0,38:162.13
-3,2,38:18.13
1,2,38:162.13
2,2,38:18.13
3,2,38:18.5
-4,-2,39:18.13
0,-2,39:191.0
1,-2,39:18.13
0,-1,39:191.0
-1,0,39:17.13
-3,1,39:18.13
-2,1,39:17.13
-1,1,39:18.5
-3,2,39:18.5
1,2,39:18.13
2,2,39:162.13
0,-2,40:191.0
1,-2,40:191.0
-2,-1,40:18.13
0,-1,40:18.13
1,-1,40:18.13
-4,0,40:18.13
-1,0,40:162.13
-2,1,40:17.13
-3,2,40:18.13
-1,2,40:18.13
2,2,40:18.13
3,2,40:191.0
0,3,40:18.13
1,3,40:18.13
-2,-2,41:18.13
1,-2,41:18.13
-1,-1,41:191.0
-2,0,41:18.13
-1,0,41:162.13
2,0,41:18.13
-1,1,41:18.13
-3,2,41:18.13
-1,2,41:191.0
2,2,41:18.13
0,3,41:191.0
-1,-1,42:18.13
-1,0,42:191.0
0,0,42:18.13
1,0,42:18.13
2,1,42:18.13
-1,0,43:18.13
