[META]
version=2.0
spawnOnBlockType=2
spawnSunlight=True
spawnDarkness=True
spawnWater=False
spawnLava=False
underFill=False
randomRotation=True
dig=True
tree=True
branch=False
needsFoundation=True
rarity=100
collisionPercentage=20
spawnElevationMin=0
spawnElevationMax=200
spawnInBiome=Custom
[DATA]
-1,-2,0:17.13
1,-1,0:17.13
0,0,0:17.13
-1,-2,1:162.13
0,-1,1:162.13
0,-1,2:162.13
0,-1,3:17.13
0,-1,4:162.13
1,-1,4:143.1
1,-5,5:18.13
-2,-4,5:18.13
1,-4,5:18.13
-4,-2,5:18.13
-1,-2,5:17.13
0,-2,5:17.13
-3,-1,5:18.13
-2,-1,5:17.13
-1,-1,5:17.13
0,-1,5:17.13
0,0,5:162.13
-1,1,5:162.13
-2,2,5:18.13
-3,3,5:18.13
-3,-5,6:18.13
1,-5,6:162.13
-2,-4,6:162.13
1,-4,6:17.13
-2,-3,6:162.13
1,-3,6:162.13
-4,-2,6:17.13
3,-2,6:18.13
-3,-1,6:162.13
0,-1,6:17.13
0,1,6:17.13
2,1,6:18.13
-2,2,6:17.13
1,2,6:162.13
-3,3,6:17.13
1,3,6:18.13
-3,-5,7:162.13
1,-5,7:18.13
-2,-4,7:18.13
1,-4,7:18.13
-2,-3,7:18.13
3,-3,7:18.13
4,-3,7:18.13
-4,-2,7:18.13
1,-2,7:17.13
2,-2,7:162.13
3,-2,7:17.13
-3,-1,7:18.13
0,-1,7:17.13
4,-1,7:18.13
5,-1,7:18.13
1,0,7:162.13
2,1,7:162.13
-2,2,7:18.13
1,2,7:18.13
3,2,7:18.13
-3,3,7:18.13
1,3,7:162.13
-3,-5,8:18.13
5,-4,8:18.13
3,-3,8:162.13
4,-3,8:17.13
-2,-2,8:18.13
3,-2,8:18.13
0,-1,8:17.13
4,-1,8:17.13
5,-1,8:162.13
-1,0,8:162.13
0,0,8:17.13
-3,1,8:18.13
2,1,8:18.13
0,2,8:18.13
3,2,8:162.13
1,3,8:18.13
4,3,8:18.13
-4,-4,9:18.13
0,-4,9:18.13
5,-4,9:17.13
-3,-3,9:18.13
0,-3,9:17.13
3,-3,9:18.13
4,-3,9:18.13
-2,-2,9:191.0
0,-2,9:162.13
-2,-1,9:191.0
-1,-1,9:191.0
0,-1,9:17.13
4,-1,9:18.13
5,-1,9:18.13
-3,1,9:17.13
-2,1,9:17.13
0,1,9:162.13
0,2,9:162.13
3,2,9:18.13
-1,3,9:18.13
4,3,9:17.13
0,-5,10:18.13
-4,-4,10:191.0
0,-4,10:162.13
5,-4,10:18.13
-4,-3,10:191.0
-3,-3,10:191.0
-2,-2,10:18.13
0,-2,10:143.4
0,-1,10:17.13
1,-1,10:17.13
2,-1,10:162.13
3,-1,10:18.13
4,-1,10:18.13
-3,1,10:18.13
0,2,10:18.13
-1,3,10:162.13
4,3,10:18.13
0,-5,11:162.13
-4,-4,11:18.13
-2,-4,11:18.13
0,-4,11:18.13
-3,-3,11:18.13
2,-3,11:18.13
-1,-2,11:17.13
1,-2,11:162.13
-2,-1,11:18.13
-1,-1,11:162.13
0,-1,11:17.13
3,-1,11:17.13
4,-1,11:17.13
5,-1,11:18.13
-3,0,11:18.13
3,0,11:162.13
3,1,11:18.13
-1,3,11:18.13
0,-5,12:18.13
-2,-4,12:162.13
2,-4,12:18.13
-1,-3,12:17.13
2,-3,12:191.0
-3,-2,12:18.13
-2,-1,12:162.13
0,-1,12:17.13
3,-1,12:18.13
4,-1,12:18.13
5,-1,12:17.13
-3,0,12:17.13
-1,0,12:17.13
1,0,12:17.13
1,1,12:18.13
3,1,12:162.13
4,2,12:18.13
-2,-4,13:18.13
2,-4,13:191.0
2,-3,13:18.13
-3,-2,13:162.13
-2,-1,13:18.13
0,-1,13:17.13
5,-1,13:18.13
-3,0,13:18.13
-1,1,13:162.13
1,1,13:162.13
3,1,13:18.13
2,2,13:18.13
4,2,13:17.13
2,-4,14:18.13
-2,-3,14:18.13
-3,-2,14:18.13
0,-2,14:143.4
0,-1,14:162.13
1,-1,14:18.13
-1,0,14:18.13
1,1,14:18.13
2,2,14:162.13
4,2,14:18.13
-1,-2,15:162.13
0,-1,15:17.13
1,-1,15:162.13
-1,0,15:191.0
2,0,15:18.13
-1,1,15:18.13
2,2,15:18.13
-1,-2,16:18.13
0,-2,16:18.13
0,-1,16:162.13
1,-1,16:18.13
-1,0,16:18.13
2,0,16:162.13
-1,1,16:191.0
1,-2,17:18.13
0,-1,17:18.13
2,0,17:18.13
-1,1,17:18.13
0,0,18:18.13
