[META]
version=2.0
spawnOnBlockType=2
spawnSunlight=True
spawnDarkness=True
spawnWater=False
spawnLava=False
underFill=False
randomRotation=True
dig=True
tree=True
branch=False
needsFoundation=True
rarity=100
collisionPercentage=20
spawnElevationMin=0
spawnElevationMax=200
spawnInBiome=Custom
[DATA]
-2,-3,0:162.13
1,-3,0:162.13
0,0,0:17.13
1,-3,1:162.13
-1,-2,1:162.13
0,-2,1:162.13
0,-1,1:17.13
0,-2,2:17.13
0,-2,3:17.13
0,-1,3:143.3
-1,-3,4:17.13
0,-2,4:162.13
5,-7,5:18.13
4,-6,5:18.13
3,-5,5:18.13
-3,-4,5:17.13
2,-4,5:162.13
-2,-3,5:17.13
1,-3,5:162.13
-1,-2,5:17.13
0,-2,5:162.13
1,-2,5:162.13
2,-2,5:162.13
-5,-1,5:18.5
-1,-1,5:18.5
0,-1,5:162.13
7,-1,5:18.13
-4,0,5:18.5
-1,0,5:162.13
0,0,5:17.13
-5,1,5:18.13
-7,-7,6:18.13
4,-7,6:18.13
5,-7,6:162.13
-6,-6,6:18.13
3,-6,6:18.5
4,-6,6:162.13
-5,-5,6:162.13
-4,-5,6:162.13
3,-5,6:17.13
4,-5,6:18.13
0,-4,6:18.5
-5,-3,6:17.13
-4,-3,6:162.13
2,-3,6:18.5
-3,-2,6:162.13
-2,-2,6:162.13
-1,-2,6:18.5
0,-2,6:17.13
3,-2,6:162.13
4,-2,6:162.13
5,-1,6:162.13
6,-1,6:162.13
7,-1,6:191.0
8,-1,6:18.13
9,-1,6:18.13
10,-1,6:18.13
-5,0,6:18.5
3,0,6:18.13
6,0,6:17.13
8,0,6:18.13
-5,1,6:17.13
-4,1,6:162.13
-3,1,6:17.13
-2,1,6:162.13
-1,1,6:17.13
7,1,6:18.13
-8,2,6:18.13
-7,2,6:18.13
-6,2,6:18.13
-5,2,6:18.13
-1,2,6:17.13
0,2,6:18.13
5,2,6:18.13
8,2,6:18.13
-2,3,6:162.13
-1,3,6:162.13
-3,4,6:162.13
-2,4,6:162.13
0,4,6:18.13
-5,5,6:18.13
-6,6,6:18.13
-2,6,6:18.13
-3,7,6:18.13
-3,8,6:18.13
-9,-8,7:18.13
1,-8,7:18.13
-8,-7,7:18.13
-7,-7,7:17.13
1,-7,7:18.13
5,-7,7:18.13
-11,-6,7:18.13
-6,-6,7:162.13
4,-6,7:18.13
-10,-5,7:18.13
3,-5,7:18.13
-9,-4,7:18.13
-8,-4,7:162.13
0,-4,7:162.13
-7,-3,7:17.13
-6,-3,7:17.13
0,-3,7:162.13
2,-3,7:18.5
-9,-2,7:18.13
0,-2,7:162.13
2,-2,7:18.5
0,-1,7:18.5
7,-1,7:18.13
8,-1,7:191.0
9,-1,7:191.0
10,-1,7:191.0
-5,1,7:18.13
7,1,7:162.13
-8,2,7:17.13
-7,2,7:17.13
-6,2,7:17.13
-5,2,7:18.13
8,2,7:162.13
9,2,7:18.13
-3,3,7:191.0
-2,3,7:18.13
9,3,7:18.13
-4,4,7:162.13
-2,4,7:191.0
0,4,7:162.13
1,4,7:17.13
10,4,7:18.13
-7,5,7:191.0
-5,5,7:17.13
-2,5,7:191.0
0,5,7:17.13
2,5,7:18.13
-7,6,7:18.13
-6,6,7:162.13
-3,6,7:191.0
-2,6,7:191.0
3,6,7:18.13
-8,7,7:18.13
-3,7,7:191.0
0,7,7:18.13
-3,8,7:191.0
1,8,7:18.13
-3,9,7:18.13
-4,10,7:18.13
1,-11,8:18.13
-5,-10,8:18.13
1,-10,8:18.13
-4,-9,8:18.13
1,-9,8:18.13
-9,-8,8:162.13
-3,-8,8:18.13
-2,-8,8:17.13
1,-8,8:162.13
-8,-7,8:162.13
-7,-7,8:18.13
-1,-7,8:17.13
1,-7,8:17.13
2,-7,8:18.13
-11,-6,8:162.13
-6,-6,8:18.13
0,-6,8:17.13
4,-6,8:18.5
-10,-5,8:162.13
-8,-5,8:18.5
-4,-5,8:18.13
0,-5,8:162.13
5,-5,8:191.0
-9,-4,8:162.13
6,-4,8:18.13
5,-3,8:18.13
-9,-2,8:162.13
-8,-2,8:162.13
0,-2,8:17.13
-11,-1,8:18.13
-10,-1,8:18.13
1,-1,8:17.13
3,-1,8:162.13
8,-1,8:18.13
9,-1,8:18.13
10,-1,8:18.13
2,0,8:162.13
3,0,8:18.13
-4,1,8:191.0
-2,1,8:18.13
7,1,8:18.13
-8,2,8:18.13
-7,2,8:18.13
-6,2,8:18.13
8,2,8:18.13
9,3,8:162.13
-6,4,8:18.13
1,4,8:18.13
10,4,8:162.13
-5,5,8:18.13
0,5,8:191.0
2,5,8:162.13
-7,6,8:162.13
-6,6,8:18.13
-2,6,8:18.13
0,6,8:191.0
3,6,8:162.13
4,6,8:18.13
-8,7,8:162.13
-3,7,8:18.13
0,7,8:191.0
5,7,8:18.13
-3,8,8:18.13
1,8,8:191.0
-4,9,8:191.0
-3,9,8:191.0
1,9,8:18.13
-4,10,8:191.0
1,10,8:18.13
1,-11,9:17.13
-5,-10,9:17.13
1,-10,9:17.13
-4,-9,9:162.13
1,-9,9:17.13
-9,-8,9:18.13
-3,-8,9:17.13
-2,-8,9:18.13
0,-8,9:18.13
1,-8,9:18.13
-8,-7,9:18.13
-4,-7,9:18.13
1,-7,9:18.13
-11,-6,9:18.13
-4,-6,9:18.13
4,-6,9:18.13
-10,-5,9:18.13
-9,-4,9:18.13
2,-4,9:162.13
6,-4,9:162.13
7,-4,9:18.13
1,-3,9:162.13
4,-3,9:18.13
5,-3,9:162.13
-9,-2,9:18.13
-6,-2,9:18.5
-2,-2,9:191.0
0,-2,9:162.13
4,-2,9:162.13
-11,-1,9:17.13
-10,-1,9:17.13
-1,-1,9:17.13
2,-1,9:18.13
3,-1,9:18.13
3,1,9:162.13
3,2,9:191.0
4,2,9:18.13
4,3,9:18.13
9,3,9:18.13
1,4,9:18.13
10,4,9:18.13
2,5,9:18.13
-7,6,9:18.13
1,6,9:18.13
3,6,9:18.13
4,6,9:191.0
-8,7,9:18.13
0,7,9:18.13
4,7,9:191.0
5,7,9:191.0
1,8,9:18.13
-3,9,9:18.13
1,9,9:191.0
-4,10,9:18.13
1,10,9:191.0
1,-11,10:18.13
-5,-10,10:18.13
1,-10,10:18.13
-4,-9,10:18.13
1,-9,10:18.13
-3,-8,10:18.13
6,-8,10:18.13
5,-7,10:18.13
-8,-6,10:18.13
4,-6,10:162.13
-3,-5,10:18.13
-2,-5,10:18.13
2,-5,10:18.13
3,-5,10:162.13
6,-4,10:18.13
7,-4,10:18.13
-3,-3,10:18.5
-2,-3,10:162.13
4,-3,10:18.13
5,-3,10:18.13
-8,-2,10:18.5
-1,-2,10:162.13
0,-2,10:17.13
-11,-1,10:18.13
-10,-1,10:18.13
-2,-1,10:17.13
-4,0,10:17.13
-3,0,10:17.13
1,0,10:191.0
-3,1,10:162.13
-8,2,10:18.13
-7,2,10:18.13
4,2,10:17.13
4,3,10:17.13
5,3,10:191.0
-6,4,10:18.13
-5,4,10:18.13
-2,4,10:18.13
5,4,10:18.13
6,5,10:18.13
4,6,10:18.13
5,7,10:18.13
1,9,10:18.13
1,10,10:18.13
-2,-9,11:18.13
-5,-8,11:18.13
-2,-8,11:18.13
-1,-8,11:18.13
6,-8,11:162.13
-5,-7,11:18.13
5,-7,11:162.13
-9,-6,11:18.13
-8,-6,11:17.13
-3,-6,11:17.13
4,-6,11:18.13
-7,-5,11:162.13
-6,-5,11:17.13
-4,-5,11:17.13
-5,-4,11:162.13
-4,-4,11:162.13
-9,-3,11:18.13
-8,-3,11:18.5
-3,-3,11:162.13
-1,-2,11:18.13
0,-2,11:17.13
0,-1,11:162.13
2,-1,11:18.13
-4,0,11:18.13
-6,1,11:17.13
-5,1,11:17.13
-8,2,11:17.13
-7,2,11:162.13
-4,2,11:162.13
-10,3,11:18.13
-9,3,11:18.13
-4,3,11:162.13
4,3,11:18.13
7,3,11:191.0
-5,4,11:162.13
5,4,11:162.13
-5,5,11:18.13
6,5,11:17.13
-6,6,11:18.13
7,6,11:18.13
-1,-11,12:18.13
-6,-10,12:18.13
-1,-10,12:18.13
-6,-9,12:18.13
-2,-9,12:191.0
-1,-9,12:191.0
-5,-8,12:162.13
-2,-8,12:191.0
0,-8,12:191.0
6,-8,12:18.13
-5,-7,12:17.13
-3,-7,12:162.13
1,-7,12:191.0
5,-7,12:18.13
-9,-6,12:162.13
-8,-6,12:18.13
-5,-6,12:17.13
-4,-6,12:18.13
1,-6,12:18.13
3,-5,12:18.13
4,-5,12:18.13
-9,-4,12:18.13
5,-4,12:191.0
-9,-3,12:17.13
-8,-3,12:162.13
-7,-3,12:162.13
-6,-3,12:17.13
-2,-3,12:18.13
1,-3,12:17.13
-11,-2,12:18.13
-10,-2,12:18.13
0,-2,12:162.13
1,-2,12:17.13
0,-1,12:18.13
5,-1,12:18.13
-1,0,12:17.13
-1,1,12:17.13
4,1,12:18.13
5,1,12:191.0
-8,2,12:18.13
-7,2,12:18.13
-1,2,12:162.13
-10,3,12:17.13
-9,3,12:162.13
-6,4,12:18.13
-5,4,12:18.13
5,4,12:18.13
-5,5,12:162.13
-2,5,12:18.13
6,5,12:18.13
-6,6,12:17.13
-2,6,12:18.13
7,6,12:162.13
-1,-11,13:191.0
-6,-10,13:162.13
-1,-10,13:191.0
-6,-9,13:162.13
-2,-9,13:18.13
-1,-9,13:191.0
-5,-8,13:18.13
-2,-8,13:18.13
-5,-7,13:18.13
3,-7,13:18.13
-9,-6,13:18.13
0,-6,13:18.13
1,-6,13:18.13
2,-6,13:18.13
-8,-5,13:18.13
2,-5,13:162.13
-1,-4,13:191.0
1,-4,13:17.13
2,-4,13:18.13
-9,-3,13:18.13
0,-3,13:191.0
1,-3,13:18.13
5,-3,13:18.13
6,-3,13:18.13
7,-3,13:18.13
-11,-2,13:162.13
-10,-2,13:17.13
0,-2,13:162.13
2,-2,13:17.13
3,-2,13:17.13
4,-2,13:17.13
-5,-1,13:18.13
0,-1,13:162.13
-2,0,13:18.13
1,0,13:162.13
-1,2,13:191.0
6,2,13:18.13
-10,3,13:18.13
-9,3,13:18.13
-2,3,13:18.13
-1,3,13:191.0
5,3,13:191.0
-2,4,13:191.0
-1,4,13:191.0
2,4,13:18.13
-5,5,13:18.13
-3,5,13:18.13
-2,5,13:191.0
-6,6,13:18.13
-2,6,13:191.0
7,6,13:18.13
-3,7,13:18.13
-2,7,13:191.0
-3,8,13:18.13
-1,-11,14:18.13
-6,-10,14:18.13
-1,-10,14:18.13
-6,-9,14:18.13
-4,-9,14:191.0
5,-9,14:18.13
-2,-8,14:18.13
3,-8,14:191.0
4,-8,14:18.13
3,-7,14:191.0
-6,-6,14:18.13
2,-6,14:191.0
3,-6,14:191.0
2,-5,14:191.0
3,-3,14:18.13
5,-3,14:17.13
6,-3,14:162.13
7,-3,14:17.13
8,-3,14:18.13
9,-3,14:18.13
-11,-2,14:18.13
-10,-2,14:18.13
0,-2,14:17.13
3,-2,14:191.0
4,-2,14:191.0
5,-2,14:191.0
-8,-1,14:18.13
-1,-1,14:17.13
5,-1,14:191.0
6,-1,14:18.13
8,-1,14:18.13
-2,0,14:17.13
6,0,14:18.13
7,0,14:18.13
1,1,14:162.13
2,1,14:17.13
3,1,14:162.13
-7,2,14:191.0
1,2,14:191.0
2,2,14:191.0
4,2,14:18.13
5,2,14:18.13
6,2,14:18.13
2,3,14:191.0
1,4,14:18.13
2,4,14:191.0
-2,5,14:18.13
2,5,14:18.13
-2,6,14:18.13
3,6,14:18.13
7,6,14:18.13
-3,7,14:191.0
-2,7,14:191.0
3,7,14:18.13
-3,8,14:191.0
-1,-9,15:18.13
5,-9,15:191.0
3,-8,15:191.0
4,-8,15:191.0
5,-8,15:191.0
3,-7,15:18.13
4,-7,15:18.13
-4,-6,15:18.13
-1,-6,15:18.13
0,-6,15:18.13
-3,-5,15:18.13
-2,-4,15:162.13
0,-4,15:162.13
-1,-3,15:162.13
0,-3,15:17.13
5,-3,15:18.13
6,-3,15:18.13
7,-3,15:18.13
8,-3,15:17.13
9,-3,15:162.13
0,-2,15:162.13
1,-2,15:143.1
-6,-1,15:18.13
-4,-1,15:162.13
2,-1,15:191.0
5,-1,15:191.0
6,-1,15:191.0
-3,0,15:17.13
-2,0,15:18.13
6,0,15:191.0
7,0,15:191.0
8,0,15:18.13
-7,1,15:18.13
-3,1,15:17.13
3,1,15:18.13
-7,2,15:18.13
-4,2,15:18.13
4,2,15:17.13
5,2,15:17.13
6,2,15:162.13
8,2,15:18.13
2,4,15:18.13
1,5,15:18.13
2,5,15:191.0
2,6,15:191.0
3,6,15:191.0
-3,7,15:18.13
3,7,15:191.0
-3,8,15:18.13
5,-9,16:18.13
0,-8,16:18.13
4,-8,16:18.13
-5,-7,16:18.13
-4,-7,16:18.13
-2,-7,16:191.0
0,-7,16:18.13
1,-7,16:18.13
-4,-6,16:17.13
-2,-6,16:18.13
0,-6,16:17.13
-3,-5,16:162.13
0,-5,16:17.13
-5,-4,16:18.13
-2,-4,16:191.0
4,-3,16:191.0
8,-3,16:18.13
9,-3,16:18.13
-8,-2,16:18.13
-7,-2,16:18.13
-6,-2,16:191.0
0,-2,16:17.13
-6,-1,16:191.0
-5,-1,16:191.0
-4,-1,16:191.0
-3,-1,16:191.0
-2,-1,16:18.13
0,-1,16:17.13
6,-1,16:18.13
-1,0,16:17.13
7,0,16:18.13
8,0,16:191.0
-7,1,16:18.13
-6,2,16:18.13
-4,2,16:17.13
-3,2,16:162.13
4,2,16:18.13
5,2,16:18.13
6,2,16:18.13
-4,3,16:162.13
-5,4,16:18.13
-1,4,16:18.13
-6,5,16:18.13
2,5,16:18.13
3,6,16:18.13
3,7,16:18.13
0,-10,17:18.13
0,-9,17:18.13
0,-8,17:17.13
-5,-7,17:162.13
0,-7,17:17.13
-4,-6,17:18.13
-1,-6,17:18.13
0,-6,17:18.13
2,-6,17:18.13
-3,-5,17:18.13
3,-5,17:191.0
4,-5,17:18.13
2,-4,17:17.13
3,-4,17:18.13
4,-4,17:191.0
1,-3,17:17.13
-8,-2,17:191.0
-7,-2,17:191.0
-6,-2,17:191.0
-2,-2,17:18.13
-1,-2,17:162.13
0,-2,17:162.13
3,-2,17:18.13
4,-2,17:18.13
-6,-1,17:18.13
-5,-1,17:18.13
1,-1,17:17.13
2,-1,17:17.13
6,-1,17:191.0
-3,0,17:191.0
-2,0,17:18.13
1,0,17:162.13
5,0,17:18.13
7,0,17:18.13
8,0,17:18.13
-9,1,17:18.13
-8,1,17:18.13
-7,1,17:17.13
-1,1,17:162.13
-6,2,17:17.13
-5,2,17:17.13
-5,3,17:191.0
-4,3,17:191.0
-6,4,17:191.0
-5,4,17:191.0
-7,5,17:191.0
-6,5,17:191.0
-7,6,17:18.13
0,-10,18:17.13
0,-9,18:17.13
0,-8,18:18.13
-5,-7,18:18.13
0,-7,18:18.13
5,-6,18:18.13
2,-5,18:18.13
4,-5,18:162.13
3,-4,18:162.13
4,-4,18:18.13
-6,-3,18:18.13
-5,-3,18:18.13
-3,-3,18:162.13
0,-3,18:162.13
-8,-2,18:18.13
-7,-2,18:18.13
-2,-2,18:17.13
0,-2,18:17.13
4,-2,18:17.13
5,-2,18:18.13
6,-2,18:18.13
1,-1,18:18.13
3,-1,18:17.13
1,0,18:18.13
-9,1,18:162.13
-8,1,18:17.13
-7,1,18:18.13
2,1,18:162.13
4,1,18:18.13
-6,2,18:18.13
-1,2,18:162.13
3,2,18:18.13
-7,3,18:191.0
-4,3,18:18.13
-1,3,18:18.13
3,3,18:18.13
-5,4,18:18.13
-2,4,18:18.13
-7,5,18:191.0
-6,5,18:18.13
-7,6,18:191.0
0,-10,19:18.13
0,-9,19:18.13
-4,-8,19:18.13
-2,-6,19:191.0
-1,-6,19:18.13
2,-6,19:18.13
5,-6,19:17.13
-3,-5,19:18.13
-1,-5,19:18.13
4,-5,19:18.13
-8,-4,19:18.13
-7,-4,19:18.13
-5,-4,19:18.13
0,-4,19:162.13
3,-4,19:18.13
-6,-3,19:17.13
-5,-3,19:17.13
-4,-3,19:162.13
1,-3,19:18.13
2,-3,19:18.13
0,-2,19:17.13
4,-2,19:18.13
5,-2,19:162.13
6,-2,19:17.13
-2,-1,19:17.13
-1,-1,19:162.13
1,-1,19:18.5
-9,1,19:18.13
-8,1,19:18.13
2,1,19:162.13
3,1,19:18.13
4,1,19:18.13
-3,2,19:18.13
-2,2,19:18.13
3,2,19:162.13
-1,3,19:162.13
3,3,19:162.13
-2,4,19:17.13
4,4,19:18.13
-2,5,19:18.13
-7,6,19:18.13
-1,-7,20:18.13
-1,-6,20:17.13
0,-6,20:18.13
5,-6,20:18.13
0,-5,20:17.13
3,-5,20:18.13
-8,-4,20:17.13
-7,-4,20:17.13
-6,-4,20:18.13
-5,-4,20:18.13
-3,-4,20:191.0
-6,-3,20:18.13
-5,-3,20:18.13
-4,-3,20:18.13
-2,-3,20:18.13
0,-2,20:17.13
1,-2,20:191.0
5,-2,20:18.13
6,-2,20:18.13
0,-1,20:191.0
-3,0,20:162.13
-5,1,20:18.13
-4,1,20:17.13
-6,2,20:18.13
0,2,20:18.5
3,2,20:18.13
-1,3,20:18.13
0,3,20:18.5
3,3,20:18.13
-2,4,20:18.13
4,4,20:162.13
-2,5,20:162.13
-1,-8,21:18.13
-1,-7,21:191.0
-1,-6,21:18.13
0,-6,21:18.13
-8,-4,21:18.13
-7,-4,21:18.13
2,-3,21:18.13
-1,-2,21:17.13
0,-2,21:162.13
1,-2,21:17.13
2,-2,21:17.13
-5,-1,21:18.13
-4,0,21:18.13
-6,1,21:18.13
-5,1,21:162.13
-4,1,21:162.13
-7,2,21:18.13
-6,2,21:17.13
-8,3,21:18.13
3,3,21:18.13
4,4,21:18.13
-2,5,21:18.13
-1,-8,22:191.0
-1,-7,22:18.13
2,-7,22:18.13
4,-6,22:18.5
3,-5,22:18.13
-4,-4,22:18.13
1,-3,22:162.13
4,-3,22:17.13
5,-3,22:18.13
6,-3,22:18.13
-3,-2,22:162.13
-2,-2,22:162.13
0,-2,22:162.13
2,-2,22:18.5
3,-2,22:162.13
4,-2,22:18.13
-1,-1,22:18.5
1,-1,22:17.13
2,-1,22:18.5
-7,1,22:18.13
-6,1,22:162.13
-5,1,22:18.13
2,1,22:18.5
-7,2,22:17.13
-6,2,22:162.13
3,2,22:18.5
-8,3,22:17.13
-1,3,22:18.5
-1,-8,23:18.13
3,-7,23:191.0
3,-6,23:18.13
2,-5,23:18.13
1,-4,23:162.13
-5,-3,23:18.13
0,-3,23:143.4
4,-3,23:18.13
5,-3,23:162.13
6,-3,23:17.13
-4,-2,23:17.13
0,-2,23:17.13
5,-2,23:18.13
-1,-1,23:162.13
0,-1,23:17.13
2,-1,23:162.13
0,0,23:18.5
-6,1,23:18.13
-7,2,23:18.13
-6,2,23:18.13
-8,3,23:18.13
3,-7,24:18.13
-3,-6,24:18.13
2,-6,24:18.13
3,-6,24:17.13
-2,-5,24:18.13
2,-5,24:162.13
3,-5,24:18.13
-7,-3,24:18.13
-6,-3,24:18.13
-5,-3,24:162.13
-1,-3,24:162.13
5,-3,24:18.13
6,-3,24:18.13
-5,-2,24:18.13
-2,-2,24:18.5
0,-2,24:162.13
-5,-1,24:18.5
5,-1,24:18.5
-2,0,24:162.13
1,0,24:17.13
3,0,24:162.13
4,0,24:17.13
5,1,24:18.13
-3,2,24:18.13
1,3,24:191.0
3,-7,25:17.13
-3,-6,25:18.13
3,-6,25:18.13
-2,-5,25:162.13
2,-5,25:18.13
-7,-4,25:18.13
-1,-4,25:17.13
3,-4,25:18.13
-8,-3,25:18.13
-7,-3,25:17.13
-6,-3,25:17.13
-5,-3,25:18.13
-7,-2,25:18.13
-6,-2,25:18.13
-2,-2,25:18.5
0,-2,25:17.13
1,-2,25:17.13
1,-1,25:191.0
2,-1,25:18.5
5,0,25:18.13
-4,1,25:18.5
-3,1,25:162.5
-2,1,25:17.13
1,1,25:17.13
5,1,25:162.13
6,1,25:18.13
-5,2,25:18.5
-3,2,25:162.13
1,2,25:18.13
-4,3,25:18.13
-3,3,25:18.13
-2,-7,26:18.13
3,-7,26:18.13
-3,-6,26:162.13
-2,-5,26:18.13
-8,-4,26:18.13
-8,-3,26:17.13
-7,-3,26:18.13
-6,-3,26:18.13
3,-3,26:17.13
4,-3,26:18.13
-1,-2,26:162.13
0,-2,26:162.13
2,-2,26:162.13
3,-2,26:18.5
-1,1,26:18.5
5,1,26:18.13
-4,2,26:18.13
-3,2,26:18.13
1,2,26:162.13
-4,3,26:17.13
1,3,26:18.13
2,3,26:18.13
-5,4,26:18.13
-4,4,26:18.13
-3,-6,27:18.13
0,-5,27:18.13
-2,-4,27:18.13
-8,-3,27:18.13
-2,-3,27:17.13
0,-3,27:17.13
4,-3,27:17.13
5,-3,27:18.13
0,-2,27:162.13
4,-2,27:18.13
1,-1,27:162.13
2,0,27:18.13
-4,1,27:18.5
-3,1,27:18.5
2,1,27:18.5
1,2,27:162.1
-5,3,27:18.13
-4,3,27:18.13
1,3,27:18.13
2,3,27:162.13
-5,4,27:162.13
2,4,27:18.13
0,-6,28:18.13
0,-5,28:17.13
0,-4,28:17.13
-3,-3,28:18.13
-2,-3,28:17.13
4,-3,28:18.13
5,-3,28:17.13
-1,-2,28:143.2
0,-2,28:17.13
5,-1,28:18.5
2,0,28:17.13
3,1,28:18.13
-3,2,28:18.5
1,2,28:18.13
1,3,28:18.13
2,3,28:18.13
-5,4,28:18.13
2,4,28:17.13
0,-6,29:17.13
0,-5,29:18.13
-4,-4,29:18.13
-3,-4,29:18.13
3,-4,29:18.13
-3,-3,29:17.13
0,-3,29:18.13
1,-3,29:17.13
5,-3,29:18.13
0,-2,29:162.13
0,-1,29:17.13
-1,0,29:18.13
2,0,29:18.13
3,1,29:17.13
2,4,29:18.13
0,-6,30:18.13
4,-5,30:18.13
-5,-4,30:18.13
-4,-4,30:17.13
-3,-4,30:18.13
3,-4,30:17.13
4,-4,30:18.13
-3,-3,30:18.13
2,-3,30:162.13
-2,-2,30:17.13
-1,-2,30:162.13
0,-2,30:162.13
3,-2,30:191.0
-5,-1,30:18.13
-4,-1,30:18.13
-3,-1,30:18.13
0,0,30:162.13
-1,1,30:18.13
3,1,30:18.13
-2,-6,31:18.13
-1,-5,31:18.13
4,-5,31:17.13
-5,-4,31:17.13
-4,-4,31:18.13
-1,-4,31:191.0
3,-4,31:18.13
-1,-3,31:191.0
0,-3,31:162.13
2,-3,31:18.13
0,-2,31:17.13
-5,-1,31:162.13
-4,-1,31:162.13
-3,-1,31:17.13
-2,-1,31:18.13
1,-1,31:162.13
2,-1,31:162.13
3,0,31:18.13
4,0,31:18.13
-1,1,31:162.1
0,1,31:191.0
1,1,31:191.0
-1,2,31:18.13
1,2,31:191.0
-2,-6,32:191.0
-2,-5,32:191.0
-1,-5,32:191.0
4,-5,32:18.13
-5,-4,32:18.13
-1,-4,32:191.0
-1,-3,32:18.13
0,-2,32:162.13
-5,-1,32:18.13
-4,-1,32:18.13
-3,-1,32:18.13
3,-1,32:18.13
3,0,32:162.13
4,0,32:162.13
-1,1,32:18.13
-1,2,32:162.1
1,2,32:191.0
-1,3,32:18.13
-2,-6,33:18.13
2,-6,33:18.13
-1,-5,33:18.13
2,-5,33:18.13
1,-4,33:17.13
2,-4,33:18.13
-3,-3,33:18.13
1,-3,33:162.13
-1,-2,33:162.13
0,-2,33:162.13
-1,-1,33:17.13
1,-1,33:17.13
-3,0,33:18.13
2,0,33:18.13
3,0,33:18.13
4,0,33:18.13
-1,2,33:18.13
-1,3,33:162.1
2,-6,34:162.13
2,-5,34:17.13
2,-4,34:18.13
-5,-3,34:18.13
-4,-3,34:18.13
-3,-3,34:162.13
-2,-2,34:162.13
0,-2,34:17.13
1,-2,34:17.13
3,-2,34:18.13
-2,-1,34:17.13
-4,0,34:18.13
-3,0,34:162.13
-1,0,34:191.0
2,0,34:162.13
-5,1,34:18.13
2,1,34:18.13
3,1,34:18.13
-1,3,34:18.13
2,-6,35:18.13
-2,-5,35:18.13
2,-5,35:18.13
-1,-4,35:17.13
1,-4,35:18.13
-5,-3,35:17.13
-4,-3,35:162.13
-3,-3,35:18.13
-1,-3,35:162.13
2,-3,35:18.13
0,-2,35:162.13
2,-2,35:162.13
3,-2,35:17.13
4,-2,35:18.13
5,-2,35:18.13
0,-1,35:143.3
-4,0,35:17.13
-3,0,35:18.13
2,0,35:18.13
-5,1,35:17.13
-4,1,35:18.13
3,1,35:162.13
-2,-6,36:18.13
-3,-5,36:18.13
-2,-5,36:162.13
-5,-3,36:18.13
-4,-3,36:18.13
-2,-3,36:18.13
0,-2,36:162.13
3,-2,36:18.13
4,-2,36:162.13
5,-2,36:162.13
0,-1,36:17.13
-4,0,36:18.13
0,0,36:191.0
-5,1,36:18.13
-1,1,36:18.13
0,1,36:191.0
3,1,36:18.13
-1,2,36:18.13
-3,-6,37:18.13
-2,-6,37:162.13
-2,-5,37:18.13
0,-4,37:191.0
1,-4,37:18.13
1,-3,37:162.13
-2,-2,37:18.13
0,-2,37:17.13
1,-2,37:18.13
4,-2,37:18.13
5,-2,37:18.13
-1,1,37:191.0
0,1,37:191.0
-1,2,37:191.0
-1,3,37:18.13
-2,-6,38:18.13
1,-5,38:191.0
2,-5,38:18.13
1,-4,38:191.0
-3,-2,38:191.0
-2,-2,38:191.0
-1,-2,38:17.13
0,-2,38:17.13
-4,-1,38:18.13
-3,-1,38:18.13
1,-1,38:17.13
1,0,38:191.0
2,0,38:18.13
-1,1,38:18.13
-1,2,38:18.13
-1,3,38:191.0
1,-5,39:191.0
2,-5,39:191.0
-2,-4,39:18.13
1,-4,39:18.13
2,-4,39:18.13
-1,-3,39:17.13
-2,-2,39:18.13
-1,-2,39:18.13
0,-2,39:17.13
-4,-1,39:191.0
-3,-1,39:191.0
-3,0,39:18.13
2,0,39:17.13
3,1,39:18.13
-1,3,39:18.13
-3,-5,40:18.13
-2,-5,40:18.13
2,-5,40:18.13
-2,-4,40:17.13
0,-2,40:162.13
-4,-1,40:18.13
-3,-1,40:18.13
-2,-1,40:191.0
-1,-1,40:17.13
0,-1,40:18.13
-2,0,40:18.13
2,0,40:18.13
2,1,40:18.13
3,1,40:162.13
-3,-5,41:162.13
-3,-4,41:18.13
-2,-4,41:18.13
2,-4,41:18.13
0,-3,41:18.13
1,-3,41:191.0
2,-3,41:191.0
0,-2,41:17.13
1,-2,41:191.0
-2,-1,41:191.0
-3,0,41:191.0
-2,0,41:191.0
-3,1,41:18.13
3,1,41:18.13
-3,-5,42:18.13
2,-4,42:191.0
0,-3,42:18.13
1,-3,42:18.13
2,-3,42:191.0
-2,-2,42:18.13
0,-2,42:162.13
1,-2,42:18.13
0,-1,42:18.13
-3,0,42:191.0
-2,0,42:18.13
-3,1,42:191.0
2,-4,43:18.13
-1,-3,43:18.13
0,-3,43:18.13
-1,-2,43:18.13
0,-2,43:191.0
2,-2,43:18.13
0,-1,43:18.13
-3,1,43:18.13
-1,1,43:18.13
-2,-4,44:18.13
0,-3,44:18.13
-1,-2,44:18.13
0,-2,44:191.0
-2,-1,44:18.13
-1,-1,44:18.13
0,-1,44:191.0
2,-1,44:18.13
-2,0,44:18.13
0,0,44:18.13
