[META]
version=2.0
spawnOnBlockType=2
spawnSunlight=True
spawnDarkness=True
spawnWater=False
spawnLava=False
underFill=False
randomRotation=True
dig=True
tree=True
branch=False
needsFoundation=True
rarity=100
collisionPercentage=20
spawnElevationMin=0
spawnElevationMax=200
spawnInBiome=Custom
[DATA]
0,-1,0:17.12
0,0,0:17.12
1,0,0:17.12
0,1,0:17.12
0,0,1:17.12
1,0,1:17.12
-1,-2,2:18.7
1,-2,2:18.7
0,-1,2:18.7
0,0,2:17.12
1,1,2:17.12
1,3,2:18.15
0,-4,3:18.7
0,-3,3:18.7
0,-1,3:17.12
-2,1,3:18.7
-1,1,3:17.12
0,1,3:18.7
1,1,3:18.7
2,1,3:18.7
-3,2,3:18.7
-1,2,3:18.7
0,2,3:18.7
2,2,3:17.12
3,2,3:18.7
0,3,3:18.15
1,3,3:18.15
2,3,3:18.15
0,-4,4:18.7
1,-4,4:18.7
-1,-3,4:18.7
0,-3,4:17.12
0,-2,4:17.12
2,-1,4:18.7
-3,0,4:18.7
-2,0,4:18.7
-1,0,4:18.7
1,0,4:18.7
2,0,4:18.7
-2,1,4:18.7
1,1,4:18.7
2,1,4:18.7
3,1,4:18.7
-3,2,4:18.7
-2,2,4:17.12
1,2,4:18.7
2,2,4:17.12
-3,3,4:18.15
1,3,4:18.15
0,-4,5:18.7
0,-3,5:18.7
-1,-2,5:18.7
0,-2,5:18.7
0,-1,5:18.7
1,-1,5:18.7
2,-1,5:18.7
-2,0,5:18.7
2,0,5:18.7
-3,1,5:18.7
0,1,5:18.7
3,1,5:18.7
0,2,5:18.7
1,2,5:18.7
3,2,5:18.7
-2,3,5:18.15
-1,3,5:18.15
0,3,5:18.15
2,3,5:18.7
3,3,5:18.7
0,-2,6:18.7
1,-2,6:18.7
0,-1,6:18.7
-2,0,6:18.7
1,0,6:18.7
2,0,6:18.7
3,0,6:18.7
-1,1,6:18.7
2,1,6:18.7
-1,2,6:18.7
1,2,6:18.7
2,2,6:18.7
3,2,6:18.7
-1,3,6:18.15
2,3,6:127.2
0,3,6:127.1
-2,3,6:127.3
1,1,6:127.3
-2,1,6:127.3
4,0,6:127.1
-1,-1,6:127.3
3,4,5:127.2
-3,3,5:127.3
4,2,5:127.1
2,2,5:127.0
0,0,5:127.0
-3,0,5:127.3
3,-1,5:127.1
1,-2,5:127.1
-1,-3,5:127.3
1,-4,5:127.1
2,3,4:127.2
-2,3,4:127.2
3,2,4:127.1
-4,2,4:127.3
4,1,4:127.1
-1,1,4:127.2
-3,1,4:127.3
3,0,4:127.1
0,-1,4:127.2
-1,-2,4:127.3
1,-3,4:127.1
1,4,3:127.2
-1,3,3:127.3
3,1,3:127.1
-1,0,3:127.0
0,-2,3:127.0
-1,-3,3:127.3
1,-4,3:127.1
0,3,2:127.3
1,2,2:127.0
1,0,2:127.1
-1,-1,2:127.2
1,-3,2:127.0
