[META]
version=2.0
spawnOnBlockType=2
spawnSunlight=True
spawnDarkness=True
spawnWater=False
spawnLava=False
underFill=False
randomRotation=True
dig=True
tree=True
branch=False
needsFoundation=True
rarity=100
collisionPercentage=20
spawnElevationMin=0
spawnElevationMax=200
spawnInBiome=Custom
[DATA]
-1,-1,0:188.0
-1,0,0:188.0
0,0,0:188.0
1,0,0:188.0
-1,1,0:188.0
1,1,0:188.0
0,0,1:17.12
0,0,2:188.0
-1,-2,3:18.4
-2,-1,3:18.6
-1,-1,3:18.4
-1,0,3:188.0
0,0,3:188.0
1,0,3:18.6
2,0,3:18.6
-1,1,3:18.4
1,1,3:18.6
2,1,3:18.6
-1,2,3:188.0
1,2,3:18.4
-2,-2,4:188.0
-1,-2,4:188.0
0,-2,4:18.6
-2,-1,4:18.4
-1,0,4:18.4
0,0,4:188.0
1,0,4:18.6
2,0,4:188.0
-1,1,4:18.6
0,1,4:18.6
1,1,4:18.4
-1,2,4:18.6
1,2,4:18.6
2,2,4:18.6
0,-2,5:18.6
-2,-1,5:18.6
-1,-1,5:18.6
0,-1,5:18.4
-2,0,5:18.6
-1,0,5:18.4
1,0,5:18.4
-2,1,5:18.6
0,1,5:18.6
-1,2,5:188.0
0,2,5:18.6
1,2,5:188.0
0,-2,6:18.6
0,-1,6:188.0
-2,0,6:18.6
-1,0,6:18.4
0,0,6:18.4
-2,1,6:18.4
1,1,6:18.4
-2,2,6:18.6
-1,2,6:18.4
-1,0,7:18.4
-2,1,7:18.6
-1,1,7:18.4
0,1,7:188.0
-1,2,7:18.6
