[META]
version=2.0
spawnOnBlockType=2
spawnSunlight=True
spawnDarkness=True
spawnWater=False
spawnLava=False
underFill=False
randomRotation=True
dig=True
tree=True
branch=False
needsFoundation=True
rarity=100
collisionPercentage=20
spawnElevationMin=0
spawnElevationMax=200
spawnInBiome=Custom
[DATA]
0,-1,0:17.12
-2,0,0:188.0
-1,0,0:188.0
0,0,0:188.0
-2,1,0:188.0
0,1,0:188.0
-1,0,1:17.12
-1,0,2:188.0
-1,-2,3:18.14
-2,-1,3:18.14
-1,-1,3:18.14
0,-1,3:18.12
-2,0,3:18.12
-1,0,3:188.0
0,0,3:18.12
-1,1,3:18.14
-2,-2,4:188.0
-1,-2,4:18.14
0,-2,4:18.12
-2,-1,4:188.0
-1,-1,4:18.12
0,-1,4:18.12
-2,0,4:18.4
-1,0,4:188.0
0,0,4:18.14
1,0,4:18.12
0,1,4:18.12
-2,-1,5:18.4
1,-1,5:18.14
-2,0,5:18.12
-1,0,5:18.14
0,0,5:18.14
-2,1,5:18.12
0,1,5:188.0
1,1,5:18.12
-2,-1,6:188.0
-2,0,6:18.12
-1,0,6:188.0
0,0,6:18.12
