[META]
version=2.0
spawnOnBlockType=2
spawnSunlight=True
spawnDarkness=True
spawnWater=False
spawnLava=False
underFill=False
randomRotation=True
dig=True
tree=False
branch=False
needsFoundation=True
rarity=100
collisionPercentage=20
spawnElevationMin=0
spawnElevationMax=200
spawnInBiome=Custom
[DATA]
0,-1,0:17.13
-1,0,0:17.13
0,0,0:17.13
1,0,0:17.13
0,1,0:17.13
0,-1,1:17.13
0,0,1:17.13
1,0,1:17.13
0,0,2:17.13
0,0,3:17.13
0,0,4:17.1
0,1,4:18.5
0,-1,5:18.13
1,-1,5:18.13
-1,0,5:18.13
0,0,5:17.13
1,0,5:18.13
0,1,5:18.13
-1,-1,6:18.5
0,-1,6:18.13
1,-1,6:18.5
-1,0,6:18.13
0,0,6:17.13
1,0,6:18.13
-1,1,6:18.5
0,1,6:18.13
1,1,6:18.5
0,2,6:18.13
0,-2,7:18.13
-2,-1,7:18.5
-1,-1,7:18.13
0,-1,7:18.13
1,-1,7:18.13
-2,0,7:18.13
-1,0,7:18.13
0,0,7:17.13
1,0,7:18.13
2,0,7:18.13
-2,1,7:18.5
-1,1,7:18.13
0,1,7:18.13
1,1,7:18.13
2,1,7:18.5
-1,2,7:18.13
0,2,7:18.13
1,2,7:18.13
-1,-2,8:18.13
0,-2,8:18.13
1,-2,8:18.13
-2,-1,8:18.13
-1,-1,8:18.13
0,-1,8:18.13
1,-1,8:18.13
2,-1,8:18.13
-3,0,8:18.5
-2,0,8:18.13
-1,0,8:18.13
0,0,8:17.13
1,0,8:18.13
2,0,8:18.13
-2,1,8:18.13
-1,1,8:18.13
0,1,8:18.13
1,1,8:18.13
2,1,8:18.13
3,1,8:18.5
-2,2,8:18.5
0,2,8:18.13
1,2,8:18.13
0,3,8:18.5
0,-3,9:18.5
-1,-2,9:18.13
0,-2,9:18.5
1,-2,9:18.13
2,-2,9:18.13
-2,-1,9:18.13
0,-1,9:18.13
1,-1,9:18.13
2,-1,9:18.13
3,-1,9:18.13
-3,0,9:18.5
-2,0,9:18.13
-1,0,9:18.13
0,0,9:17.13
1,0,9:18.13
2,0,9:18.13
3,0,9:18.13
-3,1,9:18.5
-2,1,9:18.13
0,1,9:18.13
1,1,9:18.5
2,1,9:18.13
-1,2,9:18.13
0,2,9:18.13
1,2,9:18.5
2,2,9:18.13
0,3,9:18.13
0,-3,10:18.5
1,-3,10:18.5
0,-2,10:18.5
1,-2,10:18.13
2,-2,10:18.13
0,-1,10:18.13
1,-1,10:18.13
2,-1,10:18.13
-3,0,10:18.5
-2,0,10:18.13
-1,0,10:18.13
0,0,10:17.13
1,0,10:18.13
2,0,10:18.13
3,0,10:18.13
-2,1,10:18.13
0,1,10:18.13
1,1,10:18.5
2,1,10:18.5
3,1,10:18.5
-2,2,10:18.5
0,2,10:18.13
1,2,10:18.5
0,3,10:18.5
1,3,10:18.5
0,-3,11:18.5
-2,-2,11:18.5
0,-2,11:18.13
1,-2,11:18.13
-2,-1,11:18.5
-1,-1,11:18.13
0,-1,11:18.13
1,-1,11:18.13
2,-1,11:18.13
-3,0,11:18.5
-2,0,11:18.13
-1,0,11:18.13
0,0,11:17.13
1,0,11:18.13
2,0,11:18.13
3,0,11:18.13
-1,1,11:18.13
0,1,11:18.13
1,1,11:18.13
-2,2,11:18.5
-1,2,11:18.13
0,2,11:18.13
1,2,11:18.13
2,2,11:18.5
-1,3,11:18.5
1,3,11:18.5
2,3,11:18.5
0,-3,12:18.5
1,-3,12:18.5
-1,-2,12:18.13
0,-2,12:18.13
1,-2,12:18.13
2,-2,12:18.13
-2,-1,12:18.13
-1,-1,12:18.13
0,-1,12:18.13
1,-1,12:18.13
2,-1,12:18.13
-3,0,12:18.5
-2,0,12:18.13
-1,0,12:18.13
0,0,12:17.13
1,0,12:18.13
2,0,12:18.13
-3,1,12:18.5
-2,1,12:18.13
-1,1,12:18.13
0,1,12:18.13
1,1,12:18.13
2,1,12:18.13
-1,2,12:18.13
0,2,12:18.13
1,2,12:18.13
2,2,12:18.5
0,3,12:18.5
1,3,12:18.5
0,-3,13:18.5
-2,-2,13:18.5
0,-2,13:18.13
2,-2,13:18.5
-2,-1,13:18.13
0,-1,13:18.13
2,-1,13:18.13
-2,0,13:18.13
-1,0,13:18.13
0,0,13:17.13
1,0,13:18.13
2,0,13:18.13
-2,1,13:18.5
-1,1,13:18.13
0,1,13:18.13
1,1,13:18.5
2,1,13:18.13
-1,2,13:18.5
0,2,13:18.13
1,2,13:18.5
-1,-2,14:18.5
0,-2,14:18.13
1,-2,14:18.13
-2,-1,14:18.5
-1,-1,14:18.5
0,-1,14:18.13
2,-1,14:18.13
-1,0,14:18.13
0,0,14:17.13
1,0,14:18.13
2,0,14:18.13
-1,1,14:18.5
0,1,14:18.13
0,2,14:18.13
0,-2,15:18.13
2,-2,15:18.13
-1,-1,15:18.13
0,-1,15:18.13
1,-1,15:18.13
-2,0,15:18.13
-1,0,15:18.13
0,0,15:17.1
1,0,15:18.13
2,0,15:18.13
-2,1,15:18.13
-1,1,15:18.13
0,1,15:18.13
1,1,15:18.13
-1,2,15:18.13
0,2,15:18.13
1,2,15:18.13
-1,-2,16:18.13
0,-2,16:18.13
1,-2,16:18.13
-2,-1,16:18.13
-1,-1,16:18.13
0,-1,16:18.13
1,-1,16:18.13
2,-1,16:18.13
-2,0,16:18.13
-1,0,16:18.13
0,0,16:17.1
1,0,16:18.13
2,0,16:18.13
-2,1,16:18.13
-1,1,16:18.13
0,1,16:18.13
1,1,16:18.13
2,1,16:18.13
-1,2,16:18.13
-1,-2,17:18.13
0,-2,17:18.13
0,-1,17:18.13
2,-1,17:18.13
-2,0,17:18.13
-1,0,17:18.13
0,0,17:17.1
1,0,17:18.13
0,1,17:18.13
1,1,17:18.13
0,-1,18:18.13
-1,0,18:18.5
0,0,18:17.1
1,0,18:18.13
-1,1,18:18.5
0,1,18:18.13
0,0,19:18.5
0,0,20:18.13
0,0,21:18.13
