[META]
version=2.0
spawnOnBlockType=2
spawnSunlight=True
spawnDarkness=True
spawnWater=False
spawnLava=False
underFill=False
randomRotation=True
dig=True
tree=False
branch=False
needsFoundation=True
rarity=100
collisionPercentage=20
spawnElevationMin=0
spawnElevationMax=200
spawnInBiome=Custom
[DATA]
-1,0,0:17.1
-1,0,1:17.1
-1,0,2:17.1
-1,0,3:17.1
-1,0,4:17.1
-1,0,5:17.1
-1,0,6:17.1
-1,0,7:17.1
-1,0,8:17.1
-1,0,9:17.1
-1,0,10:17.1
-1,0,11:17.1
-1,0,12:17.1
-1,0,13:17.1
-1,0,14:17.1
5,-6,15:18.13
-1,0,15:17.13
6,5,15:18.13
4,-6,16:18.13
5,-6,16:18.13
-6,-5,16:18.13
3,-5,16:18.13
4,-5,16:18.13
-5,-4,16:18.13
-1,-1,16:18.13
-2,0,16:18.13
-1,0,16:17.13
1,0,16:18.13
2,4,16:18.13
3,4,16:18.13
4,4,16:18.13
5,4,16:18.13
4,5,16:18.13
5,5,16:18.13
-3,-7,17:18.13
3,-6,17:18.13
4,-6,17:18.13
-5,-5,17:18.13
3,-5,17:17.13
4,-5,17:17.13
5,-5,17:18.13
-6,-4,17:18.13
-5,-4,17:17.13
2,-4,17:18.13
3,-4,17:18.13
4,-4,17:18.13
-6,-3,17:18.13
-5,-3,17:17.13
2,-3,17:18.13
3,-3,17:18.13
-5,-2,17:18.13
-2,-1,17:18.13
0,-1,17:18.13
-2,0,17:188.0
-1,0,17:17.13
0,0,17:188.0
-1,1,17:18.13
0,1,17:18.13
1,1,17:18.13
1,3,17:17.13
2,3,17:18.13
3,3,17:18.13
-6,4,17:18.13
1,4,17:18.13
2,4,17:17.13
3,4,17:18.13
4,4,17:18.13
2,5,17:18.13
3,5,17:18.13
4,5,17:18.13
0,7,17:18.5
0,8,17:18.5
-3,-7,18:18.13
-2,-7,18:18.13
-3,-6,18:18.13
-2,-6,18:18.13
2,-5,18:18.13
3,-5,18:18.13
4,-5,18:18.13
-5,-4,18:18.13
-4,-4,18:18.13
-3,-4,18:18.13
1,-4,18:18.13
2,-4,18:18.13
3,-4,18:18.13
4,-4,18:18.13
-5,-3,18:18.13
-4,-3,18:18.13
-3,-3,18:18.13
1,-3,18:18.13
2,-3,18:18.13
3,-3,18:18.13
4,-3,18:18.13
-5,-2,18:18.13
-4,-2,18:18.13
-3,-2,18:17.13
-2,-2,18:18.13
1,-2,18:17.13
2,-2,18:18.13
-4,-1,18:18.13
-3,-1,18:17.13
-2,-1,18:17.13
-1,-1,18:18.13
1,-1,18:18.13
6,-1,18:18.13
-2,0,18:18.13
-1,0,18:17.13
0,0,18:18.13
1,0,18:18.13
-1,1,18:188.0
0,1,18:17.13
1,1,18:18.13
0,2,18:18.13
1,2,18:18.13
-6,3,18:18.13
-5,3,18:17.13
-4,3,18:18.13
0,3,18:18.13
1,3,18:17.13
2,3,18:18.13
-6,4,18:18.13
1,4,18:18.13
2,4,18:18.13
-1,6,18:18.13
-1,7,18:18.5
0,7,18:18.5
-1,8,18:18.5
0,8,18:18.5
-2,-6,19:18.13
-2,-5,19:18.13
-1,-5,19:18.13
-3,-4,19:18.13
-1,-4,19:18.13
0,-4,19:18.13
1,-4,19:18.13
-3,-3,19:18.13
-1,-3,19:18.13
0,-3,19:18.13
1,-3,19:18.13
-4,-2,19:18.13
-3,-2,19:18.13
0,-2,19:17.13
1,-2,19:17.13
2,-2,19:18.13
5,-2,19:18.13
-4,-1,19:18.13
-3,-1,19:18.13
-2,-1,19:18.13
1,-1,19:18.13
5,-1,19:18.13
6,-1,19:18.13
-2,0,19:18.13
-1,0,19:17.13
0,0,19:17.13
1,0,19:18.13
-4,1,19:18.13
-3,1,19:18.13
-1,1,19:18.13
0,1,19:18.13
-6,2,19:18.13
-5,2,19:18.13
-4,2,19:17.13
-1,2,19:18.13
0,2,19:18.13
-6,3,19:18.13
-5,3,19:17.13
-4,3,19:18.13
1,3,19:18.13
-5,4,19:18.13
-2,5,19:18.13
-1,5,19:18.13
-2,6,19:18.13
-1,6,19:18.13
-1,7,19:18.5
-1,8,19:18.5
-2,-4,20:18.13
3,-4,20:18.13
4,-4,20:18.13
5,-4,20:18.13
-2,-3,20:18.13
3,-3,20:18.13
4,-3,20:18.13
5,-3,20:18.13
-1,-2,20:18.13
0,-2,20:18.13
1,-2,20:18.13
3,-2,20:18.13
4,-2,20:18.13
5,-2,20:18.13
-2,-1,20:18.13
-1,-1,20:17.13
0,-1,20:18.13
-3,0,20:18.13
-2,0,20:17.13
-1,0,20:17.13
0,0,20:18.13
2,0,20:18.13
3,0,20:18.13
4,0,20:18.13
-4,1,20:18.13
-3,1,20:17.13
-2,1,20:18.13
-5,2,20:18.13
-4,2,20:17.13
-3,2,20:18.13
-2,2,20:18.13
-5,3,20:18.13
-4,3,20:18.13
-2,4,20:18.13
-1,4,20:18.13
-2,5,20:18.13
-1,5,20:18.13
0,-5,21:18.13
-1,-4,21:18.13
1,-4,21:18.13
4,-4,21:18.13
-1,-3,21:18.13
1,-3,21:18.13
2,-3,21:18.13
3,-3,21:18.13
4,-3,21:18.13
-4,-2,21:18.13
-3,-2,21:18.13
-1,-2,21:18.13
1,-2,21:18.13
2,-2,21:18.13
-3,-1,21:18.13
-2,-1,21:18.13
-1,-1,21:17.13
2,-1,21:18.13
-8,0,21:18.13
-7,0,21:18.13
-2,0,21:18.13
-1,0,21:17.13
0,0,21:18.13
1,0,21:18.13
2,0,21:17.13
3,0,21:18.13
4,0,21:18.13
-4,1,21:18.13
-3,1,21:18.13
-2,1,21:18.13
-1,1,21:17.13
2,1,21:18.13
-4,2,21:18.13
-1,2,21:18.13
0,2,21:18.13
-1,3,21:18.13
0,3,21:18.13
-1,4,21:18.13
0,4,21:18.13
-5,-5,22:18.13
-4,-5,22:18.13
-5,-4,22:18.13
-4,-4,22:17.13
-3,-4,22:18.13
1,-4,22:18.13
-5,-3,22:18.13
-4,-3,22:17.13
-3,-3,22:18.13
1,-3,22:18.13
-2,-1,22:18.13
-1,-1,22:18.13
0,-1,22:18.13
1,-1,22:18.13
-8,0,22:18.13
-7,0,22:18.13
-3,0,22:18.13
-2,0,22:17.13
-1,0,22:17.13
0,0,22:18.13
1,0,22:17.13
2,0,22:18.13
-8,1,22:18.13
-7,1,22:18.13
-2,1,22:18.13
1,1,22:18.13
2,1,22:18.13
-2,2,22:18.13
-5,-5,23:18.13
-4,-5,23:18.13
-5,-4,23:18.13
-4,-4,23:17.13
-3,-4,23:18.13
-5,-3,23:18.13
-4,-3,23:17.13
-3,-3,23:18.13
1,-2,23:18.13
-2,-1,23:18.13
-1,-1,23:18.13
0,-1,23:18.13
1,-1,23:18.13
-8,0,23:18.5
-7,0,23:18.13
-3,0,23:18.13
-2,0,23:17.13
-1,0,23:17.13
0,0,23:18.13
1,0,23:17.13
2,0,23:18.13
-8,1,23:18.5
-7,1,23:18.13
-6,1,23:18.13
-2,1,23:18.13
-1,1,23:188.0
1,1,23:18.13
2,1,23:18.13
-2,2,23:18.13
-4,-5,24:18.13
-5,-4,24:18.13
-4,-4,24:17.13
-3,-4,24:18.13
-5,-3,24:18.13
-4,-3,24:17.13
-3,-3,24:18.13
-4,-2,24:18.13
-3,-2,24:17.13
-2,-2,24:18.13
-4,-1,24:18.13
-3,-1,24:17.13
-2,-1,24:17.13
-1,-1,24:18.13
0,-1,24:18.13
-3,0,24:18.13
-2,0,24:17.13
-1,0,24:17.13
0,0,24:17.13
1,0,24:18.13
-6,1,24:18.13
-5,1,24:18.13
-2,1,24:18.13
-1,1,24:18.13
0,1,24:18.13
-6,2,24:18.13
-5,2,24:18.13
-1,4,24:18.13
-1,-5,25:18.13
-4,-4,25:18.13
-4,-3,25:18.13
-4,-2,25:18.13
-3,-2,25:18.13
-2,-2,25:18.13
-3,-1,25:18.13
-2,-1,25:18.13
-1,-1,25:18.13
-3,0,25:18.13
-2,0,25:17.13
-1,0,25:17.13
0,0,25:18.13
-4,1,25:18.13
-2,1,25:18.13
-1,1,25:18.13
-5,2,25:18.13
-4,2,25:18.13
-5,3,25:18.13
-4,3,25:18.13
-2,3,25:18.13
-1,3,25:17.13
0,3,25:18.13
-1,4,25:18.13
-1,-4,26:18.13
-1,-3,26:18.13
-2,-2,26:18.13
-1,-2,26:17.13
0,-2,26:18.13
3,-2,26:18.13
4,-2,26:18.13
-1,-1,26:188.0
-3,0,26:18.13
-2,0,26:17.13
-1,0,26:17.13
0,0,26:18.13
-2,1,26:18.13
-1,1,26:17.13
0,1,26:18.13
-2,2,26:18.13
-1,2,26:17.13
0,2,26:18.13
-2,3,26:18.13
-1,3,26:18.13
0,3,26:18.13
-1,-2,27:18.13
3,-2,27:18.13
4,-2,27:18.13
-2,-1,27:18.13
-1,-1,27:17.13
0,-1,27:18.13
2,-1,27:18.13
3,-1,27:18.13
4,-1,27:18.13
-2,0,27:18.13
-1,0,27:17.13
0,0,27:18.13
2,0,27:18.13
-2,1,27:18.13
-1,1,27:18.13
-2,2,27:18.13
-1,2,27:18.13
1,2,27:18.13
-5,4,27:18.13
-5,-2,28:18.13
-4,-2,28:18.13
0,-2,28:18.13
-5,-1,28:18.13
-3,-1,28:18.13
-1,-1,28:18.13
0,-1,28:18.13
1,-1,28:18.13
2,-1,28:18.13
-2,0,28:18.5
-1,0,28:17.13
-1,1,28:18.13
-2,2,28:18.13
0,2,28:18.13
1,2,28:17.13
2,2,28:18.13
-5,3,28:18.13
-4,3,28:18.13
1,3,28:18.13
2,-5,29:18.13
-4,-2,29:18.13
-5,-1,29:18.13
-3,-1,29:18.13
-1,-1,29:18.5
-4,0,29:18.13
-2,0,29:18.13
-1,0,29:17.13
0,0,29:18.13
-2,1,29:18.13
-1,1,29:18.13
0,1,29:17.13
1,1,29:18.13
-4,2,29:18.5
-3,2,29:18.13
0,2,29:18.13
1,2,29:18.13
-4,3,29:18.13
1,-4,30:18.13
2,-4,30:18.13
1,-3,30:18.13
2,-3,30:18.13
0,-2,30:18.13
1,-2,30:18.13
-4,-1,30:18.13
-1,-1,30:18.13
0,-1,30:17.13
1,-1,30:18.13
-4,0,30:18.13
-3,0,30:18.13
-2,0,30:18.13
-1,0,30:17.13
0,0,30:18.13
-1,1,30:18.13
0,1,30:18.13
-1,-1,31:18.13
0,-1,31:18.13
-2,0,31:18.13
-1,0,31:17.13
0,0,31:18.13
-1,1,31:18.13
-1,-1,32:18.13
-2,0,32:18.13
-1,0,32:17.13
0,0,32:18.13
-1,1,32:18.13
-1,-1,33:18.13
-2,0,33:18.13
-1,0,33:18.13
