[META]
version=2.0
spawnOnBlockType=2
spawnSunlight=True
spawnDarkness=True
spawnWater=False
spawnLava=False
underFill=False
randomRotation=True
dig=True
tree=False
branch=False
needsFoundation=True
rarity=100
collisionPercentage=20
spawnElevationMin=0
spawnElevationMax=200
spawnInBiome=Custom
[DATA]
0,0,0:17.1
0,0,1:17.1
0,0,2:17.1
0,0,3:17.1
0,0,4:17.1
0,0,5:17.1
0,0,6:17.1
0,0,7:17.1
0,0,8:17.1
0,0,9:17.1
0,-4,10:18.13
-3,-3,10:18.13
3,-3,10:18.13
-4,0,10:18.13
0,0,10:17.1
4,0,10:18.13
0,-3,11:18.13
2,-3,11:18.13
-2,-2,11:18.13
0,-2,11:18.13
-1,-1,11:18.13
-3,0,11:18.13
-2,0,11:18.13
-1,0,11:188.0
0,0,11:17.1
1,0,11:188.0
2,0,11:18.13
3,0,11:18.13
4,0,11:18.13
-2,2,11:18.13
-3,3,11:18.13
3,3,11:18.13
0,4,11:18.13
0,-4,12:18.13
-3,-3,12:18.13
3,-3,12:18.13
0,-1,12:18.13
-4,0,12:18.13
-1,0,12:18.13
0,0,12:17.1
1,0,12:18.13
3,0,12:18.5
-1,1,12:18.13
0,1,12:188.0
1,1,12:18.13
0,2,12:18.13
2,2,12:18.13
0,3,12:18.13
0,-3,13:18.13
-2,-2,13:18.13
2,-2,13:18.13
-1,-1,13:18.13
0,-1,13:188.0
1,-1,13:18.13
-3,0,13:18.13
-2,0,13:18.13
0,0,13:17.1
1,0,13:188.0
2,0,13:18.13
0,1,13:18.13
-3,3,13:18.13
3,3,13:18.13
0,4,13:18.13
-3,-3,14:18.13
3,-3,14:18.13
0,-2,14:18.13
0,-1,14:18.13
-3,0,14:18.5
-1,0,14:18.13
0,0,14:17.1
1,0,14:18.13
-1,1,14:18.13
0,1,14:188.0
1,1,14:18.13
-2,2,14:18.13
2,2,14:18.13
0,3,14:18.13
0,-3,15:18.13
-2,-2,15:18.13
2,-2,15:18.13
-1,-1,15:18.13
0,-1,15:188.0
1,-1,15:18.13
-2,0,15:18.13
0,0,15:17.1
1,0,15:188.0
2,0,15:18.13
3,0,15:18.13
0,1,15:18.13
0,2,15:18.13
0,-2,16:18.13
0,-1,16:18.13
-3,0,16:18.13
-1,0,16:18.13
0,0,16:17.1
1,0,16:18.13
-1,1,16:18.13
0,1,16:188.0
-2,2,16:18.13
0,3,16:18.13
0,-3,17:18.13
-2,-2,17:18.13
2,-2,17:18.13
-1,-1,17:18.13
1,-1,17:18.13
-2,0,17:18.13
-1,0,17:18.5
0,0,17:17.1
1,0,17:188.0
3,0,17:18.13
0,1,17:18.13
0,2,17:18.13
0,-2,18:18.13
0,-1,18:18.13
-2,0,18:18.13
-1,0,18:188.0
0,0,18:17.1
1,0,18:18.13
2,0,18:18.13
-2,2,18:18.13
2,2,18:18.13
0,-2,19:18.13
0,-1,19:188.0
-1,0,19:18.13
0,0,19:17.1
2,0,19:18.13
-1,1,19:18.13
0,1,19:188.0
1,1,19:18.13
0,2,19:18.13
0,-1,20:18.13
-2,0,20:18.13
-1,0,20:188.0
0,0,20:17.1
1,0,20:18.13
0,1,20:18.13
0,-2,21:18.13
-1,0,21:18.13
0,0,21:17.1
2,0,21:18.13
0,1,21:188.0
0,2,21:18.13
0,-1,22:18.13
-1,0,22:18.5
0,0,22:17.1
1,0,22:18.13
0,1,22:18.13
0,-1,23:18.5
-1,0,23:18.5
0,0,23:18.5
1,0,23:18.5
0,1,23:18.5
0,0,24:18.13
