[META]
version=2.0
spawnOnBlockType=2
spawnSunlight=True
spawnDarkness=True
spawnWater=False
spawnLava=False
underFill=False
randomRotation=True
dig=True
tree=False
branch=False
needsFoundation=True
rarity=100
collisionPercentage=20
spawnElevationMin=0
spawnElevationMax=200
spawnInBiome=Custom
[DATA]
-4,-5,0:2.0
-3,-5,0:2.0
-2,-5,0:2.0
-1,-5,0:2.0
0,-5,0:2.0
1,-5,0:2.0
2,-5,0:2.0
3,-5,0:2.0
4,-5,0:2.0
5,-5,0:2.0
-4,-4,0:2.0
-3,-4,0:2.0
-2,-4,0:2.0
-1,-4,0:2.0
0,-4,0:2.0
1,-4,0:2.0
2,-4,0:2.0
3,-4,0:2.0
4,-4,0:2.0
5,-4,0:2.0
-4,-3,0:2.0
-3,-3,0:2.0
-2,-3,0:2.0
-1,-3,0:2.0
0,-3,0:2.0
1,-3,0:2.0
2,-3,0:2.0
3,-3,0:2.0
4,-3,0:2.0
5,-3,0:2.0
-4,-2,0:2.0
-3,-2,0:2.0
-2,-2,0:2.0
-1,-2,0:2.0
0,-2,0:3.0
1,-2,0:2.0
2,-2,0:2.0
3,-2,0:2.0
4,-2,0:2.0
5,-2,0:2.0
-4,-1,0:2.0
-3,-1,0:2.0
-2,-1,0:2.0
-1,-1,0:3.0
0,-1,0:3.0
1,-1,0:3.0
2,-1,0:2.0
3,-1,0:2.0
4,-1,0:2.0
5,-1,0:2.0
-4,0,0:2.0
-3,0,0:2.0
-2,0,0:2.0
-1,0,0:2.0
0,0,0:2.0
1,0,0:2.0
2,0,0:2.0
3,0,0:2.0
4,0,0:2.0
5,0,0:2.0
-4,1,0:2.0
-3,1,0:2.0
-2,1,0:2.0
-1,1,0:2.0
0,1,0:2.0
1,1,0:2.0
2,1,0:2.0
3,1,0:2.0
4,1,0:2.0
5,1,0:2.0
-4,2,0:2.0
-3,2,0:2.0
-2,2,0:2.0
-1,2,0:2.0
0,2,0:2.0
1,2,0:2.0
2,2,0:2.0
3,2,0:2.0
4,2,0:2.0
5,2,0:2.0
-4,3,0:2.0
-3,3,0:2.0
-2,3,0:2.0
-1,3,0:2.0
0,3,0:2.0
1,3,0:2.0
2,3,0:2.0
3,3,0:2.0
4,3,0:2.0
5,3,0:2.0
0,-2,1:17.13
-1,-1,1:17.13
0,-1,1:17.1
1,-1,1:17.13
-1,-1,2:17.13
0,-1,2:17.1
1,-1,2:17.13
-1,-1,3:17.13
0,-1,3:17.13
-1,-1,4:17.1
0,-1,4:17.13
-3,-4,5:18.5
-2,-3,5:18.5
-1,-1,5:17.13
0,-1,5:17.13
1,-1,5:18.5
-1,0,5:18.5
-3,-4,6:18.5
-2,-4,6:18.5
-3,-3,6:18.5
-2,-3,6:18.5
-1,-3,6:18.5
-2,-2,6:18.5
-1,-2,6:18.5
-2,-1,6:18.5
-1,-1,6:17.13
0,-1,6:17.13
-1,0,6:18.5
0,0,6:18.5
-2,-5,7:18.9
0,-4,7:18.9
1,-4,7:18.9
3,-4,7:18.9
2,-3,7:18.9
-4,-2,7:18.9
-1,-1,7:17.13
0,-1,7:17.13
1,-1,7:18.1
3,-1,7:18.9
-1,0,7:18.1
2,0,7:18.9
5,0,7:18.13
-3,1,7:18.9
0,1,7:18.9
-1,2,7:18.1
3,2,7:18.9
2,3,7:18.9
-1,-5,8:18.9
0,-5,8:18.9
-3,-4,8:18.9
-2,-4,8:18.1
0,-4,8:18.9
1,-4,8:18.9
2,-4,8:18.9
3,-4,8:18.9
-2,-3,8:18.1
1,-3,8:18.9
2,-3,8:18.9
-4,-2,8:18.9
-2,-2,8:18.1
-1,-2,8:18.1
4,-2,8:18.13
-4,-1,8:18.9
-1,-1,8:17.13
0,-1,8:17.13
4,-1,8:18.9
5,-1,8:18.13
-4,0,8:18.9
-1,0,8:18.1
0,0,8:18.1
3,0,8:18.9
4,0,8:18.9
5,0,8:18.13
-3,1,8:18.9
-1,1,8:18.1
4,1,8:18.5
-2,2,8:18.1
-1,2,8:18.1
2,2,8:18.9
3,2,8:18.9
0,3,8:18.9
1,3,8:18.9
0,-3,9:18.9
-2,-2,9:18.1
-1,-2,9:18.1
1,-2,9:18.9
-1,-1,9:17.13
0,-1,9:17.13
-2,0,9:18.9
1,1,9:18.9
2,1,9:18.9
-2,-3,10:18.9
-1,-3,10:18.9
1,-3,10:18.9
0,-2,10:18.1
2,-2,10:18.1
-3,-1,10:18.1
-2,-1,10:18.1
-1,-1,10:18.1
0,-1,10:17.13
1,-1,10:18.1
2,-1,10:18.1
0,0,10:18.1
1,0,10:18.1
-1,2,10:18.9
0,2,10:18.9
1,2,10:18.9
-3,-3,11:18.5
-2,-3,11:18.9
-4,-2,11:18.13
-3,-2,11:18.1
-1,-2,11:18.1
0,-2,11:18.1
1,-2,11:18.1
2,-2,11:18.1
-4,-1,11:18.13
-3,-1,11:18.1
-2,-1,11:18.1
-1,-1,11:18.1
0,-1,11:17.13
3,-1,11:18.9
-4,0,11:18.13
-3,0,11:18.13
-2,0,11:18.1
-1,0,11:18.1
0,0,11:17.13
2,0,11:18.9
3,0,11:18.9
-4,1,11:18.13
-3,1,11:18.13
0,2,11:18.9
1,2,11:18.9
0,-3,12:18.1
1,-3,12:18.1
-1,-2,12:18.1
0,-2,12:18.1
-3,-1,12:18.5
-2,-1,12:18.1
-1,-1,12:18.1
0,-1,12:17.13
1,-1,12:18.1
2,-1,12:18.1
-4,0,12:18.5
-3,0,12:18.5
-2,0,12:18.1
-1,0,12:18.1
0,0,12:18.1
1,0,12:18.1
-3,1,12:18.5
0,1,12:18.1
0,-3,13:18.1
1,-2,13:18.9
-2,-1,13:18.1
-1,-1,13:17.13
0,-1,13:17.13
2,-1,13:18.1
1,0,13:18.1
0,1,13:18.1
-1,-3,14:18.9
1,-3,14:18.9
-2,-2,14:18.1
0,-2,14:18.1
-2,-1,14:18.1
-1,-1,14:18.1
0,-1,14:17.13
1,-1,14:18.1
2,-1,14:18.1
-2,0,14:18.1
1,0,14:18.1
0,1,14:18.1
1,1,14:18.1
-1,-2,15:18.1
0,-2,15:18.1
0,-1,15:17.13
1,-1,15:18.1
-1,0,15:18.1
0,0,15:18.1
1,0,15:18.1
-1,-2,16:18.1
0,-2,16:18.1
1,-2,16:18.1
-1,-1,16:18.1
0,-1,16:17.13
0,-2,17:18.1
0,-1,17:18.1
1,-1,17:18.1
-1,0,17:18.1
0,0,17:18.1
0,-1,18:18.1
