[META]
version=2.0
spawnOnBlockType=2
spawnSunlight=True
spawnDarkness=True
spawnWater=False
spawnLava=False
underFill=False
randomRotation=True
dig=True
tree=False
branch=False
needsFoundation=True
rarity=100
collisionPercentage=20
spawnElevationMin=0
spawnElevationMax=200
spawnInBiome=Custom
[DATA]
-2,-1,0:17.13
-1,-1,0:17.1
-1,0,0:17.13
-1,-1,1:17.13
-1,0,1:17.13
-1,0,2:17.13
-1,-2,3:18.13
-1,-1,3:18.13
1,-1,3:18.13
-3,0,3:18.13
-2,0,3:18.13
-1,0,3:17.1
2,0,3:18.13
-1,2,3:18.13
-1,-3,4:18.13
-1,-2,4:18.13
-4,-1,4:18.13
-2,-1,4:18.13
-1,-1,4:17.9
1,-1,4:18.13
2,-1,4:18.13
-4,0,4:18.13
-3,0,4:18.13
-2,0,4:18.13
-1,0,4:17.1
0,0,4:18.13
1,0,4:18.13
2,0,4:18.13
3,0,4:18.13
-4,1,4:18.13
-3,1,4:18.13
-2,1,4:18.13
-1,1,4:18.13
2,1,4:18.13
-3,2,4:18.13
-2,2,4:18.13
-1,2,4:18.13
0,2,4:18.13
1,2,4:18.13
2,2,4:18.13
-1,3,4:18.13
-1,-4,5:18.13
-2,-3,5:18.13
-1,-3,5:18.13
0,-3,5:18.13
-3,-2,5:18.13
-2,-2,5:18.13
-1,-2,5:18.13
0,-2,5:18.13
1,-2,5:18.13
-1,-1,5:18.13
0,-1,5:18.13
-4,0,5:18.13
-3,0,5:18.13
-2,0,5:18.13
-1,0,5:17.1
2,0,5:18.13
-2,1,5:18.13
0,1,5:18.13
-1,2,5:18.13
0,2,5:18.13
-1,-3,6:18.13
-1,-2,6:18.13
-2,-1,6:18.13
-1,-1,6:18.13
-1,0,6:17.1
1,0,6:18.13
-2,1,6:18.13
-1,1,6:18.13
-1,2,6:18.13
-1,-2,7:18.13
-2,-1,7:18.13
-2,0,7:18.13
-1,0,7:17.1
0,0,7:18.13
-1,-1,8:18.13
0,-1,8:18.13
-1,0,8:17.1
-2,1,8:18.13
0,1,8:18.13
-1,2,8:18.13
-1,-3,9:18.13
-1,-2,9:18.13
-2,-1,9:18.13
-1,-1,9:18.13
-3,0,9:18.13
-2,0,9:18.13
-1,0,9:17.1
0,0,9:18.13
1,0,9:18.13
-1,1,9:18.13
1,1,9:18.5
-2,2,9:18.13
-1,2,9:18.13
0,2,9:18.13
1,2,9:18.5
-1,3,9:18.13
0,3,9:18.5
-1,-1,10:18.13
-2,0,10:18.13
-1,0,10:18.13
0,0,10:18.13
-1,1,10:18.13
-1,0,11:18.13
-1,0,12:18.13
