[META]
version=2.0
spawnOnBlockType=2
spawnSunlight=True
spawnDarkness=True
spawnWater=False
spawnLava=False
underFill=False
randomRotation=True
dig=True
tree=False
branch=False
needsFoundation=True
rarity=100
collisionPercentage=20
spawnElevationMin=0
spawnElevationMax=200
spawnInBiome=Custom
[DATA]
1,-1,0:17.1
1,-1,1:17.1
1,-1,2:17.1
1,-1,3:17.1
1,-1,4:17.1
1,-1,5:17.1
1,-1,6:17.1
1,-1,7:17.1
1,-1,8:17.1
1,-1,9:17.1
1,-1,10:17.1
1,-1,11:17.1
1,-1,12:17.1
-4,5,12:18.5
1,-1,13:17.13
-3,4,13:18.5
-4,5,13:18.5
-3,5,13:18.5
5,-6,14:18.13
8,-3,14:18.13
1,-2,14:18.5
1,-1,14:17.13
2,-1,14:18.13
-2,1,14:18.13
1,1,14:18.13
-3,2,14:18.13
-4,3,14:18.5
-3,3,14:18.5
5,3,14:18.13
-4,4,14:18.5
-3,4,14:18.5
-3,-6,15:18.13
4,-6,15:18.13
3,-5,15:18.13
4,-5,15:17.13
5,-5,15:18.13
7,-3,15:18.13
8,-3,15:18.13
1,-2,15:188.0
2,-2,15:18.13
8,-2,15:18.13
0,-1,15:18.5
1,-1,15:17.13
-6,0,15:18.5
-1,0,15:18.13
0,0,15:18.13
1,0,15:18.13
-3,1,15:18.13
-2,1,15:17.13
0,1,15:18.13
-4,2,15:18.13
-3,2,15:17.13
-2,2,15:18.13
-4,3,15:18.13
-3,3,15:18.13
4,3,15:18.13
5,3,15:17.13
6,3,15:18.13
5,4,15:18.13
-3,-6,16:18.13
-2,-6,16:18.13
-3,-5,16:18.13
-2,-5,16:17.13
3,-5,16:18.13
4,-5,16:18.13
-2,-4,16:18.13
-1,-4,16:18.13
2,-4,16:188.0
3,-4,16:17.13
4,-4,16:18.13
2,-3,16:17.13
3,-3,16:17.13
6,-3,16:18.13
7,-3,16:18.13
1,-2,16:18.13
2,-2,16:17.13
3,-2,16:18.13
6,-2,16:18.13
7,-2,16:18.13
-6,-1,16:18.5
-5,-1,16:18.5
1,-1,16:17.13
2,-1,16:18.13
-6,0,16:18.5
-2,0,16:18.13
-1,0,16:17.13
0,0,16:17.13
1,0,16:18.13
-3,1,16:18.13
-2,1,16:17.13
-1,1,16:18.13
0,1,16:18.13
1,1,16:18.13
2,1,16:18.13
3,1,16:17.13
4,1,16:18.13
-3,2,16:18.13
-2,2,16:18.13
3,2,16:18.13
4,2,16:17.13
5,2,16:18.13
5,3,16:18.5
2,5,16:18.13
-2,-6,17:18.13
-3,-5,17:18.13
-2,-5,17:17.13
-1,-5,17:18.13
-2,-4,17:18.13
-1,-4,17:17.13
0,-4,17:18.13
2,-4,17:18.13
3,-4,17:18.13
0,-3,17:18.13
4,-3,17:18.13
-5,-2,17:18.5
-4,-2,17:18.5
1,-2,17:18.13
2,-2,17:18.13
5,-2,17:18.13
6,-2,17:18.5
-6,-1,17:18.5
-5,-1,17:18.5
-4,-1,17:18.5
-1,-1,17:188.0
0,-1,17:17.13
1,-1,17:17.13
4,-1,17:18.13
5,-1,17:18.5
-1,0,17:18.13
0,0,17:18.13
1,0,17:17.13
3,0,17:17.13
4,0,17:18.13
-2,1,17:18.13
1,1,17:18.13
2,1,17:18.13
3,1,17:17.13
4,1,17:18.13
3,2,17:18.13
2,4,17:18.13
2,5,17:18.13
-2,-5,18:18.13
-1,-5,18:18.13
-2,-4,18:18.13
-1,-4,18:17.13
0,-4,18:18.13
-1,-3,18:18.13
0,-3,18:17.13
1,-3,18:188.0
-4,-2,18:18.5
-3,-2,18:18.5
-1,-2,18:18.13
0,-2,18:17.13
1,-2,18:17.13
2,-2,18:18.13
4,-2,18:18.13
-4,-1,18:18.5
-3,-1,18:18.5
1,-1,18:17.13
2,-1,18:17.13
3,1,18:18.13
1,2,18:18.13
1,3,18:18.13
3,4,18:18.13
4,4,18:18.5
1,-7,19:18.5
-1,-4,19:18.13
0,-4,19:18.13
3,-4,19:18.5
0,-3,19:18.13
2,-3,19:18.13
3,-3,19:18.5
0,-2,19:18.13
1,-2,19:18.13
2,-2,19:18.13
-3,-1,19:18.5
-2,-1,19:18.5
-1,-1,19:18.5
0,-1,19:17.13
1,-1,19:17.13
2,-1,19:17.13
3,-1,19:18.13
4,-1,19:18.13
-3,0,19:18.5
-2,0,19:18.5
-1,0,19:18.5
1,0,19:18.13
5,0,19:18.13
1,1,19:18.13
3,1,19:18.13
4,1,19:18.13
0,2,19:18.13
1,2,19:17.13
2,2,19:18.13
3,2,19:18.13
4,2,19:18.13
1,3,19:18.13
4,3,19:18.13
0,-7,20:18.5
1,-7,20:18.5
0,-6,20:18.5
4,-5,20:18.13
5,-5,20:18.13
4,-4,20:17.13
5,-4,20:18.13
1,-3,20:18.13
2,-3,20:188.0
4,-3,20:18.13
-1,-2,20:18.13
0,-2,20:18.13
1,-2,20:17.13
2,-2,20:18.13
0,-1,20:188.0
1,-1,20:17.13
2,-1,20:18.13
1,0,20:17.13
2,0,20:18.13
0,1,20:18.13
1,1,20:17.13
2,1,20:18.13
4,1,20:18.5
0,2,20:18.13
1,2,20:18.13
-1,-6,21:18.5
0,-6,21:18.5
-1,-5,21:18.5
0,-5,21:18.5
4,-5,21:18.13
2,-4,21:18.13
3,-4,21:18.13
4,-4,21:17.13
5,-4,21:18.13
1,-3,21:188.0
2,-3,21:17.13
3,-3,21:17.13
4,-3,21:18.13
0,-2,21:18.13
1,-2,21:17.13
2,-2,21:17.13
3,-2,21:18.13
0,-1,21:18.13
1,-1,21:17.13
2,-1,21:18.13
0,0,21:18.13
1,0,21:17.13
2,0,21:18.13
1,1,21:18.13
-2,-5,22:18.5
-1,-5,22:18.5
-2,-4,22:18.5
-1,-4,22:18.5
0,-4,22:18.13
3,-4,22:18.13
4,-4,22:18.13
1,-3,22:18.13
2,-3,22:18.13
3,-3,22:18.13
-2,-2,22:18.13
0,-2,22:18.13
1,-2,22:17.13
2,-2,22:18.13
3,-2,22:18.13
-4,-1,22:18.5
-3,-1,22:18.13
-2,-1,22:17.13
0,-1,22:18.13
1,-1,22:17.13
2,-1,22:18.13
5,-1,22:18.13
-4,0,22:18.5
-2,0,22:18.13
1,0,22:18.13
1,-3,23:18.13
-2,-2,23:18.13
-1,-2,23:18.13
0,-2,23:18.13
1,-2,23:17.13
3,-2,23:18.13
-2,-1,23:18.13
-1,-1,23:17.13
0,-1,23:17.13
1,-1,23:17.13
3,-1,23:17.13
4,-1,23:18.13
-2,0,23:18.13
-1,0,23:18.13
0,0,23:18.13
1,0,23:18.13
3,0,23:18.13
3,3,23:18.5
-3,-5,24:18.13
-1,-2,24:18.13
0,-2,24:18.13
1,-2,24:18.13
2,-2,24:18.13
3,-2,24:18.5
-1,-1,24:18.13
0,-1,24:18.13
1,-1,24:17.13
2,-1,24:17.13
3,-1,24:188.0
1,0,24:18.13
2,0,24:18.13
-1,1,24:18.13
1,2,24:18.13
2,2,24:18.13
2,3,24:18.13
3,3,24:18.5
-2,-5,25:18.13
2,-5,25:18.13
3,-5,25:18.13
-2,-4,25:18.13
3,-4,25:18.13
2,-3,25:18.13
-1,-2,25:18.13
1,-2,25:188.0
0,-1,25:18.13
1,-1,25:17.13
2,-1,25:18.13
-1,0,25:18.13
2,0,25:18.13
3,0,25:18.13
-2,1,25:18.13
-1,1,25:17.13
2,1,25:18.13
-1,2,25:18.13
2,2,25:18.13
2,-5,26:18.13
-2,-4,26:18.13
-1,-4,26:18.5
1,-4,26:18.13
3,-4,26:18.13
-1,-3,26:18.13
2,-3,26:18.13
0,-2,26:18.13
1,-2,26:18.13
0,-1,26:18.13
1,-1,26:17.13
2,-1,26:18.13
-1,0,26:18.13
0,0,26:17.13
1,0,26:18.13
-1,1,26:18.13
0,1,26:18.13
5,2,26:18.13
1,-4,27:18.13
2,-4,27:18.13
1,-3,27:18.13
1,-2,27:18.13
0,-1,27:18.13
1,-1,27:17.13
2,-1,27:188.0
0,0,27:18.13
1,0,27:18.13
2,0,27:17.13
3,0,27:18.13
2,1,27:18.13
3,1,27:18.13
4,1,27:18.13
4,2,27:18.13
1,-2,28:18.13
0,-1,28:18.13
1,-1,28:17.13
2,-1,28:18.13
1,0,28:18.13
2,0,28:18.13
1,-2,29:18.13
0,-1,29:18.13
1,-1,29:17.13
2,-1,29:18.13
1,0,29:18.13
1,-2,30:18.13
1,-1,30:18.13
2,-1,30:18.13
