[META]
version=2.0
spawnOnBlockType=2
spawnSunlight=True
spawnDarkness=True
spawnWater=False
spawnLava=False
underFill=False
randomRotation=True
dig=True
tree=False
branch=False
needsFoundation=True
rarity=100
collisionPercentage=20
spawnElevationMin=0
spawnElevationMax=200
spawnInBiome=Custom
[DATA]
-7,-6,0:2.0
-6,-6,0:2.0
-5,-6,0:2.0
-4,-6,0:2.0
-3,-6,0:2.0
-2,-6,0:2.0
-1,-6,0:2.0
0,-6,0:2.0
1,-6,0:2.0
2,-6,0:2.0
3,-6,0:2.0
4,-6,0:2.0
5,-6,0:2.0
-7,-5,0:2.0
-6,-5,0:2.0
-5,-5,0:2.0
-4,-5,0:2.0
-3,-5,0:2.0
-2,-5,0:2.0
-1,-5,0:2.0
0,-5,0:2.0
1,-5,0:2.0
2,-5,0:2.0
3,-5,0:2.0
4,-5,0:2.0
5,-5,0:2.0
-7,-4,0:2.0
-6,-4,0:2.0
-5,-4,0:2.0
-4,-4,0:2.0
-3,-4,0:2.0
-2,-4,0:2.0
-1,-4,0:2.0
0,-4,0:2.0
1,-4,0:2.0
2,-4,0:2.0
3,-4,0:2.0
4,-4,0:2.0
5,-4,0:2.0
-7,-3,0:2.0
-6,-3,0:2.0
-5,-3,0:2.0
-4,-3,0:2.0
-3,-3,0:2.0
-2,-3,0:2.0
-1,-3,0:2.0
0,-3,0:2.0
1,-3,0:2.0
2,-3,0:2.0
3,-3,0:2.0
4,-3,0:2.0
5,-3,0:2.0
-7,-2,0:2.0
-6,-2,0:2.0
-5,-2,0:2.0
-4,-2,0:2.0
-3,-2,0:2.0
-2,-2,0:2.0
-1,-2,0:2.0
0,-2,0:2.0
1,-2,0:2.0
2,-2,0:2.0
3,-2,0:2.0
4,-2,0:2.0
5,-2,0:2.0
-7,-1,0:2.0
-6,-1,0:2.0
-5,-1,0:2.0
-4,-1,0:2.0
-3,-1,0:2.0
-2,-1,0:2.0
-1,-1,0:3.0
0,-1,0:2.0
1,-1,0:2.0
2,-1,0:2.0
3,-1,0:2.0
4,-1,0:2.0
5,-1,0:2.0
-7,0,0:2.0
-6,0,0:2.0
-5,0,0:2.0
-4,0,0:2.0
-3,0,0:3.0
-2,0,0:3.0
-1,0,0:3.0
0,0,0:2.0
1,0,0:2.0
2,0,0:2.0
3,0,0:2.0
4,0,0:2.0
5,0,0:2.0
-7,1,0:2.0
-6,1,0:2.0
-5,1,0:2.0
-4,1,0:2.0
-3,1,0:2.0
-2,1,0:3.0
-1,1,0:3.0
0,1,0:3.0
1,1,0:2.0
2,1,0:2.0
3,1,0:2.0
4,1,0:2.0
5,1,0:2.0
-7,2,0:2.0
-6,2,0:2.0
-5,2,0:2.0
-4,2,0:2.0
-3,2,0:2.0
-2,2,0:2.0
-1,2,0:2.0
0,2,0:2.0
1,2,0:2.0
2,2,0:2.0
3,2,0:2.0
4,2,0:2.0
5,2,0:2.0
-7,3,0:2.0
-6,3,0:2.0
-5,3,0:2.0
-4,3,0:2.0
-3,3,0:2.0
-2,3,0:2.0
-1,3,0:2.0
0,3,0:2.0
1,3,0:2.0
2,3,0:2.0
3,3,0:2.0
4,3,0:2.0
5,3,0:2.0
-7,4,0:2.0
-6,4,0:2.0
-5,4,0:2.0
-4,4,0:2.0
-3,4,0:2.0
-2,4,0:2.0
-1,4,0:2.0
0,4,0:2.0
1,4,0:2.0
2,4,0:2.0
3,4,0:2.0
4,4,0:2.0
5,4,0:2.0
-7,5,0:2.0
-6,5,0:2.0
-5,5,0:2.0
-4,5,0:2.0
-3,5,0:2.0
-2,5,0:2.0
-1,5,0:2.0
0,5,0:2.0
1,5,0:2.0
2,5,0:2.0
3,5,0:2.0
4,5,0:2.0
5,5,0:2.0
-7,6,0:2.0
-6,6,0:2.0
-5,6,0:2.0
-4,6,0:2.0
-3,6,0:2.0
-2,6,0:2.0
-1,6,0:2.0
0,6,0:2.0
1,6,0:2.0
2,6,0:2.0
3,6,0:2.0
4,6,0:2.0
5,6,0:2.0
-7,7,0:2.0
-6,7,0:2.0
-5,7,0:2.0
-4,7,0:2.0
-3,7,0:2.0
-2,7,0:2.0
-1,7,0:2.0
0,7,0:2.0
1,7,0:2.0
2,7,0:2.0
3,7,0:2.0
4,7,0:2.0
5,7,0:2.0
-1,-1,1:17.13
-3,0,1:17.13
-2,0,1:17.1
-1,0,1:17.1
-2,1,1:17.1
-1,1,1:17.1
0,1,1:17.1
-2,0,2:17.13
-1,0,2:17.1
-2,1,2:17.1
-1,1,2:17.1
0,1,2:17.1
-1,0,3:17.1
-2,1,3:17.1
-1,1,3:17.1
0,1,3:17.1
-1,0,4:17.1
-2,1,4:17.1
-1,1,4:17.1
3,1,4:18.13
-1,0,5:17.1
1,0,5:18.13
3,0,5:18.13
-2,1,5:17.1
-1,1,5:17.1
0,1,5:17.5
1,1,5:17.13
3,1,5:18.13
4,1,5:18.13
5,1,5:18.13
1,2,5:18.13
3,2,5:18.6
0,3,5:18.13
-1,5,5:18.13
2,-2,6:18.13
-1,-1,6:18.13
1,-1,6:18.13
3,-1,6:18.13
-2,0,6:18.13
-1,0,6:17.1
0,0,6:18.13
1,0,6:18.13
2,0,6:18.13
3,0,6:18.13
4,0,6:18.13
-6,1,6:18.5
-3,1,6:18.13
-2,1,6:17.1
-1,1,6:17.1
0,1,6:17.5
1,1,6:17.5
2,1,6:17.5
3,1,6:17.5
4,1,6:17.5
5,1,6:18.13
1,2,6:18.13
2,2,6:18.13
3,2,6:18.13
4,2,6:18.13
5,2,6:18.13
1,3,6:18.13
3,3,6:18.13
-1,4,6:18.13
0,4,6:18.13
-2,5,6:18.13
-1,5,6:18.13
0,5,6:18.13
-1,6,6:18.13
0,-1,7:18.13
-5,0,7:18.13
-2,0,7:18.13
-1,0,7:17.1
1,0,7:18.13
3,0,7:18.13
-6,1,7:18.13
-4,1,7:18.13
-3,1,7:17.5
-2,1,7:17.5
-1,1,7:17.1
1,1,7:18.13
2,1,7:18.13
3,1,7:18.13
4,1,7:18.13
-4,2,7:18.13
-2,2,7:18.13
1,2,7:18.13
3,2,7:18.13
-2,3,7:18.13
-1,3,7:17.9
0,3,7:18.13
-2,4,7:18.13
-1,4,7:17.9
-3,5,7:18.13
-2,5,7:18.13
-1,5,7:17.9
0,5,7:18.6
1,5,7:18.13
-2,6,7:18.13
-1,6,7:17.9
0,6,7:18.6
-1,7,7:18.13
-4,-1,8:18.13
-2,-1,8:18.13
-1,-1,8:18.13
-6,0,8:18.13
-4,0,8:18.13
-3,0,8:18.13
-2,0,8:18.13
-1,0,8:17.1
0,0,8:18.13
-7,1,8:18.13
-6,1,8:18.13
-5,1,8:17.5
-4,1,8:17.5
-3,1,8:17.5
-2,1,8:17.5
-1,1,8:17.1
1,1,8:18.13
3,1,8:18.13
-6,2,8:18.13
-5,2,8:18.13
-4,2,8:18.13
-3,2,8:18.13
-2,2,8:18.13
0,2,8:18.13
-4,3,8:18.13
-2,3,8:18.6
-1,3,8:18.13
-1,4,8:18.13
-2,5,8:18.13
-1,5,8:18.13
0,5,8:18.13
-1,6,8:18.13
-1,-6,9:18.5
-1,-4,9:18.5
-2,-3,9:18.13
-3,-2,9:18.13
-1,-2,9:18.13
-1,-1,9:17.9
0,-1,9:18.13
-4,0,9:18.13
-2,0,9:18.13
-1,0,9:17.9
1,0,9:18.13
-5,1,9:18.13
-4,1,9:18.13
-3,1,9:18.13
-2,1,9:18.13
-1,1,9:17.1
0,1,9:18.13
-4,2,9:18.13
-2,2,9:18.13
-1,3,9:18.13
-1,5,9:18.13
-1,-6,10:18.5
-2,-5,10:18.5
-1,-5,10:18.13
-2,-4,10:18.13
-1,-4,10:17.9
0,-4,10:18.13
-3,-3,10:18.13
-2,-3,10:18.13
-1,-3,10:17.9
-2,-2,10:18.13
-1,-2,10:17.9
0,-2,10:18.13
-3,-1,10:18.13
-2,-1,10:18.13
-1,-1,10:17.9
0,-1,10:18.13
1,-1,10:18.13
-1,0,10:17.9
0,0,10:18.13
-4,1,10:18.13
-2,1,10:18.13
-1,1,10:17.1
1,1,10:18.13
-1,2,10:18.13
-1,-4,11:18.13
-3,-3,11:18.13
-2,-3,11:18.13
-1,-3,11:18.13
0,-3,11:18.13
-1,-2,11:18.13
-1,-1,11:18.13
-2,0,11:18.13
-1,0,11:17.1
-1,1,11:17.1
-3,2,11:18.13
0,2,11:18.13
-1,-3,12:18.13
-1,-1,12:18.13
-1,0,12:17.1
-1,1,12:17.1
1,1,12:18.13
-2,2,12:18.13
-1,0,13:18.13
-4,1,13:18.13
-2,1,13:18.5
-1,1,13:17.1
0,1,13:18.13
1,1,13:18.13
-3,2,13:18.13
0,2,13:18.13
1,2,13:18.13
-1,3,13:18.13
-1,-2,14:18.5
-1,-1,14:18.5
-2,0,14:18.13
-1,0,14:18.13
1,0,14:18.13
-6,1,14:18.13
-4,1,14:18.13
-3,1,14:18.13
-2,1,14:18.13
-1,1,14:17.1
0,1,14:18.5
1,1,14:18.13
2,1,14:18.13
-5,2,14:18.13
-3,2,14:18.13
-1,2,14:17.9
1,2,14:18.13
-2,3,14:18.13
-1,3,14:17.9
0,3,14:18.13
-1,4,14:18.5
-1,6,14:18.5
-1,-3,15:18.5
-2,-2,15:18.5
-1,-2,15:18.5
0,-2,15:18.13
-2,-1,15:18.13
-1,-1,15:18.5
0,-1,15:18.13
2,-1,15:18.13
-6,0,15:18.13
-4,0,15:18.13
-3,0,15:18.6
-2,0,15:18.13
-1,0,15:18.5
0,0,15:18.13
1,0,15:18.13
2,0,15:18.13
-7,1,15:18.5
-6,1,15:18.13
-5,1,15:18.13
-4,1,15:18.13
-3,1,15:18.13
-2,1,15:18.13
-1,1,15:17.1
0,1,15:18.13
1,1,15:18.13
2,1,15:18.13
3,1,15:18.13
4,1,15:18.5
-6,2,15:18.13
-4,2,15:18.13
-3,2,15:18.13
-2,2,15:18.13
-1,2,15:18.13
0,2,15:18.13
1,2,15:18.13
2,2,15:18.5
-2,3,15:18.13
-1,3,15:18.13
0,3,15:18.13
1,3,15:18.13
-2,4,15:18.13
-1,4,15:18.13
0,4,15:18.13
-1,5,15:18.13
-2,6,15:18.5
-1,6,15:18.5
0,6,15:18.5
-1,7,15:18.5
-1,-2,16:18.5
-1,-1,16:18.5
-5,0,16:18.13
-3,0,16:18.13
-2,0,16:18.13
-1,0,16:18.5
0,0,16:18.13
-6,1,16:18.13
-4,1,16:18.13
-2,1,16:18.13
-1,1,16:17.1
1,1,16:18.13
2,1,16:18.13
0,2,16:18.5
-2,3,16:18.13
-1,3,16:18.13
0,3,16:18.5
-1,4,16:18.13
-2,5,16:18.13
-1,6,16:18.5
-1,0,17:18.13
-3,1,17:18.13
-2,1,17:18.13
-1,1,17:17.1
0,1,17:18.13
1,1,17:18.13
-2,2,17:18.6
-1,2,17:18.13
-1,3,17:18.13
-2,0,18:18.13
-2,1,18:18.13
-1,1,18:17.1
-2,2,18:18.14
-1,2,18:18.13
0,2,18:18.13
-1,-1,19:18.13
-1,0,19:18.13
-3,1,19:18.5
-1,1,19:17.1
0,1,19:18.13
1,1,19:18.13
0,3,19:18.13
-1,4,19:18.13
-1,-3,20:18.5
-2,-2,20:18.13
-1,-2,20:18.13
0,-2,20:18.5
-3,-1,20:18.13
-1,-1,20:18.13
-3,0,20:18.13
-2,0,20:18.13
-1,0,20:18.13
0,0,20:18.5
-4,1,20:18.5
-3,1,20:18.5
-2,1,20:18.13
-1,1,20:17.1
0,1,20:17.5
1,1,20:18.13
2,1,20:18.13
-3,2,20:18.5
-1,2,20:18.13
-3,3,20:18.5
-1,3,20:18.13
0,3,20:18.13
-3,4,20:18.5
-2,4,20:18.5
-1,4,20:18.13
0,4,20:18.13
-1,5,20:18.5
-1,-2,21:18.5
1,-1,21:18.13
-3,0,21:18.5
-1,0,21:18.5
1,0,21:18.13
2,0,21:18.13
-3,1,21:18.5
-1,1,21:17.1
0,1,21:18.13
1,1,21:18.13
2,1,21:18.13
3,1,21:18.13
-3,2,21:18.5
-2,2,21:18.13
0,2,21:18.13
1,2,21:18.13
2,2,21:18.5
1,3,21:18.13
-1,4,21:18.13
-2,0,22:18.5
0,0,22:18.5
-3,1,22:18.5
-2,1,22:18.5
-1,1,22:17.1
0,1,22:18.13
1,1,22:18.5
2,1,22:18.13
-2,2,22:18.6
-1,3,22:18.13
-1,0,23:18.5
0,0,23:18.13
-1,1,23:17.1
1,1,23:18.13
-1,2,23:18.13
-2,0,24:18.13
-3,1,24:18.13
-1,1,24:17.1
0,1,24:18.13
-2,2,24:18.13
0,2,24:18.13
-1,-1,25:18.13
-3,0,25:18.13
-1,0,25:18.13
0,0,25:18.13
-4,1,25:18.13
-3,1,25:18.13
-2,1,25:18.13
-1,1,25:17.1
0,1,25:18.13
1,1,25:18.13
2,1,25:18.5
-3,2,25:18.13
-1,2,25:18.13
-1,3,25:18.13
-1,0,26:18.5
-2,1,26:18.13
-1,1,26:18.13
0,1,26:18.13
-1,2,26:18.13
-1,1,27:18.13
-1,1,28:18.5
