[META]
version=2.0
spawnOnBlockType=2
spawnSunlight=True
spawnDarkness=True
spawnWater=False
spawnLava=False
underFill=False
randomRotation=True
dig=True
tree=False
branch=False
needsFoundation=True
rarity=100
collisionPercentage=20
spawnElevationMin=0
spawnElevationMax=200
spawnInBiome=Custom
[DATA]
-3,-1,0:17.14
-1,-1,0:17.14
-2,0,0:17.14
-3,1,0:17.14
-2,0,1:17.14
-2,0,2:17.14
-2,0,3:17.14
-2,0,4:17.14
-2,1,4:17.14
-3,-1,5:17.14
-2,0,5:189.0
-2,1,5:17.14
-3,-1,6:17.14
-2,1,6:17.14
-1,-5,7:18.7
-2,-4,7:18.7
0,-4,7:18.15
1,-4,7:18.15
-4,-3,7:189.0
-3,-3,7:18.7
-2,-3,7:18.7
1,-3,7:18.15
-6,-2,7:189.0
-2,-2,7:18.7
-1,-2,7:17.14
0,-2,7:18.7
1,-2,7:18.15
-4,-1,7:18.15
-3,-1,7:17.14
-2,-1,7:17.14
-1,-1,7:18.7
0,-1,7:18.7
2,0,7:18.7
-6,1,7:18.15
-2,1,7:17.14
-1,1,7:18.7
2,1,7:18.7
3,1,7:18.7
-4,2,7:189.0
-3,2,7:17.14
-1,2,7:17.14
1,2,7:18.7
2,2,7:18.7
3,2,7:18.7
-4,3,7:17.14
0,3,7:17.14
1,3,7:18.7
2,4,7:18.15
0,5,7:18.15
-2,-5,8:18.7
-1,-5,8:18.7
0,-5,8:18.15
-2,-4,8:18.7
-1,-4,8:18.7
0,-4,8:18.15
1,-4,8:18.15
-1,-3,8:18.7
1,-3,8:18.15
-6,-2,8:18.7
-2,-2,8:18.7
-1,-2,8:18.7
0,-2,8:17.14
1,-2,8:18.15
-3,-1,8:17.14
-1,-1,8:18.7
0,-1,8:18.7
1,-1,8:18.15
2,0,8:18.15
-5,1,8:18.7
-2,1,8:17.14
-1,1,8:18.7
2,1,8:18.15
-6,2,8:18.15
-5,2,8:18.7
0,2,8:18.7
2,2,8:18.15
3,2,8:18.15
-6,3,8:18.7
-5,3,8:17.14
-4,3,8:18.7
-1,3,8:18.7
0,3,8:18.7
1,3,8:17.14
2,3,8:18.15
3,3,8:18.15
-2,4,8:18.7
0,4,8:18.7
1,4,8:18.7
2,4,8:18.15
-1,5,8:18.15
0,5,8:18.15
-4,-5,9:18.7
-1,-5,9:18.7
-3,-4,9:18.7
-1,-4,9:18.7
-4,-3,9:18.7
0,-3,9:18.7
-4,-2,9:17.14
-3,-2,9:18.7
-2,-2,9:18.7
0,-2,9:18.7
1,-2,9:18.15
-6,-1,9:18.7
-4,-1,9:189.0
-5,0,9:18.7
2,0,9:18.7
-6,1,9:18.15
-5,1,9:18.7
-2,1,9:17.14
-1,1,9:18.7
1,1,9:18.7
3,1,9:18.15
-5,2,9:18.7
1,2,9:18.15
3,2,9:18.15
-6,3,9:18.7
-5,3,9:17.14
2,3,9:18.15
-6,4,9:18.15
-4,4,9:18.7
-1,4,9:18.7
0,4,9:18.7
1,5,9:18.15
-4,-5,10:18.7
-3,-5,10:18.7
-4,-4,10:18.7
-3,-4,10:18.7
-2,-4,10:18.7
-5,-3,10:18.7
-6,-2,10:18.7
-5,-2,10:18.7
-4,-2,10:17.14
-3,-2,10:18.7
-6,-1,10:18.7
-4,-1,10:18.7
-3,-1,10:18.7
-3,1,10:18.7
-1,1,10:18.7
2,1,10:18.15
3,1,10:18.15
-5,2,10:18.7
-2,2,10:17.14
-1,2,10:18.7
-5,3,10:18.7
-4,3,10:18.7
-2,3,10:17.14
-3,4,10:18.7
-2,4,10:18.7
-1,4,10:189.0
-5,5,10:18.15
-4,5,10:18.15
-3,5,10:18.7
-1,5,10:18.7
-3,6,10:18.15
-4,-5,11:18.7
-5,-4,11:18.7
-4,-4,11:18.7
-3,-4,11:18.7
-6,-3,11:18.7
-5,-1,11:18.7
-4,-1,11:18.7
-2,-1,11:18.7
-2,1,11:18.7
0,2,11:18.7
-3,3,11:18.7
-5,4,11:18.15
-4,4,11:18.15
-3,4,11:17.14
-2,4,11:18.7
-1,4,11:18.7
-4,5,11:18.15
-3,5,11:18.7
-2,5,11:18.7
-1,5,11:18.7
-3,6,11:18.15
-2,6,11:18.15
-3,4,12:18.7
-2,4,12:18.7
-4,5,12:18.15
-3,5,12:18.7
-2,5,12:18.7
-3,6,12:18.7
-2,6,12:18.15
