[META]
version=2.0
spawnOnBlockType=2
spawnSunlight=True
spawnDarkness=True
spawnWater=False
spawnLava=False
underFill=False
randomRotation=True
dig=True
tree=False
branch=False
needsFoundation=True
rarity=100
collisionPercentage=20
spawnElevationMin=0
spawnElevationMax=200
spawnInBiome=Custom
[DATA]
0,0,0:17.14
0,1,0:17.14
-1,-1,1:17.14
0,1,1:17.14
-1,-1,2:17.14
0,1,2:17.14
-1,-3,3:18.7
-1,-1,3:17.14
-1,0,3:18.7
0,0,3:18.7
0,1,3:189.0
0,2,3:17.14
-2,-3,4:18.7
-1,-3,4:18.7
-2,-2,4:17.14
-1,-2,4:18.7
0,-2,4:17.14
0,-1,4:189.0
1,-1,4:18.7
-2,1,4:18.7
-1,1,4:18.7
0,1,4:18.7
-1,2,4:18.7
0,2,4:17.14
0,3,4:18.7
-2,-3,5:18.7
1,-3,5:18.7
2,-3,5:18.7
-3,-2,5:18.7
-2,-2,5:17.14
-1,-2,5:18.7
0,-2,5:18.7
1,-2,5:17.14
-3,-1,5:18.7
-2,-1,5:18.7
0,-1,5:18.7
2,-1,5:18.7
-2,0,5:18.7
-1,0,5:18.7
-1,1,5:18.15
1,1,5:18.15
-1,2,5:18.15
0,2,5:17.14
1,2,5:18.15
-1,3,5:18.15
0,3,5:18.15
1,-3,6:18.7
-3,-2,6:18.7
-2,-2,6:18.7
0,-2,6:18.7
2,-2,6:18.7
-2,-1,6:18.7
0,-1,6:18.7
2,-1,6:18.7
0,1,6:18.15
0,2,6:18.7
1,2,6:18.15
0,3,6:18.15
0,-2,7:18.7
1,-2,7:18.7
2,-2,7:18.7
1,-1,7:18.7
