[META]
version=2.0
spawnOnBlockType=2
spawnSunlight=True
spawnDarkness=True
spawnWater=False
spawnLava=False
underFill=False
randomRotation=True
dig=True
tree=True
branch=False
needsFoundation=True
rarity=100
collisionPercentage=20
spawnElevationMin=0
spawnElevationMax=200
spawnInBiome=Custom
[DATA]
0,0,0:17.1
0,0,1:17.1
0,0,2:17.1
0,0,3:17.1
0,0,4:17.1
0,0,5:17.1
0,0,6:17.1
0,0,7:17.1
0,0,8:17.1
0,-1,9:18.5
-4,0,9:18.5
0,0,9:17.1
0,1,9:18.5
0,-4,10:18.13
0,-1,10:18.5
-4,0,10:18.13
-2,0,10:18.13
-1,0,10:188.0
0,0,10:17.1
1,0,10:18.5
0,1,10:188.0
4,1,10:18.13
0,3,10:18.13
0,4,10:18.5
0,-4,11:18.5
0,-3,11:18.13
0,-2,11:188.0
-1,-1,11:18.13
0,-1,11:17.13
1,-1,11:18.13
2,-1,11:18.13
3,-1,11:18.13
-3,0,11:18.13
-2,0,11:18.13
-1,0,11:18.13
0,0,11:17.1
1,0,11:18.13
2,0,11:18.13
3,0,11:18.13
4,0,11:18.13
-3,1,11:18.13
-1,1,11:18.13
0,1,11:18.13
3,1,11:18.13
4,1,11:18.13
-1,2,11:18.13
0,2,11:18.13
0,3,11:18.13
0,-3,12:18.13
1,-3,12:18.13
-1,-2,12:18.13
0,-2,12:18.13
0,-1,12:18.13
1,-1,12:18.13
-1,0,12:18.13
0,0,12:17.1
3,0,12:18.13
1,1,12:18.13
-1,2,12:18.13
0,2,12:18.13
0,-2,13:18.13
-1,-1,13:18.13
0,-1,13:18.13
-2,0,13:18.5
-1,0,13:18.5
0,0,13:17.1
1,0,13:188.0
2,0,13:18.13
0,1,13:18.13
1,-2,14:18.13
2,-2,14:18.5
-1,-1,14:18.13
0,-1,14:18.13
1,-1,14:18.13
4,-1,14:18.13
-1,0,14:18.13
0,0,14:17.1
1,0,14:18.13
0,1,14:188.0
1,1,14:18.5
0,-1,15:18.13
1,-1,15:18.13
4,-1,15:18.13
-1,0,15:188.0
0,0,15:17.1
1,0,15:18.5
3,0,15:18.13
-1,1,15:18.13
0,1,15:18.5
0,2,15:18.13
0,3,15:18.5
0,-3,16:18.13
0,-2,16:18.13
-1,-1,16:18.13
0,-1,16:18.13
2,-1,16:18.5
3,-1,16:18.13
-2,0,16:18.13
-1,0,16:18.13
0,0,16:17.1
1,0,16:18.13
2,0,16:18.13
3,0,16:18.13
0,1,16:18.13
-1,2,16:18.13
0,2,16:18.13
1,2,16:18.13
0,3,16:18.13
0,-1,17:18.13
-1,0,17:18.5
0,0,17:18.13
1,0,17:18.13
0,1,17:18.13
0,0,18:18.13
