[META]
version=2.0
spawnOnBlockType=2
spawnSunlight=True
spawnDarkness=True
spawnWater=False
spawnLava=False
underFill=False
randomRotation=True
dig=True
tree=True
branch=False
needsFoundation=True
rarity=100
collisionPercentage=20
spawnElevationMin=0
spawnElevationMax=200
spawnInBiome=Custom
[DATA]
0,-2,0:17.13
1,-2,0:191.0
1,-1,0:17.13
2,-1,0:17.13
1,-2,1:17.13
1,-1,1:17.13
1,-1,2:17.13
1,-1,3:17.13
2,-3,4:18.4
0,-2,4:18.4
2,-2,4:18.4
3,-2,4:18.4
1,-1,4:17.13
2,-1,4:191.0
1,0,4:18.4
2,-5,5:18.6
2,-4,5:18.4
0,-2,5:18.4
-1,-1,5:18.4
1,-1,5:17.13
-1,0,5:18.6
1,0,5:17.13
2,0,5:191.0
0,1,5:18.6
3,-5,6:18.4
0,-4,6:18.6
-1,-3,6:18.6
1,-3,6:191.0
3,-3,6:18.6
1,-2,6:17.13
2,-2,6:18.6
-1,-1,6:18.4
0,-1,6:17.13
1,-1,6:17.13
2,-1,6:17.13
5,-1,6:18.6
-1,0,6:17.13
0,0,6:18.4
-1,1,6:18.4
0,1,6:18.4
1,1,6:17.13
2,-5,7:18.6
0,-3,7:18.6
2,-3,7:18.6
1,-2,7:17.13
2,-2,7:191.0
-3,-1,7:18.6
-2,-1,7:191.0
0,-1,7:18.6
1,-1,7:17.13
2,-1,7:18.6
3,-1,7:17.13
-2,0,7:17.13
3,0,7:191.0
4,0,7:18.4
-1,1,7:18.4
1,2,7:18.6
2,3,7:18.4
1,-5,8:18.6
2,-5,8:18.4
0,-4,8:18.4
2,-4,8:18.4
1,-3,8:17.13
2,-3,8:18.4
-2,-2,8:18.4
-4,-1,8:18.4
-3,-1,8:18.6
-2,-1,8:18.6
-1,-1,8:18.6
3,-1,8:17.13
5,-1,8:18.6
-3,0,8:17.13
-2,0,8:18.4
1,0,8:17.13
3,0,8:17.13
-3,1,8:18.4
4,1,8:18.4
1,-5,9:18.4
-2,-4,9:18.6
0,-4,9:18.6
1,-4,9:17.13
2,-4,9:18.4
3,-4,9:18.4
1,-3,9:18.6
3,-3,9:18.4
-2,-2,9:18.6
5,-2,9:18.4
0,-1,9:17.13
1,-1,9:18.6
2,-1,9:18.4
4,-1,9:17.13
6,-1,9:18.6
-4,0,9:18.6
-3,0,9:18.6
-1,0,9:18.4
1,0,9:17.13
2,0,9:18.6
3,0,9:18.4
4,0,9:191.0
-3,1,9:18.4
-2,1,9:18.6
1,1,9:18.6
3,1,9:17.13
4,1,9:18.6
5,1,9:18.4
3,2,9:18.4
4,2,9:18.4
-3,-4,10:18.4
-2,-4,10:18.4
0,-4,10:18.6
1,-4,10:17.13
2,-4,10:18.4
0,-3,10:18.6
1,-3,10:18.6
2,-3,10:18.4
-2,-2,10:18.6
4,-2,10:18.4
5,-2,10:18.4
6,-2,10:18.4
0,-1,10:17.13
4,-1,10:18.4
5,-1,10:17.13
6,-1,10:18.6
-3,0,10:18.6
-2,0,10:18.4
-1,0,10:18.6
4,0,10:18.6
0,1,10:18.4
1,1,10:17.13
2,1,10:191.0
3,1,10:18.4
4,1,10:18.4
5,1,10:18.6
-2,2,10:18.4
-1,2,10:18.6
2,2,10:18.6
4,2,10:18.4
2,3,10:18.6
1,-5,11:18.6
-2,-4,11:18.4
2,-4,11:18.4
-3,-3,11:18.4
-2,-3,11:18.4
-1,-3,11:18.4
-1,-2,11:17.13
2,-2,11:18.4
6,-2,11:18.4
-1,-1,11:18.4
0,-1,11:18.4
4,-1,11:18.4
5,-1,11:18.4
-3,0,11:18.6
-2,0,11:18.4
-1,0,11:18.4
5,0,11:18.4
-3,1,11:18.6
0,1,11:18.6
1,1,11:17.13
2,1,11:18.4
3,1,11:18.4
4,1,11:18.6
-2,2,11:18.6
0,2,11:18.4
1,2,11:18.4
2,2,11:18.6
3,3,11:18.4
1,-3,12:18.4
2,-3,12:18.6
-2,-2,12:18.4
-1,-2,12:17.13
0,-2,12:191.0
3,-2,12:18.4
-2,-1,12:18.6
-1,-1,12:18.4
0,-1,12:18.6
4,0,12:18.6
0,1,12:18.4
1,1,12:18.6
1,2,12:17.13
2,2,12:18.4
1,3,12:18.6
-1,-3,13:18.6
1,-3,13:18.4
-1,-2,13:18.6
0,-2,13:18.6
2,-2,13:18.4
-1,-1,13:18.4
4,-1,13:18.4
0,0,13:18.4
1,1,13:18.4
2,1,13:18.6
0,2,13:18.4
1,2,13:17.13
2,2,13:18.4
1,3,13:18.6
2,3,13:18.6
0,-2,14:18.4
1,-1,14:18.4
1,0,14:18.4
2,0,14:18.6
0,2,14:18.4
1,2,14:18.6
2,2,14:18.4
1,3,14:18.6
