[META]
version=2.0
spawnOnBlockType=2
spawnSunlight=True
spawnDarkness=True
spawnWater=False
spawnLava=False
underFill=False
randomRotation=True
dig=True
tree=True
branch=False
needsFoundation=True
rarity=100
collisionPercentage=20
spawnElevationMin=0
spawnElevationMax=200
spawnInBiome=Custom
[DATA]
-3,-2,0:17.13
-2,-2,0:191.0
-1,-2,0:191.0
-3,0,0:191.0
-2,0,0:191.0
-1,0,0:191.0
-1,1,0:17.13
0,1,0:191.0
-3,2,0:191.0
-2,2,0:191.0
-1,2,0:191.0
-3,-1,1:17.13
-2,0,1:17.13
-2,0,2:17.13
-3,0,3:191.0
-2,0,3:17.13
-3,0,4:18.6
-2,0,4:17.13
-3,0,5:191.0
-2,0,5:17.13
-5,-4,6:18.6
-4,-3,6:18.4
-3,-1,6:17.13
-2,0,6:17.13
-5,-5,7:18.6
-4,-5,7:18.4
0,-5,7:18.6
-6,-3,7:18.6
-3,-2,7:17.13
-2,0,7:17.13
-8,1,7:18.4
-6,2,7:18.6
1,3,7:18.6
0,4,7:18.4
-2,-7,8:18.6
-1,-7,8:18.6
-7,-6,8:18.4
-6,-6,8:18.4
-2,-6,8:18.4
0,-6,8:18.6
-7,-5,8:18.6
-5,-5,8:18.6
-3,-5,8:18.4
-2,-5,8:18.4
-1,-5,8:18.4
-7,-4,8:18.4
-5,-4,8:18.4
-4,-3,8:17.13
2,-2,8:18.6
-2,-1,8:191.0
2,-1,8:18.6
-8,0,8:18.6
-2,0,8:17.13
1,0,8:18.6
-8,1,8:18.6
-6,1,8:18.4
-2,1,8:191.0
-1,1,8:17.13
0,1,8:17.13
-8,2,8:18.4
-1,2,8:17.13
0,2,8:18.6
1,2,8:18.4
0,3,8:18.6
-2,4,8:18.4
-1,4,8:18.6
1,4,8:18.4
0,-7,9:18.4
-6,-6,9:18.4
-3,-6,9:18.4
-1,-6,9:18.4
0,-6,9:18.6
-3,-5,9:18.4
-2,-5,9:17.13
-1,-5,9:18.4
0,-5,9:18.4
3,-5,9:18.4
-7,-4,9:18.4
-6,-4,9:191.0
-5,-4,9:17.13
-3,-4,9:17.13
-1,-4,9:18.4
-7,-3,9:18.4
-6,-3,9:18.6
-5,-3,9:18.6
1,-3,9:18.4
3,-3,9:18.4
-9,0,9:18.4
-3,0,9:18.6
-2,0,9:17.13
2,0,9:18.6
-8,1,9:18.4
1,1,9:17.13
2,1,9:18.6
4,1,9:18.6
-8,2,9:18.4
2,2,9:18.6
-7,3,9:18.6
0,3,9:17.13
2,3,9:18.4
0,4,9:17.13
1,4,9:18.4
1,5,9:17.13
2,5,9:191.0
1,6,9:18.6
-1,-7,10:18.4
2,-7,10:18.6
-7,-6,10:18.4
2,-6,10:18.6
-8,-5,10:18.4
-6,-5,10:18.4
-3,-5,10:18.6
-7,-4,10:18.4
-5,-4,10:18.6
-4,-4,10:18.4
-2,-4,10:18.4
-1,-4,10:18.6
3,-4,10:18.6
3,-3,10:18.6
-9,-2,10:18.4
3,-2,10:18.4
-9,-1,10:18.4
-2,0,10:17.13
-8,1,10:18.4
1,1,10:18.4
3,1,10:18.6
2,2,10:18.4
-9,3,10:18.6
-6,3,10:18.6
-5,3,10:18.4
-2,4,10:18.6
-2,5,10:18.6
0,5,10:18.4
1,5,10:191.0
0,6,10:18.4
1,6,10:17.13
2,6,10:18.4
1,8,10:18.6
2,-8,11:18.4
-8,-6,11:18.6
-8,-5,11:18.4
-7,-4,11:18.6
-4,-3,11:18.4
-6,-2,11:18.4
-2,-1,11:17.13
3,-1,11:18.4
-2,0,11:17.13
4,0,11:18.6
2,2,11:18.6
-9,3,11:18.6
-5,3,11:18.6
-3,3,11:18.4
4,3,11:18.4
-5,4,11:18.4
0,4,11:18.4
2,5,11:18.4
-5,6,11:18.6
-2,6,11:18.4
0,6,11:18.6
3,6,11:18.6
0,7,11:18.4
1,7,11:17.13
0,8,11:18.6
2,8,11:18.6
3,-9,12:18.6
-7,-6,12:18.4
0,-6,12:18.6
1,-6,12:18.6
-4,-5,12:18.6
-3,-5,12:18.6
-2,-5,12:18.4
-7,-4,12:18.6
1,-4,12:18.6
-2,-3,12:17.13
1,-3,12:18.4
-2,-2,12:17.13
3,-2,12:18.6
-6,0,12:18.6
-5,0,12:18.4
-2,0,12:17.13
-1,0,12:17.13
2,0,12:18.4
-2,1,12:191.0
-5,2,12:18.4
2,2,12:18.6
-9,3,12:18.4
3,3,12:18.4
-7,6,12:18.6
1,6,12:18.6
0,7,12:18.4
0,8,12:18.6
0,-9,13:18.6
1,-9,13:18.4
3,-9,13:18.4
-1,-8,13:18.6
-5,-7,13:18.4
-2,-7,13:18.4
-2,-6,13:191.0
-1,-6,13:17.13
-6,-5,13:18.4
-4,-5,13:18.6
-2,-5,13:17.13
0,-5,13:18.4
3,-5,13:18.4
-6,-4,13:18.6
-4,-4,13:18.4
-2,-4,13:17.13
-1,-4,13:17.13
1,-3,13:18.4
-1,-1,13:18.6
0,-1,13:17.13
-4,0,13:17.13
-3,0,13:17.13
-2,0,13:17.13
-1,0,13:18.4
2,0,13:18.4
5,0,13:18.4
-5,1,13:18.4
-1,1,13:18.4
-6,2,13:18.4
-5,2,13:18.6
-9,3,13:18.4
-1,3,13:18.4
0,3,13:18.4
5,3,13:18.6
-8,4,13:18.4
-5,4,13:18.6
-3,4,13:18.4
0,4,13:18.6
3,4,13:18.4
4,4,13:18.6
-7,5,13:18.6
-6,6,13:18.6
1,6,13:18.6
-2,7,13:18.6
0,7,13:18.4
-1,-9,14:18.4
0,-9,14:18.6
-3,-8,14:18.6
0,-8,14:17.13
-3,-7,14:18.6
-1,-7,14:17.13
0,-7,14:191.0
2,-7,14:18.6
-4,-6,14:18.6
-3,-6,14:17.13
-3,-5,14:18.6
-1,-5,14:18.4
0,-5,14:18.6
0,-4,14:17.13
3,-4,14:18.6
1,-3,14:18.6
-8,-2,14:18.6
-2,-2,14:18.6
0,-1,14:17.13
-3,0,14:191.0
-2,0,14:17.13
0,0,14:18.6
5,0,14:18.4
-6,1,14:17.13
-5,1,14:17.13
-1,1,14:17.13
0,1,14:18.6
1,1,14:18.6
-7,2,14:18.6
-5,2,14:18.4
-4,2,14:18.4
-2,2,14:18.4
6,2,14:18.4
-2,3,14:18.6
-6,4,14:18.6
-4,4,14:18.6
2,4,14:18.6
3,4,14:18.4
0,5,14:18.4
1,5,14:18.4
-1,8,14:18.6
-4,-8,15:18.4
-3,-8,15:191.0
-1,-8,15:18.6
1,-8,15:18.6
-3,-7,15:17.13
-3,-6,15:18.6
1,-5,15:18.6
-7,-4,15:18.4
4,-4,15:18.6
-7,-3,15:18.4
-2,-2,15:18.6
1,-2,15:17.13
2,-2,15:18.4
-4,-1,15:18.4
-3,-1,15:18.4
1,-1,15:17.13
2,-1,15:18.4
5,-1,15:18.6
-9,0,15:18.4
-2,0,15:17.13
3,0,15:18.6
-9,1,15:18.4
-8,1,15:17.13
-7,1,15:17.13
-5,1,15:18.6
-1,1,15:17.13
4,1,15:18.4
-7,2,15:191.0
-5,2,15:18.4
-4,2,15:18.6
2,2,15:18.6
4,2,15:18.4
-8,3,15:18.4
-6,3,15:18.4
-2,3,15:18.4
1,3,15:18.6
6,3,15:18.6
-4,4,15:18.4
-3,4,15:18.4
3,4,15:18.6
4,4,15:18.4
-4,5,15:18.6
-2,5,15:18.4
-4,6,15:18.6
1,6,15:18.4
-2,7,15:18.4
-5,-9,16:18.4
-4,-9,16:18.4
-4,-8,16:17.13
-3,-8,16:191.0
-5,-7,16:18.4
-4,-7,16:18.6
0,-7,16:18.4
2,-7,16:18.4
3,-7,16:18.6
-4,-5,16:18.6
-4,-4,16:18.4
1,-3,16:17.13
-6,-2,16:18.6
4,-2,16:18.6
2,-1,16:17.13
3,-1,16:18.6
4,-1,16:18.6
-8,0,16:18.6
-2,0,16:17.13
-9,1,16:18.6
-8,1,16:18.6
-7,1,16:18.6
-1,1,16:17.13
1,1,16:18.6
2,1,16:18.4
-8,2,16:18.4
-7,2,16:18.4
-4,2,16:18.4
-3,2,16:18.4
-1,2,16:18.4
-8,3,16:18.6
-1,3,16:18.6
5,3,16:18.4
-5,4,16:18.4
4,4,16:18.4
0,5,16:18.6
2,5,16:18.4
3,5,16:18.6
-1,6,16:18.4
3,6,16:18.4
-5,7,16:18.6
-1,7,16:18.6
-5,-9,17:18.6
-2,-9,17:18.4
-1,-9,17:18.6
-3,-8,17:18.4
1,-7,17:18.4
4,-7,17:18.6
-4,-6,17:18.4
1,-4,17:18.6
4,-4,17:18.6
1,-3,17:18.6
3,-2,17:17.13
4,-2,17:18.6
6,-2,17:18.4
-2,-1,17:17.13
1,-1,17:18.6
2,-1,17:18.6
3,-1,17:17.13
4,-1,17:18.4
-2,0,17:17.13
3,0,17:17.13
4,0,17:18.6
6,0,17:18.4
1,1,17:18.6
2,1,17:18.6
4,1,17:18.4
5,1,17:18.6
-6,2,17:18.6
-1,2,17:17.13
2,2,17:18.4
2,3,17:18.6
4,3,17:18.6
-7,4,17:18.4
-3,4,17:18.6
-2,4,17:18.6
0,4,17:18.6
-7,5,17:18.6
-3,5,17:18.4
1,5,17:18.6
2,5,17:18.4
-6,6,17:18.6
-3,6,17:18.6
1,-6,18:18.6
-5,-5,18:18.6
0,-5,18:18.4
-6,-4,18:18.4
-5,-4,18:18.6
1,-4,18:18.6
-9,-3,18:18.6
-1,-3,18:17.13
-9,-2,18:18.4
-3,-2,18:17.13
-1,-2,18:17.13
4,-2,18:17.13
-3,-1,18:17.13
4,-1,18:191.0
-9,0,18:18.6
-5,0,18:18.6
-2,0,18:17.13
2,0,18:18.6
3,0,18:18.4
4,0,18:18.4
5,0,18:18.4
-7,1,18:18.4
-6,1,18:18.4
2,1,18:18.4
3,1,18:17.13
4,1,18:18.4
-8,2,18:18.4
-7,2,18:18.6
0,2,18:17.13
1,2,18:18.6
2,2,18:18.4
4,2,18:18.6
-3,3,18:18.4
0,3,18:18.4
1,3,18:18.4
-8,4,18:18.6
0,4,18:18.4
-6,5,18:18.4
-1,6,18:18.6
-7,-8,19:18.6
2,-8,19:18.4
-8,-7,19:18.6
-7,-7,19:18.4
-1,-7,19:18.4
2,-7,19:18.4
-7,-6,19:18.4
-5,-6,19:18.4
-2,-6,19:18.4
0,-6,19:18.4
1,-6,19:18.4
3,-6,19:18.4
-6,-5,19:18.4
-5,-5,19:18.6
-4,-5,19:18.6
-3,-5,19:18.4
-2,-5,19:18.6
-1,-5,19:18.6
0,-5,19:17.13
1,-5,19:18.4
-9,-4,19:18.4
-8,-4,19:18.6
-5,-4,19:17.13
-4,-4,19:18.4
0,-4,19:17.13
1,-4,19:18.6
-8,-3,19:18.4
-5,-3,19:18.4
-4,-3,19:17.13
3,-3,19:18.6
4,-3,19:191.0
7,-3,19:18.4
-9,-2,19:18.6
0,-2,19:18.6
4,-2,19:17.13
2,-1,19:18.4
4,-1,19:18.4
8,-1,19:18.4
-7,0,19:18.6
-5,0,19:18.4
-2,0,19:17.13
4,0,19:18.6
6,0,19:18.4
-8,1,19:18.4
-7,1,19:18.6
-2,1,19:18.6
2,1,19:18.4
3,1,19:18.4
6,1,19:18.4
8,1,19:18.4
-5,2,19:18.6
3,2,19:17.13
-2,3,19:18.4
0,3,19:17.13
5,3,19:18.6
-9,4,19:18.4
-6,4,19:18.6
-1,4,19:18.4
-2,5,19:18.4
-1,5,19:18.4
0,5,19:18.4
1,5,19:18.4
-8,6,19:18.4
0,-9,20:18.4
2,-9,20:18.4
-8,-8,20:18.4
-6,-8,20:18.6
0,-8,20:18.6
1,-8,20:18.6
-8,-7,20:18.4
-3,-7,20:18.4
1,-7,20:17.13
-8,-6,20:18.6
-6,-6,20:17.13
-2,-6,20:18.4
-1,-6,20:18.6
0,-6,20:191.0
1,-6,20:17.13
2,-6,20:18.6
-7,-5,20:18.4
-6,-5,20:191.0
-5,-5,20:17.13
-2,-5,20:18.6
-1,-5,20:18.6
0,-5,20:18.6
1,-5,20:18.6
-8,-4,20:18.4
-2,-4,20:18.6
0,-4,20:18.4
1,-4,20:18.4
3,-4,20:18.6
5,-4,20:191.0
6,-4,20:18.4
5,-3,20:17.13
6,-2,20:18.6
7,-2,20:18.4
2,-1,20:18.6
8,-1,20:18.6
-3,0,20:17.13
-2,0,20:17.13
5,0,20:18.6
6,0,20:18.6
-2,1,20:18.6
2,1,20:18.6
3,1,20:18.4
4,1,20:18.6
-9,2,20:18.6
-6,2,20:18.6
0,2,20:18.4
1,2,20:18.6
5,2,20:18.4
-5,3,20:18.6
-2,3,20:18.4
0,3,20:17.13
1,3,20:191.0
-2,4,20:18.6
0,4,20:18.4
-6,6,20:18.4
1,-9,21:18.6
-8,-8,21:18.6
-7,-8,21:18.4
0,-8,21:18.4
-8,-7,21:18.4
-1,-7,21:18.4
0,-7,21:18.4
1,-7,21:18.4
2,-7,21:18.6
3,-7,21:18.4
4,-7,21:18.4
-7,-6,21:18.4
2,-6,21:18.6
-1,-5,21:18.4
0,-5,21:18.4
3,-5,21:18.4
4,-5,21:18.6
-9,-4,21:18.6
-5,-4,21:18.6
1,-4,21:18.4
4,-4,21:18.4
5,-4,21:18.6
6,-4,21:18.4
7,-4,21:18.4
-6,-3,21:18.6
3,-3,21:18.6
5,-3,21:18.4
6,-3,21:17.13
-5,-2,21:18.4
1,-2,21:18.4
2,-2,21:18.4
3,-2,21:18.4
6,-2,21:18.4
7,-2,21:18.6
-6,-1,21:18.4
1,-1,21:18.6
-9,0,21:18.4
-4,0,21:17.13
-2,0,21:17.13
4,0,21:18.6
-7,1,21:18.6
-4,1,21:191.0
6,1,21:18.4
-7,2,21:18.6
-4,2,21:18.6
1,2,21:18.6
5,2,21:18.6
-6,3,21:18.6
-1,3,21:18.4
0,3,21:18.6
1,3,21:17.13
2,3,21:18.4
6,3,21:18.6
-6,4,21:18.4
-4,4,21:18.4
-1,4,21:18.4
0,4,21:18.4
1,4,21:18.6
-3,6,21:18.6
3,-7,22:18.6
-3,-6,22:18.4
0,-6,22:18.6
-8,-5,22:18.4
-4,-5,22:18.4
-1,-5,22:18.4
1,-5,22:18.6
3,-5,22:18.4
4,-5,22:18.4
-7,-4,22:18.4
4,-4,22:18.6
7,-4,22:18.6
8,-4,22:18.6
-8,-3,22:18.4
-6,-3,22:18.6
0,-3,22:18.6
1,-3,22:18.6
7,-3,22:18.4
9,-3,22:18.6
-9,-2,22:18.4
-7,-2,22:18.6
-4,-2,22:18.4
-3,-2,22:17.13
5,-2,22:18.6
7,-2,22:18.6
-7,-1,22:18.6
-2,-1,22:17.13
-5,0,22:18.4
-2,0,22:17.13
-8,1,22:18.4
-4,1,22:17.13
3,1,22:18.6
-9,2,22:18.4
-4,2,22:17.13
0,2,22:18.4
2,2,22:18.4
7,2,22:18.4
-5,3,22:18.4
-4,3,22:18.6
-3,3,22:18.4
-1,3,22:18.4
1,3,22:18.6
2,3,22:17.13
-3,4,22:18.4
-1,4,22:18.4
1,4,22:17.13
-9,5,22:18.6
-7,5,22:18.4
-4,5,22:18.6
-2,5,22:18.4
1,5,22:191.0
2,5,22:18.4
3,5,22:18.6
1,6,22:18.4
-5,-7,23:18.4
-6,-6,23:18.6
-4,-6,23:18.4
-3,-6,23:18.6
-1,-6,23:18.6
5,-6,23:18.4
-9,-5,23:18.6
-7,-5,23:18.4
-5,-5,23:18.4
-3,-5,23:18.6
-2,-5,23:18.4
1,-5,23:18.4
-6,-4,23:18.6
-4,-4,23:17.13
-2,-4,23:18.6
2,-4,23:18.6
3,-4,23:18.4
4,-4,23:18.4
-3,-3,23:17.13
0,-3,23:18.4
6,-3,23:18.6
7,-3,23:18.4
9,-2,23:18.4
-1,-1,23:17.13
2,-1,23:18.4
6,-1,23:18.6
-2,0,23:17.13
0,0,23:18.6
6,0,23:18.4
-8,1,23:18.4
-5,1,23:17.13
-3,1,23:18.4
1,1,23:18.6
-5,2,23:191.0
-4,2,23:18.6
-3,2,23:18.6
-1,2,23:18.4
2,2,23:17.13
-4,3,23:17.13
-2,3,23:18.6
2,3,23:18.4
-3,4,23:18.6
1,4,23:17.13
3,4,23:18.4
-5,5,23:18.6
-4,5,23:18.6
-1,5,23:18.4
2,5,23:18.6
1,6,23:18.4
-2,-8,24:18.4
-6,-7,24:18.4
-5,-6,24:17.13
-7,-5,24:18.4
-4,-5,24:17.13
0,-5,24:18.6
3,-5,24:18.4
-6,-4,24:18.4
-4,-4,24:18.6
-3,-4,24:18.6
-1,-4,24:18.6
-7,-3,24:18.4
-4,-3,24:17.13
-2,-3,24:18.6
2,-3,24:18.6
-6,-2,24:18.6
-5,-2,24:18.6
1,-2,24:18.6
2,-2,24:18.4
-5,-1,24:18.4
-1,-1,24:17.13
8,-1,24:18.4
-8,0,24:18.4
-7,0,24:18.4
-6,0,24:18.6
-5,0,24:18.4
-2,0,24:17.13
-6,1,24:17.13
-3,1,24:18.6
2,1,24:18.6
3,1,24:191.0
-8,2,24:18.6
-7,2,24:18.6
-6,2,24:18.4
-4,2,24:18.4
-2,2,24:18.6
3,2,24:17.13
3,3,24:191.0
-4,4,24:18.4
-2,4,24:18.6
1,4,24:17.13
2,4,24:18.6
1,5,24:18.4
1,6,24:18.6
-6,-7,25:18.6
-5,-6,25:18.6
-6,-5,25:18.6
0,-5,25:18.4
-3,-3,25:18.4
-9,-2,25:18.4
-8,-2,25:18.6
-6,-2,25:17.13
-5,-2,25:17.13
-3,-2,25:18.4
-1,-2,25:17.13
0,-2,25:18.4
1,-2,25:18.6
2,-2,25:18.6
3,-2,25:18.4
-8,-1,25:18.4
-6,-1,25:17.13
-5,-1,25:191.0
-4,-1,25:18.4
0,-1,25:18.4
-9,0,25:18.6
-8,0,25:18.4
-5,0,25:18.4
-3,0,25:18.6
-2,0,25:17.13
-9,1,25:18.4
-8,1,25:18.6
-7,1,25:17.13
-4,1,25:18.6
0,1,25:18.6
3,1,25:18.4
-4,2,25:18.6
-3,2,25:18.4
-1,2,25:18.6
3,2,25:17.13
-4,3,25:18.6
1,4,25:18.6
2,4,25:191.0
2,5,25:17.13
3,5,25:18.6
4,5,25:18.6
0,6,25:18.6
1,6,25:18.6
5,6,25:18.6
2,7,25:18.6
-3,-6,26:18.6
-4,-5,26:18.4
-3,-5,26:18.4
-6,-4,26:18.4
1,-4,26:18.6
3,-4,26:18.4
-9,-3,26:18.6
0,-3,26:18.4
1,-3,26:18.6
-7,-2,26:17.13
-6,-2,26:18.4
0,-2,26:17.13
6,-2,26:18.6
-9,-1,26:18.6
-6,-1,26:18.4
-5,-1,26:18.6
-3,-1,26:18.6
1,-1,26:18.6
5,-1,26:18.6
-9,0,26:18.6
-6,0,26:17.13
-1,0,26:18.4
4,0,26:191.0
5,0,26:18.4
-5,1,26:18.6
-4,1,26:18.4
-2,1,26:17.13
3,1,26:18.6
4,1,26:17.13
5,1,26:18.6
6,1,26:18.6
-7,2,26:18.6
-6,2,26:18.4
-2,2,26:191.0
0,3,26:18.6
-1,4,26:18.4
1,4,26:18.4
2,4,26:18.6
3,4,26:18.4
4,4,26:18.6
2,5,26:17.13
1,6,26:18.4
2,6,26:18.4
5,6,26:18.4
-4,-5,27:18.6
-6,-4,27:18.4
0,-4,27:191.0
1,-4,27:18.4
4,-4,27:18.6
-2,-3,27:18.6
0,-3,27:17.13
2,-3,27:18.6
4,-3,27:18.6
-8,-2,27:18.4
-7,-2,27:18.4
-4,-2,27:18.4
2,-2,27:18.4
6,-2,27:18.4
-8,-1,27:18.6
-5,-1,27:18.4
-3,-1,27:18.6
-1,-1,27:18.6
1,-1,27:18.6
3,-1,27:18.6
5,-1,27:18.4
-6,0,27:18.4
-2,0,27:18.4
4,0,27:18.6
6,0,27:18.4
-9,1,27:18.6
-8,1,27:18.6
-2,1,27:17.13
1,1,27:18.4
3,1,27:18.6
4,1,27:17.13
6,1,27:18.4
-7,2,27:18.4
1,2,27:18.4
6,2,27:18.4
-4,3,27:18.6
-3,3,27:18.6
-5,4,27:18.6
-1,4,27:18.6
2,4,27:18.6
-5,5,27:18.4
3,6,27:18.6
4,6,27:18.6
2,7,27:18.6
-6,-4,28:18.4
-5,-4,28:18.4
-6,-3,28:18.6
-2,-3,28:18.4
-1,-3,28:17.13
0,-3,28:17.13
-7,-2,28:18.6
-6,-2,28:18.6
-4,-2,28:18.6
-3,-2,28:18.6
3,-2,28:18.6
-1,-1,28:18.4
-4,0,28:18.4
-1,0,28:18.6
5,0,28:18.6
-3,1,28:18.6
-2,1,28:17.13
-1,1,28:18.4
3,1,28:18.4
5,1,28:18.6
-1,2,28:17.13
0,2,28:18.4
1,2,28:18.6
4,2,28:18.6
1,3,28:18.6
4,3,28:18.6
-2,4,28:18.6
-1,4,28:18.6
5,4,28:18.6
1,-4,29:17.13
-5,-3,29:18.6
-4,-3,29:18.4
1,-3,29:18.4
3,-3,29:18.4
-7,-2,29:18.4
-6,-2,29:18.6
-5,-2,29:18.4
-2,-2,29:17.13
2,-2,29:18.4
-3,-1,29:18.6
0,-1,29:18.6
-5,0,29:18.6
-3,0,29:18.4
0,0,29:18.4
2,0,29:18.6
-3,1,29:17.13
-2,1,29:18.6
-1,1,29:18.6
0,1,29:18.6
1,1,29:18.4
-3,2,29:18.4
-1,2,29:17.13
-2,3,29:18.4
-2,5,29:18.6
1,-5,30:191.0
1,-4,30:17.13
2,-4,30:18.4
3,-4,30:18.6
-5,-3,30:18.4
-3,-3,30:191.0
0,-3,30:18.6
2,-3,30:18.6
3,-3,30:18.6
-5,-2,30:18.4
-3,-2,30:17.13
1,-2,30:18.6
-4,-1,30:18.6
-1,0,30:18.4
-2,1,30:18.4
-1,1,30:18.4
-5,2,30:18.6
-4,2,30:18.6
-3,2,30:17.13
-5,3,30:18.6
-3,3,30:18.4
-2,3,30:18.6
-1,3,30:17.13
0,3,30:18.4
3,3,30:18.6
-4,4,30:18.6
-2,4,30:18.6
0,4,30:18.4
-2,5,30:18.6
2,-4,31:18.6
-3,-3,31:18.4
-2,-3,31:18.4
-1,-3,31:18.6
3,-3,31:18.6
-4,-2,31:17.13
-4,-1,31:18.6
-3,-1,31:18.6
-5,1,31:18.4
-4,1,31:18.6
-3,1,31:18.4
-4,2,31:17.13
-3,2,31:18.4
-1,3,31:17.13
0,3,31:18.6
-5,4,31:18.4
-3,4,31:18.6
-2,4,31:18.4
1,4,31:18.6
-3,-3,32:18.4
-4,-2,32:18.6
-3,-2,32:18.6
-2,-2,32:18.4
-4,1,32:18.6
-5,2,32:18.4
-4,2,32:18.4
-5,3,32:18.6
-3,3,32:18.6
-1,3,32:18.6
0,3,32:18.4
-3,4,32:18.4
-2,4,32:18.6
-1,4,32:18.4
