[META]
version=2.0
spawnOnBlockType=2
spawnSunlight=True
spawnDarkness=True
spawnWater=False
spawnLava=False
underFill=False
randomRotation=True
dig=True
tree=False
branch=False
needsFoundation=True
rarity=100
collisionPercentage=20
spawnElevationMin=0
spawnElevationMax=200
spawnInBiome=Custom
[DATA]
0,-2,1:18.7
1,-2,1:18.7
-1,-1,1:18.7
0,-1,1:175.4
1,-1,1:18.15
2,-1,1:175.4
-2,0,1:18.7
1,0,1:175.4
-1,1,1:18.7
0,1,1:175.4
-1,-2,2:18.7
0,-2,2:175.4
-2,-1,2:18.7
-1,-1,2:175.4
1,-1,2:175.4
2,-1,2:18.7
-2,0,2:175.4
0,0,2:175.4
1,0,2:18.15
-2,1,2:18.7
-1,1,2:175.4
1,1,2:175.4
-1,-2,3:175.4
0,-2,3:18.7
-2,-1,3:175.4
-1,-1,3:18.7
0,-1,3:175.4
1,-1,3:18.15
-2,0,3:18.7
-1,0,3:175.4
0,0,3:18.7
1,0,3:175.4
2,0,3:18.15
-1,1,3:18.7
0,1,3:175.4
1,1,3:18.7
0,-2,4:175.4
-1,-1,4:175.4
1,-1,4:175.4
-2,0,4:175.4
0,0,4:175.4
2,0,4:175.4
-1,1,4:175.4
1,1,4:175.4
0,1,2:85.0
2,0,2:85.0
-1,0,2:85.0
0,-1,2:85.0
0,0,1:85.0
-1,0,1:85.0
0,0,0:85.0
