[META]
version=2.0
spawnOnBlockType=2
spawnSunlight=True
spawnDarkness=True
spawnWater=False
spawnLava=False
underFill=False
randomRotation=True
dig=True
tree=False
branch=False
needsFoundation=True
rarity=100
collisionPercentage=20
spawnElevationMin=0
spawnElevationMax=200
spawnInBiome=Custom
[DATA]
1,-1,0:17.0
0,-1,1:18.7
1,-1,1:17.0
0,-3,2:18.15
1,-3,2:18.15
-2,-2,2:18.7
-1,-2,2:18.7
0,-2,2:18.7
3,-2,2:18.15
-1,-1,2:175.4
2,-1,2:175.4
3,-1,2:18.15
-1,0,2:18.15
0,0,2:175.4
-2,-3,3:18.7
0,-3,3:18.15
2,-3,3:18.15
3,-3,3:18.15
-2,-2,3:175.4
0,-2,3:175.4
2,-2,3:175.4
-2,-1,3:18.7
1,-1,3:175.4
2,-1,3:18.15
3,-1,3:175.4
-1,0,3:18.15
1,0,3:18.15
3,0,3:18.15
-1,1,3:175.4
2,1,3:175.4
0,-3,4:175.4
2,-3,4:175.4
-2,-2,4:18.15
-1,-2,4:175.4
0,-2,4:18.15
1,-2,4:175.4
2,-2,4:18.15
-2,-1,4:175.4
0,-1,4:175.4
1,-1,4:18.7
2,-1,4:175.4
-2,0,4:18.15
-1,0,4:175.4
0,0,4:18.15
1,0,4:175.4
3,0,4:175.4
-1,1,4:18.15
1,1,4:18.15
2,1,4:18.15
-1,-3,5:175.4
1,-3,5:175.4
2,-3,5:18.15
3,-3,5:175.4
-2,-2,5:175.4
-1,-2,5:18.15
0,-2,5:175.4
1,-2,5:18.15
2,-2,5:175.4
3,-2,5:18.15
-2,-1,5:18.7
-1,-1,5:175.4
0,-1,5:18.7
1,-1,5:175.4
2,-1,5:18.7
3,-1,5:175.4
-2,0,5:175.4
-1,0,5:18.15
0,0,5:175.4
1,0,5:18.7
2,0,5:18.7
-1,1,5:175.4
0,1,5:18.7
1,1,5:175.4
-1,-3,6:18.15
0,-3,6:175.4
1,-3,6:18.15
2,-3,6:175.4
-2,-2,6:18.7
-1,-2,6:175.4
0,-2,6:18.15
1,-2,6:175.4
2,-2,6:18.7
3,-2,6:175.4
-2,-1,6:175.4
-1,-1,6:18.15
0,-1,6:175.4
1,-1,6:18.15
2,-1,6:175.4
-2,0,6:18.7
-1,0,6:175.4
0,0,6:18.15
1,0,6:175.4
0,1,6:175.4
0,-3,7:18.7
1,-3,7:175.4
2,-3,7:18.7
-2,-2,7:175.4
-1,-2,7:18.15
0,-2,7:175.4
1,-2,7:18.15
2,-2,7:175.4
-2,-1,7:18.7
-1,-1,7:175.4
1,-1,7:175.4
-2,0,7:175.4
-1,0,7:18.15
0,0,7:175.4
0,-3,8:175.4
2,-3,8:175.4
-1,-2,8:175.4
1,-2,8:175.4
-2,-1,8:175.4
-1,0,8:175.4
0,1,4:85.0
2,0,4:85.0
3,-1,4:85.0
-1,-1,4:85.0
3,-2,4:85.0
1,-3,4:85.0
-1,-3,4:85.0
2,0,3:85.0
0,0,3:85.0
0,-1,3:85.0
-1,-1,3:85.0
3,-2,3:85.0
1,-2,3:85.0
-1,-2,3:85.0
1,-3,3:85.0
-1,-3,3:85.0
2,0,2:85.0
1,0,2:85.0
1,-1,2:85.0
0,-1,2:85.0
2,-2,2:85.0
1,-2,2:85.0
