[META]
version=2.0
spawnOnBlockType=2
spawnSunlight=True
spawnDarkness=True
spawnWater=False
spawnLava=False
underFill=False
randomRotation=True
dig=True
tree=True
branch=False
needsFoundation=True
rarity=100
collisionPercentage=20
spawnElevationMin=0
spawnElevationMax=200
spawnInBiome=Custom
[DATA]
1,-2,0:162.12
0,-1,0:162.12
1,0,0:162.12
3,0,0:162.12
0,1,0:162.12
2,1,0:162.12
1,-1,1:162.12
2,-1,1:162.12
1,0,1:162.12
3,0,1:162.12
0,1,1:162.12
1,-1,2:162.12
2,-1,2:162.12
3,-1,2:143.1
1,0,2:162.12
2,0,2:162.12
1,1,2:101.0
4,-10,3:18.7
3,-9,3:18.7
4,-9,3:18.7
5,-9,3:18.7
6,-9,3:18.7
2,-8,3:18.7
3,-8,3:18.7
4,-8,3:18.7
6,-8,3:18.7
7,-8,3:18.7
8,-8,3:18.7
1,-7,3:18.7
2,-7,3:18.7
3,-7,3:18.15
5,-7,3:18.15
2,-6,3:18.7
1,-3,3:162.12
1,-2,3:162.12
1,-1,3:162.12
2,-1,3:162.12
1,0,3:162.12
2,0,3:162.12
1,1,3:101.0
3,-10,4:18.7
5,-10,4:18.7
4,-9,4:18.7
5,-9,4:18.7
6,-9,4:18.7
8,-9,4:18.7
1,-8,4:18.15
3,-8,4:18.7
4,-8,4:18.7
5,-8,4:18.7
8,-8,4:18.7
1,-7,4:18.15
2,-7,4:162.12
4,-7,4:18.15
5,-7,4:18.15
6,-7,4:18.15
8,-7,4:18.7
1,-6,4:18.15
2,-6,4:162.12
3,-6,4:18.15
8,-6,4:18.7
1,-5,4:18.7
2,-5,4:162.12
9,-5,4:18.7
10,-5,4:18.7
2,-4,4:162.12
8,-4,4:18.7
10,-4,4:18.7
8,-3,4:18.7
10,-3,4:18.7
1,-1,4:162.12
2,-1,4:162.12
3,-1,4:162.12
4,-1,4:162.12
5,-1,4:162.12
9,-1,4:18.7
11,-1,4:18.7
1,0,4:162.12
2,0,4:162.12
5,0,4:101.0
9,0,4:18.7
10,0,4:18.7
11,0,4:18.7
1,1,4:162.12
2,1,4:143.3
-9,2,4:18.7
-10,3,4:18.7
-9,3,4:18.7
-8,3,4:18.7
-9,4,4:18.7
-8,4,4:18.7
-8,5,4:18.7
-7,5,4:18.7
-6,5,4:18.15
-7,6,4:18.7
-6,6,4:18.15
-5,6,4:18.15
-5,7,4:18.7
-4,7,4:18.7
-5,8,4:18.7
-3,-11,5:18.7
-2,-11,5:18.7
4,-10,5:18.15
3,-9,5:18.7
4,-9,5:18.15
6,-9,5:18.15
7,-9,5:18.7
3,-8,5:18.15
6,-8,5:18.15
8,-8,5:18.7
1,-7,5:18.15
2,-7,5:18.15
5,-7,5:18.15
7,-7,5:18.7
8,-7,5:18.7
10,-7,5:18.7
8,-6,5:18.7
9,-6,5:18.7
8,-5,5:18.7
10,-5,5:18.7
8,-4,5:18.7
0,-3,5:162.12
9,-3,5:18.7
10,-3,5:18.7
0,-2,5:162.12
8,-2,5:18.15
11,-2,5:18.7
1,-1,5:162.12
2,-1,5:162.12
9,-1,5:18.7
10,-1,5:18.7
11,-1,5:18.7
1,0,5:162.12
2,0,5:162.12
6,0,5:162.12
7,0,5:162.12
8,0,5:162.12
9,0,5:162.12
10,0,5:162.12
-8,1,5:18.7
3,1,5:162.12
10,1,5:18.7
11,1,5:18.7
-10,2,5:18.7
-9,2,5:18.7
0,2,5:162.12
8,2,5:18.15
-10,3,5:18.15
-8,3,5:18.15
-7,3,5:18.15
0,3,5:162.12
1,3,5:143.1
7,3,5:18.7
8,3,5:18.7
9,3,5:18.7
-8,4,5:18.15
-6,4,5:18.15
0,4,5:162.12
6,4,5:18.7
8,4,5:18.7
-9,5,5:18.15
-8,5,5:18.7
-7,5,5:18.7
-6,5,5:18.15
-5,5,5:18.15
0,5,5:162.12
5,5,5:18.7
6,5,5:18.7
-5,6,5:18.15
-4,6,5:18.15
-2,6,5:18.15
-1,6,5:18.15
5,6,5:18.7
-6,7,5:18.7
-2,7,5:18.7
-6,8,5:18.7
-5,8,5:18.7
-4,8,5:18.7
-2,8,5:18.7
-1,8,5:18.7
0,8,5:18.7
1,8,5:18.7
0,9,5:18.7
-2,-11,6:18.7
-4,-10,6:18.7
-3,-10,6:162.12
-2,-10,6:18.7
0,-10,6:18.7
2,-10,6:18.7
3,-10,6:18.7
-3,-9,6:162.12
-1,-9,6:18.7
0,-9,6:18.15
1,-9,6:18.15
4,-9,6:18.15
-4,-8,6:18.15
0,-8,6:18.15
1,-8,6:18.15
2,-8,6:18.15
3,-8,6:18.15
6,-7,6:18.7
8,-6,6:18.7
9,-6,6:18.7
1,-5,6:18.7
9,-5,6:18.7
10,-5,6:18.15
-1,-4,6:162.12
9,-4,6:18.15
10,-4,6:18.15
-2,-3,6:162.12
0,-3,6:162.12
3,-3,6:162.12
4,-3,6:143.1
8,-3,6:18.7
9,-3,6:18.15
3,-2,6:162.12
9,-2,6:18.15
11,-2,6:18.15
0,-1,6:101.0
1,-1,6:162.12
2,-1,6:162.12
10,-1,6:18.7
1,0,6:162.12
2,0,6:162.12
11,0,6:18.7
3,1,6:162.12
4,1,6:162.12
6,1,6:18.7
-9,2,6:18.15
6,2,6:18.15
7,2,6:18.15
9,2,6:18.7
-10,3,6:18.15
-9,3,6:18.15
-8,3,6:18.15
6,3,6:18.15
7,3,6:18.7
9,3,6:18.7
-9,4,6:18.15
-8,4,6:18.15
-7,4,6:18.15
6,4,6:18.15
7,4,6:18.7
9,4,6:18.7
-8,5,6:18.7
-6,5,6:18.15
-4,5,6:18.7
5,5,6:18.7
-5,6,6:18.15
-3,6,6:18.15
-2,6,6:18.15
-1,6,6:162.12
0,6,6:18.15
3,6,6:18.7
4,6,6:18.7
6,6,6:18.7
-6,7,6:18.15
-5,7,6:18.7
-3,7,6:18.7
-2,7,6:18.7
-1,7,6:162.12
0,7,6:18.7
2,7,6:18.7
5,7,6:18.7
-5,8,6:18.7
-4,8,6:18.7
-3,8,6:18.7
-2,8,6:18.7
4,8,6:18.7
0,9,6:18.7
-2,-11,7:18.7
-1,-11,7:18.7
0,-11,7:18.7
-3,-10,7:18.7
-2,-10,7:18.7
-1,-10,7:18.7
0,-10,7:18.7
1,-10,7:18.7
3,-10,7:18.7
4,-10,7:18.15
-6,-9,7:18.7
-5,-9,7:18.7
-4,-9,7:18.7
-3,-9,7:18.7
-1,-9,7:18.7
0,-9,7:18.7
1,-9,7:18.7
4,-9,7:18.15
6,-9,7:18.15
7,-9,7:18.7
-5,-8,7:18.7
-4,-8,7:18.7
-3,-8,7:18.7
-2,-8,7:162.12
-1,-8,7:18.7
2,-8,7:18.7
4,-8,7:18.15
6,-8,7:18.15
7,-8,7:162.12
8,-8,7:18.7
9,-8,7:18.7
-3,-7,7:18.7
-2,-7,7:162.12
-1,-7,7:18.7
0,-7,7:18.7
2,-7,7:18.15
6,-7,7:18.7
8,-7,7:18.7
9,-7,7:18.7
-8,-6,7:18.7
-2,-6,7:162.12
-1,-6,7:18.15
0,-6,7:18.7
2,-6,7:18.15
3,-6,7:18.7
8,-6,7:18.7
-8,-5,7:18.7
-7,-5,7:18.7
-2,-5,7:162.12
-8,-4,7:18.7
-7,-4,7:18.7
-6,-4,7:18.7
-1,-4,7:162.12
4,-4,7:162.12
-9,-3,7:18.7
-7,-3,7:18.7
-3,-3,7:162.12
-2,-3,7:162.12
11,-3,7:18.7
-6,-2,7:18.7
-5,-2,7:162.12
-4,-2,7:162.12
-3,-2,7:101.0
-4,-1,7:143.3
0,-1,7:162.12
2,-1,7:162.12
9,-1,7:18.7
-7,0,7:18.7
1,0,7:162.12
0,1,7:162.12
2,1,7:162.12
4,1,7:162.12
5,2,7:162.12
8,2,7:18.15
-8,3,7:18.7
5,3,7:101.0
7,3,7:18.7
2,4,7:18.7
6,4,7:18.15
7,4,7:18.7
8,4,7:18.15
4,5,7:18.7
5,5,7:18.7
6,5,7:18.7
-2,6,7:18.15
-1,6,7:18.15
3,6,7:18.7
4,6,7:18.7
6,6,7:18.7
-5,7,7:18.15
-4,7,7:18.15
-3,7,7:18.7
-2,7,7:18.7
-1,7,7:18.7
0,7,7:18.7
1,7,7:18.7
2,7,7:18.7
3,7,7:18.7
4,7,7:18.7
6,7,7:18.7
-4,8,7:18.15
-3,8,7:18.7
-2,8,7:18.7
-1,8,7:18.7
0,8,7:18.7
1,8,7:18.7
2,8,7:18.7
5,8,7:18.7
6,8,7:18.7
2,9,7:18.7
3,9,7:18.7
-3,-10,8:18.7
-1,-10,8:18.7
0,-10,8:18.7
1,-10,8:18.7
2,-10,8:18.7
3,-10,8:18.7
-3,-9,8:18.7
-1,-9,8:18.7
0,-9,8:18.7
1,-9,8:18.7
2,-9,8:18.7
3,-9,8:18.7
-7,-8,8:18.7
-5,-8,8:18.7
-4,-8,8:18.7
-3,-8,8:18.7
-1,-8,8:18.7
1,-8,8:18.7
4,-8,8:18.7
6,-8,8:18.7
7,-8,8:18.7
8,-8,8:18.7
9,-8,8:18.7
-6,-7,8:18.7
-4,-7,8:18.7
-2,-7,8:162.12
0,-7,8:18.7
3,-7,8:18.7
4,-7,8:18.7
6,-7,8:162.12
8,-7,8:18.7
-8,-6,8:18.7
-4,-6,8:18.7
-2,-6,8:162.12
-1,-6,8:18.7
0,-6,8:18.7
3,-6,8:18.7
5,-6,8:162.12
7,-6,8:18.15
-9,-5,8:18.7
-8,-5,8:18.7
-6,-5,8:18.7
-2,-5,8:18.7
4,-5,8:162.12
-8,-4,8:18.7
-6,-4,8:18.7
5,-4,8:162.12
8,-4,8:18.7
10,-4,8:18.15
-9,-3,8:18.7
-7,-3,8:18.7
-6,-3,8:18.7
5,-3,8:101.0
6,-3,8:162.12
9,-3,8:18.15
-9,-2,8:18.7
-8,-2,8:18.7
-7,-2,8:18.7
-6,-2,8:18.7
0,-2,8:101.0
-8,-1,8:18.7
-7,-1,8:162.12
-6,-1,8:162.12
0,-1,8:162.12
2,-1,8:162.12
-9,0,8:18.7
-6,0,8:18.7
1,0,8:162.12
-9,1,8:18.7
0,1,8:162.12
-9,2,8:18.15
0,2,8:143.3
2,2,8:162.12
5,2,8:162.12
9,2,8:18.7
-10,3,8:18.15
-2,3,8:18.7
1,3,8:18.7
2,3,8:162.12
-11,4,8:18.7
-10,4,8:18.15
-10,5,8:18.7
-9,5,8:18.7
-8,5,8:18.7
5,5,8:18.15
-4,6,8:18.7
2,6,8:18.15
4,6,8:18.7
5,6,8:18.7
1,7,8:18.15
3,7,8:18.15
6,7,8:18.7
0,8,8:18.15
2,8,8:18.15
1,9,8:18.15
2,9,8:18.7
-6,-10,9:18.7
-5,-10,9:18.7
-4,-10,9:18.7
-3,-10,9:18.7
-2,-10,9:18.7
-1,-10,9:18.7
0,-10,9:18.7
-5,-9,9:18.7
-3,-9,9:18.7
0,-9,9:18.7
1,-9,9:18.7
2,-9,9:18.7
-6,-8,9:18.7
-5,-8,9:18.7
-4,-8,9:18.7
-3,-8,9:18.7
-2,-8,9:18.7
-1,-8,9:18.7
0,-8,9:18.7
2,-8,9:18.7
3,-8,9:18.7
4,-8,9:18.7
5,-8,9:18.7
7,-8,9:18.7
9,-8,9:18.7
10,-8,9:18.7
-5,-7,9:18.7
-4,-7,9:18.7
-3,-7,9:18.7
-2,-7,9:18.7
-1,-7,9:18.7
0,-7,9:18.7
1,-7,9:18.7
2,-7,9:18.7
4,-7,9:18.7
9,-7,9:18.7
10,-7,9:18.7
-4,-6,9:18.7
-3,-6,9:18.7
-2,-6,9:18.7
1,-6,9:18.7
2,-6,9:18.7
3,-6,9:18.7
8,-6,9:18.7
9,-6,9:18.7
10,-6,9:18.7
-8,-5,9:18.7
-3,-5,9:18.7
10,-5,9:18.7
-9,-4,9:18.7
-6,-4,9:18.15
8,-4,9:18.7
9,-4,9:18.7
10,-4,9:18.7
-9,-3,9:18.7
-8,-3,9:18.7
-7,-3,9:18.7
7,-3,9:162.12
8,-3,9:162.12
10,-3,9:18.7
-8,-2,9:18.7
-6,-2,9:18.7
7,-2,9:18.7
8,-2,9:18.15
9,-2,9:18.15
-9,-1,9:18.7
-7,-1,9:18.7
0,-1,9:162.12
2,-1,9:162.12
7,-1,9:18.7
9,-1,9:18.15
-8,0,9:18.15
-2,0,9:162.12
-1,0,9:162.12
1,0,9:162.12
7,0,9:18.15
8,0,9:18.15
-11,1,9:18.7
-9,1,9:18.7
-8,1,9:18.15
-7,1,9:18.15
0,1,9:162.12
1,1,9:143.1
6,1,9:162.12
7,1,9:18.15
-8,2,9:18.15
5,2,9:162.12
6,2,9:162.12
-11,3,9:18.7
-10,3,9:18.7
-9,3,9:18.7
6,3,9:162.12
-8,4,9:18.15
-7,4,9:18.15
-4,4,9:18.15
2,4,9:162.12
-11,5,9:18.7
-10,5,9:18.7
-9,5,9:18.7
-5,5,9:18.15
-4,5,9:18.15
-10,6,9:18.7
-9,6,9:18.7
-7,6,9:18.7
-5,6,9:18.15
-4,6,9:18.15
-3,6,9:18.7
-2,6,9:18.7
-1,6,9:18.7
-7,7,9:18.7
-4,7,9:18.15
-3,7,9:18.7
-2,7,9:18.7
0,7,9:18.15
-6,8,9:18.15
-4,8,9:18.15
-3,8,9:18.7
-1,8,9:18.7
-2,9,9:18.7
-5,-10,10:18.7
-2,-10,10:18.7
-1,-10,10:18.7
1,-10,10:18.7
-5,-9,10:18.7
-2,-9,10:18.7
-1,-9,10:18.7
1,-9,10:18.7
2,-9,10:18.7
3,-9,10:18.7
4,-9,10:18.7
5,-9,10:18.15
-7,-8,10:18.7
-6,-8,10:18.7
-4,-8,10:18.7
-2,-8,10:18.7
0,-8,10:18.7
1,-8,10:18.7
5,-8,10:18.15
8,-8,10:18.15
10,-8,10:18.7
-6,-7,10:18.7
-3,-7,10:18.15
-2,-7,10:18.15
0,-7,10:18.7
1,-7,10:18.7
2,-7,10:18.7
11,-7,10:18.7
-3,-6,10:18.15
-2,-6,10:18.15
0,-6,10:18.7
1,-6,10:18.7
8,-6,10:18.15
9,-6,10:18.7
10,-6,10:18.7
8,-5,10:18.15
9,-5,10:18.7
10,-5,10:18.7
-9,-4,10:18.7
-8,-4,10:18.7
10,-4,10:18.7
-10,-3,10:18.7
-8,-3,10:18.7
-7,-3,10:18.7
8,-3,10:18.7
9,-3,10:18.7
-9,-2,10:18.7
-8,-2,10:18.7
7,-2,10:18.7
8,-2,10:18.7
9,-2,10:18.7
-9,-1,10:18.7
-8,-1,10:18.7
-7,-1,10:18.7
-6,-1,10:18.7
0,-1,10:162.12
2,-1,10:162.12
3,-1,10:101.0
6,-1,10:18.7
7,-1,10:18.7
8,-1,10:18.7
9,-1,10:18.7
-9,0,10:18.7
-4,0,10:101.0
-3,0,10:143.4
6,0,10:18.15
7,0,10:162.12
-11,1,10:18.7
-9,1,10:18.7
-8,1,10:18.15
-4,1,10:162.12
-3,1,10:162.12
0,1,10:162.12
-10,2,10:18.7
-9,3,10:162.12
-8,3,10:162.12
-6,3,10:18.15
-5,3,10:18.7
-4,3,10:18.7
7,3,10:162.12
-10,4,10:18.15
-9,4,10:18.15
-8,4,10:18.15
-7,4,10:18.15
-4,4,10:18.7
-3,4,10:18.15
-1,4,10:18.7
2,4,10:162.12
7,4,10:18.15
8,4,10:162.12
-9,5,10:18.15
-8,5,10:18.7
-6,5,10:18.7
-5,5,10:18.7
-4,5,10:18.7
-3,5,10:18.15
2,5,10:162.12
7,5,10:18.15
8,5,10:18.15
-7,6,10:18.7
-4,6,10:18.7
-2,6,10:18.7
-1,6,10:18.15
0,6,10:18.15
2,6,10:162.12
3,6,10:18.15
-6,7,10:18.7
-4,7,10:18.7
-1,7,10:18.7
1,7,10:18.15
2,7,10:162.12
3,7,10:18.15
6,7,10:18.7
-7,8,10:18.7
-5,8,10:18.15
-4,8,10:18.15
-3,8,10:18.7
-2,8,10:18.15
0,8,10:18.15
-4,9,10:18.15
-3,9,10:18.7
-2,9,10:18.15
-1,9,10:18.15
-1,10,10:18.7
-4,-10,11:18.7
-2,-10,11:18.7
0,-10,11:18.7
-5,-9,11:18.7
-4,-9,11:18.7
-3,-9,11:18.7
-1,-9,11:18.7
0,-9,11:18.7
2,-9,11:18.7
3,-9,11:18.7
5,-9,11:18.15
-5,-8,11:18.15
-3,-8,11:18.7
-2,-8,11:18.7
2,-8,11:18.7
4,-8,11:18.7
5,-8,11:18.15
9,-8,11:18.15
10,-8,11:18.7
11,-8,11:18.7
-5,-7,11:18.15
-4,-7,11:18.7
-2,-7,11:18.15
-1,-7,11:18.15
0,-7,11:18.15
3,-7,11:18.7
4,-7,11:18.7
5,-7,11:18.7
9,-7,11:18.15
10,-7,11:18.7
2,-6,11:18.15
3,-6,11:18.7
9,-6,11:18.7
10,-6,11:18.7
11,-6,11:18.7
8,-5,11:18.15
9,-5,11:18.7
-9,-4,11:18.15
8,-4,11:18.15
-10,-3,11:18.7
-9,-3,11:18.7
-7,-3,11:18.15
-6,-3,11:18.15
10,-3,11:18.7
-9,-2,11:18.7
-6,-2,11:18.7
8,-2,11:18.7
9,-2,11:18.7
10,-2,11:18.7
-10,-1,11:18.7
-7,-1,11:18.7
-1,-1,11:162.12
0,-1,11:162.12
2,-1,11:162.12
7,-1,11:18.15
10,-1,11:18.15
-10,0,11:18.7
-8,0,11:18.15
-7,0,11:18.15
6,0,11:18.15
7,0,11:18.15
8,0,11:18.7
9,0,11:18.7
10,0,11:18.15
-11,1,11:18.7
-10,1,11:18.7
-9,1,11:18.7
-8,1,11:18.15
-4,1,11:162.12
0,1,11:162.12
7,1,11:18.15
-7,2,11:162.12
-6,2,11:162.12
-5,2,11:162.12
-1,2,11:162.12
-8,3,11:162.12
-5,3,11:18.15
7,3,11:18.15
-10,4,11:18.7
-9,4,11:18.15
-8,4,11:18.15
-6,4,11:18.7
-5,4,11:18.15
-4,4,11:18.15
-3,4,11:18.15
6,4,11:18.7
8,4,11:18.15
-8,5,11:18.7
-6,5,11:18.7
-4,5,11:18.15
-3,5,11:18.15
-2,5,11:18.7
0,5,11:18.7
6,5,11:18.7
-7,6,11:18.7
-6,6,11:18.7
-5,6,11:18.7
-4,6,11:18.7
-2,6,11:18.7
0,6,11:18.15
1,6,11:18.15
2,6,11:18.7
3,6,11:18.15
4,6,11:18.15
5,6,11:18.15
6,6,11:18.7
7,6,11:18.7
8,6,11:18.7
-3,7,11:18.7
-2,7,11:18.7
-1,7,11:18.7
0,7,11:18.15
1,7,11:18.15
2,7,11:162.12
4,7,11:18.15
5,7,11:18.15
6,7,11:18.7
-6,8,11:18.7
-3,8,11:18.15
-2,8,11:18.15
-1,8,11:18.15
1,8,11:18.15
2,8,11:162.12
3,8,11:18.7
5,8,11:18.7
6,8,11:18.7
-3,9,11:18.15
1,9,11:18.15
3,9,11:18.7
-4,-9,12:18.7
-1,-9,12:18.7
0,-9,12:18.15
-5,-8,12:18.15
-4,-8,12:18.7
-3,-8,12:18.7
-2,-8,12:18.7
-1,-8,12:18.7
1,-8,12:18.15
5,-8,12:18.15
10,-8,12:18.7
0,-7,12:18.15
1,-7,12:18.15
3,-7,12:18.7
4,-7,12:18.7
9,-7,12:18.15
10,-7,12:18.7
11,-7,12:18.7
2,-6,12:18.15
8,-6,12:18.15
8,-5,12:18.15
10,-5,12:18.7
9,-4,12:18.15
10,-4,12:18.15
-7,-3,12:18.15
7,-3,12:18.7
-8,-2,12:18.7
-7,-2,12:18.15
0,-2,12:162.12
7,-2,12:18.7
9,-2,12:18.15
-7,-1,12:18.15
-6,-1,12:18.15
-2,-1,12:101.0
-1,-1,12:162.12
2,-1,12:162.12
8,-1,12:18.7
-10,0,12:18.7
-9,0,12:18.7
-8,0,12:18.7
-7,0,12:18.15
2,0,12:143.3
7,0,12:18.15
8,0,12:18.7
9,0,12:18.7
-7,1,12:18.15
0,1,12:162.12
-1,2,12:162.12
-9,4,12:18.15
-7,4,12:18.15
-3,4,12:18.15
6,4,12:18.7
7,4,12:18.7
8,4,12:18.7
9,4,12:18.7
-9,5,12:18.15
-8,5,12:18.7
-6,5,12:18.7
-2,5,12:18.7
7,5,12:18.7
8,5,12:18.7
-9,6,12:18.7
-8,6,12:18.7
-6,6,12:18.7
-3,6,12:18.7
-2,6,12:18.7
-1,6,12:18.15
0,6,12:18.15
3,6,12:18.7
6,6,12:18.7
7,6,12:18.7
-7,7,12:18.7
-6,7,12:18.7
-5,7,12:18.7
-3,7,12:18.7
-1,7,12:18.7
1,7,12:18.7
4,7,12:18.7
-4,8,12:18.7
-2,8,12:18.15
0,8,12:18.15
1,8,12:18.7
2,8,12:162.12
3,8,12:18.7
4,8,12:18.7
5,8,12:18.7
-4,9,12:18.7
-1,9,12:18.15
1,9,12:18.7
2,9,12:162.12
3,9,12:18.7
0,10,12:18.7
2,11,12:18.7
-3,-9,13:18.7
5,-9,13:18.7
10,-9,13:18.7
-3,-8,13:18.7
-1,-8,13:18.7
9,-8,13:18.7
11,-8,13:18.7
4,-7,13:18.15
8,-7,13:18.7
10,-7,13:18.7
0,-6,13:18.7
6,-6,13:18.7
11,-6,13:18.7
8,-5,13:18.7
10,-5,13:18.7
8,-4,13:18.7
9,-4,13:18.15
7,-3,13:18.7
8,-3,13:18.7
-7,-2,13:18.15
0,-2,13:162.12
3,-2,13:162.12
7,-2,13:18.7
-8,-1,13:18.7
-6,-1,13:18.15
-4,-1,13:18.7
-1,-1,13:162.12
2,-1,13:162.12
7,-1,13:18.15
8,-1,13:18.15
9,-1,13:18.15
-9,0,13:18.7
-8,0,13:18.7
-7,0,13:18.15
8,0,13:18.15
10,0,13:18.7
-8,1,13:18.15
-6,2,13:18.7
-1,2,13:162.12
-1,3,13:101.0
7,3,13:18.15
8,3,13:18.7
9,3,13:18.7
7,4,13:18.7
9,4,13:18.7
-9,5,13:18.15
-8,5,13:18.15
-7,5,13:18.15
-6,5,13:18.15
-1,5,13:18.7
5,5,13:18.7
6,5,13:18.7
7,5,13:18.7
-7,6,13:18.7
-6,6,13:18.7
-5,6,13:18.7
-3,6,13:18.15
5,6,13:18.7
8,6,13:18.7
-7,7,13:18.7
-6,7,13:18.7
-5,7,13:18.7
-3,7,13:18.15
-1,7,13:18.15
0,7,13:18.15
4,7,13:18.7
7,7,13:18.7
-3,8,13:18.15
-2,8,13:18.15
-1,8,13:18.15
0,8,13:18.7
2,8,13:18.7
3,8,13:18.7
5,8,13:18.7
6,8,13:18.7
0,9,13:18.7
1,9,13:18.7
5,9,13:18.7
-1,10,13:18.15
1,10,13:18.7
2,10,13:18.7
3,10,13:18.7
4,10,13:18.7
1,11,13:18.7
2,11,13:18.7
3,11,13:18.7
9,-9,14:18.15
10,-9,14:18.7
11,-9,14:18.7
11,-8,14:18.7
3,-7,14:18.7
9,-7,14:18.15
11,-7,14:18.7
3,-6,14:18.7
9,-6,14:18.7
10,-6,14:18.7
8,-5,14:18.7
9,-5,14:18.7
7,-4,14:18.15
8,-4,14:18.7
9,-4,14:18.15
-6,-3,14:18.7
0,-3,14:143.4
7,-3,14:18.15
8,-3,14:18.7
-8,-2,14:18.7
-6,-2,14:18.15
0,-2,14:162.12
3,-2,14:162.12
7,-2,14:18.15
8,-2,14:18.15
-7,-1,14:18.15
-6,-1,14:18.15
-1,-1,14:162.12
8,-1,14:18.15
-7,0,14:18.15
8,1,14:18.7
9,1,14:18.7
-1,2,14:162.12
0,2,14:162.12
8,2,14:18.7
6,3,14:18.15
8,3,14:18.7
-3,4,14:18.7
7,4,14:18.7
8,4,14:18.7
9,4,14:18.7
8,5,14:18.7
-6,6,14:18.15
4,6,14:18.7
5,6,14:18.7
7,6,14:18.7
-6,7,14:18.15
-2,7,14:18.15
-1,7,14:18.15
4,7,14:18.7
6,7,14:18.7
-4,8,14:18.7
-3,8,14:18.7
-1,8,14:18.7
0,8,14:18.7
1,8,14:18.7
2,8,14:18.7
3,8,14:18.7
4,8,14:18.7
5,8,14:18.7
-1,9,14:18.7
0,9,14:18.7
3,9,14:18.7
-2,10,14:18.7
0,10,14:18.7
2,10,14:18.7
3,10,14:18.7
2,11,14:18.7
4,-9,15:18.7
5,-9,15:18.7
10,-9,15:18.7
-5,-8,15:18.15
4,-8,15:18.15
6,-8,15:18.7
9,-8,15:18.15
10,-8,15:18.7
-6,-7,15:18.15
-5,-7,15:18.15
5,-7,15:18.7
6,-7,15:18.7
10,-7,15:18.7
-6,-6,15:18.15
-5,-6,15:18.15
-4,-6,15:18.15
-5,-5,15:18.7
7,-5,15:18.15
7,-4,15:18.15
-8,-3,15:18.15
-7,-3,15:18.15
-6,-3,15:18.15
-5,-3,15:18.7
0,-3,15:101.0
1,-3,15:162.12
7,-3,15:18.15
9,-3,15:18.7
-8,-2,15:18.7
0,-2,15:162.12
3,-2,15:162.12
8,-2,15:18.15
-7,-1,15:18.7
-6,-1,15:18.15
-2,-1,15:162.12
-8,0,15:18.7
4,0,15:18.7
7,0,15:18.7
8,0,15:18.15
9,0,15:18.15
6,1,15:18.15
7,1,15:18.15
8,1,15:18.7
-7,2,15:18.15
1,2,15:162.12
4,2,15:18.7
9,2,15:18.7
-8,3,15:18.15
-7,3,15:18.15
-6,3,15:18.15
-2,3,15:162.12
6,3,15:18.15
8,3,15:18.7
7,4,15:18.7
8,4,15:18.7
4,5,15:18.15
5,5,15:18.15
7,5,15:18.7
4,6,15:18.7
5,6,15:18.7
6,6,15:18.7
-5,7,15:18.7
-3,7,15:18.15
-2,7,15:18.15
1,7,15:18.15
3,7,15:18.7
5,7,15:18.7
6,7,15:18.7
-4,8,15:18.7
-1,8,15:18.7
1,8,15:18.7
2,8,15:18.7
4,8,15:18.7
-4,9,15:18.7
-3,9,15:18.7
-2,9,15:18.7
0,9,15:18.7
1,9,15:18.7
3,-10,16:18.7
4,-10,16:18.7
5,-10,16:18.7
4,-9,16:18.7
5,-9,16:18.7
-5,-8,16:18.7
-4,-8,16:18.7
-2,-8,16:18.15
0,-8,16:18.15
3,-8,16:18.7
5,-8,16:18.7
6,-8,16:18.7
7,-8,16:18.15
-6,-7,16:18.7
-5,-7,16:18.7
-4,-7,16:18.7
-3,-7,16:18.7
0,-7,16:18.15
1,-7,16:18.15
4,-7,16:18.15
5,-7,16:18.7
7,-7,16:18.15
-6,-6,16:18.7
-5,-6,16:18.7
-4,-6,16:18.7
0,-6,16:18.15
5,-6,16:18.7
9,-6,16:18.7
-5,-5,16:18.7
6,-5,16:18.7
-5,-4,16:18.7
7,-4,16:18.15
8,-4,16:18.7
-7,-3,16:18.7
1,-3,16:162.12
8,-3,16:18.15
-8,-2,16:18.7
-7,-2,16:18.7
-6,-2,16:18.15
-2,-2,16:101.0
1,-2,16:143.3
3,-2,16:162.12
4,-2,16:162.12
-8,-1,16:18.7
-7,-1,16:18.7
-6,-1,16:18.15
-2,-1,16:162.12
-8,0,16:18.7
-7,0,16:18.7
-6,0,16:18.7
6,0,16:18.7
7,0,16:18.15
-9,1,16:18.7
-6,1,16:18.15
4,1,16:18.7
7,1,16:18.15
9,1,16:18.15
-8,2,16:18.7
-6,2,16:18.15
-2,2,16:143.4
0,2,16:101.0
1,2,16:162.12
-8,3,16:18.7
-7,3,16:18.15
-6,3,16:18.15
-2,3,16:162.12
1,3,16:162.12
7,3,16:18.7
-8,4,16:18.7
7,4,16:18.15
5,5,16:18.15
3,6,16:18.7
4,6,16:18.15
5,6,16:18.15
2,7,16:18.7
3,7,16:18.7
4,7,16:18.15
-4,8,16:18.7
2,8,16:18.7
3,8,16:18.7
2,9,16:18.7
-5,-8,17:18.7
-4,-8,17:18.7
-3,-8,17:18.7
0,-8,17:18.15
4,-8,17:18.7
5,-8,17:18.7
-6,-7,17:18.7
-5,-7,17:18.7
-4,-7,17:18.7
-3,-7,17:18.7
0,-7,17:18.15
1,-7,17:18.15
3,-7,17:18.15
6,-7,17:18.7
7,-7,17:18.15
-6,-6,17:18.7
-5,-6,17:18.7
-3,-6,17:18.7
-2,-6,17:18.7
-1,-6,17:18.7
0,-6,17:18.7
1,-6,17:18.15
6,-6,17:18.7
7,-6,17:18.15
-6,-5,17:18.7
-5,-5,17:18.7
-4,-5,17:18.7
1,-5,17:18.15
0,-4,17:18.7
1,-4,17:162.12
2,-4,17:18.15
-5,-3,17:18.15
1,-3,17:18.15
6,-3,17:18.15
-3,-2,17:162.12
4,-2,17:162.12
5,-2,17:162.12
7,-2,17:18.15
-7,-1,17:18.7
4,-1,17:101.0
8,-1,17:18.15
-7,0,17:18.15
-6,0,17:18.15
5,0,17:18.7
6,0,17:18.7
7,0,17:18.15
8,0,17:18.7
-9,1,17:18.7
-8,1,17:18.7
-7,1,17:18.15
-6,1,17:18.15
7,1,17:18.15
8,1,17:18.15
-8,2,17:18.7
-7,2,17:18.15
-6,2,17:18.15
2,2,17:143.4
3,2,17:18.7
5,2,17:18.15
-8,3,17:18.7
-7,3,17:18.7
2,3,17:162.12
3,3,17:18.15
4,3,17:18.15
-7,4,17:18.15
-4,4,17:18.15
-3,4,17:162.12
3,4,17:18.15
-5,5,17:18.15
-3,5,17:18.7
5,5,17:18.7
-1,7,17:18.7
-1,-9,18:18.7
3,-9,18:18.7
5,-9,18:18.7
-4,-8,18:18.7
-2,-8,18:18.7
1,-8,18:18.15
3,-8,18:18.15
4,-8,18:18.7
5,-8,18:18.7
6,-8,18:18.7
-2,-7,18:18.7
-1,-7,18:18.7
0,-7,18:18.7
1,-7,18:18.15
3,-7,18:18.15
5,-7,18:18.7
6,-7,18:18.7
7,-7,18:18.7
-4,-6,18:18.7
-3,-6,18:18.7
-2,-6,18:18.7
-1,-6,18:18.7
5,-6,18:18.7
6,-6,18:18.7
7,-6,18:18.7
-4,-5,18:18.7
0,-5,18:18.7
1,-5,18:18.15
6,-5,18:18.7
-6,-4,18:18.7
0,-4,18:18.7
1,-4,18:162.12
2,-4,18:18.15
5,-4,18:18.7
7,-4,18:18.7
-5,-3,18:18.7
-4,-3,18:18.15
1,-3,18:18.15
2,-3,18:18.15
3,-3,18:18.7
5,-3,18:162.12
6,-3,18:18.7
-5,-2,18:18.7
-4,-2,18:162.12
5,-2,18:18.7
6,-2,18:18.7
7,-2,18:18.7
8,-2,18:18.7
7,-1,18:18.15
-8,0,18:18.7
-4,0,18:18.7
7,0,18:18.15
8,0,18:18.15
-9,1,18:18.7
-7,1,18:18.15
5,1,18:18.15
6,1,18:18.15
7,1,18:18.15
8,1,18:18.15
-8,2,18:18.7
-7,2,18:18.15
-6,2,18:18.15
-1,2,18:18.7
2,2,18:18.15
3,2,18:18.7
4,2,18:18.15
7,2,18:18.7
8,2,18:18.7
-7,3,18:18.7
2,3,18:18.7
3,3,18:162.12
4,3,18:18.15
-5,4,18:18.15
-3,4,18:162.12
2,4,18:18.7
3,4,18:18.7
4,4,18:18.7
-5,5,18:18.15
-5,6,18:18.15
-4,6,18:18.7
-3,6,18:18.15
0,6,18:18.15
1,6,18:18.15
2,6,18:18.7
-4,7,18:18.7
-3,7,18:18.15
-2,7,18:18.15
-1,7,18:18.15
0,7,18:18.15
-3,8,18:18.15
-1,8,18:18.15
-1,-9,19:18.7
0,-9,19:18.7
1,-9,19:18.7
4,-9,19:18.7
5,-9,19:18.7
-3,-8,19:18.7
-2,-8,19:18.7
-1,-8,19:18.7
0,-8,19:18.7
3,-8,19:18.15
5,-8,19:18.7
6,-8,19:18.7
-4,-7,19:18.7
-2,-7,19:18.7
0,-7,19:18.7
3,-7,19:18.15
4,-7,19:18.7
7,-7,19:18.7
-5,-6,19:18.7
-3,-6,19:18.7
-2,-6,19:18.7
0,-6,19:18.7
5,-6,19:18.15
6,-6,19:18.7
7,-6,19:18.7
-4,-5,19:18.7
-3,-5,19:18.7
2,-5,19:18.7
5,-5,19:18.15
-6,-4,19:18.7
-5,-4,19:18.7
0,-4,19:18.7
1,-4,19:18.7
2,-4,19:18.7
7,-4,19:18.7
-6,-3,19:18.15
-5,-3,19:162.12
1,-3,19:18.7
2,-3,19:18.7
5,-3,19:18.7
6,-3,19:162.12
7,-3,19:18.7
-5,-2,19:18.7
6,-2,19:18.7
7,-2,19:18.7
1,-1,19:18.15
2,-1,19:18.15
8,-1,19:18.7
-7,0,19:18.7
1,0,19:18.15
5,0,19:18.15
7,0,19:18.7
6,1,19:18.15
7,1,19:18.7
8,1,19:18.7
3,2,19:18.7
3,3,19:18.7
4,3,19:18.15
-6,4,19:18.7
-5,4,19:18.7
-4,4,19:18.7
-1,4,19:18.7
2,4,19:18.7
3,4,19:18.15
4,4,19:18.15
-6,5,19:18.7
-5,5,19:162.12
-4,5,19:162.12
0,5,19:18.15
1,5,19:18.7
2,5,19:18.7
3,5,19:18.15
4,5,19:18.15
-4,6,19:18.7
-3,6,19:18.7
-2,6,19:18.7
-1,6,19:18.7
0,6,19:18.7
1,6,19:18.7
2,6,19:18.7
3,6,19:18.15
-4,7,19:18.7
-2,7,19:18.7
-1,7,19:18.7
0,7,19:18.7
1,7,19:18.7
2,7,19:18.7
-4,8,19:18.7
-2,8,19:18.7
-1,-9,20:18.7
0,-9,20:18.7
-3,-8,20:18.7
0,-8,20:18.7
1,-8,20:18.15
3,-8,20:18.15
5,-8,20:18.7
-4,-7,20:18.7
-3,-7,20:18.7
0,-7,20:18.7
4,-7,20:18.7
5,-7,20:18.7
6,-7,20:18.7
-5,-6,20:18.7
-4,-6,20:18.7
-3,-6,20:18.7
-2,-6,20:18.7
5,-6,20:18.15
6,-6,20:18.7
7,-6,20:18.7
-6,-5,20:18.7
-2,-5,20:18.7
1,-5,20:18.7
5,-5,20:18.15
6,-5,20:18.7
-7,-4,20:18.7
-6,-4,20:18.7
-5,-4,20:18.7
-4,-4,20:18.7
0,-4,20:18.7
1,-4,20:18.7
2,-4,20:18.7
5,-4,20:18.15
7,-4,20:18.7
-6,-3,20:18.15
-4,-3,20:18.7
1,-3,20:18.7
2,-3,20:18.7
6,-3,20:18.7
-8,-2,20:18.7
0,-2,20:18.7
2,-2,20:18.7
6,-2,20:18.7
-5,-1,20:18.7
-2,-1,20:18.7
1,-1,20:18.7
2,-1,20:18.7
-6,0,20:18.7
-4,0,20:18.7
-3,0,20:18.15
0,0,20:18.15
1,0,20:18.15
2,0,20:18.15
-5,1,20:18.7
-4,1,20:18.7
-3,1,20:18.15
0,1,20:18.15
1,1,20:18.15
-6,2,20:18.7
-5,2,20:18.7
-4,2,20:18.7
-3,2,20:18.15
-2,2,20:18.15
-1,2,20:18.15
-5,3,20:18.7
-4,3,20:18.7
-2,3,20:18.7
-1,3,20:18.15
3,3,20:18.7
-5,4,20:18.7
-3,4,20:18.7
-2,4,20:18.7
3,4,20:18.15
-5,5,20:18.7
0,5,20:18.7
1,5,20:18.7
-5,6,20:18.7
-4,6,20:18.7
-1,6,20:18.7
0,6,20:18.7
1,6,20:18.7
2,6,20:18.7
-5,7,20:18.7
-4,7,20:18.7
-3,7,20:18.7
-2,7,20:18.7
-1,7,20:18.7
-3,8,20:18.7
-1,8,20:18.7
-2,-8,21:18.7
-4,-7,21:18.7
-4,-6,21:18.7
-3,-6,21:18.7
-7,-5,21:18.7
-5,-5,21:18.7
-4,-5,21:18.7
-3,-5,21:18.7
-2,-5,21:18.7
-7,-4,21:18.7
-6,-4,21:18.7
-4,-4,21:18.7
1,-4,21:18.7
-6,-3,21:18.15
-5,-3,21:18.7
-1,-3,21:18.7
0,-3,21:18.7
1,-3,21:18.7
2,-3,21:18.7
-2,-2,21:18.7
-1,-2,21:18.7
0,-2,21:18.7
1,-2,21:18.7
2,-2,21:18.7
-5,-1,21:18.7
-4,-1,21:18.7
-3,-1,21:18.7
0,-1,21:18.7
1,-1,21:18.7
2,-1,21:18.7
-6,0,21:18.15
-5,0,21:18.7
-4,0,21:18.7
-3,0,21:18.15
-2,0,21:18.15
-1,0,21:18.15
0,0,21:18.7
1,0,21:18.7
2,0,21:18.7
-6,1,21:18.7
-5,1,21:18.7
-4,1,21:18.7
-3,1,21:18.15
-2,1,21:18.15
-1,1,21:18.15
0,1,21:18.15
2,1,21:18.15
-5,2,21:18.7
-3,2,21:18.15
-5,3,21:18.7
-4,3,21:18.7
-3,3,21:18.7
-2,3,21:18.7
-1,3,21:18.15
-2,4,21:18.7
-1,4,21:18.15
-5,5,21:18.7
-4,6,21:18.7
-5,7,21:18.7
-3,-7,22:18.7
-4,-6,22:18.7
-3,-6,22:18.7
-2,-6,22:18.7
-6,-5,22:18.7
-7,-4,22:18.7
-5,-4,22:18.7
0,-3,22:18.7
1,-3,22:18.7
-2,-2,22:18.7
1,-2,22:18.7
2,-2,22:18.7
-3,-1,22:18.7
-2,-1,22:18.7
-1,-1,22:18.7
0,-1,22:18.7
-3,0,22:18.15
-2,0,22:18.15
1,0,22:18.7
-4,1,22:18.7
-3,1,22:18.15
-1,1,22:18.15
1,1,22:18.7
-5,2,22:18.7
-3,2,22:18.15
-1,2,22:18.15
0,2,22:18.7
-4,3,22:18.7
-3,3,22:18.7
-1,3,22:18.7
-3,4,22:18.7
-2,4,22:18.7
-4,-1,23:18.7
-4,0,23:18.7
-3,0,23:18.15
-4,1,23:18.7
