[META]
version=2.0
spawnOnBlockType=2
spawnSunlight=True
spawnDarkness=True
spawnWater=False
spawnLava=False
underFill=False
randomRotation=True
dig=True
tree=True
branch=False
needsFoundation=True
rarity=100
collisionPercentage=20
spawnElevationMin=0
spawnElevationMax=200
spawnInBiome=Custom
[DATA]
0,-2,0:162.12
0,-1,0:162.12
1,0,0:162.12
0,-1,1:162.12
-2,-7,2:18.7
-4,-6,2:18.7
-1,-6,2:18.7
-6,-5,2:18.7
-4,-5,2:18.7
-3,-5,2:18.7
-2,-5,2:18.7
-4,-4,2:18.7
-3,-4,2:18.7
-1,-1,2:162.12
0,-1,2:162.12
0,0,2:143.3
1,0,2:162.12
4,3,2:18.7
-2,6,2:18.7
-3,-7,3:18.7
-1,-7,3:18.7
-6,-6,3:18.7
-5,-6,3:18.7
-2,-6,3:18.7
-7,-5,3:18.7
-2,-5,3:18.7
-1,-5,3:18.7
-5,-4,3:18.7
-4,-4,3:18.7
-3,-4,3:18.7
0,-1,3:162.12
-4,0,3:162.12
-3,0,3:162.12
-2,0,3:162.12
0,0,3:162.12
-7,1,3:18.7
-5,1,3:18.7
-3,1,3:143.3
2,1,3:162.12
3,2,3:162.12
4,2,3:18.7
5,2,3:18.7
-6,3,3:18.7
3,3,3:18.7
5,3,3:18.7
2,4,3:18.7
4,4,3:18.7
1,6,3:18.7
-2,-7,4:18.7
-7,-6,4:18.7
-6,-6,4:18.7
-5,-6,4:18.7
-4,-6,4:18.7
-2,-6,4:18.7
-6,-5,4:18.7
-5,-5,4:18.7
-4,-5,4:18.7
-2,-5,4:18.7
1,-5,4:18.7
-7,-4,4:18.7
-6,-4,4:18.7
2,-4,4:18.7
3,-4,4:18.7
4,-4,4:18.7
-6,-3,4:18.7
4,-3,4:18.7
5,-3,4:18.7
-6,-2,4:18.7
-5,-2,4:18.7
3,-2,4:18.7
5,-2,4:18.7
-6,-1,4:18.7
-5,-1,4:18.7
-4,-1,4:18.7
0,-1,4:162.12
1,-1,4:162.12
5,-1,4:18.7
-6,0,4:18.7
-5,0,4:18.7
-4,0,4:162.12
0,0,4:162.12
5,0,4:18.7
6,0,4:18.7
-7,1,4:18.7
-6,1,4:162.12
-5,1,4:162.12
3,1,4:143.4
-7,2,4:18.7
-6,2,4:18.7
3,2,4:162.12
-7,3,4:18.7
-6,3,4:18.7
-5,3,4:18.7
-4,3,4:18.7
2,3,4:18.7
3,3,4:18.7
4,3,4:162.12
-5,4,4:18.7
-4,4,4:18.7
-1,4,4:18.7
0,4,4:18.7
1,4,4:18.7
3,4,4:18.7
5,4,4:18.7
-4,5,4:18.7
-3,5,4:18.7
-2,5,4:18.7
-1,5,4:18.7
0,5,4:18.7
2,5,4:18.7
3,5,4:18.7
4,5,4:18.7
-3,6,4:18.7
-2,6,4:18.7
-1,6,4:18.7
1,-7,5:18.7
-6,-6,5:18.7
-5,-6,5:18.7
0,-6,5:18.7
1,-6,5:18.7
2,-6,5:18.7
3,-6,5:18.7
-7,-5,5:18.7
-6,-5,5:18.7
2,-5,5:18.7
3,-5,5:18.7
4,-5,5:18.7
-5,-4,5:18.7
-4,-4,5:18.7
1,-4,5:18.7
2,-3,5:18.7
5,-3,5:18.7
-5,-2,5:18.7
-1,-2,5:162.12
4,-2,5:18.7
-6,-1,5:18.7
-5,-1,5:18.7
-4,-1,5:18.7
1,-1,5:162.12
4,-1,5:18.7
6,-1,5:18.7
-6,0,5:18.7
-5,0,5:18.7
-4,0,5:18.7
5,0,5:18.7
-7,1,5:18.7
-6,1,5:18.7
0,1,5:162.12
4,1,5:18.7
5,1,5:18.7
-7,2,5:18.7
-6,2,5:18.7
-5,2,5:18.7
-4,2,5:18.7
4,2,5:18.7
-5,3,5:18.7
-4,3,5:18.7
-3,3,5:18.7
2,3,5:18.7
5,3,5:18.7
-6,4,5:18.7
-5,4,5:18.7
-4,4,5:18.7
-3,4,5:18.7
-2,4,5:18.7
-1,4,5:18.7
0,4,5:18.7
1,4,5:18.7
3,4,5:18.7
4,4,5:18.7
-5,5,5:18.7
-3,5,5:18.7
0,5,5:18.7
2,5,5:18.7
3,5,5:18.7
-3,6,5:18.7
-2,6,5:18.7
-1,6,5:18.7
1,6,5:18.7
-2,7,5:18.7
0,-7,6:18.7
1,-7,6:18.7
2,-7,6:18.7
1,-6,6:18.7
3,-6,6:18.7
-6,-5,6:18.7
-5,-5,6:18.7
-4,-5,6:18.7
0,-5,6:18.7
1,-5,6:18.7
2,-5,6:18.7
3,-5,6:18.7
-5,-4,6:18.7
-1,-4,6:18.7
3,-4,6:18.7
-4,-3,6:18.7
2,-3,6:18.7
3,-3,6:18.7
4,-3,6:18.7
-7,-2,6:18.7
-5,-2,6:18.7
-1,-2,6:162.12
3,-2,6:18.7
4,-2,6:18.7
-6,-1,6:18.7
-4,-1,6:18.7
-1,-1,6:143.3
2,-1,6:162.12
5,-1,6:18.7
6,-1,6:18.7
-6,0,6:18.7
-4,0,6:18.7
5,0,6:18.7
6,0,6:18.7
-5,1,6:18.7
-4,1,6:18.7
0,1,6:162.12
5,1,6:18.7
-5,2,6:18.7
3,2,6:18.7
4,2,6:18.7
-5,4,6:18.7
-4,4,6:18.7
-1,4,6:18.7
1,4,6:18.7
2,4,6:18.7
3,4,6:18.7
-4,5,6:18.7
-1,5,6:18.7
1,5,6:18.7
-3,6,6:18.7
-2,6,6:18.7
-1,6,6:18.7
0,6,6:18.7
1,6,6:18.7
-2,7,6:18.7
-1,-7,7:18.7
0,-7,7:18.7
1,-7,7:18.7
2,-7,7:18.7
-1,-6,7:18.7
1,-6,7:18.7
2,-6,7:18.7
-2,-5,7:18.7
-1,-5,7:18.7
0,-5,7:18.7
2,-5,7:18.7
-4,-4,7:18.7
-3,-4,7:18.7
-2,-4,7:18.7
-1,-4,7:18.7
-3,-3,7:18.7
-4,-2,7:18.7
-2,-2,7:162.12
3,-2,7:162.12
-4,-1,7:18.7
-3,-1,7:18.7
1,-1,7:143.2
2,-1,7:162.12
-6,0,7:18.7
-5,0,7:18.7
-3,0,7:18.7
-5,1,7:18.7
-4,1,7:18.7
-3,1,7:18.7
0,1,7:162.12
0,2,7:162.12
1,2,7:143.1
0,-6,8:18.7
1,-6,8:18.7
-4,-5,8:18.7
-1,-5,8:18.7
0,-5,8:18.7
1,-5,8:18.7
-3,-4,8:18.7
-2,-4,8:18.7
-1,-4,8:18.7
0,-4,8:18.7
1,-4,8:18.7
2,-4,8:18.7
-4,-3,8:18.7
-2,-3,8:162.12
-1,-3,8:18.7
0,-3,8:18.7
1,-3,8:18.7
-4,-2,8:18.7
-2,-2,8:162.12
-1,-2,8:18.7
0,-2,8:18.7
3,-2,8:162.12
4,-2,8:18.7
5,-2,8:18.7
-4,-1,8:18.7
2,-1,8:18.7
5,-1,8:18.7
-4,0,8:18.7
-3,0,8:18.7
2,0,8:18.7
3,0,8:18.7
4,0,8:18.7
-3,1,8:18.7
1,1,8:18.7
-5,2,8:18.7
-4,2,8:18.7
0,2,8:162.12
-4,3,8:18.7
-1,3,8:18.7
0,4,8:18.7
-3,-5,9:18.7
-2,-5,9:18.7
-1,-5,9:18.7
1,-5,9:18.7
-1,-4,9:18.7
1,-4,9:18.7
2,-4,9:18.7
-3,-3,9:162.12
-2,-3,9:18.7
-1,-3,9:18.7
0,-3,9:18.7
2,-3,9:18.7
3,-3,9:18.7
-4,-2,9:18.7
-3,-2,9:18.7
-2,-2,9:18.7
-1,-2,9:18.7
0,-2,9:18.7
1,-2,9:18.7
3,-2,9:18.7
4,-2,9:162.12
-3,-1,9:18.7
-2,-1,9:18.7
-1,-1,9:18.7
0,-1,9:18.7
3,-1,9:18.7
4,-1,9:18.7
5,-1,9:18.7
-4,0,9:18.7
-3,0,9:18.7
-1,0,9:18.7
2,0,9:18.7
3,0,9:18.7
4,0,9:18.7
5,0,9:18.7
-4,1,9:18.7
2,1,9:18.7
3,1,9:18.7
4,1,9:18.7
-3,2,9:18.7
0,2,9:18.7
1,2,9:18.7
2,2,9:18.7
3,2,9:18.7
-4,3,9:18.7
-1,3,9:18.7
0,3,9:162.12
1,3,9:18.7
0,4,9:18.7
1,4,9:18.7
1,-5,10:18.7
-3,-4,10:18.7
1,-4,10:18.7
-4,-3,10:18.7
-3,-3,10:18.7
-2,-3,10:18.7
-1,-3,10:18.7
1,-3,10:18.7
-3,-2,10:18.7
-2,-2,10:18.7
2,-2,10:18.7
4,-2,10:18.7
5,-2,10:18.7
-4,-1,10:18.7
-3,-1,10:18.7
-2,-1,10:18.7
0,-1,10:18.7
2,-1,10:18.7
4,-1,10:18.7
-5,0,10:18.7
-4,0,10:18.7
-3,0,10:18.7
-1,0,10:18.7
0,0,10:18.7
2,0,10:18.7
3,0,10:18.7
-3,1,10:18.7
1,1,10:18.7
3,1,10:18.7
-5,2,10:18.7
-4,2,10:18.7
-2,2,10:18.7
1,2,10:18.7
3,2,10:18.7
-4,3,10:18.7
1,3,10:18.7
2,3,10:18.7
3,3,10:18.7
-2,4,10:18.7
-1,4,10:18.7
0,4,10:18.7
-3,-2,11:18.7
-2,-2,11:18.7
0,-2,11:18.7
1,-2,11:18.7
-1,-1,11:18.7
1,-1,11:18.7
-4,0,11:18.7
-3,0,11:18.7
0,0,11:18.7
1,0,11:18.7
-5,1,11:18.7
-4,1,11:18.7
-3,1,11:18.7
-1,2,11:18.7
0,2,11:18.7
1,2,11:18.7
3,2,11:18.7
-2,3,11:18.7
-1,3,11:18.7
0,3,11:18.7
0,-2,12:18.7
-1,-1,12:18.7
0,-1,12:18.7
0,0,12:18.7
