[META]
version=2.0
spawnOnBlockType=2
spawnSunlight=True
spawnDarkness=True
spawnWater=False
spawnLava=False
underFill=False
randomRotation=True
dig=True
tree=True
branch=False
needsFoundation=True
rarity=100
collisionPercentage=20
spawnElevationMin=0
spawnElevationMax=200
spawnInBiome=Custom
[DATA]
-1,-3,0:162.12
0,-2,0:162.12
1,-1,0:162.12
-1,0,0:162.12
0,0,0:162.12
-1,-2,1:162.12
0,-2,1:162.12
0,-1,1:162.12
1,-1,1:162.12
-1,0,1:162.12
5,-12,2:18.7
4,-11,2:18.7
5,-11,2:18.7
6,-11,2:18.7
10,-10,2:18.7
-5,-9,2:18.7
10,-9,2:18.7
11,-9,2:18.7
10,-8,2:18.7
10,-5,2:18.7
11,-5,2:18.7
10,-4,2:18.7
11,-4,2:18.7
12,-4,2:18.7
11,-3,2:18.7
12,-3,2:18.7
-1,-2,2:162.12
0,-2,2:162.12
-1,-1,2:162.12
0,-1,2:162.12
-7,3,2:18.7
7,3,2:18.7
5,4,2:18.7
6,5,2:18.7
-5,6,2:18.7
-4,6,2:18.7
-3,6,2:18.7
-2,6,2:18.7
-4,7,2:18.7
4,-12,3:18.7
3,-11,3:18.7
5,-11,3:18.7
-6,-10,3:18.7
0,-10,3:18.7
5,-10,3:18.7
6,-10,3:18.7
9,-10,3:18.7
11,-10,3:18.7
-6,-9,3:18.7
5,-9,3:18.7
8,-9,3:18.7
9,-9,3:18.7
11,-9,3:18.7
-4,-8,3:18.7
10,-8,3:18.7
11,-8,3:18.7
10,-6,3:18.7
11,-6,3:18.7
10,-5,3:18.7
11,-5,3:18.7
12,-5,3:18.7
10,-4,3:18.7
11,-4,3:18.7
12,-4,3:18.7
-9,-3,3:18.7
11,-3,3:18.7
-1,-2,3:162.12
0,-2,3:162.12
-1,-1,3:162.12
0,-1,3:162.12
12,-1,3:18.7
11,0,3:18.7
12,0,3:18.7
-7,2,3:18.7
-6,3,3:18.7
4,4,3:18.7
6,4,3:18.7
-5,5,3:18.7
-4,5,3:18.7
-3,5,3:18.7
-2,5,3:18.7
0,5,3:18.7
5,5,3:18.7
6,5,3:18.7
7,5,3:18.7
-5,6,3:18.7
-3,6,3:18.7
-2,6,3:18.7
-1,6,3:18.7
2,6,3:18.7
4,6,3:18.7
6,6,3:18.7
-3,7,3:18.7
-2,7,3:18.7
-1,7,3:18.7
0,7,3:18.7
2,-12,4:18.7
4,-12,4:18.7
-2,-11,4:18.7
4,-11,4:18.7
5,-11,4:18.7
6,-11,4:18.7
7,-11,4:18.7
8,-11,4:18.7
9,-11,4:18.7
-1,-10,4:18.7
4,-10,4:18.7
6,-10,4:18.7
8,-10,4:18.7
-4,-9,4:18.7
4,-9,4:18.7
6,-9,4:18.7
7,-9,4:18.7
8,-9,4:18.7
-7,-8,4:18.7
-6,-8,4:18.7
-5,-8,4:18.7
-4,-8,4:18.7
9,-8,4:18.7
10,-8,4:18.7
-6,-7,4:18.7
11,-6,4:18.7
-9,-5,4:18.7
10,-5,4:18.7
11,-5,4:18.7
12,-5,4:18.7
-10,-4,4:18.7
10,-4,4:18.7
12,-4,4:18.7
-9,-3,4:18.7
10,-3,4:18.7
12,-3,4:18.7
-7,-2,4:18.7
-3,-2,4:162.12
-2,-2,4:162.12
-1,-2,4:162.12
1,-2,4:162.12
9,-2,4:18.15
11,-2,4:18.7
12,-2,4:18.7
13,-2,4:18.7
-3,-1,4:143.3
-1,-1,4:162.12
0,-1,4:162.12
1,-1,4:101.0
11,-1,4:18.7
12,-1,4:18.7
13,-1,4:18.7
-7,0,4:18.7
-1,0,4:101.0
0,0,4:162.12
10,0,4:18.15
11,0,4:18.7
12,0,4:18.7
5,1,4:18.15
10,1,4:18.15
4,2,4:18.15
11,2,4:18.7
-8,3,4:18.7
2,4,4:18.15
3,4,4:18.15
4,4,4:18.15
5,4,4:18.15
-7,5,4:18.7
-5,5,4:18.7
-3,5,4:18.7
-1,5,4:18.7
1,5,4:18.7
2,5,4:18.15
3,5,4:18.15
5,5,4:18.15
6,5,4:18.15
-8,6,4:18.7
-7,6,4:18.7
-5,6,4:18.7
-4,6,4:18.7
-2,6,4:18.7
-1,6,4:18.7
1,6,4:18.7
3,6,4:18.15
4,6,4:18.15
-5,7,4:18.7
-2,7,4:18.7
0,7,4:18.7
1,7,4:18.7
3,-12,5:18.7
4,-12,5:18.7
5,-12,5:18.7
-2,-11,5:18.7
-1,-11,5:18.7
2,-11,5:18.7
4,-11,5:18.7
5,-11,5:18.7
6,-11,5:18.7
7,-11,5:18.7
8,-11,5:18.7
-5,-10,5:18.7
-3,-10,5:18.7
-2,-10,5:18.7
-1,-10,5:18.7
7,-10,5:18.7
8,-10,5:18.7
9,-10,5:18.7
-6,-9,5:18.7
-3,-9,5:18.7
-2,-9,5:18.7
-1,-9,5:18.7
4,-9,5:18.7
5,-9,5:18.7
6,-9,5:18.7
-7,-8,5:18.7
-6,-8,5:18.7
-4,-8,5:18.7
-3,-8,5:18.7
7,-8,5:18.7
9,-8,5:18.7
10,-8,5:18.7
-6,-7,5:18.7
-5,-7,5:18.7
-9,-6,5:18.7
-6,-6,5:18.7
9,-6,5:18.7
-10,-5,5:18.7
-9,-5,5:18.7
-8,-5,5:18.7
-9,-4,5:162.12
-10,-3,5:18.7
-8,-3,5:162.12
-5,-3,5:162.12
-4,-3,5:143.1
2,-3,5:162.12
9,-3,5:18.7
11,-3,5:18.7
-9,-2,5:18.7
-4,-2,5:162.12
-1,-2,5:162.12
2,-2,5:143.3
12,-2,5:18.7
-10,-1,5:18.7
-9,-1,5:18.7
-8,-1,5:18.7
-5,-1,5:162.12
0,-1,5:162.12
1,-1,5:101.0
9,-1,5:18.15
10,-1,5:18.15
13,-1,5:18.7
-9,0,5:18.7
-8,0,5:18.7
-7,0,5:18.7
-6,0,5:162.12
-2,0,5:162.12
11,0,5:18.7
-9,1,5:18.7
-8,1,5:18.7
-7,1,5:162.12
-6,1,5:18.7
-3,1,5:162.12
10,1,5:18.15
11,1,5:18.7
12,1,5:18.7
-8,2,5:18.7
-7,2,5:18.7
4,2,5:18.15
11,2,5:18.7
-6,3,5:18.7
5,3,5:18.15
6,3,5:18.15
7,3,5:18.15
-8,4,5:18.7
-4,4,5:18.7
1,4,5:18.7
2,4,5:18.15
4,4,5:18.15
-7,5,5:18.7
-6,5,5:18.7
-5,5,5:18.7
-4,5,5:18.7
-3,5,5:18.7
-1,5,5:18.7
0,5,5:18.7
2,5,5:18.15
3,5,5:18.15
5,5,5:18.15
-8,6,5:18.7
-7,6,5:162.12
-6,6,5:18.7
-5,6,5:18.7
1,6,5:18.7
4,6,5:18.15
-7,7,5:18.7
-4,7,5:18.7
-2,7,5:18.7
-1,7,5:18.7
0,7,5:18.7
1,7,5:18.7
2,7,5:18.7
0,-12,6:18.7
-2,-11,6:18.7
4,-11,6:18.7
5,-11,6:18.7
-3,-10,6:18.7
0,-10,6:18.7
4,-10,6:18.7
6,-10,6:18.7
8,-10,6:18.7
-6,-9,6:18.7
-3,-9,6:18.7
-2,-9,6:18.7
-1,-9,6:18.7
4,-9,6:18.7
5,-9,6:18.7
6,-9,6:18.7
7,-9,6:18.7
8,-9,6:18.7
9,-9,6:18.7
11,-9,6:18.7
-6,-8,6:18.7
-4,-8,6:18.7
-3,-8,6:18.7
4,-8,6:18.7
5,-8,6:18.7
6,-8,6:18.7
7,-8,6:18.7
-6,-7,6:18.7
-4,-7,6:18.7
-3,-7,6:18.7
8,-7,6:18.7
9,-7,6:18.7
10,-7,6:18.7
11,-7,6:18.7
-7,-6,6:18.7
-6,-6,6:18.7
9,-6,6:18.7
-9,-5,6:18.7
8,-5,6:18.7
9,-5,6:18.7
10,-5,6:18.7
-10,-4,6:18.7
-9,-4,6:18.7
-8,-4,6:18.7
-10,-3,6:18.7
-9,-3,6:18.7
-8,-3,6:162.12
-7,-3,6:162.12
-6,-3,6:162.12
-5,-3,6:162.12
3,-3,6:162.12
10,-3,6:18.7
-10,-2,6:18.7
-9,-2,6:18.7
-8,-2,6:18.7
-1,-2,6:162.12
10,-2,6:18.15
-9,-1,6:18.7
-8,-1,6:18.7
-7,-1,6:18.7
0,-1,6:162.12
10,-1,6:18.15
12,-1,6:18.7
-10,0,6:18.7
-9,0,6:18.7
-8,0,6:18.7
-3,0,6:143.4
8,0,6:18.15
11,0,6:18.7
-9,1,6:18.7
-8,1,6:18.7
-7,1,6:18.7
-3,1,6:162.12
10,1,6:18.15
12,1,6:18.7
-3,2,6:162.12
5,2,6:18.15
-8,3,6:18.7
-4,3,6:162.12
4,3,6:18.15
6,3,6:18.15
-3,4,6:18.7
1,4,6:18.7
2,4,6:18.15
3,4,6:18.15
4,4,6:18.15
5,4,6:18.15
6,4,6:18.15
9,4,6:18.15
10,4,6:18.15
-6,5,6:162.12
-4,5,6:18.7
-3,5,6:18.7
-1,5,6:18.7
3,5,6:18.15
5,5,6:18.15
6,5,6:18.15
10,5,6:18.15
-7,6,6:18.7
-6,6,6:18.7
-5,6,6:18.7
-4,6,6:18.7
-2,6,6:18.7
-1,6,6:18.7
1,6,6:18.7
-7,7,6:18.7
-6,7,6:18.7
0,7,6:18.7
1,7,6:18.7
-2,-11,7:18.7
-1,-11,7:18.7
0,-11,7:18.7
5,-11,7:18.7
6,-11,7:18.7
-1,-10,7:18.7
3,-10,7:18.7
4,-10,7:18.7
5,-10,7:162.12
6,-10,7:18.7
7,-10,7:18.7
8,-10,7:18.7
9,-10,7:18.7
-7,-9,7:18.7
-6,-9,7:18.7
-5,-9,7:18.7
-2,-9,7:18.7
5,-9,7:18.7
6,-9,7:18.7
8,-9,7:18.7
9,-9,7:18.7
10,-9,7:18.7
11,-9,7:18.7
-6,-8,7:18.7
-5,-8,7:18.7
-3,-8,7:18.7
-1,-8,7:18.7
6,-8,7:18.7
8,-8,7:18.7
9,-8,7:18.7
10,-8,7:162.12
11,-8,7:18.7
-7,-7,7:18.7
-6,-7,7:18.7
-4,-7,7:18.15
-3,-7,7:18.15
8,-7,7:18.7
9,-7,7:18.7
11,-7,7:18.7
-7,-6,7:18.7
8,-6,7:18.7
9,-6,7:18.7
10,-6,7:18.7
8,-5,7:18.7
10,-5,7:18.7
-10,-4,7:18.7
-9,-4,7:18.7
-8,-4,7:18.7
-2,-4,7:162.12
4,-4,7:162.12
8,-4,7:18.7
9,-4,7:18.7
10,-4,7:18.7
-9,-3,7:18.7
-1,-3,7:162.12
3,-3,7:162.12
-10,-2,7:18.7
-8,-2,7:18.7
-1,-2,7:162.12
11,-2,7:18.7
12,-2,7:18.7
-9,-1,7:18.7
-8,-1,7:18.7
0,-1,7:162.12
1,-1,7:143.1
11,-1,7:18.7
-9,0,7:18.7
-8,0,7:18.7
-7,0,7:18.7
0,0,7:162.12
1,0,7:162.12
10,0,7:18.15
-9,1,7:18.7
-8,1,7:18.7
-9,2,7:18.7
-8,2,7:18.7
-7,2,7:18.7
-6,2,7:18.7
-9,3,7:18.7
-8,3,7:18.7
-2,3,7:162.12
1,3,7:18.7
3,3,7:18.15
9,3,7:18.15
-6,4,7:18.7
-5,4,7:162.12
-3,4,7:18.7
-2,4,7:162.12
0,4,7:18.7
2,4,7:18.15
3,4,7:18.15
5,4,7:18.15
6,4,7:18.15
10,4,7:162.12
11,4,7:18.7
-6,5,7:162.12
-2,5,7:18.7
1,5,7:18.7
3,5,7:18.15
8,5,7:18.15
9,5,7:18.15
11,5,7:18.7
-5,6,7:18.7
-4,6,7:18.7
-3,6,7:18.7
-2,6,7:18.7
1,6,7:18.7
3,6,7:18.15
10,6,7:18.15
-7,7,7:18.7
-6,7,7:18.7
-4,7,7:18.7
-2,7,7:18.7
-1,7,7:18.7
-6,8,7:18.7
-2,-11,8:18.7
-1,-11,8:18.7
-3,-10,8:18.7
-1,-10,8:18.7
0,-10,8:18.7
1,-10,8:18.7
2,-10,8:18.7
4,-10,8:18.7
8,-10,8:18.7
-6,-9,8:18.7
-5,-9,8:18.7
-4,-9,8:18.7
-3,-9,8:18.7
-1,-9,8:18.7
3,-9,8:18.7
5,-9,8:162.12
6,-9,8:18.7
7,-9,8:18.7
8,-9,8:18.7
10,-9,8:18.7
-8,-8,8:18.7
-7,-8,8:18.7
-5,-8,8:18.7
-4,-8,8:18.7
-2,-8,8:18.7
4,-8,8:162.12
5,-8,8:18.7
6,-8,8:18.7
7,-8,8:18.7
9,-8,8:18.7
11,-8,8:18.7
-7,-7,8:18.7
-6,-7,8:18.7
-5,-7,8:18.15
-3,-7,8:18.15
7,-7,8:18.7
8,-7,8:18.7
9,-7,8:162.12
10,-7,8:18.7
-8,-6,8:18.7
-3,-6,8:162.12
4,-6,8:162.12
8,-6,8:162.12
-3,-5,8:162.12
4,-5,8:162.12
8,-5,8:18.7
9,-5,8:18.7
11,-5,8:18.7
-8,-4,8:18.7
-2,-4,8:162.12
4,-4,8:162.12
5,-4,8:162.12
8,-4,8:18.7
9,-4,8:18.7
11,-4,8:18.7
-10,-3,8:18.7
-8,-3,8:18.7
-1,-3,8:162.12
7,-3,8:18.7
10,-3,8:18.7
-7,-2,8:18.7
-1,-2,8:162.12
6,-2,8:18.15
8,-2,8:18.15
-8,-1,8:18.7
7,-1,8:18.15
-9,0,8:18.7
-8,0,8:18.7
-7,0,8:18.7
0,0,8:162.12
1,0,8:162.12
5,0,8:162.12
-8,1,8:18.7
-6,1,8:18.7
2,1,8:162.12
3,1,8:162.12
4,1,8:162.12
7,1,8:18.15
8,1,8:18.15
11,1,8:18.7
-9,2,8:18.7
-8,2,8:18.7
-6,2,8:18.7
0,2,8:18.7
5,2,8:162.12
8,2,8:18.15
9,2,8:18.15
-8,3,8:18.7
-7,3,8:18.7
-6,3,8:18.7
7,3,8:162.12
8,3,8:162.12
9,3,8:18.15
10,3,8:18.15
-4,4,8:18.7
-2,4,8:162.12
-1,4,8:18.7
1,4,8:18.7
2,4,8:18.15
3,4,8:18.15
9,4,8:162.12
11,4,8:18.7
-4,5,8:18.7
-3,5,8:18.7
-2,5,8:18.7
-1,5,8:162.12
1,5,8:18.7
2,5,8:18.15
3,5,8:18.15
4,5,8:18.15
8,5,8:18.15
9,5,8:18.15
-6,6,8:18.7
-5,6,8:18.7
-4,6,8:18.7
-1,6,8:18.7
0,6,8:18.7
2,6,8:18.15
3,6,8:18.15
9,6,8:18.15
10,6,8:18.15
11,6,8:18.7
-5,7,8:18.7
-4,7,8:18.7
-3,7,8:18.7
-1,7,8:18.7
-7,8,8:18.7
-6,8,8:18.7
-5,8,8:18.7
-1,-11,9:18.7
0,-11,9:18.7
1,-11,9:18.7
2,-11,9:18.7
4,-11,9:18.7
-3,-10,9:18.7
-2,-10,9:18.7
-1,-10,9:18.7
1,-10,9:18.7
3,-10,9:18.7
5,-10,9:18.7
8,-10,9:18.7
-4,-9,9:18.7
-3,-9,9:18.7
-1,-9,9:18.7
0,-9,9:18.7
1,-9,9:18.7
10,-9,9:18.7
11,-9,9:18.7
-7,-8,9:18.7
-6,-8,9:18.7
-5,-8,9:162.12
-4,-8,9:18.7
-3,-8,9:18.7
5,-8,9:18.7
7,-8,9:18.7
9,-8,9:18.7
10,-8,9:18.7
-8,-7,9:18.7
-7,-7,9:18.7
-6,-7,9:18.7
-5,-7,9:18.15
-4,-7,9:162.12
4,-7,9:162.12
9,-7,9:18.7
-8,-6,9:18.7
-7,-6,9:18.7
-3,-6,9:162.12
-2,-6,9:143.1
4,-6,9:162.12
7,-6,9:162.12
9,-6,9:18.7
10,-6,9:18.7
11,-6,9:18.7
6,-5,9:162.12
8,-5,9:18.7
10,-5,9:18.7
11,-5,9:18.7
10,-4,9:18.7
11,-4,9:18.7
-10,-3,9:18.7
-7,-3,9:18.7
-2,-3,9:143.2
-1,-3,9:162.12
0,-3,9:101.0
7,-3,9:18.7
8,-3,9:18.7
9,-3,9:18.7
11,-3,9:18.7
-9,-2,9:18.7
-8,-2,9:18.7
-7,-2,9:18.7
6,-2,9:18.15
7,-2,9:162.12
-9,-1,9:18.7
-8,-1,9:18.7
5,-1,9:162.12
6,-1,9:162.12
10,-1,9:18.15
-9,0,9:18.7
-7,0,9:18.7
0,0,9:162.12
5,0,9:162.12
6,0,9:18.15
7,0,9:18.15
8,0,9:18.15
-8,1,9:18.7
-7,1,9:18.7
-6,1,9:18.7
6,1,9:18.15
8,1,9:18.15
-7,2,9:18.7
-6,2,9:18.7
5,2,9:162.12
6,2,9:162.12
8,2,9:18.15
9,2,9:18.15
10,2,9:18.15
-6,3,9:18.7
-1,3,9:18.7
1,3,9:18.7
7,3,9:162.12
8,3,9:18.15
9,3,9:18.15
10,3,9:18.15
9,4,9:18.15
10,4,9:18.15
11,4,9:18.7
-5,5,9:18.7
-4,5,9:18.7
-1,5,9:18.7
0,5,9:18.7
1,5,9:18.7
9,5,9:18.15
11,5,9:18.7
-6,6,9:18.7
-3,6,9:18.7
-2,6,9:18.7
-1,6,9:18.7
0,6,9:18.7
-5,7,9:18.7
-6,8,9:18.7
3,-12,10:18.7
-2,-11,10:18.7
-1,-11,10:18.7
1,-11,10:18.7
5,-11,10:18.7
-3,-10,10:18.7
-2,-10,10:18.7
3,-10,10:18.7
4,-10,10:18.7
6,-10,10:18.7
8,-10,10:18.7
-7,-9,10:18.7
-6,-9,10:18.7
-1,-9,10:18.7
0,-9,10:18.7
3,-9,10:18.7
4,-9,10:18.7
5,-9,10:18.7
6,-9,10:18.7
9,-9,10:18.7
10,-9,10:18.7
-7,-8,10:18.7
-6,-8,10:18.7
-4,-8,10:18.7
-3,-8,10:18.7
-1,-8,10:18.7
4,-8,10:18.7
6,-8,10:18.7
7,-8,10:18.7
8,-8,10:18.7
10,-8,10:18.7
11,-8,10:18.7
-8,-7,10:18.7
-6,-7,10:18.15
-4,-7,10:18.15
-1,-7,10:18.15
7,-7,10:18.7
8,-7,10:18.7
9,-7,10:18.7
10,-7,10:18.7
11,-7,10:18.7
-9,-6,10:18.7
-8,-6,10:18.7
-7,-6,10:18.15
6,-6,10:18.7
9,-6,10:18.7
-9,-5,10:18.7
-8,-5,10:18.7
-7,-5,10:18.15
9,-5,10:18.7
10,-5,10:18.7
11,-5,10:18.7
-9,-4,10:18.7
-7,-4,10:18.15
9,-4,10:18.7
10,-4,10:18.7
11,-4,10:18.7
-9,-3,10:18.7
-2,-3,10:162.12
-1,-3,10:162.12
0,-3,10:162.12
8,-3,10:18.7
9,-3,10:18.7
10,-3,10:18.7
-9,-2,10:18.7
-8,-2,10:18.7
-7,-2,10:18.15
6,-2,10:18.15
7,-2,10:18.15
8,-2,10:18.15
-8,-1,10:18.7
6,-1,10:18.15
-8,0,10:18.7
0,0,10:162.12
5,0,10:18.15
8,0,10:18.15
-8,1,10:18.7
-7,1,10:18.15
-6,1,10:18.15
5,1,10:18.15
6,1,10:18.15
7,1,10:18.15
9,1,10:18.15
10,1,10:18.15
-8,2,10:18.7
-7,2,10:18.7
-6,2,10:18.7
6,2,10:18.15
7,2,10:18.15
-7,3,10:18.7
-6,3,10:18.7
8,3,10:18.15
9,3,10:18.15
10,3,10:18.15
8,4,10:18.15
10,4,10:18.15
11,4,10:18.7
8,5,10:18.15
9,5,10:18.15
10,5,10:18.15
-1,-11,11:18.7
5,-11,11:18.7
-3,-10,11:18.7
-2,-10,11:18.7
1,-10,11:18.7
4,-10,11:18.7
7,-10,11:18.7
-6,-9,11:18.7
-4,-9,11:18.7
-3,-9,11:18.7
-2,-9,11:18.7
1,-9,11:18.7
5,-9,11:18.7
6,-9,11:18.7
7,-9,11:18.7
9,-9,11:18.7
-7,-8,11:18.7
-6,-8,11:18.7
-5,-8,11:18.7
-4,-8,11:18.7
7,-8,11:18.7
8,-8,11:18.7
9,-8,11:18.7
10,-8,11:18.7
-8,-7,11:18.7
-6,-7,11:18.15
-5,-7,11:18.15
-4,-7,11:18.15
7,-7,11:18.7
8,-7,11:18.7
9,-7,11:18.7
-7,-6,11:18.15
9,-6,11:18.7
10,-6,11:18.7
9,-5,11:18.7
10,-5,11:18.7
-8,-4,11:18.7
9,-4,11:18.7
10,-4,11:18.7
-9,-3,11:18.7
-8,-3,11:18.7
-7,-3,11:18.15
-2,-3,11:162.12
0,-3,11:162.12
7,-3,11:18.7
9,-3,11:18.7
10,-3,11:18.7
11,-3,11:18.7
-9,-2,11:18.7
-8,-2,11:18.7
-7,-2,11:18.15
-6,-2,11:18.15
-2,-2,11:101.0
8,-2,11:18.15
-8,-1,11:18.7
-7,-1,11:18.15
-6,-1,11:18.15
7,-1,11:18.15
8,-1,11:18.15
0,0,11:162.12
1,0,11:162.12
5,0,11:18.15
8,0,11:18.15
-8,1,11:18.7
-7,1,11:18.15
0,1,11:162.12
6,1,11:18.15
7,1,11:18.15
-8,2,11:18.7
8,2,11:18.15
-7,3,11:18.7
0,3,11:18.7
3,3,11:18.15
8,3,11:18.15
9,3,11:18.15
10,3,11:18.15
11,3,11:18.7
-3,4,11:18.7
0,4,11:18.7
2,4,11:18.15
4,4,11:18.15
8,4,11:18.15
10,4,11:18.15
-3,5,11:18.7
-2,5,11:18.7
-1,5,11:18.7
0,5,11:18.7
4,5,11:18.15
6,5,11:18.15
9,5,11:18.15
-4,6,11:18.7
-2,6,11:18.7
-1,6,11:18.7
0,6,11:18.7
4,6,11:18.15
0,-11,12:18.7
4,-11,12:18.7
0,-10,12:18.7
3,-10,12:18.7
5,-10,12:18.7
-5,-9,12:18.7
0,-9,12:18.7
4,-9,12:18.7
8,-9,12:18.7
-7,-8,12:18.7
-6,-8,12:18.7
-5,-8,12:18.7
-4,-8,12:18.7
-1,-8,12:18.7
8,-8,12:18.7
-7,-7,12:18.15
7,-7,12:18.7
8,-7,12:18.7
9,-7,12:18.7
-10,-6,12:18.7
-8,-6,12:18.7
-7,-6,12:18.15
-6,-6,12:18.15
9,-6,12:18.7
10,-6,12:18.7
-9,-5,12:18.7
-8,-5,12:18.7
-7,-5,12:18.15
9,-5,12:18.7
11,-5,12:18.7
-9,-4,12:18.7
-8,-4,12:18.7
0,-4,12:162.12
8,-4,12:18.7
10,-4,12:18.7
11,-4,12:18.7
-2,-3,12:162.12
10,-3,12:18.7
7,-2,12:18.15
8,-2,12:18.15
10,-2,12:18.15
6,-1,12:18.15
7,-1,12:18.15
8,-1,12:18.15
-8,0,12:18.7
-6,0,12:18.15
0,0,12:162.12
1,0,12:162.12
2,0,12:101.0
6,0,12:18.15
7,0,12:18.15
8,0,12:18.15
-7,1,12:18.15
-6,1,12:18.15
-1,1,12:162.12
0,1,12:162.12
8,1,12:18.15
9,1,12:18.15
-7,2,12:18.7
-2,2,12:18.7
1,2,12:162.12
5,2,12:18.15
7,2,12:18.15
8,2,12:18.15
9,2,12:18.15
10,2,12:18.15
0,3,12:18.7
1,3,12:162.12
2,3,12:18.15
4,3,12:18.15
5,3,12:18.15
8,3,12:18.15
10,3,12:18.15
-3,4,12:18.7
-2,4,12:18.7
0,4,12:18.7
1,4,12:18.7
2,4,12:18.15
4,4,12:18.15
8,4,12:18.15
9,4,12:18.15
10,4,12:18.15
-7,5,12:18.7
-4,5,12:18.7
-3,5,12:18.7
-2,5,12:18.7
-1,5,12:18.7
0,5,12:18.7
1,5,12:18.7
2,5,12:18.15
3,5,12:18.15
6,5,12:18.15
9,5,12:18.15
10,5,12:18.15
-4,6,12:18.7
-3,6,12:18.7
-1,6,12:18.7
0,6,12:18.7
3,6,12:18.15
4,6,12:18.15
1,7,12:18.7
3,7,12:18.7
-1,-12,13:18.7
-2,-11,13:18.7
-1,-11,13:18.7
-1,-10,13:18.7
1,-10,13:18.7
3,-10,13:18.7
6,-10,13:18.7
0,-9,13:18.7
-7,-8,13:18.7
5,-8,13:18.7
9,-8,13:18.7
-8,-7,13:18.7
-6,-7,13:18.15
9,-7,13:18.7
10,-7,13:18.7
-9,-6,13:18.7
-7,-6,13:18.15
8,-6,13:18.7
9,-6,13:18.7
-9,-5,13:18.7
5,-5,13:18.7
11,-5,13:18.7
-9,-4,13:18.7
-2,-4,13:162.12
0,-4,13:162.12
1,-4,13:162.12
7,-4,13:18.7
9,-4,13:18.7
10,-4,13:18.7
11,-4,13:18.7
-3,-3,13:162.12
0,-3,13:143.3
7,-2,13:18.7
7,-1,13:18.7
10,-1,13:18.7
1,0,13:162.12
-1,1,13:162.12
7,1,13:18.7
8,1,13:18.7
-4,2,13:18.7
0,2,13:18.7
7,2,13:18.7
8,2,13:18.7
-6,3,13:18.7
-5,3,13:18.7
2,3,13:18.7
3,3,13:18.7
6,3,13:18.7
8,3,13:18.7
10,3,13:18.7
-5,4,13:18.7
-2,4,13:18.7
-1,4,13:18.7
1,4,13:162.12
2,4,13:18.7
9,4,13:18.7
10,4,13:18.7
2,5,13:18.7
3,5,13:18.7
4,5,13:18.7
5,5,13:18.7
8,5,13:18.7
9,5,13:18.7
-2,6,13:18.7
0,6,13:18.7
1,6,13:18.7
3,6,13:18.7
4,6,13:18.7
5,6,13:18.7
7,6,13:18.7
8,6,13:18.7
9,6,13:18.7
10,6,13:18.7
2,7,13:18.7
-2,-12,14:18.7
0,-12,14:18.7
-2,-10,14:18.7
1,-10,14:18.7
7,-10,14:18.7
-1,-9,14:18.7
0,-9,14:18.7
1,-9,14:18.7
6,-7,14:18.7
-3,-5,14:162.12
-1,-5,14:18.15
11,-5,14:18.7
1,-4,14:162.12
10,-4,14:18.7
-6,-3,14:18.15
-3,-3,14:162.12
8,-3,14:18.7
-7,-2,14:18.15
-6,-2,14:18.15
-4,-2,14:162.12
8,-2,14:18.7
-6,-1,14:18.15
-5,-1,14:18.15
-1,0,14:143.4
1,0,14:162.12
2,0,14:162.12
-1,1,14:162.12
-5,2,14:18.7
-3,2,14:18.7
4,2,14:18.7
8,2,14:18.7
1,3,14:18.7
8,3,14:18.7
9,3,14:18.7
10,3,14:18.7
-5,4,14:18.7
-1,4,14:18.7
0,4,14:18.7
1,4,14:18.7
4,4,14:18.7
8,4,14:18.7
-5,5,14:18.7
-3,5,14:18.7
-1,5,14:18.7
0,5,14:18.7
1,5,14:18.7
3,5,14:18.7
8,5,14:18.7
9,5,14:18.7
10,5,14:18.7
-3,6,14:18.7
-1,6,14:18.7
3,6,14:18.7
6,6,14:18.7
8,6,14:18.7
9,6,14:18.7
10,6,14:18.7
3,7,14:18.7
8,7,14:18.7
9,7,14:18.7
10,7,14:18.7
-1,-12,15:18.7
-2,-11,15:18.7
0,-11,15:18.7
1,-11,15:18.7
0,-10,15:18.7
2,-10,15:18.7
2,-9,15:18.7
3,-9,15:18.7
4,-9,15:18.7
-5,-8,15:18.7
0,-8,15:18.7
4,-8,15:18.7
5,-8,15:18.7
6,-8,15:18.7
-6,-7,15:18.15
-5,-7,15:18.15
-4,-7,15:18.15
5,-7,15:18.7
-7,-6,15:18.15
-5,-6,15:18.15
-3,-6,15:162.12
-2,-6,15:143.1
5,-6,15:18.7
6,-6,15:18.7
-7,-5,15:18.15
-6,-5,15:18.15
-5,-5,15:18.15
-3,-5,15:162.12
6,-5,15:18.7
7,-5,15:18.7
8,-5,15:18.7
-8,-4,15:18.7
-7,-4,15:18.15
1,-4,15:162.12
7,-4,15:18.7
-8,-3,15:18.7
-7,-3,15:18.15
-6,-3,15:18.15
-5,-3,15:18.15
1,-3,15:101.0
7,-3,15:18.7
8,-3,15:18.7
9,-3,15:18.7
-7,-2,15:18.15
-6,-2,15:18.15
-5,-2,15:162.12
-4,-2,15:18.15
7,-2,15:18.7
8,-2,15:18.7
-7,-1,15:18.15
-6,-1,15:18.15
-4,-1,15:18.15
8,-1,15:18.7
9,-1,15:18.7
10,-1,15:18.7
2,0,15:162.12
5,0,15:18.7
-4,1,15:18.15
-2,1,15:162.12
-1,1,15:162.12
0,1,15:18.15
-4,2,15:18.7
5,2,15:18.7
-4,3,15:18.7
-3,3,15:18.7
9,3,15:18.7
10,3,15:18.7
-6,4,15:18.7
-5,4,15:18.7
-4,4,15:18.7
-3,4,15:18.7
-2,4,15:18.7
-1,4,15:18.7
-4,5,15:18.7
-3,5,15:18.7
-1,5,15:18.7
8,5,15:18.7
9,5,15:18.7
3,6,15:18.7
9,7,15:18.7
1,-11,16:18.7
2,-11,16:18.7
3,-11,16:18.7
0,-10,16:18.7
2,-10,16:18.7
-5,-9,16:18.7
1,-9,16:18.7
4,-9,16:18.7
6,-9,16:18.7
-5,-8,16:18.7
-2,-8,16:18.7
3,-8,16:18.7
5,-8,16:18.7
-7,-7,16:18.15
-5,-7,16:18.15
-4,-7,16:162.12
-3,-7,16:18.15
-1,-7,16:18.15
4,-7,16:18.7
6,-7,16:18.7
7,-7,16:18.7
-7,-6,16:18.15
0,-6,16:18.15
8,-6,16:18.7
-7,-5,16:18.15
-6,-5,16:18.15
2,-5,16:162.12
5,-5,16:18.7
7,-5,16:18.7
8,-5,16:18.7
-7,-4,16:18.15
-6,-4,16:18.15
6,-4,16:18.7
7,-4,16:18.7
9,-4,16:18.7
-6,-3,16:18.15
7,-3,16:18.7
-7,-2,16:18.15
8,-2,16:18.7
9,-2,16:18.7
10,-2,16:18.7
-6,-1,16:18.15
-5,-1,16:18.15
8,-1,16:18.7
10,-1,16:18.7
2,0,16:18.7
3,0,16:162.12
4,0,16:18.7
6,0,16:18.7
7,0,16:18.7
8,0,16:18.7
10,0,16:18.7
-2,1,16:162.12
4,1,16:18.7
5,1,16:18.7
7,1,16:18.7
2,2,16:18.7
3,2,16:18.7
4,2,16:18.7
5,2,16:18.7
6,2,16:18.7
-5,3,16:18.7
2,3,16:18.7
-5,4,16:18.7
-4,4,16:18.7
3,4,16:18.7
8,5,16:18.7
2,-11,17:18.7
-3,-10,17:18.7
2,-10,17:18.7
3,-10,17:18.7
-4,-9,17:18.7
-3,-9,17:18.7
-2,-9,17:18.7
2,-9,17:18.7
3,-9,17:18.7
4,-9,17:18.7
5,-9,17:18.7
-6,-8,17:18.7
-5,-8,17:162.12
-3,-8,17:18.7
6,-8,17:18.7
-6,-7,17:18.15
4,-7,17:18.7
8,-7,17:18.7
-4,-6,17:18.15
5,-6,17:18.7
7,-6,17:18.7
-4,-5,17:18.15
2,-5,17:162.12
6,-5,17:18.7
8,-5,17:18.7
-8,-4,17:18.7
-6,-4,17:18.15
-4,-4,17:18.15
2,-4,17:143.3
6,-4,17:18.7
7,-4,17:18.7
9,-4,17:18.7
-7,-3,17:18.15
-6,-3,17:18.15
6,-3,17:18.7
8,-3,17:18.7
9,-3,17:18.7
-7,-2,17:18.15
-6,-2,17:18.15
-5,-2,17:18.15
7,-2,17:18.7
9,-2,17:18.7
-6,-1,17:18.15
2,-1,17:18.7
3,-1,17:18.7
7,-1,17:18.7
8,-1,17:18.7
9,-1,17:18.7
0,0,17:18.15
3,0,17:162.12
7,0,17:18.7
8,0,17:18.7
9,0,17:18.7
-2,1,17:162.12
3,1,17:18.7
6,1,17:18.7
7,1,17:18.7
8,1,17:18.7
-7,2,17:18.7
-6,2,17:18.7
-5,2,17:18.7
-3,2,17:162.12
-2,2,17:18.7
2,2,17:18.7
3,2,17:18.7
4,2,17:18.7
6,2,17:18.7
7,2,17:18.7
-6,3,17:18.7
-5,3,17:18.7
-4,3,17:18.7
5,3,17:18.7
-6,4,17:18.7
-5,4,17:18.7
0,4,17:18.7
2,4,17:18.7
4,4,17:18.7
8,4,17:18.7
-5,5,17:18.7
-4,5,17:18.7
-3,5,17:18.7
0,5,17:18.7
3,5,17:18.7
-4,6,17:18.7
-3,6,17:18.7
-2,6,17:18.7
2,6,17:18.7
-3,7,17:18.7
-4,-10,18:18.7
-3,-10,18:18.7
-2,-10,18:18.7
-4,-9,18:18.7
-3,-9,18:18.7
-2,-9,18:18.7
-6,-8,18:18.7
-4,-8,18:18.7
-3,-8,18:18.7
-1,-8,18:18.7
-6,-7,18:18.15
-3,-7,18:18.15
-2,-7,18:18.15
0,-7,18:18.15
7,-7,18:18.7
-4,-6,18:18.15
-3,-6,18:18.15
1,-6,18:162.12
7,-6,18:18.7
8,-6,18:18.7
-5,-5,18:18.15
-3,-5,18:18.15
2,-5,18:162.12
3,-5,18:162.12
6,-5,18:18.7
-7,-4,18:18.15
-5,-4,18:18.15
-4,-4,18:18.15
-3,-4,18:18.15
4,-4,18:162.12
5,-4,18:18.7
6,-4,18:18.7
7,-4,18:18.7
8,-4,18:18.7
-7,-3,18:18.15
-6,-3,18:18.15
-1,-3,18:18.15
7,-3,18:18.7
-7,-2,18:18.15
-5,-2,18:18.15
-3,-2,18:18.15
-2,-2,18:18.15
0,-2,18:18.15
5,-2,18:18.7
6,-2,18:18.7
7,-2,18:18.7
8,-2,18:18.7
-7,-1,18:18.15
-6,-1,18:18.15
-2,-1,18:162.12
0,-1,18:18.15
3,-1,18:18.7
4,-1,18:18.7
5,-1,18:18.7
6,-1,18:18.7
7,-1,18:18.7
-2,0,18:162.12
3,0,18:18.7
4,0,18:18.7
8,0,18:18.7
-7,1,18:18.15
4,1,18:18.7
5,1,18:18.7
7,1,18:18.7
-7,2,18:18.7
2,2,18:18.7
3,2,18:18.7
6,2,18:18.7
-6,3,18:18.7
-5,3,18:18.7
-4,3,18:162.12
2,3,18:18.7
3,3,18:18.7
7,3,18:18.7
-5,4,18:162.12
-3,4,18:18.7
-1,4,18:18.7
0,4,18:18.7
1,4,18:18.7
2,4,18:18.7
4,4,18:18.7
-6,5,18:18.7
-5,5,18:18.7
-3,5,18:18.7
-2,5,18:18.7
-1,5,18:18.7
1,5,18:18.7
2,5,18:18.7
3,5,18:18.7
4,5,18:18.7
-4,6,18:18.7
-1,6,18:18.7
1,6,18:18.7
3,6,18:18.7
-3,7,18:18.7
-2,7,18:18.7
-4,-10,19:18.7
0,-10,19:18.7
-5,-9,19:18.7
-4,-9,19:18.7
-2,-9,19:18.7
0,-9,19:18.7
1,-9,19:18.7
2,-9,19:18.7
-5,-8,19:18.7
-4,-8,19:18.7
-3,-8,19:18.7
-2,-8,19:18.7
-1,-8,19:18.7
2,-8,19:18.7
3,-8,19:18.7
-5,-7,19:18.7
-1,-7,19:18.7
1,-7,19:162.12
4,-7,19:18.7
-6,-6,19:18.7
-4,-6,19:18.7
-1,-6,19:18.7
0,-6,19:18.7
4,-6,19:18.7
5,-6,19:18.7
-6,-5,19:18.7
-3,-5,19:18.7
-2,-5,19:18.7
-1,-5,19:18.7
4,-5,19:18.7
5,-5,19:18.7
6,-5,19:18.7
7,-5,19:18.7
-6,-4,19:18.7
-3,-4,19:18.7
-2,-4,19:18.7
5,-4,19:162.12
6,-4,19:162.12
7,-4,19:18.7
-1,-3,19:18.7
7,-3,19:18.7
-7,-2,19:18.7
-6,-2,19:18.7
-5,-2,19:18.7
-3,-2,19:18.7
-2,-2,19:162.12
-1,-2,19:18.7
5,-2,19:18.7
-6,-1,19:18.7
-4,-1,19:18.7
-3,-1,19:18.7
-2,-1,19:18.7
4,-1,19:18.7
5,-1,19:18.7
6,-1,19:18.7
7,-1,19:18.7
2,0,19:18.7
3,0,19:18.7
4,0,19:18.7
3,1,19:18.7
4,1,19:18.7
5,1,19:18.7
6,1,19:18.7
-7,2,19:18.7
-6,2,19:18.7
3,2,19:18.7
4,2,19:18.7
-6,3,19:18.7
4,3,19:18.7
-5,4,19:18.7
-4,4,19:18.7
1,4,19:18.7
2,4,19:18.7
-4,5,19:18.7
-3,5,19:18.7
-1,5,19:18.7
1,5,19:18.7
-3,6,19:18.7
-2,6,19:18.7
1,6,19:18.7
2,6,19:18.7
-3,7,19:18.7
-5,-10,20:18.7
-3,-10,20:18.7
-1,-10,20:18.7
1,-10,20:18.7
-5,-9,20:18.7
-4,-9,20:18.7
-2,-9,20:18.7
-1,-9,20:18.7
1,-9,20:18.7
2,-9,20:18.7
-3,-8,20:18.7
-1,-8,20:18.7
0,-8,20:162.12
1,-8,20:18.7
2,-8,20:18.7
-4,-7,20:18.7
-3,-7,20:18.7
-2,-7,20:18.7
-1,-7,20:18.7
0,-7,20:18.7
1,-7,20:18.7
3,-7,20:18.7
4,-7,20:18.7
-5,-6,20:18.7
-4,-6,20:18.7
-3,-6,20:18.7
-2,-6,20:18.7
2,-6,20:18.7
3,-6,20:18.7
5,-6,20:18.7
-6,-5,20:18.7
-5,-5,20:18.7
-4,-5,20:18.7
-3,-5,20:18.7
-2,-5,20:18.7
0,-5,20:18.7
7,-5,20:18.7
-5,-4,20:18.7
-1,-4,20:18.7
1,-4,20:18.7
4,-4,20:18.7
5,-4,20:18.7
7,-4,20:18.7
-5,-3,20:18.7
-4,-3,20:18.7
5,-3,20:18.7
7,-3,20:18.7
-5,-2,20:18.7
-4,-2,20:18.7
-3,-2,20:18.7
-2,-2,20:18.7
-1,-2,20:18.7
-5,-1,20:18.7
-4,-1,20:18.7
-3,-1,20:18.7
-2,-1,20:18.7
5,-1,20:18.7
6,-1,20:18.7
0,0,20:18.7
1,0,20:18.7
5,0,20:18.7
-1,1,20:18.7
0,1,20:18.7
1,1,20:18.7
4,1,20:18.7
5,1,20:18.7
-3,2,20:18.7
-2,2,20:18.7
0,2,20:18.7
4,2,20:18.7
-2,3,20:18.7
-1,3,20:18.7
-4,4,20:18.7
-4,-10,21:18.7
0,-10,21:18.7
-5,-9,21:18.7
1,-9,21:18.7
2,-9,21:18.7
-4,-8,21:18.7
-2,-8,21:18.7
-1,-8,21:18.7
2,-8,21:18.7
3,-8,21:18.7
-5,-7,21:18.7
-1,-7,21:18.7
-4,-6,21:18.7
-2,-6,21:18.7
3,-6,21:18.7
-3,-5,21:18.7
-2,-5,21:18.7
0,-5,21:18.7
1,-5,21:18.7
4,-5,21:18.7
5,-5,21:18.7
-4,-4,21:18.7
-3,-4,21:18.7
-2,-4,21:18.7
0,-4,21:18.7
1,-4,21:18.7
2,-4,21:18.7
5,-4,21:18.7
6,-4,21:18.7
7,-4,21:18.7
-4,-3,21:18.7
-3,-3,21:18.7
1,-3,21:18.7
-4,-2,21:18.7
-4,-1,21:18.7
-3,-1,21:18.7
-1,0,21:18.7
0,0,21:18.7
2,0,21:18.7
-3,1,21:18.7
1,1,21:18.7
2,1,21:18.7
-3,2,21:18.7
-2,2,21:18.7
0,2,21:18.7
1,2,21:18.7
2,2,21:18.7
-3,3,21:18.7
-1,3,21:18.7
2,3,21:18.7
-1,4,21:18.7
2,4,21:18.7
4,4,21:18.7
-3,5,21:18.7
-1,-6,22:18.7
3,-6,22:18.7
-1,-5,22:18.7
1,-5,22:18.7
2,-5,22:18.7
-1,-4,22:18.7
1,-4,22:18.7
3,-4,22:18.7
2,-3,22:18.7
-2,-2,22:18.7
2,-2,22:18.7
3,-2,22:18.7
0,0,22:18.7
1,1,22:18.7
2,1,22:18.7
-3,2,22:18.7
-2,2,22:18.7
-1,2,22:18.7
1,2,22:18.7
-2,3,22:18.7
3,3,22:18.7
0,-6,23:18.7
-1,-5,23:18.7
0,-5,23:18.7
1,-5,23:18.7
0,-3,23:18.7
1,-3,23:18.7
2,-3,23:18.7
0,-2,23:18.7
1,-2,23:18.7
2,-2,23:18.7
5,-2,23:18.7
1,-4,24:18.7
0,-3,24:18.7
2,-3,24:18.7
