[META]
version=2.0
spawnOnBlockType=2
spawnSunlight=True
spawnDarkness=True
spawnWater=False
spawnLava=False
underFill=False
randomRotation=True
dig=True
tree=False
branch=False
needsFoundation=True
rarity=100
collisionPercentage=20
spawnElevationMin=0
spawnElevationMax=200
spawnInBiome=Custom
[DATA]
0,-2,0:17.12
0,-1,0:17.12
-1,0,0:17.12
0,0,0:17.12
1,0,0:17.12
0,1,0:17.12
0,-1,1:17.12
-1,0,1:17.12
0,0,1:17.12
0,1,1:17.12
0,-1,2:17.12
0,0,2:17.12
0,-1,3:17.12
0,0,3:17.12
1,-2,4:18.2
-2,-1,4:18.2
0,-1,4:17.12
-3,0,4:18.0
-2,0,4:18.2
-1,0,4:18.0
0,0,4:17.12
-2,1,4:18.2
-1,-3,5:18.2
0,-3,5:18.2
1,-3,5:18.0
2,-3,5:18.0
3,-3,5:18.0
-2,-2,5:18.2
-1,-2,5:18.2
0,-2,5:17.12
1,-2,5:18.2
2,-2,5:18.2
-3,-1,5:18.0
-2,-1,5:18.2
-1,-1,5:18.2
0,-1,5:17.12
1,-1,5:18.0
2,-1,5:18.2
3,-1,5:18.0
-2,0,5:18.0
-1,0,5:17.12
0,0,5:17.12
1,0,5:17.12
3,0,5:18.0
4,0,5:18.2
-3,1,5:18.2
-2,1,5:18.0
-1,1,5:18.0
0,1,5:18.0
2,1,5:18.0
3,1,5:18.2
0,2,5:18.0
-3,-4,6:18.0
-2,-4,6:18.2
-1,-4,6:18.0
2,-4,6:18.0
0,-3,6:18.2
1,-3,6:18.2
2,-3,6:18.0
3,-3,6:18.2
4,-3,6:18.0
-4,-2,6:18.2
-3,-2,6:18.2
-2,-2,6:18.2
-1,-2,6:17.12
0,-2,6:18.2
1,-2,6:18.2
2,-2,6:17.12
3,-2,6:18.2
-5,-1,6:18.2
-4,-1,6:18.0
-3,-1,6:18.0
-2,-1,6:17.12
-1,-1,6:18.2
0,-1,6:18.0
1,-1,6:17.12
2,-1,6:18.2
3,-1,6:18.2
-1,0,6:18.2
0,0,6:17.12
1,0,6:18.0
2,0,6:18.2
3,0,6:17.12
5,0,6:18.0
-4,1,6:18.8
-2,1,6:18.0
-1,1,6:18.0
0,1,6:17.12
1,1,6:17.12
2,1,6:17.12
3,1,6:17.12
4,1,6:18.2
-2,2,6:18.0
-1,2,6:18.2
0,2,6:18.0
1,2,6:18.0
2,2,6:18.2
3,2,6:18.2
-2,3,6:18.2
-1,3,6:18.2
0,3,6:18.0
1,3,6:18.0
2,3,6:18.2
3,3,6:18.0
2,4,6:18.2
-3,-5,7:18.2
-1,-5,7:18.2
3,-5,7:18.2
-4,-4,7:18.6
-3,-4,7:18.0
-2,-4,7:17.12
0,-4,7:18.2
2,-4,7:18.2
3,-4,7:18.0
-4,-3,7:18.6
-3,-3,7:18.0
-2,-3,7:18.0
-1,-3,7:17.12
0,-3,7:18.0
1,-3,7:18.0
3,-3,7:17.12
4,-3,7:18.0
-5,-2,7:18.2
-3,-2,7:18.0
-2,-2,7:18.2
-1,-2,7:18.0
1,-2,7:18.0
2,-2,7:17.12
3,-2,7:18.0
4,-2,7:18.0
-5,-1,7:18.2
-4,-1,7:17.12
-3,-1,7:17.12
-2,-1,7:18.2
-1,-1,7:18.0
0,-1,7:18.0
1,-1,7:18.2
2,-1,7:18.2
3,-1,7:18.2
5,-1,7:18.0
-5,0,7:18.0
-4,0,7:17.12
-3,0,7:18.2
-2,0,7:18.0
-1,0,7:18.0
0,0,7:17.12
2,0,7:18.2
3,0,7:18.0
4,0,7:17.12
5,0,7:18.0
-5,1,7:18.2
-3,1,7:18.2
-2,1,7:18.2
-1,1,7:18.0
0,1,7:18.0
2,1,7:18.2
4,1,7:18.2
-3,2,7:18.2
-2,2,7:17.12
-1,2,7:17.12
0,2,7:17.12
1,2,7:18.2
2,2,7:17.12
3,2,7:18.0
-3,3,7:18.2
-2,3,7:18.0
0,3,7:18.2
2,3,7:17.12
3,3,7:18.0
-2,4,7:18.2
1,4,7:18.2
2,4,7:18.2
3,4,7:18.0
-2,-5,8:18.2
3,-5,8:18.0
4,-5,8:18.2
-3,-4,8:18.2
-2,-4,8:18.2
-1,-4,8:18.2
2,-4,8:18.0
3,-4,8:17.12
-2,-3,8:18.2
-1,-3,8:18.2
0,-3,8:18.0
1,-3,8:18.0
-3,-2,8:18.2
-2,-2,8:18.2
-1,-2,8:18.0
1,-2,8:18.0
2,-2,8:18.2
3,-2,8:18.0
4,-2,8:18.0
-5,-1,8:18.2
-3,-1,8:18.0
-2,-1,8:18.2
-1,-1,8:17.12
0,-1,8:18.2
1,-1,8:18.2
2,-1,8:17.12
3,-1,8:17.12
4,-1,8:18.2
-4,0,8:18.0
-3,0,8:18.0
-2,0,8:18.2
-1,0,8:17.12
0,0,8:17.12
1,0,8:17.12
2,0,8:17.12
3,0,8:18.0
4,0,8:18.2
5,0,8:18.0
-4,1,8:18.0
-2,1,8:18.2
-1,1,8:18.2
1,1,8:18.2
3,1,8:18.0
4,1,8:18.0
-3,2,8:18.0
-1,2,8:18.0
0,2,8:18.2
1,2,8:18.0
2,2,8:18.0
4,2,8:18.2
-4,3,8:18.6
-3,3,8:18.0
-2,3,8:17.12
-1,3,8:18.2
0,3,8:18.2
1,3,8:18.0
2,3,8:18.0
3,3,8:17.12
4,3,8:18.0
5,3,8:18.14
-3,4,8:18.2
-1,4,8:18.0
0,4,8:18.14
2,4,8:18.2
3,4,8:18.2
4,4,8:18.0
3,-5,9:18.2
2,-4,9:18.2
3,-4,9:18.0
4,-4,9:18.2
3,-3,9:18.0
-1,-2,9:18.2
3,-2,9:18.2
-1,-1,9:18.0
1,-1,9:18.2
2,-1,9:18.0
3,-1,9:18.2
4,-1,9:18.0
-2,0,9:18.2
0,0,9:18.2
1,0,9:18.2
3,0,9:18.2
1,1,9:18.0
2,1,9:18.2
-2,2,9:18.2
0,2,9:18.0
-3,3,9:18.2
-2,3,9:18.0
-1,3,9:18.2
2,3,9:18.0
3,3,9:18.2
4,3,9:18.0
3,4,9:18.0
4,4,9:18.6
1,0,10:18.0
0,1,10:18.0
1,1,10:18.2
2,1,10:18.0
1,2,10:18.2
