[META]
version=2.0
spawnOnBlockType=2
spawnSunlight=True
spawnDarkness=True
spawnWater=False
spawnLava=False
underFill=False
randomRotation=True
dig=True
tree=False
branch=False
needsFoundation=True
rarity=100
collisionPercentage=20
spawnElevationMin=0
spawnElevationMax=200
spawnInBiome=Custom
[DATA]
-2,-1,0:17.13
-1,-1,0:191.0
0,-1,0:191.0
-1,0,0:191.0
-3,1,0:191.0
-2,1,0:17.13
0,1,0:17.13
1,1,0:191.0
-2,2,0:191.0
-2,0,1:17.13
-1,0,1:17.13
-1,0,2:17.13
-3,-2,3:18.6
-2,-2,3:18.6
-4,-1,3:18.6
-3,-1,3:18.6
-4,0,3:18.6
-1,0,3:17.13
0,0,3:191.0
-4,-3,4:18.4
-1,-3,4:18.4
0,-2,4:18.6
-5,-1,4:18.6
-3,-1,4:18.4
-1,-1,4:191.0
-1,0,4:17.13
-5,1,4:18.4
-2,1,4:18.6
-1,1,4:17.13
-5,2,4:18.4
1,3,4:18.6
-2,4,4:18.6
0,4,4:18.6
-2,5,4:18.6
-3,-4,5:18.4
-4,-3,5:18.6
-2,-3,5:18.6
-1,-3,5:18.4
-4,-2,5:18.4
1,-2,5:18.4
-1,0,5:17.13
2,0,5:18.6
-5,2,5:18.6
-1,2,5:17.13
0,2,5:191.0
-3,3,5:18.4
-2,3,5:17.13
-1,3,5:191.0
-3,4,5:18.6
-2,4,5:17.13
-1,4,5:18.4
0,4,5:18.6
-3,5,5:18.4
-2,5,5:18.4
0,-5,6:18.6
1,-4,6:18.6
-4,-3,6:18.4
-1,-3,6:18.6
0,-2,6:17.13
1,-2,6:191.0
-1,-1,6:17.13
0,-1,6:18.6
-6,0,6:18.4
-2,0,6:17.13
-1,0,6:17.13
2,1,6:18.4
3,1,6:18.6
-3,3,6:18.4
1,3,6:18.4
-3,4,6:18.4
-1,4,6:18.6
0,4,6:18.4
-4,-6,7:18.6
-4,-5,7:18.6
-4,-4,7:18.4
-2,-4,7:18.4
-1,-4,7:18.6
0,-4,7:17.13
1,-4,7:18.4
-2,-3,7:17.13
0,-3,7:17.13
-2,-2,7:17.13
-1,-2,7:191.0
2,-2,7:18.6
-6,-1,7:18.6
-3,-1,7:191.0
-1,-1,7:18.6
2,-1,7:18.4
-3,0,7:17.13
-1,0,7:17.13
-5,1,7:18.6
-3,1,7:17.13
-1,1,7:17.13
0,1,7:17.13
1,1,7:17.13
2,1,7:18.4
-4,2,7:18.6
-2,2,7:18.6
0,2,7:191.0
1,2,7:18.6
-4,3,7:18.4
-3,3,7:18.6
-1,3,7:18.4
-4,4,7:18.6
-3,4,7:18.4
-2,4,7:18.4
-5,-6,8:18.4
-5,-5,8:18.6
-4,-5,8:17.13
-3,-5,8:18.6
0,-5,8:18.6
-4,-4,8:18.4
-3,-4,8:17.13
-1,-4,8:18.6
0,-4,8:18.4
1,-4,8:18.6
-4,-3,8:18.4
-5,-2,8:18.4
-3,-2,8:18.6
-3,0,8:17.13
-1,0,8:17.13
3,0,8:18.4
4,0,8:18.4
-4,1,8:18.4
-2,1,8:18.6
-1,1,8:17.13
2,1,8:17.13
3,1,8:191.0
4,1,8:18.6
-5,2,8:18.4
-3,2,8:17.13
-2,2,8:18.4
1,2,8:18.6
2,2,8:17.13
3,2,8:17.13
-5,3,8:18.4
-4,3,8:18.4
-2,3,8:18.4
0,3,8:18.4
4,3,8:18.6
5,3,8:18.4
-2,4,8:18.4
2,4,8:18.6
3,4,8:18.6
4,4,8:18.6
3,5,8:18.4
1,-6,9:18.4
-1,-5,9:18.6
0,-5,9:18.4
2,-5,9:18.6
-5,-4,9:18.6
-4,-4,9:18.4
2,-4,9:18.6
-2,-3,9:18.6
1,-3,9:18.6
2,-3,9:18.6
-5,-1,9:18.6
2,-1,9:18.6
3,-1,9:18.6
-4,0,9:17.13
-1,0,9:17.13
0,0,9:17.13
1,0,9:18.4
2,0,9:17.13
3,0,9:18.6
-4,1,9:191.0
-3,1,9:18.6
1,1,9:18.4
2,1,9:18.6
3,1,9:18.4
-4,2,9:18.4
-3,2,9:18.4
-1,2,9:17.13
3,2,9:18.4
4,2,9:18.6
-1,3,9:191.0
2,3,9:18.4
3,3,9:18.6
4,3,9:17.13
-3,4,9:18.4
-2,4,9:18.6
-1,4,9:18.6
5,4,9:18.6
-3,5,9:18.6
2,5,9:18.4
3,5,9:18.6
-4,-6,10:18.6
-1,-6,10:18.4
0,-6,10:18.6
-4,-5,10:18.6
0,-5,10:18.6
2,-5,10:18.4
-2,-4,10:18.6
1,-4,10:18.4
-5,-3,10:18.4
-2,-3,10:18.4
0,-3,10:18.4
3,-3,10:18.4
-4,-2,10:18.6
-1,-2,10:18.4
-6,-1,10:18.4
-5,-1,10:18.6
-4,-1,10:18.6
0,-1,10:17.13
2,-1,10:18.6
-5,0,10:17.13
0,0,10:17.13
2,0,10:18.4
-5,1,10:18.6
-4,1,10:18.6
-1,2,10:17.13
1,2,10:18.6
2,2,10:18.6
4,2,10:18.6
-4,3,10:18.6
0,3,10:18.4
1,3,10:18.4
3,3,10:18.4
4,3,10:18.4
5,3,10:18.6
1,4,10:18.6
4,4,10:18.4
-2,5,10:18.4
-1,-6,11:18.4
1,-6,11:18.4
-3,-5,11:18.4
-1,-5,11:18.6
0,-5,11:18.4
2,-5,11:18.6
-4,-4,11:18.4
-3,-4,11:18.4
1,-3,11:18.4
-5,-2,11:18.6
-4,-2,11:18.6
0,-2,11:17.13
-5,-1,11:18.4
-1,-1,11:18.6
1,-1,11:18.6
-6,0,11:18.6
-5,0,11:18.4
-1,0,11:17.13
0,0,11:17.13
2,0,11:18.4
-4,1,11:18.4
3,1,11:18.4
-4,2,11:18.4
2,2,11:18.4
-2,3,11:17.13
0,3,11:17.13
-1,4,11:18.4
0,4,11:18.4
1,4,11:18.6
-2,-6,12:18.4
0,-6,12:18.6
-2,-3,12:18.4
0,-3,12:18.6
1,-3,12:18.4
0,-2,12:18.6
1,-2,12:18.6
-3,-1,12:191.0
-2,-1,12:17.13
-1,-1,12:191.0
1,-1,12:17.13
2,-1,12:18.4
-3,0,12:18.4
1,0,12:191.0
2,0,12:18.4
-3,1,12:18.6
2,1,12:18.4
0,2,12:18.4
3,2,12:18.4
-2,3,12:17.13
0,3,12:17.13
1,3,12:18.4
-1,-6,13:18.6
1,-6,13:18.6
-2,-5,13:18.6
-1,-5,13:18.4
0,-5,13:18.6
2,-5,13:18.4
-2,-4,13:18.4
-1,-4,13:18.4
1,-4,13:18.6
-1,-3,13:17.13
0,-3,13:18.4
2,-3,13:18.6
-3,-2,13:18.6
-2,-2,13:17.13
2,-2,13:18.4
-2,-1,13:17.13
1,-1,13:17.13
2,0,13:18.4
2,1,13:18.6
0,2,13:18.4
2,2,13:18.4
-1,3,13:18.4
0,3,13:18.4
-2,4,13:17.13
-1,4,13:18.4
0,4,13:18.6
1,4,13:17.13
2,4,13:18.6
-2,5,13:18.4
-1,-6,14:18.6
0,-6,14:18.4
-3,-5,14:18.6
-2,-5,14:18.6
-1,-5,14:17.13
0,-5,14:18.6
-5,-4,14:18.4
-2,-4,14:18.6
-1,-4,14:17.13
0,-4,14:18.4
-5,-3,14:18.4
-4,-3,14:18.6
-2,-3,14:18.4
-1,-3,14:191.0
-5,-2,14:18.6
-4,-2,14:18.6
-3,-2,14:17.13
3,-2,14:18.6
-6,-1,14:18.4
-4,-1,14:18.4
1,-1,14:17.13
1,0,14:191.0
2,0,14:18.4
3,0,14:18.6
-5,1,14:18.6
1,1,14:18.4
2,1,14:18.6
-2,2,14:18.4
-1,2,14:18.4
-4,3,14:18.6
-3,3,14:18.4
-2,3,14:18.4
0,3,14:18.4
1,3,14:18.4
2,3,14:18.4
-3,4,14:18.4
-2,4,14:17.13
0,4,14:18.4
1,4,14:17.13
-1,5,14:18.6
0,5,14:18.4
-1,-6,15:18.4
1,-6,15:18.4
-1,-5,15:18.4
0,-5,15:18.4
2,-4,15:18.6
-4,-3,15:18.4
-3,-3,15:18.4
0,-3,15:18.4
-5,-2,15:18.4
-4,-2,15:17.13
-2,-2,15:18.4
2,-2,15:18.6
-4,-1,15:18.4
-2,-1,15:18.6
0,-1,15:18.4
1,-1,15:18.4
2,-1,15:17.13
3,-1,15:18.6
2,0,15:18.6
0,1,15:18.6
1,1,15:18.4
0,2,15:18.6
1,2,15:18.4
-2,3,15:18.6
-1,3,15:18.4
0,3,15:18.6
-3,4,15:18.6
-2,4,15:18.6
2,4,15:18.6
-2,5,15:18.6
1,5,15:18.4
1,-3,16:18.6
-4,-2,16:18.6
-2,-2,16:18.6
1,-2,16:18.6
2,-2,16:18.6
-1,-1,16:18.4
0,-1,16:18.6
1,-1,16:18.6
2,-1,16:17.13
-2,0,16:18.4
1,0,16:18.4
2,0,16:18.6
3,0,16:18.6
-4,1,16:18.4
1,2,16:18.6
3,-1,17:18.4
2,0,17:18.6
