[META]
version=2.0
spawnOnBlockType=2
spawnSunlight=True
spawnDarkness=True
spawnWater=False
spawnLava=False
underFill=False
randomRotation=True
dig=True
tree=True
branch=False
needsFoundation=True
rarity=100
collisionPercentage=20
spawnElevationMin=0
spawnElevationMax=200
spawnInBiome=Custom
[DATA]
0,-3,0:191.0
1,-3,0:191.0
0,-2,0:17.13
2,-2,0:17.13
-1,-1,0:191.0
2,-1,0:191.0
3,-1,0:191.0
-1,0,0:17.13
0,-2,1:17.13
2,-2,1:17.13
2,-1,1:17.13
0,0,1:17.13
1,-1,2:17.13
1,-1,3:17.13
1,-1,4:17.13
1,-1,5:17.13
1,0,5:17.9
1,-1,6:17.13
1,-1,7:17.13
1,-1,8:17.13
-3,3,8:18.15
-2,3,8:18.12
-3,-6,9:18.4
-1,-6,9:18.7
-2,-5,9:18.7
-4,-4,9:18.7
-3,-4,9:18.12
-3,-3,9:18.15
-2,-3,9:18.12
-5,-2,9:18.4
-4,-2,9:18.4
-2,-2,9:18.12
-6,-1,9:18.4
1,-1,9:17.13
-4,2,9:18.7
-2,2,9:18.15
-5,3,9:18.7
-3,3,9:18.15
-2,3,9:18.12
-1,3,9:18.15
-3,-7,10:18.4
-2,-7,10:18.4
-1,-6,10:18.4
-4,-4,10:18.7
0,-3,10:17.13
-6,-2,10:18.7
0,-2,10:17.13
1,-1,10:17.13
6,-1,10:18.4
-7,0,10:18.4
-4,0,10:18.4
5,0,10:18.4
2,1,10:18.7
-1,2,10:191.0
3,2,10:18.4
-4,3,10:18.4
-1,3,10:18.4
0,3,10:18.4
2,3,10:18.4
-2,4,10:18.7
-1,4,10:18.7
-1,5,10:18.7
-1,6,10:18.4
-2,-7,11:18.7
0,-7,11:18.7
-1,-6,11:18.4
-3,-5,11:18.4
-2,-5,11:17.13
3,-5,11:18.4
-4,-4,11:18.7
-2,-4,11:18.7
-1,-4,11:17.13
5,-4,11:18.7
-6,-3,11:18.4
-4,-3,11:18.7
-3,-3,11:18.7
-2,-3,11:18.7
-6,-2,11:18.4
-4,-2,11:18.4
-5,-1,11:18.7
0,-1,11:17.13
1,-1,11:17.13
-3,0,11:18.7
-2,0,11:18.7
2,0,11:17.13
7,0,11:18.4
-6,1,11:18.4
-4,1,11:18.7
-3,1,11:191.0
-1,1,11:18.7
1,1,11:18.4
6,1,11:18.7
-7,2,11:18.7
-3,2,11:18.4
-2,2,11:18.7
-1,2,11:18.7
0,2,11:18.7
2,2,11:191.0
4,2,11:18.4
6,2,11:18.4
-5,3,11:18.7
-2,3,11:18.4
5,3,11:18.4
-4,4,11:18.4
-3,4,11:18.7
-1,4,11:18.7
-1,5,11:18.4
0,5,11:18.7
2,5,11:18.7
-1,6,11:18.7
0,6,11:18.7
1,6,11:18.4
-1,-9,12:18.7
0,-9,12:18.4
1,-9,12:18.7
2,-8,12:18.7
-2,-7,12:18.4
3,-7,12:18.4
4,-7,12:18.4
-4,-6,12:18.7
-3,-6,12:18.4
-2,-6,12:18.7
2,-6,12:18.4
-2,-5,12:18.4
2,-5,12:18.4
3,-5,12:18.4
-5,-4,12:18.4
2,-4,12:18.7
3,-4,12:18.4
2,-3,12:17.13
3,-3,12:18.7
4,-3,12:18.4
-7,-2,12:18.4
-4,-2,12:17.13
-3,-2,12:17.13
2,-2,12:17.13
6,-2,12:18.4
-2,-1,12:17.13
-1,-1,12:17.13
1,-1,12:17.13
7,-1,12:18.4
-3,0,12:191.0
-2,0,12:17.13
5,0,12:18.4
7,0,12:18.4
8,0,12:18.4
-3,1,12:18.4
-2,1,12:18.4
3,1,12:17.13
4,2,12:18.7
-6,3,12:18.4
-5,3,12:18.4
4,3,12:18.7
-3,4,12:18.7
1,4,12:18.7
4,4,12:18.4
5,4,12:18.4
1,5,12:191.0
2,5,12:18.4
-3,7,12:18.4
-2,7,12:18.7
-1,-9,13:18.7
1,-9,13:18.4
-3,-8,13:18.7
-2,-8,13:18.7
-1,-8,13:18.4
0,-8,13:18.7
1,-8,13:18.4
-4,-7,13:18.7
-3,-7,13:18.4
-1,-7,13:18.7
3,-7,13:18.4
4,-7,13:18.4
-4,-6,13:18.7
-1,-6,13:18.7
-4,-5,13:18.4
-3,-5,13:18.7
4,-5,13:17.13
5,-5,13:18.4
6,-5,13:18.4
-6,-4,13:18.7
3,-4,13:17.13
5,-4,13:18.7
8,-3,13:18.4
-7,-2,13:18.4
-6,-2,13:17.13
-5,-2,13:17.13
6,-2,13:18.7
1,-1,13:17.13
6,-1,13:18.7
-7,0,13:18.4
9,0,13:18.4
-2,1,13:17.13
-7,2,13:18.4
-3,2,13:17.13
0,2,13:191.0
3,2,13:17.13
4,2,13:17.13
5,2,13:18.4
7,2,13:18.4
-4,3,13:18.7
3,3,13:17.13
-5,4,13:18.7
-3,4,13:18.4
5,4,13:18.4
0,5,13:18.4
-4,6,13:18.4
-3,6,13:18.7
1,6,13:18.4
3,6,13:18.4
4,6,13:18.7
-4,7,13:18.4
-2,7,13:18.7
-3,8,13:18.4
-1,8,13:18.7
-2,-8,14:18.7
-1,-8,14:18.4
0,-8,14:18.4
3,-8,14:18.4
4,-8,14:18.7
-1,-7,14:18.4
0,-7,14:18.4
1,-7,14:18.7
2,-7,14:18.4
-4,-6,14:18.4
0,-6,14:18.7
1,-6,14:18.7
3,-6,14:18.4
-5,-5,14:18.4
-3,-5,14:18.4
1,-5,14:18.7
3,-5,14:18.7
4,-5,14:18.4
-6,-4,14:18.4
5,-4,14:18.4
7,-4,14:18.4
0,-3,14:18.4
1,-3,14:18.4
2,-3,14:191.0
5,-3,14:18.7
8,-3,14:18.4
-8,-2,14:18.4
-6,-2,14:18.7
-5,-2,14:18.4
0,-2,14:17.13
6,-2,14:18.4
7,-2,14:18.4
-7,-1,14:18.4
6,-1,14:18.7
7,-1,14:18.7
9,-1,14:18.7
-5,0,14:18.7
-2,0,14:191.0
0,0,14:191.0
1,0,14:17.13
7,0,14:18.4
8,0,14:18.4
-7,1,14:18.4
-6,1,14:18.7
-5,1,14:18.7
0,1,14:17.13
-1,2,14:18.4
5,2,14:18.7
6,2,14:18.4
8,2,14:18.4
-5,3,14:18.4
-3,3,14:17.13
-2,3,14:18.4
5,3,14:17.13
-4,4,14:17.13
-3,4,14:18.7
3,4,14:17.13
4,4,14:18.4
-3,5,14:18.7
0,5,14:191.0
2,5,14:18.7
3,5,14:18.4
6,5,14:18.7
-3,6,14:18.4
1,6,14:18.7
-3,7,14:17.13
-4,8,14:18.7
-1,-10,15:18.7
-1,-8,15:18.4
1,-8,15:18.4
1,-7,15:18.7
-6,-6,15:18.4
-5,-6,15:18.4
0,-6,15:18.4
5,-6,15:18.4
-7,-5,15:18.7
-6,-5,15:18.4
-5,-5,15:18.7
3,-5,15:18.7
7,-5,15:18.7
-8,-4,15:18.7
-7,-4,15:18.4
-6,-4,15:18.4
1,-4,15:18.7
5,-4,15:18.4
6,-4,15:18.7
7,-4,15:18.7
-9,-3,15:18.7
-8,-3,15:18.7
-6,-3,15:18.4
1,-3,15:18.7
5,-3,15:18.7
0,-2,15:17.13
1,-2,15:17.13
2,-2,15:18.7
8,-2,15:18.7
9,-2,15:18.7
-8,-1,15:18.7
-6,-1,15:18.4
7,-1,15:18.4
9,-1,15:18.7
-2,0,15:191.0
1,0,15:191.0
5,0,15:191.0
-7,1,15:18.7
6,1,15:18.7
7,1,15:18.4
9,1,15:18.4
-7,2,15:18.4
-6,2,15:18.7
-2,2,15:191.0
-1,2,15:18.7
0,2,15:17.13
5,2,15:18.4
6,2,15:18.4
7,2,15:18.4
-8,3,15:18.7
-1,3,15:17.13
0,3,15:191.0
7,3,15:18.7
8,3,15:18.7
-5,4,15:18.4
-4,4,15:18.7
-1,4,15:18.7
6,4,15:17.13
-2,5,15:17.13
1,5,15:18.4
2,5,15:17.13
4,5,15:18.7
7,5,15:18.7
-5,6,15:18.4
-4,6,15:18.4
-2,6,15:17.13
-1,6,15:18.7
2,6,15:17.13
-3,7,15:18.4
-1,7,15:18.7
0,7,15:18.7
1,7,15:18.4
-3,8,15:18.4
0,8,15:18.4
-1,-10,16:18.4
0,-10,16:18.7
-3,-9,16:18.4
-2,-9,16:18.4
1,-9,16:18.7
-3,-7,16:18.7
-2,-7,16:18.7
0,-7,16:18.4
1,-7,16:18.7
2,-7,16:18.7
3,-7,16:18.4
-5,-6,16:18.7
-4,-6,16:18.4
0,-6,16:18.4
-8,-5,16:18.7
-7,-5,16:18.4
1,-5,16:191.0
8,-5,16:18.4
-9,-4,16:18.7
-8,-4,16:18.4
-2,-4,16:17.13
-1,-4,16:18.4
1,-4,16:191.0
4,-4,16:18.4
7,-4,16:18.7
8,-4,16:18.7
-7,-3,16:18.7
-6,-3,16:18.7
-1,-3,16:17.13
8,-3,16:18.7
-7,-2,16:18.4
-5,-2,16:18.4
-1,-2,16:18.7
0,-2,16:17.13
2,-2,16:17.13
3,-2,16:17.13
-1,-1,16:17.13
7,-1,16:18.4
9,-1,16:18.7
-7,0,16:18.4
-6,0,16:18.4
-2,0,16:17.13
-1,0,16:18.4
1,0,16:18.7
-8,1,16:18.4
-5,1,16:18.7
-3,1,16:18.4
0,1,16:191.0
-6,2,16:18.4
-1,2,16:18.4
2,2,16:18.4
6,2,16:18.7
-7,3,16:17.13
-5,3,16:18.7
4,3,16:18.7
-5,4,16:18.4
-4,4,16:18.4
-2,4,16:18.7
-1,4,16:17.13
5,4,16:18.4
-6,5,16:18.7
-4,5,16:18.4
-2,5,16:18.4
2,5,16:18.4
4,5,16:18.4
5,5,16:18.7
-5,6,16:18.7
-3,6,16:18.4
0,6,16:18.4
1,6,16:18.4
-1,7,16:18.4
2,7,16:17.13
3,7,16:18.7
3,8,16:18.7
-2,-10,17:18.7
-1,-10,17:18.7
-2,-9,17:18.7
1,-9,17:18.4
2,-9,17:18.4
4,-9,17:18.4
5,-9,17:18.4
0,-8,17:18.4
3,-8,17:18.7
-5,-7,17:18.4
-3,-7,17:18.7
0,-7,17:18.4
2,-7,17:18.4
4,-7,17:18.4
-6,-6,17:18.7
-3,-6,17:17.13
7,-6,17:18.7
-2,-5,17:17.13
4,-5,17:18.7
6,-5,17:18.7
-3,-4,17:17.13
-2,-4,17:18.7
-8,-3,17:18.7
5,-3,17:17.13
8,-3,17:18.4
-1,-2,17:18.4
0,-2,17:17.13
3,-2,17:191.0
4,-2,17:17.13
7,-2,17:18.7
-3,-1,17:18.4
-1,-1,17:191.0
1,-1,17:17.13
4,-1,17:17.13
5,-1,17:17.13
6,-1,17:17.13
9,-1,17:18.7
-6,0,17:18.7
-5,0,17:18.4
-3,0,17:17.13
0,0,17:18.7
1,0,17:17.13
2,0,17:18.7
4,0,17:191.0
8,0,17:18.7
-7,1,17:18.7
-6,1,17:18.4
-4,1,17:17.13
3,1,17:18.7
5,1,17:18.4
-7,2,17:18.4
-5,2,17:17.13
-1,2,17:18.4
5,2,17:18.7
6,2,17:18.7
-8,3,17:18.7
-6,3,17:17.13
-5,3,17:18.7
-4,3,17:18.4
1,3,17:18.4
4,3,17:18.7
5,3,17:18.4
6,3,17:18.7
-8,4,17:18.4
-5,4,17:18.7
-2,4,17:18.4
-1,4,17:18.4
3,5,17:18.7
4,5,17:18.4
-3,6,17:18.4
-2,6,17:18.4
-1,6,17:18.4
1,6,17:18.7
2,6,17:18.4
3,6,17:18.7
-2,7,17:18.7
2,7,17:18.4
3,7,17:18.7
-1,8,17:18.4
0,8,17:18.4
4,-10,18:18.7
6,-10,18:18.7
-2,-9,18:18.7
2,-9,18:18.7
3,-9,18:18.7
4,-9,18:18.4
5,-9,18:17.13
6,-9,18:18.7
-4,-8,18:18.4
-1,-8,18:18.4
4,-8,18:17.13
5,-8,18:18.7
6,-8,18:18.4
-5,-7,18:18.7
-4,-7,18:17.13
-3,-7,18:18.4
2,-7,18:18.4
3,-7,18:18.4
4,-7,18:18.7
8,-6,18:18.4
-2,-5,18:18.4
-7,-4,18:18.7
-5,-4,18:17.13
-4,-4,18:17.13
1,-4,18:17.13
5,-4,18:18.4
7,-4,18:17.13
8,-4,18:18.4
-5,-3,18:18.4
-3,-3,18:18.4
-1,-3,18:18.4
1,-3,18:17.13
2,-3,18:18.7
6,-3,18:17.13
-2,-2,18:18.4
0,-2,18:17.13
4,-2,18:18.7
8,-2,18:18.7
-8,-1,18:18.7
-5,-1,18:17.13
-1,-1,18:18.7
0,-1,18:191.0
7,-1,18:17.13
8,-1,18:17.13
-4,0,18:17.13
-1,0,18:18.7
1,0,18:18.7
0,1,18:18.7
1,1,18:191.0
2,1,18:17.13
6,1,18:18.4
7,1,18:18.7
8,1,18:18.4
-2,2,18:18.4
3,2,18:18.4
7,2,18:18.7
-4,3,18:18.7
1,3,18:18.4
6,3,18:18.7
-7,4,18:18.7
-5,4,18:18.7
-1,4,18:191.0
4,4,18:18.7
7,4,18:18.7
-6,5,18:18.7
-4,5,18:18.7
-3,5,18:18.4
-2,5,18:18.7
2,5,18:18.7
6,5,18:18.4
-5,6,18:18.4
-4,6,18:18.4
-1,6,18:18.7
0,6,18:18.7
2,6,18:18.7
-3,7,18:18.4
-2,7,18:18.7
-1,7,18:18.4
0,7,18:18.4
-2,8,18:18.4
1,8,18:18.7
-3,-9,19:18.7
-2,-9,19:18.4
0,-9,19:18.7
1,-9,19:18.4
5,-9,19:18.7
-4,-8,19:18.4
-2,-8,19:18.7
0,-8,19:18.4
1,-8,19:18.7
3,-8,19:191.0
1,-7,19:18.7
2,-7,19:18.4
3,-7,19:17.13
4,-7,19:18.4
5,-7,19:18.7
6,-7,19:18.7
-5,-6,19:18.7
-2,-6,19:191.0
2,-6,19:17.13
7,-6,19:18.7
-7,-5,19:18.7
-2,-5,19:18.4
-1,-5,19:18.7
1,-5,19:18.4
2,-5,19:17.13
3,-5,19:17.13
4,-5,19:17.13
6,-5,19:18.4
7,-5,19:18.7
-7,-4,19:18.7
-6,-4,19:17.13
-3,-4,19:191.0
-2,-4,19:18.7
-8,-3,19:18.7
-7,-3,19:18.4
-3,-3,19:18.7
-1,-3,19:17.13
3,-3,19:18.4
-7,-2,19:17.13
-1,-2,19:18.7
0,-2,19:17.13
8,-2,19:18.4
-6,-1,19:17.13
-5,-1,19:18.4
-1,-1,19:191.0
-6,0,19:18.4
7,0,19:18.4
8,0,19:18.4
-8,1,19:18.7
-7,1,19:18.7
6,1,19:18.7
-6,2,19:18.7
2,2,19:17.13
3,2,19:18.4
7,2,19:18.7
8,2,19:18.4
-6,3,19:18.4
-5,3,19:18.4
-1,3,19:18.7
0,3,19:18.7
2,3,19:18.7
3,3,19:17.13
5,3,19:18.4
8,3,19:18.7
-6,4,19:18.4
-5,4,19:18.4
0,4,19:191.0
2,4,19:18.4
-5,5,19:18.4
-3,5,19:18.7
1,5,19:18.7
-2,6,19:18.4
-2,7,19:18.7
0,7,19:18.4
-2,8,19:18.4
-1,8,19:18.4
-1,-9,20:18.7
2,-9,20:18.4
3,-9,20:18.4
4,-9,20:18.4
-2,-8,20:18.7
3,-8,20:18.7
4,-8,20:18.7
0,-7,20:18.4
3,-7,20:18.4
4,-7,20:18.4
7,-7,20:18.4
-4,-6,20:18.7
2,-6,20:18.7
6,-6,20:191.0
-5,-5,20:18.4
5,-5,20:17.13
6,-5,20:17.13
7,-5,20:17.13
8,-5,20:18.7
-2,-4,20:18.7
4,-4,20:18.4
-7,-3,20:18.7
-6,-3,20:18.4
-2,-3,20:17.13
-4,-2,20:18.7
-3,-2,20:18.4
-1,-2,20:18.4
0,-2,20:17.13
1,-2,20:17.13
3,-2,20:18.7
9,-2,20:18.7
-5,-1,20:18.7
1,-1,20:18.7
2,-1,20:191.0
7,-1,20:18.4
8,-1,20:18.4
-4,0,20:18.7
0,0,20:18.4
8,0,20:18.4
-7,1,20:18.7
-6,1,20:18.7
7,1,20:18.7
-8,2,20:18.7
5,2,20:18.4
6,2,20:18.4
8,2,20:18.4
1,3,20:17.13
2,3,20:18.4
4,3,20:18.7
6,3,20:18.4
-6,4,20:18.4
-3,4,20:18.4
3,4,20:17.13
4,4,20:18.4
-3,5,20:18.7
5,5,20:18.7
-5,6,20:18.7
-2,6,20:18.4
-1,6,20:18.4
1,6,20:18.7
2,6,20:18.7
3,6,20:18.7
-4,7,20:18.4
-1,7,20:18.7
1,8,20:18.4
0,-9,21:18.7
1,-9,21:18.7
3,-9,21:18.4
-2,-8,21:18.4
-1,-8,21:18.7
2,-8,21:18.4
3,-8,21:18.7
5,-6,21:18.7
7,-6,21:18.7
-5,-5,21:18.7
-2,-5,21:191.0
0,-5,21:18.7
5,-5,21:18.7
-3,-4,21:17.13
0,-4,21:191.0
3,-4,21:18.4
6,-4,21:18.4
7,-4,21:18.4
8,-4,21:18.4
-7,-3,21:18.4
-6,-3,21:18.4
-1,-3,21:191.0
0,-3,21:18.4
3,-3,21:18.4
8,-3,21:18.7
9,-3,21:18.4
-5,-2,21:18.4
-3,-2,21:191.0
-1,-2,21:191.0
0,-2,21:17.13
3,-2,21:18.7
4,-2,21:18.7
9,-2,21:18.7
-6,-1,21:18.4
2,-1,21:17.13
7,-1,21:18.7
-8,0,21:18.7
-7,0,21:18.7
-5,0,21:18.7
-3,0,21:18.4
-2,0,21:191.0
-1,0,21:191.0
3,0,21:18.7
7,0,21:18.4
8,0,21:18.4
-6,1,21:18.4
-4,1,21:18.4
-1,1,21:18.4
1,1,21:191.0
-6,2,21:18.7
-1,2,21:191.0
2,2,21:18.4
8,2,21:18.7
-6,3,21:18.7
-5,3,21:18.4
1,3,21:18.4
3,3,21:18.7
6,3,21:18.4
7,3,21:18.7
-7,4,21:18.4
-3,4,21:18.4
-2,4,21:18.7
1,4,21:17.13
4,4,21:18.7
6,4,21:18.4
-4,5,21:18.7
-3,5,21:18.7
4,5,21:18.7
-5,6,21:18.4
-2,6,21:18.7
-1,6,21:18.7
0,6,21:18.4
3,6,21:18.4
-1,8,21:18.7
0,8,21:18.7
-2,-9,22:18.7
-1,-9,22:18.4
0,-9,22:18.7
3,-9,22:18.4
-3,-8,22:18.4
0,-8,22:18.7
5,-8,22:18.7
-4,-7,22:18.4
-2,-7,22:18.7
2,-7,22:18.7
7,-7,22:18.7
3,-6,22:18.7
5,-6,22:18.4
6,-6,22:18.7
8,-6,22:18.7
-4,-5,22:17.13
-3,-5,22:191.0
-2,-5,22:191.0
6,-5,22:18.7
7,-5,22:18.4
9,-5,22:18.4
-5,-4,22:18.4
2,-4,22:18.4
4,-4,22:18.7
6,-4,22:18.4
9,-4,22:18.4
-4,-3,22:18.7
1,-3,22:18.7
5,-3,22:18.4
7,-3,22:18.7
8,-3,22:18.7
9,-3,22:18.7
10,-3,22:18.7
-7,-2,22:18.4
-2,-2,22:18.7
0,-2,22:17.13
7,-2,22:18.7
9,-2,22:18.7
10,-2,22:18.4
-5,-1,22:18.7
-3,-1,22:18.7
3,-1,22:17.13
9,-1,22:18.7
-7,0,22:18.7
-5,0,22:18.7
-4,0,22:18.7
-2,0,22:18.7
6,0,22:18.4
7,0,22:18.4
8,0,22:18.7
9,0,22:18.4
-7,1,22:18.7
-1,1,22:18.7
2,1,22:18.4
6,1,22:18.4
8,1,22:18.7
-7,2,22:18.4
-6,2,22:18.4
0,2,22:191.0
3,2,22:18.4
6,2,22:18.7
3,4,22:18.4
4,4,22:18.7
6,4,22:18.7
-1,5,22:18.4
0,5,22:17.13
4,5,22:18.7
-5,6,22:18.4
-4,6,22:18.7
1,6,22:18.4
4,6,22:18.7
0,7,22:18.4
1,7,22:18.7
-1,8,22:18.7
0,8,22:18.4
-1,-8,23:18.7
0,-8,23:18.7
2,-8,23:18.7
4,-8,23:18.4
-1,-7,23:18.7
1,-7,23:18.7
2,-7,23:18.7
-2,-6,23:18.7
3,-6,23:18.4
7,-6,23:18.4
9,-6,23:18.4
-5,-5,23:17.13
-4,-5,23:17.13
-3,-5,23:18.7
8,-5,23:18.7
-1,-4,23:18.4
3,-4,23:18.7
-6,-3,23:18.7
-1,-3,23:191.0
6,-3,23:191.0
9,-3,23:18.7
-2,-2,23:18.7
0,-2,23:17.13
3,-2,23:191.0
5,-2,23:191.0
-7,-1,23:18.7
-2,-1,23:17.13
-1,-1,23:17.13
3,-1,23:17.13
8,-1,23:18.4
-5,0,23:18.4
4,0,23:18.4
5,0,23:18.4
6,0,23:18.7
7,0,23:18.4
-8,1,23:18.7
-6,1,23:18.7
-2,1,23:191.0
-1,1,23:191.0
3,1,23:18.4
4,1,23:18.7
-6,2,23:18.7
-5,2,23:18.7
1,2,23:18.7
5,2,23:18.7
6,2,23:18.7
8,2,23:18.7
-7,3,23:18.7
-6,3,23:18.4
-4,3,23:18.7
-2,3,23:18.7
3,3,23:18.7
6,3,23:18.4
-5,4,23:18.7
-4,4,23:18.7
6,4,23:18.7
-6,5,23:18.4
-5,5,23:18.4
-4,5,23:18.4
-1,5,23:18.4
4,5,23:18.4
5,5,23:18.4
-5,6,23:18.4
-1,6,23:17.13
4,6,23:18.4
-1,7,23:18.4
1,7,23:18.7
-2,8,23:18.7
-1,8,23:18.7
0,8,23:18.7
0,-10,24:18.7
-4,-8,24:18.7
-2,-8,24:18.7
3,-8,24:18.7
5,-8,24:18.7
0,-7,24:18.7
1,-7,24:18.4
3,-7,24:18.7
-7,-6,24:18.7
-4,-6,24:17.13
3,-6,24:18.7
4,-6,24:18.4
7,-6,24:18.7
8,-6,24:18.7
-5,-5,24:17.13
-3,-5,24:18.4
6,-5,24:18.7
-5,-4,24:18.4
1,-4,24:191.0
2,-4,24:18.4
4,-4,24:18.4
0,-2,24:17.13
2,-2,24:191.0
5,-2,24:191.0
7,-2,24:18.7
-7,-1,24:18.7
-1,-1,24:18.7
4,-1,24:17.13
7,-1,24:18.7
8,-1,24:18.7
9,-1,24:18.7
-9,0,24:18.7
-3,0,24:17.13
1,0,24:18.4
4,0,24:18.4
5,0,24:18.4
8,0,24:18.7
-9,1,24:18.4
-8,1,24:17.13
-7,1,24:17.13
-6,1,24:18.4
-2,1,24:18.7
5,1,24:18.4
6,1,24:18.7
7,1,24:18.7
-1,2,24:18.7
7,2,24:18.4
-7,3,24:18.7
5,3,24:18.4
6,3,24:18.4
-6,4,24:18.7
-5,4,24:18.4
1,4,24:18.4
2,4,24:18.4
-5,5,24:18.4
2,6,24:18.4
4,6,24:18.4
5,6,24:18.7
-1,7,24:18.4
0,7,24:18.7
-3,8,24:18.4
-2,8,24:18.4
-1,8,24:18.7
1,-10,25:18.4
-3,-9,25:18.7
2,-9,25:18.4
3,-9,25:18.4
-1,-8,25:18.4
1,-8,25:18.4
2,-8,25:18.4
5,-8,25:18.7
-5,-7,25:18.4
7,-7,25:18.7
-5,-6,25:18.4
-4,-6,25:18.7
-3,-6,25:17.13
5,-6,25:18.4
6,-6,25:18.4
-5,-5,25:18.7
-4,-5,25:18.7
-3,-5,25:18.7
7,-5,25:18.4
-6,-4,25:17.13
-5,-4,25:18.7
0,-3,25:17.13
1,-3,25:18.7
8,-3,25:18.7
-1,-2,25:18.7
7,-2,25:18.7
8,-2,25:18.7
-6,-1,25:18.7
0,-1,25:17.13
1,-1,25:191.0
-8,0,25:18.7
-6,0,25:18.4
-5,0,25:17.13
-4,0,25:17.13
3,0,25:18.4
5,0,25:17.13
7,0,25:18.7
-9,1,25:18.7
-8,1,25:18.4
-6,1,25:17.13
-5,1,25:18.7
3,1,25:191.0
5,1,25:18.4
-6,2,25:18.7
3,2,25:18.7
5,3,25:18.4
-5,4,25:18.7
-4,4,25:18.7
3,4,25:18.7
5,4,25:18.7
6,4,25:18.4
-5,5,25:18.7
-3,5,25:18.4
-2,5,25:18.7
3,5,25:18.7
-4,6,25:18.7
0,6,25:18.4
1,6,25:18.7
2,6,25:18.7
-4,7,25:18.4
-3,8,25:18.7
-2,8,25:18.7
-1,-10,26:18.4
0,-10,26:18.4
-3,-9,26:18.7
0,-9,26:18.7
2,-9,26:18.7
-1,-8,26:18.4
0,-8,26:18.4
2,-8,26:18.7
3,-8,26:18.4
4,-8,26:18.4
5,-8,26:18.4
-3,-7,26:17.13
4,-7,26:18.7
6,-7,26:18.7
7,-7,26:18.7
-2,-6,26:18.4
0,-6,26:18.4
5,-6,26:17.13
6,-6,26:18.4
-7,-5,26:18.7
-5,-5,26:18.7
-4,-5,26:18.4
-7,-4,26:18.4
-6,-4,26:17.13
-2,-4,26:191.0
-1,-4,26:191.0
1,-4,26:17.13
2,-4,26:17.13
-8,-3,26:18.7
-6,-3,26:18.4
-3,-3,26:191.0
-1,-3,26:17.13
1,-2,26:18.4
0,-1,26:17.13
-3,0,26:191.0
-2,0,26:191.0
-1,0,26:191.0
0,0,26:18.4
2,0,26:18.7
6,0,26:17.13
9,0,26:18.7
-7,1,26:18.7
-5,1,26:18.4
-1,1,26:18.4
1,1,26:191.0
2,1,26:18.4
7,1,26:18.4
-5,2,26:18.4
-4,2,26:18.4
3,2,26:18.7
-3,3,26:18.7
4,3,26:18.4
6,3,26:18.7
-5,4,26:18.7
-3,4,26:18.4
3,4,26:18.7
4,4,26:18.7
-4,5,26:18.7
1,5,26:18.7
2,5,26:18.4
4,5,26:18.7
0,6,26:18.4
-2,7,26:18.4
-1,7,26:18.7
-1,8,26:18.7
1,-9,27:18.4
2,-9,27:18.7
3,-9,27:18.7
-3,-8,27:18.7
3,-8,27:18.4
5,-8,27:18.4
-3,-7,27:17.13
-2,-7,27:18.7
-1,-7,27:18.4
1,-7,27:18.4
0,-6,27:18.7
2,-6,27:17.13
6,-6,27:18.4
-4,-5,27:18.4
-3,-5,27:18.7
0,-5,27:18.7
1,-5,27:17.13
3,-5,27:17.13
4,-5,27:17.13
7,-5,27:18.7
8,-5,27:18.7
-7,-4,27:17.13
-4,-4,27:18.7
1,-4,27:18.7
5,-4,27:191.0
6,-4,27:18.7
-4,-3,27:191.0
-3,-3,27:18.4
-1,-3,27:17.13
0,-3,27:18.4
7,-3,27:18.4
-6,-2,27:18.7
-3,-2,27:18.4
-1,-2,27:191.0
4,-2,27:18.7
6,-2,27:18.7
7,-2,27:18.4
9,-2,27:18.4
-7,-1,27:18.7
-6,-1,27:18.4
0,-1,27:17.13
2,-1,27:191.0
-7,0,27:18.4
1,0,27:18.7
5,0,27:18.4
6,0,27:18.4
7,0,27:18.7
-7,1,27:18.4
-6,1,27:18.7
-5,1,27:18.7
1,1,27:18.4
3,1,27:191.0
6,1,27:18.7
-7,2,27:18.7
4,2,27:18.7
5,2,27:18.7
-4,3,27:18.7
-2,3,27:18.7
1,3,27:18.7
-4,5,27:18.7
-3,5,27:18.7
-1,5,27:18.4
3,5,27:18.4
-3,6,27:18.7
-1,6,27:18.4
1,6,27:18.7
-3,7,27:18.7
-4,-9,28:18.7
-3,-9,28:18.4
1,-9,28:18.7
3,-9,28:18.4
4,-9,28:18.7
-3,-8,28:17.13
2,-8,28:17.13
4,-8,28:18.4
-3,-7,28:18.4
2,-7,28:17.13
-1,-6,28:18.7
5,-6,28:18.7
6,-6,28:18.7
-6,-5,28:18.4
0,-5,28:191.0
6,-5,28:18.7
-8,-4,28:18.4
-6,-4,28:18.4
-5,-4,28:18.4
-1,-4,28:17.13
0,-4,28:191.0
7,-4,28:18.7
8,-4,28:18.7
9,-4,28:18.4
-6,-3,28:18.4
-4,-3,28:191.0
0,-3,28:18.4
4,-3,28:191.0
6,-3,28:18.4
8,-3,28:18.4
9,-3,28:18.7
-6,-2,28:18.7
5,-2,28:191.0
9,-2,28:18.4
-6,-1,28:18.7
-4,-1,28:18.7
-3,-1,28:18.7
0,-1,28:17.13
7,-1,28:18.4
-6,0,28:18.4
-1,0,28:18.7
7,0,28:18.7
-6,1,28:18.4
-4,1,28:18.4
-1,1,28:18.4
2,1,28:18.7
5,1,28:18.7
-5,2,28:18.7
2,3,28:18.4
4,3,28:18.7
5,3,28:18.7
7,3,28:18.4
-4,4,28:18.7
-3,4,28:18.4
1,4,28:18.7
2,4,28:18.4
3,4,28:18.4
4,4,28:18.7
-4,5,28:18.7
-3,5,28:18.7
2,5,28:18.4
3,5,28:18.4
-2,6,28:18.4
-1,-10,29:18.7
-3,-9,29:18.7
-1,-9,29:18.7
3,-9,29:18.4
4,-9,29:18.4
-4,-8,29:18.4
0,-8,29:18.7
2,-8,29:18.4
4,-8,29:18.7
5,-8,29:18.7
6,-8,29:18.4
-4,-7,29:18.4
-3,-7,29:18.7
0,-7,29:18.4
3,-7,29:18.7
4,-7,29:18.7
5,-7,29:18.4
6,-6,29:18.4
2,-5,29:191.0
4,-5,29:18.7
7,-5,29:18.4
-2,-4,29:18.4
-1,-4,29:17.13
5,-4,29:18.7
1,-3,29:191.0
2,-3,29:18.7
5,-3,29:191.0
-4,-2,29:18.4
0,-2,29:191.0
5,-2,29:18.7
6,-2,29:18.7
-2,-1,29:18.7
-1,-1,29:191.0
7,-1,29:18.7
-6,0,29:18.7
-1,0,29:18.7
1,0,29:17.13
6,0,29:18.7
8,0,29:18.7
-7,1,29:18.7
-4,1,29:18.7
3,1,29:18.4
6,1,29:18.7
7,1,29:18.7
-6,2,29:18.7
-5,2,29:18.7
1,2,29:191.0
5,2,29:18.4
-6,3,29:18.4
7,3,29:18.4
-4,4,29:18.7
5,4,29:18.4
-4,5,29:18.4
-1,5,29:18.4
2,5,29:18.7
4,5,29:18.4
-3,6,29:18.4
-2,6,29:18.4
-3,7,29:18.7
-2,7,29:18.4
-1,-10,30:18.7
-3,-9,30:18.7
0,-9,30:18.4
2,-9,30:18.7
3,-9,30:18.4
4,-9,30:18.7
-3,-8,30:18.7
0,-8,30:18.7
5,-8,30:18.4
-4,-7,30:18.4
0,-7,30:18.4
5,-7,30:18.7
-5,-6,30:18.7
-3,-6,30:18.4
5,-6,30:18.7
-5,-5,30:18.7
-4,-5,30:18.7
-1,-5,30:17.13
2,-5,30:18.7
5,-5,30:18.4
6,-5,30:18.4
-7,-4,30:18.4
-6,-4,30:18.7
-3,-4,30:18.4
0,-4,30:17.13
3,-4,30:18.7
-3,-3,30:18.7
-6,-2,30:18.4
0,-1,30:18.4
3,-1,30:18.4
7,-1,30:18.4
-8,0,30:18.7
-7,0,30:18.7
-6,0,30:18.4
-1,0,30:18.4
1,0,30:17.13
3,0,30:18.7
4,0,30:18.4
5,0,30:18.4
7,0,30:18.7
-7,1,30:18.7
-2,1,30:18.7
1,1,30:18.4
2,1,30:18.4
6,1,30:18.4
5,2,30:18.4
6,2,30:18.7
-5,3,30:18.4
4,3,30:18.4
5,3,30:18.4
-4,4,30:18.4
-3,4,30:18.4
2,4,30:18.7
3,4,30:18.7
5,4,30:18.4
-3,5,30:18.4
4,5,30:18.4
-1,-9,31:18.7
1,-9,31:18.4
2,-9,31:18.4
-3,-8,31:18.7
1,-8,31:18.7
3,-8,31:18.7
-3,-7,31:18.4
-2,-7,31:18.7
-5,-6,31:18.7
-4,-6,31:18.4
-1,-6,31:18.7
-1,-5,31:17.13
0,-5,31:17.13
1,-5,31:18.4
4,-5,31:18.4
5,-5,31:18.4
-6,-4,31:18.7
-4,-4,31:18.7
4,-4,31:18.7
7,-3,31:18.4
8,-3,31:18.4
-5,-2,31:18.7
7,-2,31:18.4
-8,-1,31:18.7
-7,-1,31:18.4
-4,-1,31:191.0
-3,-1,31:18.7
-2,-1,31:191.0
0,-1,31:18.4
2,-1,31:18.4
1,0,31:17.13
5,0,31:18.7
6,0,31:18.7
7,0,31:18.7
-5,1,31:18.7
0,1,31:18.7
-3,2,31:18.7
2,2,31:18.7
6,2,31:18.4
-5,3,31:18.4
-3,3,31:18.4
3,3,31:18.4
0,4,31:18.4
1,4,31:18.7
2,4,31:18.7
-2,5,31:18.4
-1,6,31:18.7
1,6,31:18.4
-1,7,31:18.4
0,7,31:18.7
2,-10,32:18.4
-2,-9,32:18.7
-1,-9,32:18.7
-1,-8,32:18.4
4,-8,32:18.4
6,-8,32:18.7
2,-7,32:18.4
6,-7,32:18.7
-2,-6,32:18.4
-1,-6,32:18.7
2,-6,32:18.7
3,-6,32:18.7
5,-6,32:18.7
6,-6,32:18.7
-4,-5,32:18.4
-2,-5,32:17.13
1,-5,32:17.13
5,-5,32:18.7
6,-5,32:18.4
2,-4,32:191.0
3,-4,32:191.0
6,-4,32:18.7
-4,-3,32:18.4
2,-3,32:18.4
6,-3,32:18.7
7,-3,32:18.7
1,-2,32:18.7
5,-2,32:18.7
6,-2,32:18.7
8,-2,32:18.7
-7,-1,32:18.7
-2,-1,32:18.4
1,-1,32:191.0
5,-1,32:18.4
8,-1,32:18.4
-8,0,32:18.4
-7,0,32:18.7
-1,0,32:18.4
1,0,32:17.13
2,0,32:191.0
7,0,32:18.4
9,0,32:18.7
-5,1,32:18.4
-4,1,32:18.4
-3,1,32:18.7
-2,1,32:18.7
4,1,32:18.4
7,1,32:18.4
8,1,32:18.4
-5,2,32:18.4
-2,2,32:18.7
-1,2,32:18.4
0,2,32:18.7
6,2,32:18.4
-4,3,32:18.7
6,3,32:18.7
-4,5,32:18.4
-3,5,32:18.7
-1,5,32:18.4
0,6,32:18.7
2,-10,33:18.7
-1,-9,33:18.7
1,-9,33:18.4
-1,-8,33:18.4
0,-8,33:18.7
-2,-7,33:18.4
2,-7,33:18.4
4,-7,33:18.7
6,-7,33:18.7
-2,-6,33:17.13
-1,-6,33:18.4
1,-6,33:17.13
2,-6,33:18.7
-4,-5,33:18.7
1,-5,33:18.4
-5,-4,33:18.7
-3,-4,33:18.4
3,-4,33:18.7
4,-4,33:18.7
7,-4,33:18.4
-2,-3,33:18.7
-5,-2,33:18.7
-4,-2,33:18.4
1,-2,33:18.4
3,-2,33:18.7
5,-2,33:18.4
7,-2,33:18.7
6,-1,33:18.4
7,-1,33:18.7
-3,0,33:18.4
6,0,33:18.7
-3,1,33:18.7
0,1,33:18.7
1,1,33:17.13
2,1,33:18.4
4,1,33:18.7
5,1,33:18.7
7,1,33:18.7
8,1,33:18.4
-1,2,33:18.7
0,2,33:18.7
3,2,33:18.4
-1,3,33:18.4
3,3,33:18.4
-3,5,33:18.7
0,-7,34:18.7
5,-7,34:18.4
-2,-6,34:17.13
-1,-6,34:18.7
2,-6,34:17.13
5,-6,34:18.7
-2,-5,34:18.4
0,-5,34:18.7
5,-4,34:18.4
6,-4,34:18.7
-3,-3,34:18.4
6,-3,34:18.7
-2,-2,34:18.4
-1,-2,34:18.4
1,-2,34:18.4
6,-2,34:18.4
-1,-1,34:18.7
3,-1,34:18.7
4,-1,34:18.7
5,-1,34:18.4
0,0,34:18.7
4,0,34:18.4
7,0,34:18.4
0,1,34:18.4
1,1,34:18.7
2,1,34:18.4
4,1,34:18.4
-1,3,34:18.7
2,-7,35:18.4
5,-6,35:18.4
-2,-5,35:18.4
1,-5,35:18.4
5,-5,35:18.4
0,-4,35:18.4
5,-4,35:18.4
-1,-3,35:18.4
1,-3,35:18.4
3,-3,35:18.7
4,-3,35:18.4
5,-3,35:18.4
6,-3,35:18.7
-1,-2,35:18.4
0,-2,35:18.7
4,-2,35:18.7
-3,-1,35:18.4
2,-1,35:18.4
4,-1,35:18.7
-1,0,35:18.4
0,0,35:18.7
1,0,35:18.7
2,0,35:18.7
5,0,35:18.4
3,-3,36:18.7
5,-3,36:18.4
0,-2,36:18.4
5,-2,36:18.4
7,-2,36:18.7
6,-1,36:18.4
