[META]
version=2.0
spawnOnBlockType=2
spawnSunlight=True
spawnDarkness=True
spawnWater=False
spawnLava=False
underFill=False
randomRotation=True
dig=True
tree=True
branch=False
needsFoundation=True
rarity=100
collisionPercentage=20
spawnElevationMin=0
spawnElevationMax=200
spawnInBiome=Custom
[DATA]
-1,-2,0:17.13
-3,-1,0:17.13
-1,1,0:17.13
-1,-2,1:17.13
-2,0,1:17.13
-1,0,1:17.13
-1,-1,2:17.13
-1,-1,3:17.13
-1,-1,4:17.13
0,-1,4:18.4
3,0,4:18.4
1,1,4:18.7
2,1,4:18.4
4,1,4:18.4
1,2,4:18.7
3,2,4:18.4
4,-4,5:18.7
3,-3,5:18.4
5,-3,5:18.7
-1,-2,5:191.0
-1,-1,5:17.13
2,-1,5:18.4
3,-1,5:18.4
-3,0,5:18.4
-2,0,5:18.7
0,0,5:191.0
3,0,5:18.4
-4,1,5:18.7
-3,1,5:18.4
-2,1,5:18.7
-1,1,5:191.0
3,1,5:18.4
1,2,5:18.4
2,2,5:18.4
0,3,5:18.4
2,3,5:18.4
0,-6,6:18.4
1,-6,6:18.4
2,-6,6:18.4
2,-5,6:18.4
4,-5,6:18.4
3,-4,6:18.4
4,-4,6:18.7
-5,-3,6:18.7
3,-3,6:18.7
4,-3,6:18.4
5,-3,6:18.4
-6,-2,6:18.7
-1,-2,6:17.13
4,-2,6:18.4
-5,-1,6:18.4
-4,-1,6:18.4
-1,-1,6:17.13
0,-1,6:17.13
5,-1,6:18.4
-4,0,6:18.4
-3,0,6:18.7
-2,0,6:18.4
3,0,6:18.4
4,0,6:18.4
5,0,6:18.4
6,0,6:18.4
-3,1,6:18.4
2,1,6:18.4
-4,2,6:18.7
-3,2,6:18.7
0,2,6:18.4
1,2,6:18.7
-2,3,6:18.4
-1,3,6:18.4
0,3,6:18.4
2,3,6:18.7
3,3,6:18.7
1,-7,7:18.7
2,-7,7:18.4
2,-6,7:18.4
4,-6,7:18.4
-3,-5,7:18.4
-2,-5,7:18.7
0,-5,7:18.7
1,-5,7:18.7
2,-5,7:18.7
4,-5,7:18.7
-2,-4,7:18.4
3,-4,7:18.4
-5,-3,7:18.4
-4,-3,7:18.7
-1,-3,7:18.7
0,-3,7:17.13
3,-3,7:18.4
6,-3,7:18.4
-6,-2,7:18.4
-1,-2,7:17.13
3,-2,7:18.4
-6,-1,7:18.7
-5,-1,7:18.4
-4,-1,7:18.7
0,-1,7:18.4
1,-1,7:17.13
2,-1,7:17.13
3,-1,7:18.4
4,-1,7:18.7
6,-1,7:18.4
-4,0,7:18.7
-2,0,7:17.13
1,0,7:18.7
4,0,7:18.4
-4,1,7:18.7
-4,2,7:18.4
-2,2,7:18.4
1,2,7:18.4
3,2,7:18.4
4,2,7:18.4
-2,3,7:18.7
-1,3,7:18.7
0,3,7:18.4
2,4,7:18.7
-1,-7,8:18.4
1,-7,8:18.7
-4,-6,8:18.4
0,-6,8:18.7
1,-6,8:17.13
2,-6,8:18.4
4,-6,8:18.4
-3,-5,8:18.4
1,-5,8:17.13
3,-5,8:18.4
-5,-4,8:18.4
-4,-4,8:18.4
0,-4,8:17.13
3,-4,8:18.7
4,-4,8:18.7
5,-4,8:18.4
6,-4,8:18.7
-6,-3,8:18.4
-2,-3,8:18.4
3,-3,8:18.7
4,-3,8:18.4
5,-3,8:18.4
-6,-2,8:18.7
-5,-2,8:18.7
-2,-2,8:17.13
-1,-2,8:17.13
6,-2,8:18.4
-6,-1,8:18.7
-1,-1,8:18.4
2,-1,8:191.0
3,-1,8:17.13
6,-1,8:18.4
-5,0,8:18.4
-2,0,8:17.13
2,0,8:18.4
3,0,8:18.4
4,0,8:18.7
5,0,8:18.4
-2,1,8:18.7
-1,1,8:18.4
0,1,8:18.4
2,1,8:18.4
4,1,8:18.7
-3,2,8:18.7
-2,2,8:18.4
0,2,8:18.7
1,2,8:18.4
2,2,8:18.7
3,2,8:18.4
-2,3,8:18.7
-1,3,8:18.7
1,3,8:18.7
0,-7,9:18.4
-5,-6,9:18.7
-4,-6,9:18.4
-1,-6,9:18.7
0,-6,9:18.4
1,-6,9:18.7
2,-6,9:18.4
4,-6,9:18.4
5,-6,9:18.4
-2,-5,9:18.7
-1,-5,9:18.7
2,-5,9:18.7
3,-5,9:18.7
4,-5,9:18.7
5,-5,9:18.4
-5,-4,9:18.7
-4,-4,9:18.7
-2,-4,9:18.7
3,-4,9:18.4
5,-4,9:18.4
-5,-3,9:18.4
-4,-3,9:18.4
6,-3,9:18.7
-4,-2,9:18.7
-3,-2,9:17.13
-1,-2,9:17.13
-5,-1,9:18.4
0,-1,9:18.4
3,-1,9:17.13
4,-1,9:18.7
5,-1,9:18.7
-6,0,9:18.4
-5,0,9:18.4
-1,0,9:191.0
3,0,9:191.0
6,0,9:18.4
-4,1,9:18.4
-3,1,9:17.13
4,1,9:18.4
5,1,9:18.4
-4,2,9:18.4
-3,2,9:18.7
-2,2,9:18.7
-1,2,9:18.7
0,2,9:18.7
3,2,9:18.4
4,2,9:18.4
5,2,9:18.4
-1,3,9:18.4
0,3,9:18.7
0,4,9:18.4
1,4,9:18.4
2,4,9:18.7
1,-7,10:18.7
2,-7,10:18.7
-4,-6,10:18.7
-1,-6,10:18.7
0,-6,10:18.7
2,-6,10:18.4
-4,-5,10:18.7
-1,-5,10:18.7
2,-5,10:18.7
3,-5,10:18.7
4,-5,10:18.7
6,-5,10:18.4
-4,-4,10:18.7
-3,-4,10:18.4
0,-4,10:18.7
1,-4,10:18.4
5,-4,10:18.4
6,-4,10:18.7
-6,-3,10:18.7
-5,-3,10:18.7
-4,-3,10:17.13
-1,-3,10:17.13
4,-3,10:18.4
-6,-2,10:18.7
-5,-2,10:18.7
-4,-2,10:18.4
-3,-2,10:191.0
0,-2,10:18.7
3,-2,10:17.13
4,-2,10:18.4
-6,-1,10:18.7
-5,-1,10:18.7
-3,-1,10:18.4
0,-1,10:17.13
3,-1,10:17.13
4,-1,10:18.4
5,-1,10:18.4
-6,0,10:18.4
-5,0,10:18.7
-3,0,10:18.7
3,0,10:18.7
5,0,10:18.4
7,0,10:18.4
-4,1,10:18.7
-3,1,10:17.13
1,1,10:18.4
3,1,10:18.4
4,1,10:18.4
5,1,10:18.4
-4,2,10:18.7
-3,2,10:18.7
-2,2,10:18.4
-1,2,10:18.7
1,2,10:18.7
2,2,10:18.4
3,2,10:18.4
4,2,10:18.7
0,3,10:18.4
1,3,10:18.7
2,3,10:18.7
4,3,10:18.7
-1,4,10:18.7
2,4,10:18.4
3,4,10:18.4
1,-7,11:18.4
2,-7,11:18.7
3,-7,11:18.4
-4,-6,11:18.7
0,-6,11:18.7
3,-6,11:18.7
4,-6,11:18.7
5,-6,11:18.4
-5,-5,11:18.4
-3,-5,11:18.4
2,-5,11:18.4
3,-5,11:18.4
4,-5,11:18.7
6,-5,11:18.4
-6,-4,11:18.4
-4,-4,11:18.7
-1,-4,11:18.4
2,-4,11:18.4
3,-4,11:18.4
4,-4,11:18.7
-5,-3,11:17.13
-1,-3,11:17.13
2,-3,11:191.0
4,-3,11:18.4
5,-3,11:18.7
-6,-2,11:18.4
-5,-2,11:18.7
-4,-2,11:18.7
-3,-2,11:18.7
1,-2,11:18.4
4,-2,11:17.13
-5,-1,11:18.4
-3,-1,11:18.4
-1,-1,11:191.0
0,-1,11:18.4
2,-1,11:18.4
3,-1,11:17.13
4,-1,11:18.4
5,-1,11:18.7
6,-1,11:18.4
7,-1,11:18.7
-5,0,11:18.7
-2,0,11:18.4
0,0,11:17.13
3,0,11:18.7
4,0,11:18.4
5,0,11:18.4
6,0,11:18.7
7,0,11:18.7
-2,1,11:18.7
3,1,11:18.7
4,1,11:18.4
7,1,11:18.4
-4,2,11:18.4
-1,2,11:18.4
1,2,11:18.7
3,2,11:18.4
2,3,11:18.4
0,-7,12:18.4
1,-7,12:18.4
1,-6,12:18.4
3,-6,12:18.7
5,-6,12:18.4
3,-5,12:18.7
5,-5,12:18.7
-5,-4,12:18.7
-3,-4,12:18.4
-2,-4,12:18.4
1,-4,12:18.4
2,-4,12:18.4
3,-4,12:18.4
5,-4,12:18.4
7,-4,12:18.4
-5,-3,12:18.4
-1,-3,12:17.13
0,-3,12:18.4
3,-3,12:18.7
4,-3,12:17.13
5,-3,12:18.4
-5,-2,12:18.7
-1,-2,12:18.7
0,-2,12:191.0
3,-2,12:18.4
4,-2,12:17.13
5,-2,12:18.4
6,-2,12:18.7
3,-1,12:18.7
-3,0,12:18.4
-1,0,12:191.0
0,0,12:18.4
1,0,12:17.13
4,0,12:17.13
5,0,12:18.7
-4,1,12:18.4
-1,1,12:18.7
0,1,12:18.4
5,1,12:18.4
6,1,12:18.7
-2,2,12:18.4
0,2,12:18.7
4,2,12:18.4
-1,3,12:18.7
0,3,12:18.7
1,3,12:18.4
0,-6,13:18.4
2,-6,13:18.7
4,-6,13:18.4
6,-6,13:18.7
2,-5,13:18.4
3,-5,13:18.4
4,-5,13:18.7
5,-5,13:18.4
6,-5,13:18.4
-2,-4,13:18.4
1,-4,13:18.7
2,-4,13:18.7
3,-4,13:18.4
4,-4,13:18.4
5,-4,13:18.7
-3,-3,13:18.7
-2,-3,13:18.7
-1,-3,13:18.7
1,-3,13:18.4
2,-3,13:18.4
3,-3,13:18.4
4,-3,13:17.13
-5,-2,13:18.7
-4,-2,13:18.7
-1,-2,13:18.7
2,-2,13:18.7
5,-2,13:18.7
-4,-1,13:18.7
-2,-1,13:18.7
4,-1,13:18.4
5,-1,13:18.4
-2,0,13:18.7
-1,0,13:18.7
0,0,13:18.4
1,0,13:18.7
4,0,13:17.13
5,0,13:18.7
0,1,13:18.4
1,1,13:17.13
3,1,13:18.4
4,1,13:18.4
5,1,13:18.7
-1,2,13:18.4
-1,3,13:18.7
2,-5,14:18.4
5,-5,14:18.7
6,-5,14:18.7
-1,-3,14:18.7
1,-3,14:18.7
2,-3,14:18.7
3,-3,14:18.7
5,-3,14:18.7
-2,-2,14:18.4
-1,-2,14:18.4
0,-2,14:18.7
3,-2,14:18.4
-2,-1,14:18.7
3,-1,14:18.7
5,-1,14:18.7
2,0,14:18.7
3,0,14:18.4
4,0,14:17.13
2,1,14:18.7
3,1,14:18.7
1,2,14:18.4
3,0,15:18.7
5,0,15:18.4
4,1,15:18.7
